ply
format ascii 1.0
comment : MagicaVoxel @ Ephtracy
element vertex 212
property float x
property float y
property float z
property uchar red
property uchar green
property uchar blue
end_header
5 1 20 255 102 0
5 2 20 255 102 0
2 1 20 255 102 0
5 4 22 204 255 51
5 3 22 204 255 51
6 3 22 204 255 51
2 1 22 204 255 51
5 1 28 204 255 51
6 1 27 204 255 51
4 1 28 204 255 51
5 1 27 238 238 238
6 1 26 204 255 51
3 1 28 204 255 51
4 1 27 204 255 51
1 1 24 204 255 51
6 1 25 204 255 51
2 1 28 204 255 51
3 1 27 204 255 51
4 1 26 204 255 51
5 1 25 204 255 51
6 1 24 204 255 51
1 1 23 204 255 51
3 1 22 204 255 51
3 1 26 204 255 51
4 1 25 204 255 51
5 1 24 204 255 51
6 1 23 204 255 51
1 1 27 204 255 51
2 1 23 204 255 51
3 1 25 204 255 51
4 1 24 204 255 51
5 1 23 204 255 51
1 1 26 204 255 51
2 1 25 204 255 51
3 1 24 204 255 51
4 1 23 204 255 51
5 1 22 204 255 51
1 1 25 204 255 51
2 1 24 204 255 51
3 1 23 204 255 51
4 1 22 204 255 51
5 1 26 0 0 17
2 1 26 0 0 17
2 1 27 238 238 238
3 0 25 255 102 0
4 0 25 255 102 0
1 2 23 204 255 51
1 2 24 204 255 51
1 2 25 204 255 51
1 2 26 204 255 51
1 2 27 204 255 51
1 2 28 204 255 51
1 2 22 204 255 51
2 2 22 204 255 51
3 2 22 204 255 51
4 2 22 204 255 51
5 2 22 204 255 51
6 2 22 204 255 51
2 2 23 204 255 51
3 2 23 204 255 51
4 2 23 204 255 51
5 2 23 204 255 51
6 2 23 204 255 51
2 2 24 204 255 51
3 2 24 204 255 51
4 2 24 204 255 51
5 2 24 204 255 51
6 2 24 204 255 51
2 2 25 204 255 51
3 2 25 204 255 51
4 2 25 204 255 51
5 2 25 204 255 51
6 2 25 204 255 51
2 2 26 204 255 51
3 2 26 204 255 51
4 2 26 204 255 51
5 2 26 204 255 51
6 2 26 204 255 51
2 2 27 204 255 51
3 2 27 204 255 51
4 2 27 204 255 51
5 2 27 204 255 51
6 2 27 204 255 51
2 2 28 204 255 51
3 2 28 204 255 51
4 2 28 204 255 51
5 2 28 204 255 51
6 2 28 204 255 51
1 3 28 204 255 51
5 3 25 204 255 51
2 2 21 255 102 0
2 3 28 204 255 51
2 4 28 204 255 51
5 2 21 255 102 0
1 3 27 204 255 51
1 4 27 204 255 51
6 4 23 204 255 51
3 3 28 204 255 51
3 4 28 204 255 51
6 3 23 204 255 51
2 3 27 204 255 51
2 4 27 204 255 51
4 4 22 204 255 51
1 3 26 204 255 51
1 4 26 204 255 51
4 3 22 204 255 51
4 3 28 204 255 51
4 4 28 204 255 51
5 4 23 204 255 51
3 3 27 204 255 51
3 4 27 204 255 51
5 3 23 204 255 51
2 3 26 204 255 51
2 4 26 204 255 51
6 4 24 204 255 51
1 3 25 204 255 51
1 4 25 204 255 51
6 3 24 204 255 51
5 3 28 204 255 51
5 4 28 204 255 51
3 4 22 204 255 51
4 3 27 204 255 51
4 4 27 204 255 51
3 3 22 204 255 51
3 3 26 204 255 51
3 4 26 204 255 51
4 4 23 204 255 51
2 3 25 204 255 51
2 4 25 204 255 51
4 3 23 204 255 51
1 3 24 204 255 51
1 4 24 204 255 51
5 4 24 204 255 51
6 3 28 204 255 51
6 4 26 204 255 51
2 2 20 255 102 0
5 3 27 204 255 51
5 4 27 204 255 51
5 3 24 204 255 51
4 3 26 204 255 51
4 4 26 204 255 51
6 4 25 204 255 51
3 3 25 204 255 51
3 4 25 204 255 51
6 3 25 204 255 51
2 3 24 204 255 51
6 3 26 204 255 51
2 4 22 204 255 51
1 3 23 204 255 51
1 4 23 204 255 51
2 3 22 204 255 51
6 3 27 204 255 51
6 4 27 204 255 51
3 4 23 204 255 51
5 3 26 204 255 51
5 4 26 204 255 51
3 3 23 204 255 51
4 3 25 204 255 51
4 4 25 204 255 51
4 4 24 204 255 51
3 3 24 204 255 51
3 4 24 204 255 51
4 3 24 204 255 51
2 3 23 204 255 51
2 4 23 204 255 51
5 4 25 204 255 51
1 3 22 204 255 51
2 4 24 204 255 51
2 5 24 204 255 51
3 5 24 204 255 51
4 5 24 204 255 51
5 5 24 204 255 51
6 5 24 204 255 51
1 5 24 204 255 51
1 5 23 204 255 51
2 5 23 204 255 51
3 5 23 204 255 51
4 5 23 204 255 51
5 5 23 204 255 51
6 5 23 204 255 51
5 5 22 204 255 51
4 5 22 204 255 51
3 5 22 204 255 51
2 5 22 204 255 51
5 6 24 204 255 51
4 6 24 204 255 51
3 6 24 204 255 51
2 6 24 204 255 51
1 6 23 204 255 51
2 6 23 204 255 51
3 6 23 204 255 51
4 6 23 204 255 51
5 6 23 204 255 51
6 6 23 204 255 51
5 6 22 204 255 51
4 6 22 204 255 51
3 6 22 204 255 51
2 6 22 204 255 51
0 5 23 204 255 51
0 4 24 204 255 51
0 4 23 204 255 51
0 3 23 204 255 51
0 3 24 204 255 51
0 2 24 204 255 51
0 2 23 204 255 51
7 5 23 204 255 51
7 4 23 204 255 51
7 3 23 204 255 51
7 2 23 204 255 51
7 2 24 204 255 51
7 3 24 204 255 51
7 4 24 204 255 51
