ply
format ascii 1.0
comment : MagicaVoxel @ Ephtracy
element vertex 18595
property float x
property float y
property float z
property uchar red
property uchar green
property uchar blue
end_header
9 25 21 153 102 51
26 26 21 153 102 51
8 19 23 153 102 51
38 28 22 153 102 51
10 26 21 153 102 51
37 29 22 153 102 51
16 34 21 153 102 51
25 27 21 153 102 51
36 30 22 153 102 51
0 30 22 153 102 51
35 31 22 153 102 51
1 31 22 153 102 51
34 32 22 153 102 51
2 32 22 153 102 51
16 32 21 153 102 51
33 33 22 153 102 51
3 33 22 153 102 51
32 34 22 153 102 51
4 34 22 153 102 51
31 35 22 153 102 51
5 35 22 153 102 51
30 36 22 153 102 51
14 30 21 153 102 51
6 36 22 153 102 51
29 37 22 153 102 51
7 37 22 153 102 51
28 38 22 153 102 51
8 38 22 153 102 51
19 33 21 153 102 51
8 18 23 153 102 51
8 17 23 153 102 51
8 16 23 153 102 51
7 38 22 153 102 51
36 29 22 153 102 51
0 29 22 153 102 51
35 30 22 153 102 51
21 31 21 153 102 51
1 30 22 153 102 51
34 31 22 153 102 51
2 31 22 153 102 51
33 32 22 153 102 51
3 32 22 153 102 51
32 33 22 153 102 51
4 33 22 153 102 51
31 34 22 153 102 51
5 34 22 153 102 51
18 16 20 153 102 51
30 35 22 153 102 51
6 35 22 153 102 51
29 36 22 153 102 51
7 36 22 153 102 51
28 37 22 153 102 51
8 37 22 153 102 51
27 38 22 153 102 51
9 38 22 153 102 51
8 15 23 153 102 51
15 31 21 153 102 51
8 14 23 153 102 51
29 38 22 153 102 51
6 37 22 153 102 51
11 28 21 153 102 51
0 28 22 153 102 51
35 29 22 153 102 51
1 29 22 153 102 51
34 30 22 153 102 51
2 30 22 153 102 51
33 31 22 153 102 51
3 31 22 153 102 51
17 16 20 153 102 51
32 32 22 153 102 51
4 32 22 153 102 51
24 29 21 153 102 51
31 33 22 153 102 51
5 33 22 153 102 51
30 34 22 153 102 51
6 34 22 153 102 51
29 35 22 153 102 51
7 35 22 153 102 51
28 36 22 153 102 51
8 36 22 153 102 51
27 37 22 153 102 51
9 37 22 153 102 51
12 29 21 153 102 51
15 18 20 153 102 51
26 38 22 153 102 51
10 38 22 153 102 51
8 13 23 153 102 51
8 12 23 153 102 51
0 27 22 153 102 51
30 37 22 153 102 51
1 28 22 153 102 51
34 29 22 153 102 51
2 29 22 153 102 51
33 30 22 153 102 51
16 16 20 153 102 51
23 30 21 153 102 51
15 17 20 153 102 51
3 30 22 153 102 51
32 31 22 153 102 51
4 31 22 153 102 51
31 32 22 153 102 51
5 32 22 153 102 51
30 33 22 153 102 51
6 33 22 153 102 51
29 34 22 153 102 51
7 34 22 153 102 51
13 30 21 153 102 51
16 20 20 153 102 51
22 31 21 153 102 51
15 19 20 153 102 51
28 35 22 153 102 51
14 18 20 153 102 51
8 35 22 153 102 51
27 36 22 153 102 51
9 36 22 153 102 51
26 37 22 153 102 51
10 37 22 153 102 51
25 38 22 153 102 51
11 38 22 153 102 51
9 27 24 153 102 51
9 26 24 153 102 51
0 26 22 153 102 51
16 15 20 153 102 51
14 31 21 153 102 51
15 16 20 153 102 51
5 36 22 153 102 51
14 17 20 153 102 51
1 27 22 153 102 51
31 36 22 153 102 51
2 28 22 153 102 51
33 29 22 153 102 51
3 29 22 153 102 51
32 30 22 153 102 51
4 30 22 153 102 51
31 31 22 153 102 51
5 31 22 153 102 51
30 32 22 153 102 51
16 21 20 153 102 51
21 32 21 153 102 51
15 20 20 153 102 51
6 32 22 153 102 51
14 19 20 153 102 51
29 33 22 153 102 51
13 18 20 153 102 51
7 33 22 153 102 51
28 34 22 153 102 51
8 34 22 153 102 51
27 35 22 153 102 51
9 35 22 153 102 51
26 36 22 153 102 51
10 36 22 153 102 51
25 37 22 153 102 51
11 37 22 153 102 51
24 38 22 153 102 51
12 38 22 153 102 51
9 25 24 153 102 51
15 15 20 153 102 51
15 32 21 153 102 51
14 16 20 153 102 51
9 24 24 153 102 51
13 17 20 153 102 51
0 25 22 153 102 51
21 27 20 153 102 51
1 26 22 153 102 51
4 35 22 153 102 51
2 27 22 153 102 51
32 35 22 153 102 51
3 28 22 153 102 51
32 29 22 153 102 51
4 29 22 153 102 51
31 30 22 153 102 51
16 22 20 153 102 51
5 30 22 153 102 51
15 21 20 153 102 51
30 31 22 153 102 51
14 20 20 153 102 51
6 31 22 153 102 51
13 19 20 153 102 51
29 32 22 153 102 51
12 18 20 153 102 51
7 32 22 153 102 51
28 33 22 153 102 51
8 33 22 153 102 51
27 34 22 153 102 51
9 34 22 153 102 51
26 35 22 153 102 51
10 35 22 153 102 51
25 36 22 153 102 51
11 36 22 153 102 51
24 37 22 153 102 51
12 37 22 153 102 51
23 38 22 153 102 51
13 38 22 153 102 51
20 33 21 153 102 51
14 15 20 153 102 51
9 23 24 153 102 51
13 16 20 153 102 51
9 22 24 153 102 51
12 17 20 153 102 51
0 24 22 153 102 51
21 28 20 153 102 51
20 27 20 153 102 51
22 27 20 153 102 51
19 26 20 153 102 51
23 26 20 153 102 51
1 25 22 153 102 51
2 26 22 153 102 51
17 24 20 153 102 51
3 34 22 153 102 51
16 23 20 153 102 51
3 27 22 153 102 51
15 22 20 153 102 51
32 28 22 153 102 51
14 21 20 153 102 51
4 28 22 153 102 51
13 20 20 153 102 51
31 29 22 153 102 51
12 19 20 153 102 51
5 29 22 153 102 51
11 18 20 153 102 51
30 30 22 153 102 51
6 30 22 153 102 51
29 31 22 153 102 51
7 31 22 153 102 51
28 32 22 153 102 51
8 32 22 153 102 51
27 33 22 153 102 51
9 33 22 153 102 51
26 34 22 153 102 51
10 34 22 153 102 51
25 35 22 153 102 51
11 35 22 153 102 51
24 36 22 153 102 51
16 33 21 153 102 51
14 14 20 153 102 51
12 36 22 153 102 51
13 15 20 153 102 51
23 37 22 153 102 51
12 16 20 153 102 51
13 37 22 153 102 51
11 17 20 153 102 51
22 38 22 153 102 51
21 29 20 153 102 51
20 28 20 153 102 51
22 28 20 153 102 51
19 27 20 153 102 51
23 27 20 153 102 51
18 26 20 153 102 51
24 26 20 153 102 51
17 25 20 153 102 51
14 38 22 153 102 51
16 24 20 153 102 51
9 21 24 153 102 51
15 23 20 153 102 51
9 20 24 153 102 51
14 22 20 153 102 51
0 23 22 153 102 51
13 21 20 153 102 51
1 24 22 153 102 51
12 20 20 153 102 51
2 25 22 153 102 51
11 19 20 153 102 51
3 26 22 153 102 51
10 18 20 153 102 51
33 34 22 153 102 51
4 27 22 153 102 51
31 28 22 153 102 51
5 28 22 153 102 51
30 29 22 153 102 51
6 29 22 153 102 51
29 30 22 153 102 51
7 30 22 153 102 51
28 31 22 153 102 51
8 31 22 153 102 51
27 32 22 153 102 51
9 32 22 153 102 51
26 33 22 153 102 51
10 33 22 153 102 51
25 34 22 153 102 51
11 34 22 153 102 51
13 14 20 153 102 51
24 35 22 153 102 51
12 15 20 153 102 51
12 35 22 153 102 51
11 16 20 153 102 51
23 36 22 153 102 51
10 17 20 153 102 51
13 36 22 153 102 51
21 30 20 153 102 51
20 29 20 153 102 51
22 29 20 153 102 51
19 28 20 153 102 51
23 28 20 153 102 51
18 27 20 153 102 51
24 27 20 153 102 51
17 26 20 153 102 51
25 26 20 153 102 51
16 25 20 153 102 51
22 37 22 153 102 51
15 24 20 153 102 51
14 37 22 153 102 51
14 23 20 153 102 51
21 38 22 153 102 51
13 22 20 153 102 51
15 38 22 153 102 51
12 21 20 153 102 51
9 19 24 153 102 51
11 20 20 153 102 51
9 18 24 153 102 51
10 19 20 153 102 51
0 22 22 153 102 51
9 18 20 153 102 51
1 23 22 153 102 51
2 24 22 153 102 51
3 25 22 153 102 51
4 26 22 153 102 51
2 33 22 153 102 51
5 27 22 153 102 51
30 28 22 153 102 51
6 28 22 153 102 51
29 29 22 153 102 51
7 29 22 153 102 51
28 30 22 153 102 51
8 30 22 153 102 51
27 31 22 153 102 51
9 31 22 153 102 51
26 32 22 153 102 51
19 34 21 153 102 51
13 13 20 153 102 51
10 32 22 153 102 51
12 14 20 153 102 51
25 33 22 153 102 51
11 15 20 153 102 51
11 33 22 153 102 51
10 16 20 153 102 51
24 34 22 153 102 51
9 17 20 153 102 51
12 34 22 153 102 51
21 31 20 153 102 51
20 30 20 153 102 51
22 30 20 153 102 51
19 29 20 153 102 51
23 29 20 153 102 51
18 28 20 153 102 51
24 28 20 153 102 51
17 27 20 153 102 51
25 27 20 153 102 51
16 26 20 153 102 51
26 26 20 153 102 51
15 25 20 153 102 51
27 25 20 153 102 51
14 24 20 153 102 51
23 35 22 153 102 51
13 23 20 153 102 51
13 35 22 153 102 51
12 22 20 153 102 51
22 36 22 153 102 51
11 21 20 153 102 51
14 36 22 153 102 51
10 20 20 153 102 51
21 37 22 153 102 51
9 19 20 153 102 51
15 37 22 153 102 51
8 18 20 153 102 51
20 38 22 153 102 51
16 38 22 153 102 51
9 17 24 153 102 51
9 16 24 153 102 51
0 21 22 153 102 51
1 22 22 153 102 51
2 23 22 153 102 51
3 24 22 153 102 51
4 25 22 153 102 51
34 33 22 153 102 51
5 26 22 153 102 51
1 32 22 153 102 51
6 27 22 153 102 51
29 28 22 153 102 51
7 28 22 153 102 51
17 34 21 153 102 51
28 29 22 153 102 51
8 29 22 153 102 51
12 13 20 153 102 51
27 30 22 153 102 51
11 14 20 153 102 51
9 30 22 153 102 51
10 15 20 153 102 51
26 31 22 153 102 51
9 16 20 153 102 51
10 31 22 153 102 51
8 17 20 153 102 51
25 32 22 153 102 51
21 32 20 153 102 51
20 31 20 153 102 51
22 31 20 153 102 51
19 30 20 153 102 51
23 30 20 153 102 51
18 29 20 153 102 51
24 29 20 153 102 51
17 28 20 153 102 51
25 28 20 153 102 51
16 27 20 153 102 51
26 27 20 153 102 51
15 26 20 153 102 51
27 26 20 153 102 51
14 25 20 153 102 51
11 32 22 153 102 51
13 24 20 153 102 51
24 33 22 153 102 51
12 23 20 153 102 51
12 33 22 153 102 51
11 22 20 153 102 51
23 34 22 153 102 51
10 21 20 153 102 51
13 34 22 153 102 51
9 20 20 153 102 51
22 35 22 153 102 51
8 19 20 153 102 51
14 35 22 153 102 51
7 18 20 153 102 51
21 36 22 153 102 51
15 36 22 153 102 51
20 37 22 153 102 51
16 37 22 153 102 51
19 38 22 153 102 51
17 38 22 153 102 51
9 15 24 153 102 51
0 20 22 153 102 51
1 21 22 153 102 51
2 22 22 153 102 51
3 23 22 153 102 51
4 24 22 153 102 51
5 25 22 153 102 51
35 32 22 153 102 51
6 26 22 153 102 51
0 31 22 153 102 51
7 27 22 153 102 51
28 28 22 153 102 51
12 12 20 153 102 51
8 28 22 153 102 51
11 13 20 153 102 51
27 29 22 153 102 51
10 14 20 153 102 51
9 29 22 153 102 51
9 15 20 153 102 51
26 30 22 153 102 51
8 16 20 153 102 51
10 30 22 153 102 51
7 17 20 153 102 51
25 31 22 153 102 51
21 33 20 153 102 51
20 32 20 153 102 51
22 32 20 153 102 51
19 31 20 153 102 51
23 31 20 153 102 51
18 30 20 153 102 51
24 30 20 153 102 51
17 29 20 153 102 51
25 29 20 153 102 51
16 28 20 153 102 51
26 28 20 153 102 51
15 27 20 153 102 51
27 27 20 153 102 51
14 26 20 153 102 51
28 26 20 153 102 51
13 25 20 153 102 51
11 31 22 153 102 51
12 24 20 153 102 51
24 32 22 153 102 51
11 23 20 153 102 51
12 32 22 153 102 51
10 22 20 153 102 51
23 33 22 153 102 51
9 21 20 153 102 51
13 33 22 153 102 51
8 20 20 153 102 51
22 34 22 153 102 51
7 19 20 153 102 51
14 34 22 153 102 51
6 18 20 153 102 51
21 35 22 153 102 51
15 35 22 153 102 51
20 36 22 153 102 51
16 36 22 153 102 51
19 37 22 153 102 51
17 37 22 153 102 51
18 38 22 153 102 51
0 19 22 153 102 51
1 20 22 153 102 51
2 21 22 153 102 51
3 22 22 153 102 51
4 23 22 153 102 51
5 24 22 153 102 51
6 25 22 153 102 51
36 31 22 153 102 51
7 26 22 153 102 51
37 30 22 153 102 51
18 35 21 153 102 51
12 11 20 153 102 51
8 27 22 153 102 51
11 12 20 153 102 51
27 28 22 153 102 51
10 13 20 153 102 51
9 28 22 153 102 51
9 14 20 153 102 51
26 29 22 153 102 51
8 15 20 153 102 51
10 29 22 153 102 51
7 16 20 153 102 51
25 30 22 153 102 51
6 17 20 153 102 51
11 30 22 153 102 51
21 34 20 153 102 51
20 33 20 153 102 51
22 33 20 153 102 51
19 32 20 153 102 51
23 32 20 153 102 51
18 31 20 153 102 51
24 31 20 153 102 51
17 30 20 153 102 51
25 30 20 153 102 51
16 29 20 153 102 51
26 29 20 153 102 51
15 28 20 153 102 51
27 28 20 153 102 51
14 27 20 153 102 51
28 27 20 153 102 51
13 26 20 153 102 51
29 26 20 153 102 51
12 25 20 153 102 51
24 31 22 153 102 51
11 24 20 153 102 51
12 31 22 153 102 51
10 23 20 153 102 51
23 32 22 153 102 51
9 22 20 153 102 51
13 32 22 153 102 51
8 21 20 153 102 51
22 33 22 153 102 51
7 20 20 153 102 51
14 33 22 153 102 51
6 19 20 153 102 51
21 34 22 153 102 51
5 18 20 153 102 51
15 34 22 153 102 51
20 35 22 153 102 51
16 35 22 153 102 51
19 36 22 153 102 51
17 36 22 153 102 51
18 37 22 153 102 51
0 18 22 153 102 51
1 19 22 153 102 51
2 20 22 153 102 51
3 21 22 153 102 51
4 22 22 153 102 51
5 23 22 153 102 51
6 24 22 153 102 51
7 25 22 153 102 51
38 29 22 153 102 51
8 26 22 153 102 51
39 28 22 153 102 51
9 27 22 153 102 51
26 28 22 153 102 51
10 27 21 153 102 51
11 11 20 153 102 51
10 28 22 153 102 51
10 12 20 153 102 51
25 29 22 153 102 51
9 13 20 153 102 51
11 29 22 153 102 51
8 14 20 153 102 51
24 30 22 153 102 51
7 15 20 153 102 51
12 30 22 153 102 51
6 16 20 153 102 51
23 31 22 153 102 51
5 17 20 153 102 51
13 31 22 153 102 51
21 35 20 153 102 51
20 34 20 153 102 51
22 34 20 153 102 51
19 33 20 153 102 51
23 33 20 153 102 51
18 32 20 153 102 51
24 32 20 153 102 51
17 31 20 153 102 51
25 31 20 153 102 51
16 30 20 153 102 51
26 30 20 153 102 51
15 29 20 153 102 51
27 29 20 153 102 51
14 28 20 153 102 51
28 28 20 153 102 51
13 27 20 153 102 51
29 27 20 153 102 51
12 26 20 153 102 51
30 26 20 153 102 51
11 25 20 153 102 51
22 32 22 153 102 51
10 24 20 153 102 51
14 32 22 153 102 51
9 23 20 153 102 51
21 33 22 153 102 51
8 22 20 153 102 51
15 33 22 153 102 51
7 21 20 153 102 51
20 34 22 153 102 51
6 20 20 153 102 51
16 34 22 153 102 51
5 19 20 153 102 51
19 35 22 153 102 51
4 18 20 153 102 51
17 35 22 153 102 51
18 36 22 153 102 51
0 17 22 153 102 51
1 18 22 153 102 51
2 19 22 153 102 51
3 20 22 153 102 51
4 21 22 153 102 51
5 22 22 153 102 51
6 23 22 153 102 51
7 24 22 153 102 51
8 25 22 153 102 51
9 14 24 153 102 51
9 26 22 153 102 51
9 13 24 153 102 51
10 27 22 153 102 51
25 28 22 153 102 51
11 28 22 153 102 51
24 29 22 153 102 51
12 29 22 153 102 51
23 30 22 153 102 51
11 10 20 153 102 51
26 27 21 153 102 51
10 11 20 153 102 51
13 30 22 153 102 51
9 12 20 153 102 51
22 31 22 153 102 51
8 13 20 153 102 51
14 31 22 153 102 51
7 14 20 153 102 51
21 32 22 153 102 51
6 15 20 153 102 51
15 32 22 153 102 51
5 16 20 153 102 51
20 33 22 153 102 51
4 17 20 153 102 51
16 33 22 153 102 51
21 36 20 153 102 51
20 35 20 153 102 51
22 35 20 153 102 51
19 34 20 153 102 51
23 34 20 153 102 51
18 33 20 153 102 51
24 33 20 153 102 51
17 32 20 153 102 51
25 32 20 153 102 51
16 31 20 153 102 51
26 31 20 153 102 51
15 30 20 153 102 51
27 30 20 153 102 51
14 29 20 153 102 51
28 29 20 153 102 51
13 28 20 153 102 51
29 28 20 153 102 51
12 27 20 153 102 51
30 27 20 153 102 51
11 26 20 153 102 51
31 26 20 153 102 51
10 25 20 153 102 51
19 34 22 153 102 51
9 24 20 153 102 51
17 34 22 153 102 51
8 23 20 153 102 51
18 35 22 153 102 51
7 22 20 153 102 51
0 16 22 153 102 51
6 21 20 153 102 51
1 17 22 153 102 51
5 20 20 153 102 51
2 18 22 153 102 51
4 19 20 153 102 51
3 19 22 153 102 51
3 18 20 153 102 51
4 20 22 153 102 51
5 21 22 153 102 51
6 22 22 153 102 51
7 23 22 153 102 51
8 24 22 153 102 51
6 38 22 153 102 51
9 25 22 153 102 51
30 38 22 153 102 51
10 26 22 153 102 51
5 37 22 153 102 51
11 27 22 153 102 51
24 28 22 153 102 51
12 28 22 153 102 51
23 29 22 153 102 51
13 29 22 153 102 51
22 30 22 153 102 51
14 30 22 153 102 51
21 31 22 153 102 51
15 31 22 153 102 51
11 9 20 153 102 51
9 26 21 153 102 51
10 10 20 153 102 51
20 32 22 153 102 51
9 11 20 153 102 51
16 32 22 153 102 51
8 12 20 153 102 51
19 33 22 153 102 51
7 13 20 153 102 51
17 33 22 153 102 51
6 14 20 153 102 51
18 34 22 153 102 51
5 15 20 153 102 51
0 15 22 153 102 51
4 16 20 153 102 51
1 16 22 153 102 51
3 17 20 153 102 51
2 17 22 153 102 51
21 37 20 153 102 51
20 36 20 153 102 51
22 36 20 153 102 51
19 35 20 153 102 51
23 35 20 153 102 51
18 34 20 153 102 51
24 34 20 153 102 51
17 33 20 153 102 51
25 33 20 153 102 51
16 32 20 153 102 51
26 32 20 153 102 51
15 31 20 153 102 51
27 31 20 153 102 51
14 30 20 153 102 51
28 30 20 153 102 51
13 29 20 153 102 51
29 29 20 153 102 51
12 28 20 153 102 51
30 28 20 153 102 51
11 27 20 153 102 51
31 27 20 153 102 51
10 26 20 153 102 51
3 18 22 153 102 51
9 25 20 153 102 51
4 19 22 153 102 51
8 24 20 153 102 51
5 20 22 153 102 51
7 23 20 153 102 51
6 21 22 153 102 51
6 22 20 153 102 51
7 22 22 153 102 51
5 21 20 153 102 51
8 23 22 153 102 51
4 20 20 153 102 51
9 24 22 153 102 51
3 19 20 153 102 51
10 25 22 153 102 51
2 18 20 153 102 51
31 37 22 153 102 51
11 26 22 153 102 51
4 36 22 153 102 51
12 27 22 153 102 51
23 28 22 153 102 51
13 28 22 153 102 51
22 29 22 153 102 51
14 29 22 153 102 51
21 30 22 153 102 51
15 30 22 153 102 51
20 31 22 153 102 51
16 31 22 153 102 51
19 32 22 153 102 51
17 32 22 153 102 51
18 33 22 153 102 51
0 14 22 153 102 51
1 15 22 153 102 51
2 16 22 153 102 51
10 9 20 153 102 51
27 26 21 153 102 51
9 10 20 153 102 51
3 17 22 153 102 51
8 11 20 153 102 51
4 18 22 153 102 51
7 12 20 153 102 51
5 19 22 153 102 51
6 13 20 153 102 51
6 20 22 153 102 51
5 14 20 153 102 51
7 21 22 153 102 51
4 15 20 153 102 51
8 22 22 153 102 51
3 16 20 153 102 51
9 23 22 153 102 51
2 17 20 153 102 51
21 38 20 153 102 51
20 37 20 153 102 51
22 37 20 153 102 51
19 36 20 153 102 51
23 36 20 153 102 51
18 35 20 153 102 51
24 35 20 153 102 51
17 34 20 153 102 51
25 34 20 153 102 51
16 33 20 153 102 51
26 33 20 153 102 51
15 32 20 153 102 51
27 32 20 153 102 51
14 31 20 153 102 51
28 31 20 153 102 51
13 30 20 153 102 51
29 30 20 153 102 51
12 29 20 153 102 51
30 29 20 153 102 51
11 28 20 153 102 51
31 28 20 153 102 51
10 27 20 153 102 51
32 27 20 153 102 51
9 26 20 153 102 51
10 24 22 153 102 51
8 25 20 153 102 51
11 25 22 153 102 51
7 24 20 153 102 51
32 36 22 153 102 51
6 23 20 153 102 51
12 26 22 153 102 51
5 22 20 153 102 51
3 35 22 153 102 51
4 21 20 153 102 51
13 27 22 153 102 51
3 20 20 153 102 51
22 28 22 153 102 51
2 19 20 153 102 51
1 18 20 153 102 51
14 28 22 153 102 51
21 29 22 153 102 51
15 29 22 153 102 51
20 30 22 153 102 51
16 30 22 153 102 51
19 31 22 153 102 51
17 31 22 153 102 51
18 32 22 153 102 51
0 0 22 153 102 51
0 13 22 153 102 51
1 14 22 153 102 51
2 15 22 153 102 51
3 16 22 153 102 51
4 17 22 153 102 51
5 18 22 153 102 51
6 19 22 153 102 51
10 8 20 153 102 51
7 20 22 153 102 51
9 9 20 153 102 51
8 25 21 153 102 51
8 10 20 153 102 51
8 21 22 153 102 51
7 11 20 153 102 51
9 22 22 153 102 51
6 12 20 153 102 51
10 23 22 153 102 51
5 13 20 153 102 51
11 24 22 153 102 51
4 14 20 153 102 51
12 25 22 153 102 51
3 15 20 153 102 51
33 35 22 153 102 51
2 16 20 153 102 51
1 17 20 153 102 51
9 12 24 153 102 51
20 38 20 153 102 51
22 38 20 153 102 51
19 37 20 153 102 51
23 37 20 153 102 51
18 36 20 153 102 51
24 36 20 153 102 51
17 35 20 153 102 51
25 35 20 153 102 51
16 34 20 153 102 51
26 34 20 153 102 51
15 33 20 153 102 51
27 33 20 153 102 51
14 32 20 153 102 51
28 32 20 153 102 51
13 31 20 153 102 51
29 31 20 153 102 51
12 30 20 153 102 51
30 30 20 153 102 51
11 29 20 153 102 51
31 29 20 153 102 51
10 28 20 153 102 51
32 28 20 153 102 51
9 27 20 153 102 51
33 27 20 153 102 51
8 26 20 153 102 51
13 26 22 153 102 51
7 25 20 153 102 51
2 34 22 153 102 51
6 24 20 153 102 51
14 27 22 153 102 51
5 23 20 153 102 51
21 28 22 153 102 51
4 22 20 153 102 51
15 28 22 153 102 51
3 21 20 153 102 51
20 29 22 153 102 51
2 20 20 153 102 51
1 19 20 153 102 51
0 18 20 153 102 51
16 29 22 153 102 51
19 30 22 153 102 51
17 30 22 153 102 51
18 31 22 153 102 51
0 1 22 153 102 51
1 0 22 153 102 51
0 12 22 153 102 51
1 13 22 153 102 51
2 14 22 153 102 51
3 15 22 153 102 51
4 16 22 153 102 51
5 17 22 153 102 51
6 18 22 153 102 51
7 19 22 153 102 51
8 20 22 153 102 51
9 21 22 153 102 51
9 8 20 153 102 51
10 22 22 153 102 51
8 9 20 153 102 51
25 28 21 153 102 51
7 10 20 153 102 51
11 23 22 153 102 51
6 11 20 153 102 51
12 24 22 153 102 51
5 12 20 153 102 51
13 25 22 153 102 51
4 13 20 153 102 51
14 26 22 153 102 51
3 14 20 153 102 51
34 34 22 153 102 51
2 15 20 153 102 51
1 16 20 153 102 51
0 17 20 153 102 51
7 27 23 153 102 51
7 26 23 153 102 51
19 38 20 153 102 51
23 38 20 153 102 51
18 37 20 153 102 51
24 37 20 153 102 51
17 36 20 153 102 51
25 36 20 153 102 51
16 35 20 153 102 51
26 35 20 153 102 51
15 34 20 153 102 51
27 34 20 153 102 51
14 33 20 153 102 51
28 33 20 153 102 51
13 32 20 153 102 51
29 32 20 153 102 51
12 31 20 153 102 51
30 31 20 153 102 51
11 30 20 153 102 51
31 30 20 153 102 51
10 29 20 153 102 51
32 29 20 153 102 51
9 28 20 153 102 51
33 28 20 153 102 51
8 27 20 153 102 51
34 27 20 153 102 51
7 26 20 153 102 51
15 27 22 153 102 51
6 25 20 153 102 51
20 28 22 153 102 51
5 24 20 153 102 51
16 28 22 153 102 51
4 23 20 153 102 51
19 29 22 153 102 51
3 22 20 153 102 51
17 29 22 153 102 51
2 21 20 153 102 51
1 20 20 153 102 51
0 19 20 153 102 51
18 30 22 153 102 51
0 2 22 153 102 51
1 1 22 153 102 51
2 0 22 153 102 51
0 11 22 153 102 51
1 12 22 153 102 51
2 13 22 153 102 51
3 14 22 153 102 51
4 15 22 153 102 51
5 16 22 153 102 51
6 17 22 153 102 51
7 18 22 153 102 51
8 19 22 153 102 51
9 20 22 153 102 51
1 33 22 153 102 51
10 21 22 153 102 51
8 8 20 153 102 51
11 22 22 153 102 51
7 9 20 153 102 51
12 23 22 153 102 51
6 10 20 153 102 51
13 24 22 153 102 51
5 11 20 153 102 51
14 25 22 153 102 51
4 12 20 153 102 51
15 26 22 153 102 51
3 13 20 153 102 51
35 33 22 153 102 51
2 14 20 153 102 51
1 15 20 153 102 51
0 16 20 153 102 51
7 25 23 153 102 51
7 24 23 153 102 51
18 38 20 153 102 51
24 38 20 153 102 51
17 37 20 153 102 51
25 37 20 153 102 51
16 36 20 153 102 51
26 36 20 153 102 51
15 35 20 153 102 51
27 35 20 153 102 51
14 34 20 153 102 51
28 34 20 153 102 51
13 33 20 153 102 51
29 33 20 153 102 51
12 32 20 153 102 51
30 32 20 153 102 51
11 31 20 153 102 51
31 31 20 153 102 51
10 30 20 153 102 51
32 30 20 153 102 51
9 29 20 153 102 51
33 29 20 153 102 51
8 28 20 153 102 51
34 28 20 153 102 51
7 27 20 153 102 51
35 27 20 153 102 51
6 26 20 153 102 51
16 27 22 153 102 51
5 25 20 153 102 51
19 28 22 153 102 51
4 24 20 153 102 51
17 28 22 153 102 51
3 23 20 153 102 51
18 29 22 153 102 51
2 22 20 153 102 51
1 21 20 153 102 51
0 20 20 153 102 51
0 3 22 153 102 51
1 2 22 153 102 51
2 1 22 153 102 51
3 0 22 153 102 51
0 10 22 153 102 51
1 11 22 153 102 51
2 12 22 153 102 51
3 13 22 153 102 51
4 14 22 153 102 51
5 15 22 153 102 51
6 16 22 153 102 51
7 17 22 153 102 51
8 18 22 153 102 51
9 19 22 153 102 51
8 7 20 153 102 51
0 32 22 153 102 51
7 8 20 153 102 51
10 20 22 153 102 51
6 9 20 153 102 51
36 32 22 153 102 51
5 10 20 153 102 51
11 21 22 153 102 51
4 11 20 153 102 51
12 22 22 153 102 51
3 12 20 153 102 51
13 23 22 153 102 51
2 13 20 153 102 51
1 14 20 153 102 51
0 15 20 153 102 51
7 23 23 153 102 51
7 22 23 153 102 51
17 38 20 153 102 51
25 38 20 153 102 51
16 37 20 153 102 51
26 37 20 153 102 51
15 36 20 153 102 51
27 36 20 153 102 51
14 35 20 153 102 51
28 35 20 153 102 51
13 34 20 153 102 51
29 34 20 153 102 51
12 33 20 153 102 51
30 33 20 153 102 51
11 32 20 153 102 51
31 32 20 153 102 51
10 31 20 153 102 51
32 31 20 153 102 51
9 30 20 153 102 51
33 30 20 153 102 51
8 29 20 153 102 51
34 29 20 153 102 51
7 28 20 153 102 51
35 28 20 153 102 51
6 27 20 153 102 51
14 24 22 153 102 51
5 26 20 153 102 51
15 25 22 153 102 51
4 25 20 153 102 51
37 31 22 153 102 51
3 24 20 153 102 51
38 30 22 153 102 51
2 23 20 153 102 51
1 22 20 153 102 51
0 21 20 153 102 51
39 29 22 153 102 51
18 28 22 153 102 51
0 4 22 153 102 51
1 3 22 153 102 51
2 2 22 153 102 51
3 1 22 153 102 51
7 21 23 153 102 51
0 9 22 153 102 51
1 10 22 153 102 51
2 11 22 153 102 51
3 12 22 153 102 51
4 13 22 153 102 51
5 14 22 153 102 51
6 15 22 153 102 51
7 7 20 153 102 51
7 16 22 153 102 51
6 8 20 153 102 51
8 17 22 153 102 51
5 9 20 153 102 51
9 18 22 153 102 51
4 10 20 153 102 51
7 20 23 153 102 51
3 11 20 153 102 51
10 19 22 153 102 51
2 12 20 153 102 51
1 13 20 153 102 51
0 14 20 153 102 51
7 19 23 153 102 51
7 18 23 153 102 51
16 38 20 153 102 51
26 38 20 153 102 51
15 37 20 153 102 51
27 37 20 153 102 51
14 36 20 153 102 51
28 36 20 153 102 51
13 35 20 153 102 51
29 35 20 153 102 51
12 34 20 153 102 51
30 34 20 153 102 51
11 33 20 153 102 51
31 33 20 153 102 51
10 32 20 153 102 51
32 32 20 153 102 51
9 31 20 153 102 51
33 31 20 153 102 51
8 30 20 153 102 51
34 30 20 153 102 51
7 29 20 153 102 51
35 29 20 153 102 51
6 28 20 153 102 51
36 28 20 153 102 51
5 27 20 153 102 51
37 27 20 153 102 51
4 26 20 153 102 51
11 20 22 153 102 51
3 25 20 153 102 51
12 21 22 153 102 51
2 24 20 153 102 51
1 23 20 153 102 51
0 22 20 153 102 51
13 22 22 153 102 51
14 23 22 153 102 51
15 24 22 153 102 51
5 38 22 153 102 51
31 38 22 153 102 51
4 37 22 153 102 51
32 37 22 153 102 51
0 5 22 153 102 51
1 4 22 153 102 51
2 3 22 153 102 51
3 2 22 153 102 51
3 36 22 153 102 51
7 6 20 153 102 51
0 8 22 153 102 51
6 7 20 153 102 51
1 9 22 153 102 51
5 8 20 153 102 51
2 10 22 153 102 51
4 9 20 153 102 51
3 11 22 153 102 51
3 10 20 153 102 51
4 12 22 153 102 51
2 11 20 153 102 51
1 12 20 153 102 51
0 13 20 153 102 51
7 17 23 153 102 51
7 16 23 153 102 51
15 38 20 153 102 51
27 38 20 153 102 51
14 37 20 153 102 51
28 37 20 153 102 51
13 36 20 153 102 51
29 36 20 153 102 51
12 35 20 153 102 51
30 35 20 153 102 51
11 34 20 153 102 51
31 34 20 153 102 51
10 33 20 153 102 51
32 33 20 153 102 51
9 32 20 153 102 51
33 32 20 153 102 51
8 31 20 153 102 51
34 31 20 153 102 51
7 30 20 153 102 51
35 30 20 153 102 51
6 29 20 153 102 51
36 29 20 153 102 51
5 28 20 153 102 51
37 28 20 153 102 51
4 27 20 153 102 51
38 27 20 153 102 51
3 26 20 153 102 51
5 13 22 153 102 51
2 25 20 153 102 51
1 24 20 153 102 51
0 23 20 153 102 51
6 14 22 153 102 51
7 15 22 153 102 51
8 16 22 153 102 51
9 17 22 153 102 51
33 36 22 153 102 51
10 18 22 153 102 51
11 19 22 153 102 51
2 35 22 153 102 51
12 20 22 153 102 51
13 21 22 153 102 51
14 22 22 153 102 51
34 35 22 153 102 51
6 6 20 153 102 51
1 34 22 153 102 51
5 7 20 153 102 51
35 34 22 153 102 51
4 8 20 153 102 51
0 33 22 153 102 51
3 9 20 153 102 51
0 6 22 153 102 51
2 10 20 153 102 51
1 11 20 153 102 51
0 12 20 153 102 51
7 15 23 153 102 51
7 14 23 153 102 51
14 38 20 153 102 51
28 38 20 153 102 51
13 37 20 153 102 51
29 37 20 153 102 51
12 36 20 153 102 51
30 36 20 153 102 51
11 35 20 153 102 51
31 35 20 153 102 51
10 34 20 153 102 51
32 34 20 153 102 51
9 33 20 153 102 51
33 33 20 153 102 51
8 32 20 153 102 51
34 32 20 153 102 51
7 31 20 153 102 51
35 31 20 153 102 51
6 30 20 153 102 51
36 30 20 153 102 51
5 29 20 153 102 51
37 29 20 153 102 51
4 28 20 153 102 51
38 28 20 153 102 51
3 27 20 153 102 51
39 27 20 153 102 51
2 26 20 153 102 51
1 25 20 153 102 51
0 24 20 153 102 51
1 5 22 153 102 51
2 4 22 153 102 51
3 3 22 153 102 51
4 2 22 153 102 51
36 33 22 153 102 51
0 7 22 153 102 51
1 8 22 153 102 51
37 32 22 153 102 51
2 9 22 153 102 51
3 10 22 153 102 51
6 5 20 153 102 51
4 11 22 153 102 51
5 6 20 153 102 51
5 12 22 153 102 51
4 7 20 153 102 51
6 13 22 153 102 51
3 8 20 153 102 51
7 14 22 153 102 51
2 9 20 153 102 51
1 10 20 153 102 51
0 11 20 153 102 51
7 13 23 153 102 51
7 12 23 153 102 51
13 38 20 153 102 51
29 38 20 153 102 51
12 37 20 153 102 51
30 37 20 153 102 51
11 36 20 153 102 51
31 36 20 153 102 51
10 35 20 153 102 51
32 35 20 153 102 51
9 34 20 153 102 51
33 34 20 153 102 51
8 33 20 153 102 51
34 33 20 153 102 51
7 32 20 153 102 51
35 32 20 153 102 51
6 31 20 153 102 51
36 31 20 153 102 51
5 30 20 153 102 51
37 30 20 153 102 51
4 29 20 153 102 51
38 29 20 153 102 51
3 28 20 153 102 51
39 28 20 153 102 51
2 27 20 153 102 51
1 26 20 153 102 51
0 25 20 153 102 51
8 15 22 153 102 51
9 16 22 153 102 51
38 31 22 153 102 51
10 17 22 153 102 51
11 18 22 153 102 51
12 19 22 153 102 51
39 30 22 153 102 51
13 20 22 153 102 51
6 4 20 153 102 51
14 21 22 153 102 51
5 5 20 153 102 51
8 27 24 153 102 51
4 6 20 153 102 51
8 26 24 153 102 51
3 7 20 153 102 51
4 38 22 153 102 51
2 8 20 153 102 51
1 9 20 153 102 51
0 10 20 153 102 51
8 25 24 153 102 51
8 24 24 153 102 51
12 38 20 153 102 51
30 38 20 153 102 51
11 37 20 153 102 51
31 37 20 153 102 51
10 36 20 153 102 51
32 36 20 153 102 51
9 35 20 153 102 51
33 35 20 153 102 51
8 34 20 153 102 51
34 34 20 153 102 51
7 33 20 153 102 51
35 33 20 153 102 51
6 32 20 153 102 51
36 32 20 153 102 51
5 31 20 153 102 51
37 31 20 153 102 51
4 30 20 153 102 51
38 30 20 153 102 51
3 29 20 153 102 51
39 29 20 153 102 51
2 28 20 153 102 51
1 27 20 153 102 51
0 26 20 153 102 51
1 6 22 153 102 51
2 5 22 153 102 51
3 4 22 153 102 51
4 3 22 153 102 51
32 38 22 153 102 51
1 7 22 153 102 51
2 8 22 153 102 51
3 37 22 153 102 51
5 4 20 153 102 51
3 9 22 153 102 51
4 5 20 153 102 51
4 10 22 153 102 51
3 6 20 153 102 51
5 11 22 153 102 51
2 7 20 153 102 51
1 8 20 153 102 51
0 9 20 153 102 51
8 23 24 153 102 51
8 22 24 153 102 51
11 38 20 153 102 51
31 38 20 153 102 51
10 37 20 153 102 51
32 37 20 153 102 51
9 36 20 153 102 51
33 36 20 153 102 51
8 35 20 153 102 51
34 35 20 153 102 51
7 34 20 153 102 51
35 34 20 153 102 51
6 33 20 153 102 51
36 33 20 153 102 51
5 32 20 153 102 51
37 32 20 153 102 51
4 31 20 153 102 51
38 31 20 153 102 51
3 30 20 153 102 51
39 30 20 153 102 51
2 29 20 153 102 51
1 28 20 153 102 51
0 27 20 153 102 51
6 12 22 153 102 51
7 13 22 153 102 51
8 14 22 153 102 51
33 37 22 153 102 51
9 15 22 153 102 51
2 36 22 153 102 51
5 3 20 153 102 51
10 16 22 153 102 51
4 4 20 153 102 51
11 17 22 153 102 51
3 5 20 153 102 51
12 18 22 153 102 51
2 6 20 153 102 51
1 7 20 153 102 51
0 8 20 153 102 51
8 21 24 153 102 51
8 20 24 153 102 51
10 38 20 153 102 51
32 38 20 153 102 51
9 37 20 153 102 51
33 37 20 153 102 51
8 36 20 153 102 51
34 36 20 153 102 51
7 35 20 153 102 51
35 35 20 153 102 51
6 34 20 153 102 51
36 34 20 153 102 51
5 33 20 153 102 51
37 33 20 153 102 51
4 32 20 153 102 51
38 32 20 153 102 51
3 31 20 153 102 51
39 31 20 153 102 51
2 30 20 153 102 51
1 29 20 153 102 51
0 28 20 153 102 51
34 36 22 153 102 51
13 19 22 153 102 51
14 20 22 153 102 51
1 35 22 153 102 51
5 2 20 153 102 51
35 35 22 153 102 51
4 3 20 153 102 51
2 6 22 153 102 51
3 4 20 153 102 51
3 5 22 153 102 51
2 5 20 153 102 51
1 6 20 153 102 51
0 7 20 153 102 51
8 19 24 153 102 51
8 18 24 153 102 51
9 38 20 153 102 51
33 38 20 153 102 51
8 37 20 153 102 51
34 37 20 153 102 51
7 36 20 153 102 51
35 36 20 153 102 51
6 35 20 153 102 51
36 35 20 153 102 51
5 34 20 153 102 51
37 34 20 153 102 51
4 33 20 153 102 51
38 33 20 153 102 51
3 32 20 153 102 51
39 32 20 153 102 51
2 31 20 153 102 51
1 30 20 153 102 51
0 29 20 153 102 51
4 4 22 153 102 51
0 34 22 153 102 51
5 1 20 153 102 51
2 7 22 153 102 51
4 2 20 153 102 51
3 8 22 153 102 51
3 3 20 153 102 51
36 34 22 153 102 51
2 4 20 153 102 51
1 5 20 153 102 51
0 6 20 153 102 51
8 17 24 153 102 51
8 16 24 153 102 51
8 38 20 153 102 51
34 38 20 153 102 51
7 37 20 153 102 51
35 37 20 153 102 51
6 36 20 153 102 51
36 36 20 153 102 51
5 35 20 153 102 51
37 35 20 153 102 51
4 34 20 153 102 51
38 34 20 153 102 51
3 33 20 153 102 51
39 33 20 153 102 51
2 32 20 153 102 51
1 31 20 153 102 51
0 30 20 153 102 51
4 9 22 153 102 51
37 33 22 153 102 51
4 1 20 153 102 51
5 10 22 153 102 51
3 2 20 153 102 51
6 11 22 153 102 51
2 3 20 153 102 51
1 4 20 153 102 51
0 5 20 153 102 51
8 15 24 153 102 51
8 14 24 153 102 51
7 38 20 153 102 51
35 38 20 153 102 51
6 37 20 153 102 51
36 37 20 153 102 51
5 36 20 153 102 51
37 36 20 153 102 51
4 35 20 153 102 51
38 35 20 153 102 51
3 34 20 153 102 51
39 34 20 153 102 51
2 33 20 153 102 51
1 32 20 153 102 51
0 31 20 153 102 51
8 13 24 153 102 51
7 12 22 153 102 51
3 1 20 153 102 51
8 13 22 153 102 51
2 2 20 153 102 51
1 3 20 153 102 51
0 4 20 153 102 51
8 12 24 153 102 51
9 27 25 153 102 51
6 38 20 153 102 51
36 38 20 153 102 51
5 37 20 153 102 51
37 37 20 153 102 51
4 36 20 153 102 51
38 36 20 153 102 51
3 35 20 153 102 51
39 35 20 153 102 51
2 34 20 153 102 51
1 33 20 153 102 51
0 32 20 153 102 51
3 0 20 153 102 51
38 32 22 153 102 51
2 1 20 153 102 51
1 2 20 153 102 51
0 3 20 153 102 51
9 26 25 153 102 51
9 25 25 153 102 51
5 38 20 153 102 51
37 38 20 153 102 51
4 37 20 153 102 51
38 37 20 153 102 51
3 36 20 153 102 51
39 36 20 153 102 51
2 35 20 153 102 51
1 34 20 153 102 51
0 33 20 153 102 51
2 0 20 153 102 51
1 1 20 153 102 51
0 2 20 153 102 51
9 24 25 153 102 51
9 23 25 153 102 51
4 38 20 153 102 51
38 38 20 153 102 51
3 37 20 153 102 51
39 37 20 153 102 51
2 36 20 153 102 51
1 35 20 153 102 51
0 34 20 153 102 51
1 0 20 153 102 51
0 1 20 153 102 51
9 22 25 153 102 51
9 21 25 153 102 51
3 38 20 153 102 51
39 38 20 153 102 51
2 37 20 153 102 51
1 36 20 153 102 51
0 35 20 153 102 51
0 0 20 153 102 51
9 20 25 153 102 51
9 19 25 153 102 51
2 38 20 153 102 51
1 37 20 153 102 51
0 36 20 153 102 51
9 18 25 153 102 51
1 38 20 153 102 51
0 37 20 153 102 51
9 17 25 153 102 51
0 38 20 153 102 51
9 16 25 153 102 51
9 14 22 153 102 51
39 31 22 153 102 51
10 15 22 153 102 51
11 16 22 153 102 51
12 17 22 153 102 51
13 18 22 153 102 51
14 19 22 153 102 51
9 15 25 153 102 51
9 14 25 153 102 51
3 6 22 153 102 51
4 5 22 153 102 51
3 38 22 153 102 51
3 7 22 153 102 51
4 8 22 153 102 51
33 38 22 153 102 51
5 9 22 153 102 51
2 37 22 153 102 51
6 10 22 153 102 51
7 11 22 153 102 51
34 37 22 153 102 51
8 12 22 153 102 51
1 36 22 153 102 51
9 13 22 153 102 51
10 14 22 153 102 51
11 15 22 153 102 51
12 16 22 153 102 51
13 17 22 153 102 51
35 36 22 153 102 51
0 35 22 153 102 51
36 35 22 153 102 51
37 34 22 153 102 51
4 6 22 153 102 51
5 5 22 153 102 51
38 33 22 153 102 51
4 7 22 153 102 51
5 8 22 153 102 51
6 9 22 153 102 51
39 32 22 153 102 51
7 10 22 153 102 51
9 13 25 153 102 51
8 11 22 153 102 51
9 12 22 153 102 51
10 13 22 153 102 51
11 14 22 153 102 51
12 15 22 153 102 51
13 16 22 153 102 51
9 12 25 153 102 51
2 38 22 153 102 51
34 38 22 153 102 51
1 37 22 153 102 51
5 6 22 153 102 51
35 37 22 153 102 51
5 7 22 153 102 51
6 8 22 153 102 51
7 9 22 153 102 51
8 10 22 153 102 51
9 11 22 153 102 51
10 12 22 153 102 51
11 13 22 153 102 51
12 14 22 153 102 51
13 15 22 153 102 51
0 36 22 153 102 51
36 36 22 153 102 51
37 35 22 153 102 51
38 34 22 153 102 51
6 7 22 153 102 51
7 8 22 153 102 51
8 9 22 153 102 51
9 10 22 153 102 51
10 11 22 153 102 51
11 12 22 153 102 51
39 33 22 153 102 51
6 27 23 153 102 51
6 26 23 153 102 51
1 38 22 153 102 51
35 38 22 153 102 51
0 37 22 153 102 51
36 37 22 153 102 51
37 36 22 153 102 51
9 9 22 153 102 51
10 10 22 153 102 51
38 35 22 153 102 51
39 34 22 153 102 51
6 25 23 153 102 51
6 24 23 153 102 51
0 38 22 153 102 51
36 38 22 153 102 51
37 37 22 153 102 51
38 36 22 153 102 51
39 35 22 153 102 51
6 23 23 153 102 51
6 22 23 153 102 51
37 38 22 153 102 51
38 37 22 153 102 51
39 36 22 153 102 51
6 21 23 153 102 51
38 38 22 153 102 51
39 37 22 153 102 51
6 20 23 153 102 51
6 19 23 153 102 51
39 38 21 153 102 51
6 18 23 153 102 51
39 37 21 153 102 51
38 38 21 153 102 51
6 17 23 153 102 51
39 36 21 153 102 51
38 37 21 153 102 51
37 38 21 153 102 51
6 16 23 153 102 51
6 15 23 153 102 51
39 35 21 153 102 51
38 36 21 153 102 51
37 37 21 153 102 51
36 38 21 153 102 51
0 38 21 153 102 51
6 14 23 153 102 51
6 13 23 153 102 51
39 34 21 153 102 51
38 35 21 153 102 51
37 36 21 153 102 51
36 37 21 153 102 51
0 37 21 153 102 51
35 38 21 153 102 51
1 38 21 153 102 51
6 12 23 153 102 51
7 27 24 153 102 51
39 33 21 153 102 51
38 34 21 153 102 51
18 16 21 153 102 51
37 35 21 153 102 51
36 36 21 153 102 51
0 36 21 153 102 51
35 37 21 153 102 51
1 37 21 153 102 51
34 38 21 153 102 51
2 38 21 153 102 51
7 26 24 153 102 51
7 25 24 153 102 51
39 32 21 153 102 51
38 33 21 153 102 51
37 34 21 153 102 51
11 9 21 153 102 51
36 35 21 153 102 51
10 8 21 153 102 51
0 35 21 153 102 51
35 36 21 153 102 51
1 36 21 153 102 51
34 37 21 153 102 51
2 37 21 153 102 51
33 38 21 153 102 51
3 38 21 153 102 51
7 24 24 153 102 51
7 23 24 153 102 51
39 31 21 153 102 51
38 32 21 153 102 51
37 33 21 153 102 51
36 34 21 153 102 51
0 34 21 153 102 51
35 35 21 153 102 51
1 35 21 153 102 51
34 36 21 153 102 51
2 36 21 153 102 51
17 16 21 153 102 51
17 33 21 153 102 51
16 15 21 153 102 51
33 37 21 153 102 51
3 37 21 153 102 51
32 38 21 153 102 51
4 38 21 153 102 51
7 22 24 153 102 51
7 21 24 153 102 51
39 30 21 153 102 51
12 11 21 153 102 51
38 31 21 153 102 51
11 10 21 153 102 51
37 32 21 153 102 51
10 9 21 153 102 51
36 33 21 153 102 51
9 8 21 153 102 51
0 33 21 153 102 51
35 34 21 153 102 51
1 34 21 153 102 51
34 35 21 153 102 51
2 35 21 153 102 51
33 36 21 153 102 51
3 36 21 153 102 51
32 37 21 153 102 51
4 37 21 153 102 51
31 38 21 153 102 51
5 38 21 153 102 51
7 20 24 153 102 51
7 19 24 153 102 51
39 29 21 153 102 51
38 30 21 153 102 51
37 31 21 153 102 51
36 32 21 153 102 51
0 32 21 153 102 51
35 33 21 153 102 51
1 33 21 153 102 51
16 16 21 153 102 51
18 34 21 153 102 51
15 15 21 153 102 51
34 34 21 153 102 51
14 14 21 153 102 51
2 34 21 153 102 51
13 13 21 153 102 51
33 35 21 153 102 51
12 12 21 153 102 51
3 35 21 153 102 51
11 11 21 153 102 51
32 36 21 153 102 51
10 10 21 153 102 51
4 36 21 153 102 51
9 9 21 153 102 51
31 37 21 153 102 51
8 8 21 153 102 51
5 37 21 153 102 51
30 38 21 153 102 51
6 38 21 153 102 51
7 18 24 153 102 51
7 17 24 153 102 51
39 28 21 153 102 51
38 29 21 153 102 51
37 30 21 153 102 51
36 31 21 153 102 51
0 31 21 153 102 51
35 32 21 153 102 51
1 32 21 153 102 51
34 33 21 153 102 51
2 33 21 153 102 51
33 34 21 153 102 51
8 7 21 153 102 51
3 34 21 153 102 51
32 35 21 153 102 51
4 35 21 153 102 51
31 36 21 153 102 51
5 36 21 153 102 51
19 35 21 153 102 51
15 16 21 153 102 51
30 37 21 153 102 51
14 15 21 153 102 51
6 37 21 153 102 51
13 14 21 153 102 51
29 38 21 153 102 51
12 13 21 153 102 51
7 38 21 153 102 51
11 12 21 153 102 51
7 16 24 153 102 51
10 11 21 153 102 51
7 15 24 153 102 51
9 10 21 153 102 51
39 27 21 153 102 51
8 9 21 153 102 51
38 28 21 153 102 51
7 8 21 153 102 51
37 29 21 153 102 51
36 30 21 153 102 51
0 30 21 153 102 51
35 31 21 153 102 51
1 31 21 153 102 51
34 32 21 153 102 51
2 32 21 153 102 51
33 33 21 153 102 51
3 33 21 153 102 51
32 34 21 153 102 51
4 34 21 153 102 51
31 35 21 153 102 51
5 35 21 153 102 51
30 36 21 153 102 51
6 36 21 153 102 51
7 7 21 153 102 51
29 37 21 153 102 51
7 37 21 153 102 51
28 38 21 153 102 51
8 38 21 153 102 51
7 14 24 153 102 51
7 13 24 153 102 51
15 17 21 153 102 51
11 27 21 153 102 51
14 16 21 153 102 51
38 27 21 153 102 51
13 15 21 153 102 51
37 28 21 153 102 51
12 14 21 153 102 51
36 29 21 153 102 51
11 13 21 153 102 51
0 29 21 153 102 51
10 12 21 153 102 51
35 30 21 153 102 51
9 11 21 153 102 51
1 30 21 153 102 51
8 10 21 153 102 51
34 31 21 153 102 51
7 9 21 153 102 51
2 31 21 153 102 51
6 8 21 153 102 51
33 32 21 153 102 51
3 32 21 153 102 51
32 33 21 153 102 51
4 33 21 153 102 51
31 34 21 153 102 51
5 34 21 153 102 51
30 35 21 153 102 51
6 35 21 153 102 51
29 36 21 153 102 51
7 36 21 153 102 51
28 37 21 153 102 51
8 37 21 153 102 51
27 38 21 153 102 51
7 6 21 153 102 51
9 38 21 153 102 51
6 7 21 153 102 51
7 12 24 153 102 51
8 27 25 153 102 51
37 27 21 153 102 51
36 28 21 153 102 51
0 28 21 153 102 51
35 29 21 153 102 51
15 18 21 153 102 51
24 28 21 153 102 51
14 17 21 153 102 51
12 28 21 153 102 51
13 16 21 153 102 51
1 29 21 153 102 51
12 15 21 153 102 51
34 30 21 153 102 51
11 14 21 153 102 51
2 30 21 153 102 51
10 13 21 153 102 51
33 31 21 153 102 51
9 12 21 153 102 51
3 31 21 153 102 51
8 11 21 153 102 51
7 24 21 153 102 51
7 10 21 153 102 51
6 23 21 153 102 51
6 9 21 153 102 51
32 32 21 153 102 51
5 8 21 153 102 51
4 32 21 153 102 51
31 33 21 153 102 51
5 33 21 153 102 51
30 34 21 153 102 51
6 34 21 153 102 51
29 35 21 153 102 51
7 35 21 153 102 51
28 36 21 153 102 51
8 36 21 153 102 51
27 37 21 153 102 51
9 37 21 153 102 51
26 38 21 153 102 51
10 38 21 153 102 51
6 6 21 153 102 51
8 26 25 153 102 51
5 7 21 153 102 51
8 25 25 153 102 51
0 27 21 153 102 51
35 28 21 153 102 51
1 28 21 153 102 51
16 20 21 153 102 51
34 29 21 153 102 51
15 19 21 153 102 51
2 29 21 153 102 51
14 18 21 153 102 51
23 29 21 153 102 51
13 17 21 153 102 51
33 30 21 153 102 51
12 16 21 153 102 51
3 30 21 153 102 51
11 15 21 153 102 51
32 31 21 153 102 51
10 14 21 153 102 51
4 31 21 153 102 51
9 13 21 153 102 51
0 16 21 153 102 51
8 12 21 153 102 51
5 22 21 153 102 51
7 11 21 153 102 51
31 32 21 153 102 51
6 10 21 153 102 51
1 17 21 153 102 51
5 9 21 153 102 51
4 21 21 153 102 51
4 8 21 153 102 51
5 32 21 153 102 51
30 33 21 153 102 51
6 33 21 153 102 51
29 34 21 153 102 51
7 34 21 153 102 51
28 35 21 153 102 51
8 35 21 153 102 51
27 36 21 153 102 51
9 36 21 153 102 51
26 37 21 153 102 51
10 37 21 153 102 51
6 5 21 153 102 51
25 38 21 153 102 51
5 6 21 153 102 51
11 38 21 153 102 51
4 7 21 153 102 51
8 24 25 153 102 51
8 23 25 153 102 51
0 26 21 153 102 51
35 27 21 153 102 51
16 21 21 153 102 51
1 27 21 153 102 51
15 20 21 153 102 51
34 28 21 153 102 51
14 19 21 153 102 51
2 28 21 153 102 51
13 18 21 153 102 51
33 29 21 153 102 51
12 17 21 153 102 51
3 29 21 153 102 51
11 16 21 153 102 51
32 30 21 153 102 51
10 15 21 153 102 51
2 18 21 153 102 51
9 14 21 153 102 51
3 20 21 153 102 51
8 13 21 153 102 51
4 30 21 153 102 51
7 12 21 153 102 51
31 31 21 153 102 51
6 11 21 153 102 51
5 31 21 153 102 51
5 10 21 153 102 51
3 19 21 153 102 51
4 9 21 153 102 51
2 19 21 153 102 51
3 8 21 153 102 51
30 32 21 153 102 51
6 32 21 153 102 51
29 33 21 153 102 51
7 33 21 153 102 51
28 34 21 153 102 51
8 34 21 153 102 51
27 35 21 153 102 51
9 35 21 153 102 51
26 36 21 153 102 51
6 4 21 153 102 51
10 36 21 153 102 51
5 5 21 153 102 51
25 37 21 153 102 51
4 6 21 153 102 51
11 37 21 153 102 51
3 7 21 153 102 51
24 38 21 153 102 51
12 38 21 153 102 51
8 22 25 153 102 51
8 21 25 153 102 51
16 22 21 153 102 51
0 25 21 153 102 51
15 21 21 153 102 51
1 26 21 153 102 51
14 20 21 153 102 51
34 27 21 153 102 51
13 19 21 153 102 51
22 30 21 153 102 51
12 18 21 153 102 51
2 27 21 153 102 51
11 17 21 153 102 51
33 28 21 153 102 51
10 16 21 153 102 51
4 20 21 153 102 51
9 15 21 153 102 51
1 18 21 153 102 51
8 14 21 153 102 51
3 28 21 153 102 51
7 13 21 153 102 51
32 29 21 153 102 51
6 12 21 153 102 51
4 29 21 153 102 51
5 11 21 153 102 51
31 30 21 153 102 51
4 10 21 153 102 51
5 30 21 153 102 51
3 9 21 153 102 51
5 21 21 153 102 51
2 8 21 153 102 51
30 31 21 153 102 51
6 31 21 153 102 51
29 32 21 153 102 51
7 32 21 153 102 51
28 33 21 153 102 51
8 33 21 153 102 51
27 34 21 153 102 51
9 34 21 153 102 51
26 35 21 153 102 51
5 4 21 153 102 51
10 35 21 153 102 51
4 5 21 153 102 51
25 36 21 153 102 51
3 6 21 153 102 51
11 36 21 153 102 51
2 7 21 153 102 51
24 37 21 153 102 51
12 37 21 153 102 51
17 24 21 153 102 51
23 38 21 153 102 51
16 23 21 153 102 51
13 38 21 153 102 51
15 22 21 153 102 51
8 20 25 153 102 51
14 21 21 153 102 51
8 19 25 153 102 51
13 20 21 153 102 51
20 32 21 153 102 51
12 19 21 153 102 51
0 24 21 153 102 51
11 18 21 153 102 51
1 25 21 153 102 51
10 17 21 153 102 51
0 17 21 153 102 51
9 16 21 153 102 51
2 26 21 153 102 51
8 15 21 153 102 51
33 27 21 153 102 51
7 14 21 153 102 51
3 27 21 153 102 51
6 13 21 153 102 51
32 28 21 153 102 51
5 12 21 153 102 51
4 28 21 153 102 51
4 11 21 153 102 51
31 29 21 153 102 51
3 10 21 153 102 51
5 29 21 153 102 51
2 9 21 153 102 51
6 22 21 153 102 51
1 8 21 153 102 51
30 30 21 153 102 51
6 30 21 153 102 51
29 31 21 153 102 51
7 31 21 153 102 51
28 32 21 153 102 51
8 32 21 153 102 51
27 33 21 153 102 51
5 3 21 153 102 51
9 33 21 153 102 51
4 4 21 153 102 51
26 34 21 153 102 51
3 5 21 153 102 51
10 34 21 153 102 51
2 6 21 153 102 51
25 35 21 153 102 51
1 7 21 153 102 51
11 35 21 153 102 51
18 26 21 153 102 51
17 25 21 153 102 51
24 36 21 153 102 51
16 24 21 153 102 51
12 36 21 153 102 51
15 23 21 153 102 51
23 37 21 153 102 51
14 22 21 153 102 51
13 37 21 153 102 51
13 21 21 153 102 51
22 38 21 153 102 51
12 20 21 153 102 51
13 29 21 153 102 51
11 19 21 153 102 51
14 38 21 153 102 51
10 18 21 153 102 51
18 36 21 153 102 51
9 17 21 153 102 51
8 18 25 153 102 51
8 16 21 153 102 51
8 17 25 153 102 51
7 15 21 153 102 51
0 23 21 153 102 51
6 14 21 153 102 51
1 24 21 153 102 51
5 13 21 153 102 51
2 25 21 153 102 51
4 12 21 153 102 51
3 26 21 153 102 51
3 11 21 153 102 51
32 27 21 153 102 51
2 10 21 153 102 51
4 27 21 153 102 51
1 9 21 153 102 51
31 28 21 153 102 51
0 8 21 153 102 51
5 28 21 153 102 51
30 29 21 153 102 51
6 29 21 153 102 51
29 30 21 153 102 51
7 30 21 153 102 51
5 2 21 153 102 51
28 31 21 153 102 51
4 3 21 153 102 51
8 31 21 153 102 51
3 4 21 153 102 51
27 32 21 153 102 51
2 5 21 153 102 51
9 32 21 153 102 51
1 6 21 153 102 51
26 33 21 153 102 51
0 7 21 153 102 51
10 33 21 153 102 51
18 27 21 153 102 51
17 26 21 153 102 51
19 26 21 153 102 51
16 25 21 153 102 51
25 34 21 153 102 51
15 24 21 153 102 51
11 34 21 153 102 51
14 23 21 153 102 51
24 35 21 153 102 51
13 22 21 153 102 51
12 35 21 153 102 51
12 21 21 153 102 51
23 36 21 153 102 51
11 20 21 153 102 51
13 36 21 153 102 51
10 19 21 153 102 51
7 23 21 153 102 51
9 18 21 153 102 51
22 37 21 153 102 51
8 17 21 153 102 51
14 37 21 153 102 51
7 16 21 153 102 51
21 38 21 153 102 51
6 15 21 153 102 51
15 38 21 153 102 51
5 14 21 153 102 51
8 16 25 153 102 51
4 13 21 153 102 51
8 15 25 153 102 51
3 12 21 153 102 51
0 22 21 153 102 51
2 11 21 153 102 51
1 23 21 153 102 51
1 10 21 153 102 51
2 24 21 153 102 51
0 9 21 153 102 51
3 25 21 153 102 51
4 26 21 153 102 51
31 27 21 153 102 51
5 27 21 153 102 51
5 1 21 153 102 51
30 28 21 153 102 51
4 2 21 153 102 51
6 28 21 153 102 51
3 3 21 153 102 51
29 29 21 153 102 51
2 4 21 153 102 51
7 29 21 153 102 51
1 5 21 153 102 51
28 30 21 153 102 51
0 6 21 153 102 51
8 30 21 153 102 51
27 31 21 153 102 51
18 28 21 153 102 51
17 27 21 153 102 51
19 27 21 153 102 51
16 26 21 153 102 51
9 31 21 153 102 51
15 25 21 153 102 51
26 32 21 153 102 51
14 24 21 153 102 51
10 32 21 153 102 51
13 23 21 153 102 51
25 33 21 153 102 51
12 22 21 153 102 51
11 33 21 153 102 51
11 21 21 153 102 51
17 35 21 153 102 51
10 20 21 153 102 51
8 24 21 153 102 51
9 19 21 153 102 51
24 34 21 153 102 51
8 18 21 153 102 51
12 34 21 153 102 51
7 17 21 153 102 51
23 35 21 153 102 51
6 16 21 153 102 51
13 35 21 153 102 51
5 15 21 153 102 51
22 36 21 153 102 51
4 14 21 153 102 51
14 36 21 153 102 51
3 13 21 153 102 51
21 37 21 153 102 51
2 12 21 153 102 51
15 37 21 153 102 51
1 11 21 153 102 51
20 38 21 153 102 51
0 10 21 153 102 51
16 38 21 153 102 51
8 14 25 153 102 51
8 13 25 153 102 51
0 21 21 153 102 51
1 22 21 153 102 51
4 1 21 153 102 51
2 23 21 153 102 51
3 2 21 153 102 51
3 24 21 153 102 51
2 3 21 153 102 51
4 25 21 153 102 51
1 4 21 153 102 51
31 26 21 153 102 51
0 5 21 153 102 51
5 26 21 153 102 51
30 27 21 153 102 51
6 27 21 153 102 51
18 29 21 153 102 51
17 28 21 153 102 51
19 28 21 153 102 51
16 27 21 153 102 51
20 27 21 153 102 51
15 26 21 153 102 51
29 28 21 153 102 51
14 25 21 153 102 51
7 28 21 153 102 51
13 24 21 153 102 51
28 29 21 153 102 51
12 23 21 153 102 51
8 29 21 153 102 51
11 22 21 153 102 51
27 30 21 153 102 51
10 21 21 153 102 51
27 25 21 153 102 51
9 20 21 153 102 51
9 30 21 153 102 51
8 19 21 153 102 51
26 31 21 153 102 51
7 18 21 153 102 51
10 31 21 153 102 51
6 17 21 153 102 51
25 32 21 153 102 51
5 16 21 153 102 51
11 32 21 153 102 51
4 15 21 153 102 51
24 33 21 153 102 51
3 14 21 153 102 51
12 33 21 153 102 51
2 13 21 153 102 51
23 34 21 153 102 51
1 12 21 153 102 51
13 34 21 153 102 51
0 11 21 153 102 51
22 35 21 153 102 51
14 35 21 153 102 51
21 36 21 153 102 51
15 36 21 153 102 51
39 38 22 153 102 51
20 37 21 153 102 51
3 1 21 153 102 51
16 37 21 153 102 51
2 2 21 153 102 51
19 38 21 153 102 51
1 3 21 153 102 51
17 38 21 153 102 51
0 4 21 153 102 51
8 12 25 153 102 51
0 20 21 153 102 51
1 21 21 153 102 51
2 22 21 153 102 51
18 30 21 153 102 51
17 29 21 153 102 51
19 29 21 153 102 51
16 28 21 153 102 51
20 28 21 153 102 51
15 27 21 153 102 51
21 27 21 153 102 51
14 26 21 153 102 51
3 23 21 153 102 51
13 25 21 153 102 51
4 24 21 153 102 51
12 24 21 153 102 51
5 25 21 153 102 51
11 23 21 153 102 51
30 26 21 153 102 51
10 22 21 153 102 51
6 26 21 153 102 51
9 21 21 153 102 51
29 27 21 153 102 51
8 20 21 153 102 51
7 27 21 153 102 51
7 19 21 153 102 51
28 28 21 153 102 51
6 18 21 153 102 51
8 28 21 153 102 51
5 17 21 153 102 51
27 29 21 153 102 51
4 16 21 153 102 51
9 29 21 153 102 51
3 15 21 153 102 51
26 30 21 153 102 51
2 14 21 153 102 51
10 30 21 153 102 51
1 13 21 153 102 51
25 31 21 153 102 51
0 12 21 153 102 51
11 31 21 153 102 51
24 32 21 153 102 51
12 32 21 153 102 51
23 33 21 153 102 51
3 0 21 153 102 51
13 33 21 153 102 51
2 1 21 153 102 51
22 34 21 153 102 51
1 2 21 153 102 51
14 34 21 153 102 51
0 3 21 153 102 51
21 35 21 153 102 51
15 35 21 153 102 51
20 36 21 153 102 51
16 36 21 153 102 51
18 31 21 153 102 51
17 30 21 153 102 51
19 30 21 153 102 51
16 29 21 153 102 51
20 29 21 153 102 51
15 28 21 153 102 51
21 28 21 153 102 51
14 27 21 153 102 51
22 27 21 153 102 51
13 26 21 153 102 51
23 26 21 153 102 51
12 25 21 153 102 51
19 37 21 153 102 51
11 24 21 153 102 51
17 37 21 153 102 51
10 23 21 153 102 51
18 38 21 153 102 51
9 22 21 153 102 51
0 19 21 153 102 51
8 21 21 153 102 51
1 20 21 153 102 51
7 20 21 153 102 51
2 21 21 153 102 51
6 19 21 153 102 51
3 22 21 153 102 51
5 18 21 153 102 51
4 23 21 153 102 51
4 17 21 153 102 51
5 24 21 153 102 51
3 16 21 153 102 51
6 25 21 153 102 51
2 15 21 153 102 51
29 26 21 153 102 51
1 14 21 153 102 51
7 26 21 153 102 51
0 13 21 153 102 51
28 27 21 153 102 51
8 27 21 153 102 51
27 28 21 153 102 51
9 28 21 153 102 51
2 0 21 153 102 51
26 29 21 153 102 51
1 1 21 153 102 51
10 29 21 153 102 51
0 2 21 153 102 51
25 30 21 153 102 51
11 30 21 153 102 51
24 31 21 153 102 51
12 31 21 153 102 51
18 32 21 153 102 51
17 31 21 153 102 51
19 31 21 153 102 51
16 30 21 153 102 51
20 30 21 153 102 51
15 29 21 153 102 51
21 29 21 153 102 51
14 28 21 153 102 51
22 28 21 153 102 51
13 27 21 153 102 51
23 27 21 153 102 51
12 26 21 153 102 51
24 26 21 153 102 51
11 25 21 153 102 51
23 32 21 153 102 51
10 24 21 153 102 51
13 32 21 153 102 51
9 23 21 153 102 51
22 33 21 153 102 51
8 22 21 153 102 51
14 33 21 153 102 51
7 21 21 153 102 51
21 34 21 153 102 51
6 20 21 153 102 51
15 34 21 153 102 51
5 19 21 153 102 51
20 35 21 153 102 51
4 18 21 153 102 51
16 35 21 153 102 51
3 17 21 153 102 51
19 36 21 153 102 51
2 16 21 153 102 51
17 36 21 153 102 51
1 15 21 153 102 51
18 37 21 153 102 51
0 14 21 153 102 51
0 18 21 153 102 51
1 19 21 153 102 51
2 20 21 153 102 51
3 21 21 153 102 51
1 0 21 153 102 51
4 22 21 153 102 51
0 1 21 153 102 51
5 23 21 153 102 51
6 24 21 153 102 51
7 25 21 153 102 51
28 26 21 153 102 51
18 33 21 153 102 51
17 32 21 153 102 51
19 32 21 153 102 51
16 31 21 153 102 51
20 31 21 153 102 51
15 30 21 153 102 51
21 30 21 153 102 51
14 29 21 153 102 51
22 29 21 153 102 51
13 28 21 153 102 51
23 28 21 153 102 51
12 27 21 153 102 51
24 27 21 153 102 51
11 26 21 153 102 51
25 26 21 153 102 51
10 25 21 153 102 51
8 26 21 153 102 51
9 24 21 153 102 51
27 27 21 153 102 51
8 23 21 153 102 51
9 27 21 153 102 51
7 22 21 153 102 51
26 28 21 153 102 51
6 21 21 153 102 51
10 28 21 153 102 51
5 20 21 153 102 51
25 29 21 153 102 51
4 19 21 153 102 51
11 29 21 153 102 51
3 18 21 153 102 51
24 30 21 153 102 51
2 17 21 153 102 51
12 30 21 153 102 51
1 16 21 153 102 51
23 31 21 153 102 51
0 15 21 153 102 51
13 31 21 153 102 51
22 32 21 153 102 51
14 32 21 153 102 51
21 33 21 153 102 51
0 0 21 153 102 51
15 33 21 153 102 51
20 34 21 153 102 51
37 33 23 153 102 51
38 33 23 153 102 51
39 33 23 153 102 51
35 34 23 153 102 51
36 34 23 153 102 51
37 34 23 153 102 51
38 34 23 153 102 51
39 34 23 153 102 51
34 35 23 153 102 51
35 35 23 153 102 51
36 35 23 153 102 51
37 35 23 153 102 51
38 35 23 153 102 51
39 35 23 153 102 51
34 36 23 153 102 51
35 36 23 153 102 51
36 36 23 153 102 51
37 36 23 153 102 51
38 36 23 153 102 51
39 36 23 153 102 51
33 37 23 153 102 51
34 37 23 153 102 51
35 37 23 153 102 51
36 37 23 153 102 51
37 37 23 153 102 51
38 37 23 153 102 51
39 37 23 153 102 51
33 38 23 153 102 51
34 38 23 153 102 51
35 38 23 153 102 51
36 38 23 153 102 51
37 38 23 153 102 51
38 38 23 153 102 51
39 38 23 153 102 51
9 27 26 153 102 51
9 26 26 153 102 51
9 25 26 153 102 51
9 24 26 153 102 51
9 23 26 153 102 51
9 22 26 153 102 51
9 21 26 153 102 51
9 20 26 153 102 51
9 19 26 153 102 51
9 18 26 153 102 51
30 38 23 153 102 51
29 38 23 153 102 51
28 38 23 153 102 51
27 38 23 153 102 51
26 38 23 153 102 51
25 38 23 153 102 51
9 17 26 153 102 51
9 16 26 153 102 51
9 15 26 153 102 51
9 14 26 153 102 51
9 13 26 153 102 51
31 38 23 153 102 51
32 38 23 153 102 51
28 34 23 153 102 51
28 35 23 153 102 51
28 36 23 153 102 51
28 37 23 153 102 51
27 34 23 153 102 51
27 35 23 153 102 51
27 36 23 153 102 51
27 37 23 153 102 51
29 34 23 153 102 51
29 35 23 153 102 51
29 36 23 153 102 51
29 37 23 153 102 51
26 34 23 153 102 51
26 35 23 153 102 51
26 36 23 153 102 51
26 37 23 153 102 51
30 34 23 153 102 51
30 35 23 153 102 51
30 36 23 153 102 51
30 37 23 153 102 51
25 34 23 153 102 51
25 35 23 153 102 51
25 36 23 153 102 51
25 37 23 153 102 51
31 34 23 153 102 51
31 35 23 153 102 51
31 36 23 153 102 51
31 37 23 153 102 51
32 34 23 153 102 51
32 35 23 153 102 51
32 36 23 153 102 51
32 37 23 153 102 51
33 31 23 153 102 51
33 32 23 153 102 51
33 33 23 153 102 51
33 34 23 153 102 51
33 35 23 153 102 51
33 36 23 153 102 51
34 31 23 153 102 51
34 32 23 153 102 51
34 33 23 153 102 51
34 34 23 153 102 51
36 31 23 153 102 51
36 32 23 153 102 51
36 33 23 153 102 51
35 31 23 153 102 51
35 32 23 153 102 51
35 33 23 153 102 51
38 31 23 153 102 51
38 32 23 153 102 51
37 31 23 153 102 51
37 32 23 153 102 51
39 31 23 153 102 51
39 32 23 153 102 51
36 33 24 153 102 51
36 33 25 153 102 51
36 33 26 153 102 51
36 33 27 153 102 51
36 33 28 153 102 51
36 33 29 153 102 51
36 33 30 153 102 51
36 33 31 153 102 51
36 33 32 153 102 51
36 33 33 153 102 51
36 33 34 153 102 51
36 33 35 153 102 51
36 33 36 153 102 51
36 33 37 153 102 51
36 33 38 153 102 51
36 33 39 153 102 51
36 33 40 153 102 51
36 33 41 153 102 51
36 33 42 153 102 51
36 32 24 153 102 51
36 32 25 153 102 51
36 32 26 153 102 51
36 32 27 153 102 51
36 32 28 153 102 51
36 32 29 153 102 51
36 32 30 153 102 51
36 32 31 153 102 51
36 32 32 153 102 51
36 32 33 153 102 51
36 32 34 153 102 51
36 32 35 153 102 51
36 32 36 153 102 51
36 32 37 153 102 51
36 32 38 153 102 51
36 32 39 153 102 51
36 32 40 153 102 51
36 32 41 153 102 51
36 32 42 153 102 51
36 34 24 153 102 51
36 34 25 153 102 51
36 34 26 153 102 51
36 34 27 153 102 51
36 34 28 153 102 51
36 34 29 153 102 51
36 34 30 153 102 51
36 34 31 153 102 51
36 34 32 153 102 51
36 34 33 153 102 51
36 34 34 153 102 51
36 34 35 153 102 51
36 34 36 153 102 51
36 34 37 153 102 51
36 34 38 153 102 51
36 34 39 153 102 51
36 34 40 153 102 51
36 34 41 153 102 51
36 34 42 153 102 51
35 33 24 153 102 51
35 33 25 153 102 51
35 33 26 153 102 51
35 33 27 153 102 51
35 33 28 153 102 51
35 33 29 153 102 51
35 33 30 153 102 51
35 33 31 153 102 51
35 33 32 153 102 51
35 33 33 153 102 51
35 33 34 153 102 51
35 33 35 153 102 51
35 33 36 153 102 51
35 33 37 153 102 51
35 33 38 153 102 51
35 33 39 153 102 51
35 33 40 153 102 51
35 33 41 153 102 51
35 33 42 153 102 51
37 33 24 153 102 51
37 33 25 153 102 51
37 33 26 153 102 51
37 33 27 153 102 51
37 33 28 153 102 51
37 33 29 153 102 51
37 33 30 153 102 51
37 33 31 153 102 51
37 33 32 153 102 51
37 33 33 153 102 51
37 33 34 153 102 51
37 33 35 153 102 51
37 33 36 153 102 51
37 33 37 153 102 51
37 33 38 153 102 51
37 33 39 153 102 51
37 33 40 153 102 51
37 33 41 153 102 51
37 33 42 153 102 51
36 31 24 153 102 51
36 31 25 153 102 51
36 31 26 153 102 51
36 31 27 153 102 51
36 31 28 153 102 51
36 31 29 153 102 51
36 31 30 153 102 51
36 31 31 153 102 51
36 31 32 153 102 51
36 31 33 153 102 51
36 31 34 153 102 51
36 31 35 153 102 51
36 31 36 153 102 51
36 31 37 153 102 51
36 31 38 153 102 51
36 31 39 153 102 51
36 31 40 153 102 51
36 31 41 153 102 51
36 31 42 153 102 51
35 32 24 153 102 51
35 32 25 153 102 51
35 32 26 153 102 51
35 32 27 153 102 51
35 32 28 153 102 51
35 32 29 153 102 51
35 32 30 153 102 51
35 32 31 153 102 51
35 32 32 153 102 51
35 32 33 153 102 51
35 32 34 153 102 51
35 32 35 153 102 51
35 32 36 153 102 51
35 32 37 153 102 51
35 32 38 153 102 51
35 32 39 153 102 51
35 32 40 153 102 51
35 32 41 153 102 51
35 32 42 153 102 51
37 32 24 153 102 51
37 32 25 153 102 51
37 32 26 153 102 51
37 32 27 153 102 51
37 32 28 153 102 51
37 32 29 153 102 51
37 32 30 153 102 51
37 32 31 153 102 51
37 32 32 153 102 51
37 32 33 153 102 51
37 32 34 153 102 51
37 32 35 153 102 51
37 32 36 153 102 51
37 32 37 153 102 51
37 32 38 153 102 51
37 32 39 153 102 51
37 32 40 153 102 51
37 32 41 153 102 51
37 32 42 153 102 51
36 35 24 153 102 51
36 35 25 153 102 51
36 35 26 153 102 51
36 35 27 153 102 51
36 35 28 153 102 51
36 35 29 153 102 51
36 35 30 153 102 51
36 35 31 153 102 51
36 35 32 153 102 51
36 35 33 153 102 51
36 35 34 153 102 51
36 35 35 153 102 51
36 35 36 153 102 51
36 35 37 153 102 51
36 35 38 153 102 51
36 35 39 153 102 51
36 35 40 153 102 51
36 35 41 153 102 51
36 35 42 153 102 51
35 34 24 153 102 51
35 34 25 153 102 51
35 34 26 153 102 51
35 34 27 153 102 51
35 34 28 153 102 51
35 34 29 153 102 51
35 34 30 153 102 51
35 34 31 153 102 51
35 34 32 153 102 51
35 34 33 153 102 51
35 34 34 153 102 51
35 34 35 153 102 51
35 34 36 153 102 51
35 34 37 153 102 51
35 34 38 153 102 51
35 34 39 153 102 51
35 34 40 153 102 51
35 34 41 153 102 51
35 34 42 153 102 51
37 34 24 153 102 51
37 34 25 153 102 51
37 34 26 153 102 51
37 34 27 153 102 51
37 34 28 153 102 51
37 34 29 153 102 51
37 34 30 153 102 51
37 34 31 153 102 51
37 34 32 153 102 51
37 34 33 153 102 51
37 34 34 153 102 51
37 34 35 153 102 51
37 34 36 153 102 51
37 34 37 153 102 51
37 34 38 153 102 51
37 34 39 153 102 51
37 34 40 153 102 51
37 34 41 153 102 51
37 34 42 153 102 51
34 33 24 153 102 51
34 33 25 153 102 51
34 33 26 153 102 51
34 33 27 153 102 51
34 33 28 153 102 51
34 33 29 153 102 51
34 33 30 153 102 51
34 33 31 153 102 51
34 33 32 153 102 51
34 33 33 153 102 51
34 33 34 153 102 51
34 33 35 153 102 51
34 33 36 153 102 51
34 33 37 153 102 51
34 33 38 153 102 51
34 33 39 153 102 51
34 33 40 153 102 51
34 33 41 153 102 51
34 33 42 153 102 51
38 33 24 153 102 51
38 33 25 153 102 51
38 33 26 153 102 51
38 33 27 153 102 51
38 33 28 153 102 51
38 33 29 153 102 51
38 33 30 153 102 51
38 33 31 153 102 51
38 33 32 153 102 51
38 33 33 153 102 51
38 33 34 153 102 51
38 33 35 153 102 51
38 33 36 153 102 51
38 33 37 153 102 51
38 33 38 153 102 51
38 33 39 153 102 51
38 33 40 153 102 51
38 33 41 153 102 51
38 33 42 153 102 51
35 31 24 153 102 51
35 31 25 153 102 51
35 31 26 153 102 51
35 31 27 153 102 51
35 31 28 153 102 51
35 31 29 153 102 51
35 31 30 153 102 51
35 31 31 153 102 51
35 31 32 153 102 51
35 31 33 153 102 51
35 31 34 153 102 51
35 31 35 153 102 51
35 31 36 153 102 51
35 31 37 153 102 51
35 31 38 153 102 51
35 31 39 153 102 51
35 31 40 0 153 0
35 31 41 0 153 0
35 31 42 0 153 0
37 31 24 153 102 51
37 31 25 153 102 51
37 31 26 153 102 51
37 31 27 153 102 51
37 31 28 153 102 51
37 31 29 153 102 51
37 31 30 153 102 51
37 31 31 153 102 51
37 31 32 153 102 51
37 31 33 153 102 51
37 31 34 153 102 51
37 31 35 153 102 51
37 31 36 153 102 51
37 31 37 153 102 51
37 31 38 153 102 51
37 31 39 0 153 0
37 31 40 0 153 0
37 31 41 0 153 0
37 31 42 0 153 0
34 32 24 153 102 51
34 32 25 153 102 51
34 32 26 153 102 51
34 32 27 153 102 51
34 32 28 153 102 51
34 32 29 153 102 51
34 32 30 153 102 51
34 32 31 153 102 51
34 32 32 153 102 51
34 32 33 153 102 51
34 32 34 153 102 51
34 32 35 153 102 51
34 32 36 153 102 51
34 32 37 153 102 51
34 32 38 153 102 51
34 32 39 153 102 51
34 32 40 153 102 51
34 32 41 153 102 51
34 32 42 153 102 51
38 32 24 153 102 51
38 32 25 153 102 51
38 32 26 153 102 51
38 32 27 153 102 51
38 32 28 153 102 51
38 32 29 153 102 51
38 32 30 153 102 51
38 32 31 153 102 51
38 32 32 153 102 51
38 32 33 153 102 51
38 32 34 153 102 51
38 32 35 153 102 51
38 32 36 153 102 51
38 32 37 153 102 51
38 32 38 153 102 51
38 32 39 153 102 51
38 32 40 153 102 51
38 32 41 153 102 51
38 32 42 153 102 51
36 36 24 153 102 51
36 36 25 153 102 51
36 36 26 153 102 51
36 36 27 153 102 51
36 36 28 153 102 51
36 36 29 153 102 51
36 36 30 153 102 51
36 36 31 153 102 51
36 36 32 153 102 51
36 36 33 153 102 51
36 36 34 153 102 51
36 36 35 153 102 51
36 36 36 153 102 51
36 36 37 153 102 51
36 36 38 153 102 51
36 36 39 153 102 51
36 36 40 153 102 51
36 36 41 153 102 51
36 36 42 153 102 51
35 35 24 153 102 51
35 35 25 153 102 51
35 35 26 153 102 51
35 35 27 153 102 51
35 35 28 153 102 51
35 35 29 153 102 51
35 35 30 153 102 51
35 35 31 153 102 51
35 35 32 153 102 51
35 35 33 153 102 51
35 35 34 153 102 51
35 35 35 153 102 51
35 35 36 153 102 51
35 35 37 153 102 51
35 35 38 153 102 51
35 35 39 153 102 51
35 35 40 153 102 51
35 35 41 153 102 51
35 35 42 153 102 51
37 35 24 153 102 51
37 35 25 153 102 51
37 35 26 153 102 51
37 35 27 153 102 51
37 35 28 153 102 51
37 35 29 153 102 51
37 35 30 153 102 51
37 35 31 153 102 51
37 35 32 153 102 51
37 35 33 153 102 51
37 35 34 153 102 51
37 35 35 153 102 51
37 35 36 153 102 51
37 35 37 153 102 51
37 35 38 153 102 51
37 35 39 153 102 51
37 35 40 153 102 51
37 35 41 153 102 51
37 35 42 153 102 51
34 34 24 153 102 51
34 34 25 153 102 51
34 34 26 153 102 51
34 34 27 153 102 51
34 34 28 153 102 51
34 34 29 153 102 51
34 34 30 153 102 51
34 34 31 153 102 51
34 34 32 153 102 51
34 34 33 153 102 51
34 34 34 153 102 51
34 34 35 153 102 51
34 34 36 153 102 51
34 34 37 153 102 51
34 34 38 153 102 51
34 34 39 153 102 51
34 34 40 153 102 51
34 34 41 153 102 51
34 34 42 153 102 51
38 34 24 153 102 51
38 34 25 153 102 51
38 34 26 153 102 51
38 34 27 153 102 51
38 34 28 153 102 51
38 34 29 153 102 51
38 34 30 153 102 51
38 34 31 153 102 51
38 34 32 153 102 51
38 34 33 153 102 51
38 34 34 153 102 51
38 34 35 153 102 51
38 34 36 153 102 51
38 34 37 153 102 51
38 34 38 153 102 51
38 34 39 153 102 51
38 34 40 153 102 51
38 34 41 153 102 51
38 34 42 153 102 51
33 33 24 153 102 51
33 33 25 153 102 51
33 33 26 153 102 51
33 33 27 153 102 51
33 33 28 153 102 51
33 33 29 153 102 51
33 33 30 153 102 51
33 33 31 153 102 51
33 33 32 153 102 51
33 33 33 153 102 51
33 33 34 153 102 51
33 33 35 153 102 51
33 33 36 153 102 51
33 33 37 153 102 51
33 33 38 153 102 51
33 33 39 153 102 51
33 33 40 153 102 51
33 33 41 153 102 51
33 33 42 153 102 51
39 33 24 153 102 51
39 33 25 153 102 51
39 33 26 153 102 51
39 33 27 153 102 51
39 33 28 153 102 51
39 33 29 153 102 51
39 33 30 153 102 51
39 33 31 153 102 51
39 33 32 153 102 51
39 33 33 153 102 51
39 33 34 153 102 51
39 33 35 153 102 51
39 33 36 153 102 51
39 33 37 153 102 51
39 33 38 153 102 51
39 33 39 153 102 51
39 33 40 153 102 51
39 33 41 153 102 51
39 33 42 153 102 51
34 31 24 153 102 51
34 31 25 153 102 51
34 31 26 153 102 51
34 31 27 153 102 51
34 31 28 153 102 51
34 31 29 153 102 51
34 31 30 153 102 51
34 31 31 153 102 51
34 31 32 153 102 51
34 31 33 153 102 51
34 31 34 153 102 51
34 31 35 153 102 51
34 31 36 153 102 51
34 31 37 153 102 51
34 31 38 153 102 51
34 31 39 153 102 51
34 31 40 153 102 51
34 31 41 153 102 51
34 31 42 0 153 0
38 31 24 153 102 51
38 31 25 153 102 51
38 31 26 153 102 51
38 31 27 153 102 51
38 31 28 153 102 51
38 31 29 153 102 51
38 31 30 153 102 51
38 31 31 153 102 51
38 31 32 153 102 51
38 31 33 153 102 51
38 31 34 153 102 51
38 31 35 153 102 51
38 31 36 153 102 51
38 31 37 153 102 51
38 31 38 153 102 51
38 31 39 153 102 51
38 31 40 0 153 0
38 31 41 0 153 0
38 31 42 0 153 0
33 32 24 153 102 51
33 32 25 153 102 51
33 32 26 153 102 51
33 32 27 153 102 51
33 32 28 153 102 51
33 32 29 153 102 51
33 32 30 153 102 51
33 32 31 153 102 51
33 32 32 153 102 51
33 32 33 153 102 51
33 32 34 153 102 51
33 32 35 153 102 51
33 32 36 153 102 51
33 32 37 153 102 51
33 32 38 153 102 51
33 32 39 153 102 51
33 32 40 153 102 51
33 32 41 153 102 51
33 32 42 153 102 51
39 32 24 153 102 51
39 32 25 153 102 51
39 32 26 153 102 51
39 32 27 153 102 51
39 32 28 153 102 51
39 32 29 153 102 51
39 32 30 153 102 51
39 32 31 153 102 51
39 32 32 153 102 51
39 32 33 153 102 51
39 32 34 153 102 51
39 32 35 153 102 51
39 32 36 153 102 51
39 32 37 153 102 51
39 32 38 153 102 51
39 32 39 153 102 51
39 32 40 0 153 0
39 32 41 0 153 0
39 32 42 0 153 0
36 37 24 153 102 51
36 37 25 153 102 51
36 37 26 153 102 51
36 37 27 153 102 51
36 37 28 153 102 51
36 37 29 153 102 51
36 37 30 153 102 51
36 37 31 153 102 51
36 37 32 153 102 51
36 37 33 153 102 51
36 37 34 153 102 51
36 37 35 153 102 51
36 37 36 153 102 51
36 37 37 153 102 51
36 37 38 153 102 51
36 37 39 153 102 51
36 37 40 153 102 51
36 37 41 153 102 51
36 37 42 153 102 51
35 36 24 153 102 51
35 36 25 153 102 51
35 36 26 153 102 51
35 36 27 153 102 51
35 36 28 153 102 51
35 36 29 153 102 51
35 36 30 153 102 51
35 36 31 153 102 51
35 36 32 153 102 51
35 36 33 153 102 51
35 36 34 153 102 51
35 36 35 153 102 51
35 36 36 153 102 51
35 36 37 153 102 51
35 36 38 153 102 51
35 36 39 153 102 51
35 36 40 153 102 51
35 36 41 153 102 51
35 36 42 153 102 51
37 36 24 153 102 51
37 36 25 153 102 51
37 36 26 153 102 51
37 36 27 153 102 51
37 36 28 153 102 51
37 36 29 153 102 51
37 36 30 153 102 51
37 36 31 153 102 51
37 36 32 153 102 51
37 36 33 153 102 51
37 36 34 153 102 51
37 36 35 153 102 51
37 36 36 153 102 51
37 36 37 153 102 51
37 36 38 153 102 51
37 36 39 153 102 51
37 36 40 153 102 51
37 36 41 153 102 51
37 36 42 153 102 51
34 35 24 153 102 51
34 35 25 153 102 51
34 35 26 153 102 51
34 35 27 153 102 51
34 35 28 153 102 51
34 35 29 153 102 51
34 35 30 153 102 51
34 35 31 153 102 51
34 35 32 153 102 51
34 35 33 153 102 51
34 35 34 153 102 51
34 35 35 153 102 51
34 35 36 153 102 51
34 35 37 153 102 51
34 35 38 153 102 51
34 35 39 153 102 51
34 35 40 153 102 51
34 35 41 153 102 51
34 35 42 153 102 51
38 35 24 153 102 51
38 35 25 153 102 51
38 35 26 153 102 51
38 35 27 153 102 51
38 35 28 153 102 51
38 35 29 153 102 51
38 35 30 153 102 51
38 35 31 153 102 51
38 35 32 153 102 51
38 35 33 153 102 51
38 35 34 153 102 51
38 35 35 153 102 51
38 35 36 153 102 51
38 35 37 153 102 51
38 35 38 153 102 51
38 35 39 153 102 51
38 35 40 153 102 51
38 35 41 153 102 51
38 35 42 153 102 51
33 34 24 153 102 51
33 34 25 153 102 51
33 34 26 153 102 51
33 34 27 153 102 51
33 34 28 153 102 51
33 34 29 153 102 51
33 34 30 153 102 51
33 34 31 153 102 51
33 34 32 153 102 51
33 34 33 153 102 51
33 34 34 153 102 51
33 34 35 153 102 51
33 34 36 153 102 51
33 34 37 153 102 51
33 34 38 153 102 51
33 34 39 153 102 51
33 34 40 153 102 51
33 34 41 153 102 51
33 34 42 17 17 17
39 34 24 153 102 51
39 34 25 153 102 51
39 34 26 153 102 51
39 34 27 153 102 51
39 34 28 153 102 51
39 34 29 153 102 51
39 34 30 153 102 51
39 34 31 153 102 51
39 34 32 153 102 51
39 34 33 153 102 51
39 34 34 153 102 51
39 34 35 153 102 51
39 34 36 153 102 51
39 34 37 153 102 51
39 34 38 153 102 51
39 34 39 153 102 51
39 34 40 153 102 51
39 34 41 153 102 51
39 34 42 153 102 51
33 31 24 153 102 51
33 31 25 153 102 51
33 31 26 153 102 51
33 31 27 153 102 51
33 31 28 153 102 51
33 31 29 153 102 51
33 31 30 153 102 51
33 31 31 153 102 51
33 31 32 153 102 51
33 31 33 153 102 51
33 31 34 153 102 51
33 31 35 153 102 51
33 31 36 153 102 51
33 31 37 153 102 51
33 31 38 153 102 51
33 31 39 153 102 51
33 31 40 153 102 51
33 31 41 153 102 51
33 31 42 153 102 51
39 31 24 153 102 51
39 31 25 153 102 51
39 31 26 153 102 51
39 31 27 153 102 51
39 31 28 153 102 51
39 31 29 153 102 51
39 31 30 153 102 51
39 31 31 153 102 51
39 31 32 153 102 51
39 31 33 153 102 51
39 31 34 153 102 51
39 31 35 153 102 51
39 31 36 153 102 51
39 31 37 153 102 51
39 31 38 0 153 0
39 31 39 0 153 0
39 31 40 0 153 0
39 31 41 0 153 0
39 31 42 0 153 0
36 38 24 153 102 51
36 38 25 153 102 51
36 38 26 153 102 51
36 38 27 153 102 51
36 38 28 153 102 51
36 38 29 153 102 51
36 38 30 153 102 51
36 38 31 153 102 51
36 38 32 153 102 51
36 38 33 153 102 51
36 38 34 153 102 51
36 38 35 153 102 51
36 38 36 153 102 51
36 38 37 153 102 51
36 38 38 153 102 51
36 38 39 153 102 51
36 38 40 153 102 51
36 38 41 153 102 51
36 38 42 153 102 51
35 37 24 153 102 51
35 37 25 153 102 51
35 37 26 153 102 51
35 37 27 153 102 51
35 37 28 153 102 51
35 37 29 153 102 51
35 37 30 153 102 51
35 37 31 153 102 51
35 37 32 153 102 51
35 37 33 153 102 51
35 37 34 153 102 51
35 37 35 153 102 51
35 37 36 153 102 51
35 37 37 153 102 51
35 37 38 153 102 51
35 37 39 153 102 51
35 37 40 153 102 51
35 37 41 153 102 51
35 37 42 153 102 51
37 37 24 153 102 51
37 37 25 153 102 51
37 37 26 153 102 51
37 37 27 153 102 51
37 37 28 153 102 51
37 37 29 153 102 51
37 37 30 153 102 51
37 37 31 153 102 51
37 37 32 153 102 51
37 37 33 153 102 51
37 37 34 153 102 51
37 37 35 153 102 51
37 37 36 153 102 51
37 37 37 153 102 51
37 37 38 153 102 51
37 37 39 153 102 51
37 37 40 153 102 51
37 37 41 153 102 51
37 37 42 153 102 51
34 36 24 153 102 51
34 36 25 153 102 51
34 36 26 153 102 51
34 36 27 153 102 51
34 36 28 153 102 51
34 36 29 153 102 51
34 36 30 153 102 51
34 36 31 153 102 51
34 36 32 153 102 51
34 36 33 153 102 51
34 36 34 153 102 51
34 36 35 153 102 51
34 36 36 153 102 51
34 36 37 153 102 51
34 36 38 153 102 51
34 36 39 153 102 51
34 36 40 153 102 51
34 36 41 153 102 51
34 36 42 153 102 51
38 36 24 153 102 51
38 36 25 153 102 51
38 36 26 153 102 51
38 36 27 153 102 51
38 36 28 153 102 51
38 36 29 153 102 51
38 36 30 153 102 51
38 36 31 153 102 51
38 36 32 153 102 51
38 36 33 153 102 51
38 36 34 153 102 51
38 36 35 153 102 51
38 36 36 153 102 51
38 36 37 153 102 51
38 36 38 153 102 51
38 36 39 153 102 51
38 36 40 153 102 51
38 36 41 153 102 51
38 36 42 153 102 51
33 35 24 153 102 51
33 35 25 153 102 51
33 35 26 153 102 51
33 35 27 153 102 51
33 35 28 153 102 51
33 35 29 153 102 51
33 35 30 153 102 51
33 35 31 153 102 51
33 35 32 153 102 51
33 35 33 153 102 51
33 35 34 153 102 51
33 35 35 153 102 51
33 35 36 153 102 51
33 35 37 153 102 51
33 35 38 153 102 51
33 35 39 153 102 51
33 35 40 153 102 51
33 35 41 153 102 51
33 35 42 17 17 17
39 35 24 153 102 51
39 35 25 153 102 51
39 35 26 153 102 51
39 35 27 153 102 51
39 35 28 153 102 51
39 35 29 153 102 51
39 35 30 153 102 51
39 35 31 153 102 51
39 35 32 153 102 51
39 35 33 153 102 51
39 35 34 153 102 51
39 35 35 153 102 51
39 35 36 153 102 51
39 35 37 153 102 51
39 35 38 153 102 51
39 35 39 153 102 51
39 35 40 0 153 0
39 35 41 0 153 0
39 35 42 0 153 0
32 34 24 153 102 51
32 34 25 153 102 51
32 34 26 153 102 51
32 27 23 153 102 51
32 27 22 153 102 51
31 26 24 153 102 51
31 26 23 153 102 51
31 26 22 153 102 51
5 1 23 153 102 51
5 1 22 153 102 51
5 1 24 153 102 51
4 1 24 153 102 51
4 1 23 153 102 51
4 1 22 153 102 51
31 27 24 153 102 51
34 27 22 153 102 51
1 15 25 153 102 51
1 14 25 153 102 51
32 34 42 17 17 17
9 12 26 153 102 51
0 27 23 153 102 51
0 26 23 153 102 51
0 25 23 153 102 51
0 24 23 153 102 51
0 23 23 153 102 51
0 22 23 153 102 51
0 21 23 153 102 51
0 20 23 153 102 51
0 19 23 153 102 51
0 18 23 153 102 51
0 17 23 153 102 51
0 16 23 153 102 51
0 15 23 153 102 51
0 14 23 153 102 51
0 13 23 153 102 51
0 12 23 153 102 51
5 27 23 153 102 51
5 26 23 153 102 51
35 38 24 153 102 51
35 38 25 153 102 51
35 38 26 153 102 51
35 38 27 153 102 51
35 38 28 153 102 51
35 38 29 153 102 51
35 38 30 153 102 51
35 38 31 153 102 51
35 38 32 153 102 51
35 38 33 153 102 51
35 38 34 153 102 51
35 38 35 153 102 51
35 38 36 153 102 51
35 38 37 153 102 51
35 38 38 153 102 51
35 38 39 153 102 51
35 38 40 153 102 51
35 38 41 153 102 51
35 38 42 153 102 51
37 38 24 153 102 51
37 38 25 153 102 51
37 38 26 153 102 51
37 38 27 153 102 51
37 38 28 153 102 51
37 38 29 153 102 51
37 38 30 153 102 51
37 38 31 153 102 51
37 38 32 153 102 51
37 38 33 153 102 51
37 38 34 153 102 51
37 38 35 153 102 51
37 38 36 153 102 51
37 38 37 153 102 51
37 38 38 153 102 51
37 38 39 153 102 51
37 38 40 153 102 51
37 38 41 153 102 51
37 38 42 153 102 51
34 37 24 153 102 51
34 37 25 153 102 51
34 37 26 153 102 51
34 37 27 153 102 51
34 37 28 153 102 51
34 37 29 153 102 51
34 37 30 153 102 51
34 37 31 153 102 51
34 37 32 153 102 51
34 37 33 153 102 51
34 37 34 153 102 51
34 37 35 153 102 51
34 37 36 153 102 51
34 37 37 153 102 51
34 37 38 153 102 51
34 37 39 153 102 51
34 37 40 153 102 51
34 37 41 153 102 51
34 37 42 153 102 51
38 37 24 153 102 51
38 37 25 153 102 51
38 37 26 153 102 51
38 37 27 153 102 51
38 37 28 153 102 51
38 37 29 153 102 51
38 37 30 153 102 51
38 37 31 153 102 51
38 37 32 153 102 51
38 37 33 153 102 51
38 37 34 153 102 51
38 37 35 153 102 51
38 37 36 153 102 51
38 37 37 153 102 51
38 37 38 153 102 51
38 37 39 153 102 51
38 37 40 153 102 51
38 37 41 153 102 51
38 37 42 153 102 51
33 36 24 153 102 51
33 36 25 153 102 51
33 36 26 153 102 51
33 36 27 153 102 51
33 36 28 153 102 51
33 36 29 153 102 51
33 36 30 153 102 51
33 36 31 153 102 51
33 36 32 153 102 51
33 36 33 153 102 51
33 36 34 153 102 51
33 36 35 153 102 51
33 36 36 153 102 51
33 36 37 153 102 51
33 36 38 153 102 51
33 36 39 153 102 51
33 36 40 153 102 51
33 36 41 153 102 51
33 36 42 17 17 17
39 36 24 153 102 51
39 36 25 153 102 51
39 36 26 153 102 51
39 36 27 153 102 51
39 36 28 153 102 51
39 36 29 153 102 51
39 36 30 153 102 51
39 36 31 153 102 51
39 36 32 153 102 51
39 36 33 153 102 51
39 36 34 153 102 51
39 36 35 153 102 51
39 36 36 153 102 51
39 36 37 153 102 51
39 36 38 153 102 51
39 36 39 153 102 51
39 36 40 153 102 51
39 36 41 0 153 0
39 36 42 0 153 0
32 35 24 153 102 51
32 35 25 153 102 51
32 35 26 153 102 51
14 14 24 153 102 51
14 14 23 153 102 51
14 14 22 153 102 51
15 20 24 153 102 51
15 20 23 153 102 51
15 20 22 153 102 51
17 16 24 153 102 51
17 16 23 153 102 51
17 16 22 153 102 51
16 15 24 153 102 51
16 15 23 153 102 51
16 15 22 153 102 51
14 15 24 153 102 51
1 13 25 153 102 51
1 12 25 153 102 51
32 35 42 17 17 17
31 34 24 153 102 51
31 34 25 153 102 51
31 34 26 153 102 51
30 27 24 153 102 51
30 27 23 153 102 51
30 27 22 153 102 51
29 26 24 153 102 51
31 27 23 153 102 51
31 27 22 153 102 51
30 26 24 153 102 51
30 26 23 153 102 51
30 26 22 153 102 51
29 26 23 153 102 51
29 26 22 153 102 51
33 28 24 153 102 51
33 28 23 153 102 51
0 27 26 153 102 51
0 26 26 153 102 51
31 34 42 17 17 17
5 25 23 153 102 51
5 24 23 153 102 51
5 23 23 153 102 51
5 22 23 153 102 51
5 21 23 153 102 51
5 20 23 153 102 51
5 19 23 153 102 51
5 18 23 153 102 51
5 17 23 153 102 51
5 16 23 153 102 51
5 15 23 153 102 51
5 14 23 153 102 51
5 13 23 153 102 51
5 12 23 153 102 51
6 27 24 153 102 51
6 26 24 153 102 51
6 25 24 153 102 51
6 24 24 153 102 51
6 23 24 153 102 51
6 22 24 153 102 51
6 21 24 153 102 51
6 20 24 153 102 51
6 19 24 153 102 51
6 18 24 153 102 51
6 17 24 153 102 51
6 16 24 153 102 51
6 15 24 153 102 51
6 14 24 153 102 51
6 13 24 153 102 51
6 12 24 153 102 51
7 27 25 153 102 51
7 26 25 153 102 51
7 25 25 153 102 51
7 24 25 153 102 51
7 23 25 153 102 51
7 22 25 153 102 51
7 21 25 153 102 51
7 20 25 153 102 51
34 38 24 153 102 51
34 38 25 153 102 51
34 38 26 153 102 51
34 38 27 153 102 51
34 38 28 153 102 51
34 38 29 153 102 51
34 38 30 153 102 51
34 38 31 153 102 51
34 38 32 153 102 51
34 38 33 153 102 51
34 38 34 153 102 51
34 38 35 153 102 51
34 38 36 153 102 51
34 38 37 153 102 51
34 38 38 153 102 51
34 38 39 153 102 51
34 38 40 153 102 51
34 38 41 153 102 51
34 38 42 153 102 51
38 38 24 153 102 51
38 38 25 153 102 51
38 38 26 153 102 51
38 38 27 153 102 51
38 38 28 153 102 51
38 38 29 153 102 51
38 38 30 153 102 51
38 38 31 153 102 51
38 38 32 153 102 51
38 38 33 153 102 51
38 38 34 153 102 51
38 38 35 153 102 51
38 38 36 153 102 51
38 38 37 153 102 51
38 38 38 153 102 51
38 38 39 153 102 51
38 38 40 153 102 51
38 38 41 153 102 51
38 38 42 153 102 51
33 37 24 153 102 51
33 37 25 153 102 51
33 37 26 153 102 51
33 37 27 153 102 51
33 37 28 153 102 51
33 37 29 153 102 51
33 37 30 153 102 51
33 37 31 153 102 51
33 37 32 153 102 51
33 37 33 153 102 51
33 37 34 153 102 51
33 37 35 153 102 51
33 37 36 153 102 51
33 37 37 153 102 51
33 37 38 153 102 51
33 37 39 153 102 51
33 37 40 153 102 51
33 37 41 153 102 51
33 37 42 17 17 17
39 37 24 153 102 51
39 37 25 153 102 51
39 37 26 153 102 51
39 37 27 153 102 51
39 37 28 153 102 51
39 37 29 153 102 51
39 37 30 153 102 51
39 37 31 153 102 51
39 37 32 153 102 51
39 37 33 153 102 51
39 37 34 153 102 51
39 37 35 153 102 51
39 37 36 153 102 51
39 37 37 153 102 51
39 37 38 0 153 0
39 37 39 0 153 0
39 37 40 0 153 0
39 37 41 0 153 0
39 37 42 153 102 51
32 36 24 153 102 51
32 36 25 153 102 51
32 36 26 153 102 51
1 4 24 153 102 51
1 4 23 153 102 51
2 3 26 153 102 51
2 3 25 153 102 51
2 3 24 153 102 51
2 3 23 153 102 51
3 2 26 153 102 51
3 2 25 153 102 51
3 2 24 153 102 51
3 2 23 153 102 51
32 28 26 153 102 51
32 28 25 153 102 51
32 28 24 153 102 51
0 25 26 153 102 51
0 24 26 153 102 51
32 36 42 17 17 17
31 35 24 153 102 51
31 35 25 153 102 51
31 35 26 153 102 51
14 15 23 153 102 51
14 15 22 153 102 51
14 18 24 153 102 51
14 18 23 153 102 51
14 18 22 153 102 51
15 19 24 153 102 51
15 19 23 153 102 51
15 19 22 153 102 51
16 16 24 153 102 51
16 16 23 153 102 51
16 16 22 153 102 51
14 16 24 153 102 51
14 16 23 153 102 51
0 23 26 153 102 51
0 22 26 153 102 51
31 35 42 17 17 17
30 34 24 153 102 51
30 34 25 153 102 51
30 34 26 153 102 51
5 2 24 153 102 51
5 2 23 153 102 51
5 2 22 153 102 51
29 27 24 153 102 51
29 27 23 153 102 51
29 27 22 153 102 51
28 26 24 153 102 51
28 26 23 153 102 51
28 26 22 153 102 51
27 25 24 153 102 51
27 25 23 153 102 51
33 28 22 153 102 51
33 27 24 153 102 51
0 21 26 153 102 51
0 20 26 153 102 51
30 34 42 17 17 17
7 19 25 153 102 51
7 18 25 153 102 51
7 17 25 153 102 51
7 16 25 153 102 51
7 15 25 153 102 51
7 14 25 153 102 51
7 13 25 153 102 51
7 12 25 153 102 51
8 27 26 153 102 51
8 26 26 153 102 51
8 25 26 153 102 51
8 24 26 153 102 51
8 23 26 153 102 51
8 22 26 153 102 51
8 21 26 153 102 51
8 20 26 153 102 51
8 19 26 153 102 51
8 18 26 153 102 51
8 17 26 153 102 51
8 16 26 153 102 51
8 15 26 153 102 51
8 14 26 153 102 51
8 13 26 153 102 51
8 12 26 153 102 51
9 27 27 153 102 51
9 26 27 153 102 51
9 25 27 153 102 51
9 24 27 153 102 51
9 23 27 153 102 51
9 22 27 153 102 51
9 21 27 153 102 51
9 20 27 153 102 51
9 19 27 153 102 51
9 18 27 153 102 51
9 17 27 153 102 51
9 16 27 153 102 51
9 15 27 153 102 51
9 14 27 153 102 51
33 38 24 153 102 51
33 38 25 153 102 51
33 38 26 153 102 51
33 38 27 153 102 51
33 38 28 153 102 51
33 38 29 153 102 51
33 38 30 153 102 51
33 38 31 153 102 51
33 38 32 153 102 51
33 38 33 153 102 51
33 38 34 153 102 51
33 38 35 153 102 51
33 38 36 153 102 51
33 38 37 153 102 51
33 38 38 153 102 51
33 38 39 153 102 51
33 38 40 153 102 51
33 38 41 153 102 51
33 38 42 153 102 51
39 38 24 153 102 51
39 38 25 153 102 51
39 38 26 153 102 51
39 38 27 153 102 51
39 38 28 153 102 51
39 38 29 153 102 51
39 38 30 153 102 51
39 38 31 153 102 51
39 38 32 153 102 51
39 38 33 153 102 51
39 38 34 153 102 51
39 38 35 153 102 51
39 38 36 153 102 51
39 38 37 153 102 51
39 38 38 153 102 51
39 38 39 153 102 51
39 38 40 0 153 0
39 38 41 0 153 0
39 38 42 0 153 0
32 37 24 153 102 51
32 37 25 153 102 51
32 37 26 153 102 51
4 6 24 153 102 51
4 6 23 153 102 51
5 5 26 153 102 51
5 5 25 153 102 51
5 5 24 153 102 51
5 5 23 153 102 51
27 28 26 153 102 51
27 28 25 153 102 51
27 28 24 153 102 51
27 28 23 153 102 51
26 29 26 153 102 51
26 29 25 153 102 51
26 29 24 153 102 51
0 19 26 153 102 51
0 18 26 153 102 51
32 37 42 17 17 17
31 36 24 153 102 51
31 36 25 153 102 51
31 36 26 153 102 51
32 28 23 153 102 51
31 29 26 153 102 51
31 29 25 153 102 51
31 29 24 153 102 51
31 29 23 153 102 51
30 30 26 153 102 51
30 30 25 153 102 51
30 30 24 153 102 51
30 30 23 153 102 51
29 31 26 153 102 51
29 31 25 153 102 51
29 31 24 153 102 51
29 31 23 153 102 51
0 17 26 153 102 51
0 16 26 153 102 51
31 36 42 17 17 17
30 35 24 153 102 51
30 35 25 153 102 51
30 35 26 153 102 51
14 16 22 153 102 51
15 15 24 153 102 51
15 15 23 153 102 51
15 15 22 153 102 51
14 17 24 153 102 51
14 17 23 153 102 51
14 17 22 153 102 51
15 18 24 153 102 51
15 18 23 153 102 51
15 18 22 153 102 51
15 16 24 153 102 51
15 16 23 153 102 51
15 16 22 153 102 51
0 15 26 153 102 51
0 14 26 153 102 51
30 35 42 17 17 17
29 34 24 153 102 51
29 34 25 153 102 51
29 34 26 153 102 51
27 25 22 153 102 51
5 3 24 153 102 51
5 3 23 153 102 51
5 3 22 153 102 51
28 27 24 153 102 51
28 27 23 153 102 51
28 27 22 153 102 51
27 26 24 153 102 51
27 26 23 153 102 51
27 26 22 153 102 51
5 4 24 153 102 51
33 27 23 153 102 51
33 27 22 153 102 51
0 13 26 153 102 51
0 12 26 153 102 51
29 34 42 17 17 17
9 13 27 153 102 51
9 12 27 153 102 51
10 27 42 153 102 51
10 26 42 153 102 51
10 25 42 153 102 51
10 24 42 153 102 51
3 27 24 153 102 51
3 26 24 153 102 51
3 25 24 153 102 51
3 24 24 153 102 51
3 23 24 153 102 51
10 18 42 68 68 68
10 17 42 153 102 51
10 16 42 153 102 51
10 15 42 153 102 51
3 22 24 153 102 51
3 21 24 153 102 51
3 20 24 153 102 51
10 27 28 153 102 51
10 26 28 153 102 51
10 25 28 153 102 51
10 24 28 153 102 51
10 23 28 153 102 51
10 22 28 153 102 51
10 21 28 153 102 51
10 20 28 153 102 51
10 19 28 153 102 51
10 18 28 153 102 51
10 17 28 153 102 51
10 16 28 153 102 51
10 15 28 153 102 51
10 14 28 153 102 51
10 13 28 153 102 51
3 19 24 153 102 51
1 27 23 153 102 51
1 26 23 153 102 51
1 25 23 153 102 51
1 24 23 153 102 51
32 38 24 153 102 51
32 38 25 153 102 51
32 38 26 153 102 51
21 29 24 153 102 51
21 29 23 153 102 51
20 30 26 153 102 51
20 30 25 153 102 51
20 30 24 153 102 51
20 30 23 153 102 51
19 31 26 153 102 51
19 31 25 153 102 51
19 31 24 153 102 51
19 31 23 153 102 51
18 32 26 153 102 51
18 32 25 153 102 51
18 32 24 153 102 51
3 18 24 153 102 51
3 17 24 153 102 51
3 16 24 153 102 51
31 37 24 153 102 51
31 37 25 153 102 51
31 37 26 153 102 51
26 29 23 153 102 51
25 30 26 153 102 51
25 30 25 153 102 51
25 30 24 153 102 51
25 30 23 153 102 51
24 31 26 153 102 51
24 31 25 153 102 51
24 31 24 153 102 51
24 31 23 153 102 51
23 32 26 153 102 51
23 32 25 153 102 51
23 32 24 153 102 51
23 32 23 153 102 51
3 15 24 153 102 51
3 14 24 153 102 51
31 37 42 17 17 17
30 36 24 153 102 51
30 36 25 153 102 51
30 36 26 153 102 51
28 32 26 153 102 51
28 32 25 153 102 51
28 32 24 153 102 51
28 32 23 153 102 51
27 33 26 153 102 51
27 33 25 153 102 51
27 33 24 153 102 51
27 33 23 153 102 51
0 6 26 153 102 51
0 6 25 153 102 51
0 6 24 153 102 51
0 6 23 153 102 51
1 5 26 153 102 51
3 13 24 153 102 51
3 12 24 153 102 51
30 36 42 17 17 17
29 35 24 153 102 51
29 35 25 153 102 51
29 35 26 153 102 51
15 17 24 153 102 51
15 17 23 153 102 51
15 17 22 153 102 51
39 28 26 153 102 51
39 28 25 153 102 51
39 28 24 153 102 51
39 28 23 153 102 51
39 30 26 153 102 51
39 30 25 153 102 51
39 30 24 153 102 51
39 30 23 153 102 51
39 29 26 153 102 51
39 29 25 153 102 51
4 27 25 153 102 51
4 26 25 153 102 51
29 35 42 17 17 17
28 34 24 153 102 51
28 34 25 153 102 51
28 34 26 153 102 51
5 4 23 153 102 51
5 4 22 153 102 51
27 27 24 153 102 51
27 27 23 153 102 51
27 27 22 153 102 51
26 26 24 153 102 51
26 26 23 153 102 51
26 26 22 153 102 51
6 4 24 153 102 51
6 4 23 153 102 51
6 4 22 153 102 51
26 27 24 153 102 51
32 27 24 153 102 51
4 25 25 153 102 51
4 24 25 153 102 51
28 34 42 17 17 17
1 23 23 153 102 51
1 22 23 153 102 51
1 21 23 153 102 51
15 25 25 153 102 51
15 25 24 153 102 51
15 25 23 153 102 51
9 25 23 153 102 51
9 17 23 153 102 51
10 16 26 153 102 51
10 16 25 153 102 51
10 16 24 153 102 51
10 16 23 153 102 51
13 15 26 153 102 51
13 15 25 153 102 51
13 15 24 153 102 51
13 15 23 153 102 51
1 20 23 153 102 51
1 19 23 153 102 51
1 18 23 153 102 51
31 38 24 153 102 51
31 38 25 153 102 51
31 38 26 153 102 51
18 32 23 153 102 51
17 33 26 153 102 51
17 33 25 153 102 51
17 33 24 153 102 51
17 33 23 153 102 51
5 11 26 153 102 51
5 11 25 153 102 51
5 11 24 153 102 51
5 11 23 153 102 51
6 10 26 153 102 51
6 10 25 153 102 51
6 10 24 153 102 51
6 10 23 153 102 51
4 23 25 153 102 51
4 22 25 153 102 51
4 21 25 153 102 51
30 37 24 153 102 51
30 37 25 153 102 51
30 37 26 153 102 51
22 33 26 153 102 51
22 33 25 153 102 51
22 33 24 153 102 51
22 33 23 153 102 51
0 11 26 153 102 51
0 11 25 153 102 51
0 11 24 153 102 51
0 11 23 153 102 51
1 10 26 153 102 51
1 10 25 153 102 51
1 10 24 153 102 51
1 10 23 153 102 51
2 9 26 153 102 51
4 20 25 153 102 51
4 19 25 153 102 51
30 37 42 17 17 17
29 36 24 153 102 51
29 36 25 153 102 51
29 36 26 153 102 51
1 5 25 153 102 51
1 5 24 153 102 51
1 5 23 153 102 51
2 4 26 153 102 51
2 4 25 153 102 51
2 4 24 153 102 51
2 4 23 153 102 51
3 3 26 153 102 51
3 3 25 153 102 51
3 3 24 153 102 51
3 3 23 153 102 51
4 2 26 153 102 51
4 2 25 153 102 51
4 18 25 153 102 51
4 17 25 153 102 51
29 36 42 17 17 17
28 35 24 153 102 51
28 35 25 153 102 51
28 35 26 153 102 51
39 29 24 153 102 51
39 29 23 153 102 51
38 28 26 153 102 51
38 28 25 153 102 51
38 28 24 153 102 51
38 28 23 153 102 51
38 30 26 153 102 51
38 30 25 153 102 51
38 30 24 153 102 51
38 30 23 153 102 51
38 29 26 153 102 51
38 29 25 153 102 51
38 29 24 153 102 51
4 16 25 153 102 51
4 15 25 153 102 51
28 35 42 17 17 17
27 34 24 153 102 51
27 34 25 153 102 51
27 34 26 153 102 51
26 27 23 153 102 51
26 27 22 153 102 51
25 26 24 153 102 51
25 26 23 153 102 51
25 26 22 153 102 51
6 5 24 153 102 51
6 5 23 153 102 51
6 5 22 153 102 51
39 27 24 153 102 51
39 27 23 153 102 51
39 27 22 153 102 51
38 27 24 153 102 51
38 27 23 153 102 51
4 14 25 153 102 51
4 13 25 153 102 51
27 34 42 17 17 17
1 17 23 153 102 51
1 16 23 153 102 51
1 15 23 153 102 51
11 15 26 153 102 51
11 15 25 153 102 51
11 15 24 153 102 51
11 15 23 153 102 51
12 14 26 153 102 51
12 14 25 153 102 51
12 14 24 153 102 51
12 14 23 153 102 51
15 24 26 153 102 51
15 24 25 153 102 51
15 24 24 153 102 51
15 24 23 153 102 51
9 24 23 153 102 51
1 14 23 153 102 51
1 13 23 153 102 51
1 12 23 153 102 51
30 38 24 153 102 51
30 38 25 153 102 51
30 38 26 153 102 51
7 9 26 153 102 51
7 9 25 153 102 51
7 9 24 153 102 51
7 9 23 153 102 51
21 28 26 153 102 51
21 28 25 153 102 51
21 28 24 153 102 51
21 28 23 153 102 51
20 29 26 153 102 51
20 29 25 153 102 51
20 29 24 153 102 51
20 29 23 153 102 51
16 28 26 51 204 255
4 12 25 153 102 51
5 27 26 153 102 51
5 26 26 153 102 51
29 37 24 153 102 51
29 37 25 153 102 51
29 37 26 153 102 51
2 9 25 153 102 51
2 9 24 153 102 51
2 9 23 153 102 51
3 8 26 153 102 51
3 8 25 153 102 51
3 8 24 153 102 51
3 8 23 153 102 51
4 7 26 153 102 51
4 7 25 153 102 51
4 7 24 153 102 51
4 7 23 153 102 51
5 6 26 153 102 51
5 6 25 153 102 51
5 25 26 153 102 51
5 24 26 153 102 51
29 37 42 17 17 17
28 36 24 153 102 51
28 36 25 153 102 51
28 36 26 153 102 51
4 2 24 153 102 51
4 2 23 153 102 51
31 28 26 153 102 51
31 28 25 153 102 51
31 28 24 153 102 51
31 28 23 153 102 51
30 29 26 153 102 51
30 29 25 153 102 51
30 29 24 153 102 51
30 29 23 153 102 51
29 30 26 153 102 51
29 30 25 153 102 51
29 30 24 153 102 51
5 23 26 153 102 51
5 22 26 153 102 51
28 36 42 17 17 17
27 35 24 153 102 51
27 35 25 153 102 51
27 35 26 153 102 51
38 29 23 153 102 51
37 30 26 153 102 51
37 30 25 153 102 51
37 30 24 153 102 51
37 30 23 153 102 51
37 29 26 153 102 51
37 29 25 153 102 51
37 29 24 153 102 51
37 29 23 153 102 51
36 30 26 153 102 51
36 30 25 153 102 51
36 30 24 153 102 51
36 30 23 153 102 51
5 21 26 153 102 51
5 20 26 153 102 51
27 35 42 17 17 17
26 34 24 153 102 51
26 34 25 153 102 51
26 34 26 153 102 51
38 27 22 153 102 51
37 27 24 153 102 51
37 27 23 153 102 51
37 27 22 153 102 51
37 28 24 153 102 51
37 28 23 153 102 51
37 28 22 153 102 51
36 28 24 153 102 51
36 28 23 153 102 51
25 27 24 153 102 51
25 27 23 153 102 51
36 28 22 153 102 51
35 28 24 153 102 51
5 19 26 153 102 51
5 18 26 153 102 51
26 34 42 17 17 17
0 27 24 153 102 51
0 26 24 153 102 51
0 25 24 153 102 51
14 25 26 153 102 51
14 25 25 153 102 51
14 25 24 153 102 51
14 25 23 153 102 51
10 25 26 153 102 51
10 25 25 153 102 51
10 25 24 153 102 51
10 25 23 153 102 51
9 18 23 153 102 51
10 17 26 153 102 51
10 17 25 153 102 51
10 17 24 153 102 51
10 17 23 153 102 51
0 24 24 153 102 51
0 23 24 153 102 51
0 22 24 153 102 51
29 38 24 153 102 51
29 38 25 153 102 51
29 38 26 153 102 51
19 30 25 153 102 51
19 30 24 153 102 51
19 30 23 153 102 51
16 30 26 51 204 255
18 31 25 153 102 51
18 31 24 153 102 51
18 31 23 153 102 51
17 32 26 153 102 51
17 32 25 153 102 51
17 32 24 153 102 51
17 32 23 153 102 51
16 33 26 153 102 51
16 33 25 153 102 51
5 17 26 153 102 51
5 16 26 153 102 51
5 15 26 153 102 51
28 37 24 153 102 51
28 37 25 153 102 51
28 37 26 153 102 51
5 6 24 153 102 51
5 6 23 153 102 51
26 28 26 153 102 51
26 28 25 153 102 51
26 28 24 153 102 51
26 28 23 153 102 51
25 29 26 153 102 51
25 29 25 153 102 51
25 29 24 153 102 51
25 29 23 153 102 51
24 30 26 153 102 51
24 30 25 153 102 51
24 30 24 153 102 51
5 14 26 153 102 51
5 13 26 153 102 51
28 37 42 17 17 17
27 36 24 153 102 51
27 36 25 153 102 51
27 36 26 153 102 51
29 30 23 153 102 51
28 31 26 153 102 51
28 31 25 153 102 51
28 31 24 153 102 51
28 31 23 153 102 51
27 32 26 153 102 51
27 32 25 153 102 51
27 32 24 153 102 51
27 32 23 153 102 51
26 33 26 153 102 51
26 33 25 153 102 51
26 33 24 153 102 51
26 33 23 153 102 51
5 12 26 153 102 51
6 27 27 153 102 51
27 36 42 17 17 17
26 35 24 153 102 51
26 35 25 153 102 51
26 35 26 153 102 51
0 0 26 153 102 51
0 0 25 153 102 51
0 0 24 153 102 51
0 0 23 153 102 51
36 29 26 153 102 51
36 29 25 153 102 51
36 29 24 153 102 51
36 29 23 153 102 51
35 30 26 153 102 51
35 30 25 153 102 51
35 30 24 153 102 51
35 30 23 153 102 51
32 33 26 153 102 51
6 26 27 153 102 51
6 25 27 153 102 51
26 35 42 17 17 17
25 34 24 153 102 51
25 34 25 153 102 51
25 34 26 153 102 51
25 27 22 153 102 51
24 26 24 153 102 51
24 26 23 153 102 51
24 26 22 153 102 51
6 6 24 153 102 51
6 6 23 153 102 51
6 6 22 153 102 51
24 27 24 153 102 51
24 27 23 153 102 51
24 27 22 153 102 51
23 26 24 153 102 51
23 26 23 153 102 51
35 28 23 153 102 51
6 24 27 153 102 51
6 23 27 153 102 51
25 34 42 17 17 17
0 21 24 153 102 51
0 20 24 153 102 51
0 19 24 153 102 51
13 16 26 153 102 51
13 16 25 153 102 51
13 16 24 153 102 51
13 16 23 153 102 51
11 16 26 153 102 51
11 16 25 153 102 51
11 16 24 153 102 51
11 16 23 153 102 51
12 15 26 153 102 51
12 15 25 153 102 51
12 15 24 153 102 51
12 15 23 153 102 51
9 23 23 153 102 51
0 18 24 153 102 51
0 17 24 153 102 51
0 16 24 153 102 51
28 38 24 153 102 51
28 38 25 153 102 51
28 38 26 153 102 51
16 33 24 153 102 51
16 33 23 153 102 51
6 11 26 153 102 51
6 11 25 153 102 51
6 11 24 153 102 51
6 11 23 153 102 51
7 10 26 153 102 51
7 10 25 153 102 51
7 10 24 153 102 51
7 10 23 153 102 51
8 9 26 153 102 51
8 9 25 153 102 51
8 9 24 153 102 51
6 22 27 153 102 51
6 21 27 153 102 51
6 20 27 153 102 51
27 37 24 153 102 51
27 37 25 153 102 51
27 37 26 153 102 51
24 30 23 153 102 51
23 31 26 153 102 51
23 31 25 153 102 51
23 31 24 153 102 51
23 31 23 153 102 51
22 32 26 153 102 51
22 32 25 153 102 51
22 32 24 153 102 51
22 32 23 153 102 51
21 33 26 153 102 51
21 33 25 153 102 51
21 33 24 153 102 51
21 33 23 153 102 51
6 19 27 153 102 51
6 18 27 153 102 51
27 37 42 17 17 17
26 36 24 153 102 51
26 36 25 153 102 51
26 36 26 153 102 51
0 7 26 153 102 51
0 7 25 153 102 51
0 7 24 153 102 51
0 7 23 153 102 51
1 6 26 153 102 51
1 6 25 153 102 51
1 6 24 153 102 51
1 6 23 153 102 51
2 5 26 153 102 51
2 5 25 153 102 51
2 5 24 153 102 51
2 5 23 153 102 51
3 4 26 153 102 51
6 17 27 153 102 51
6 16 27 153 102 51
26 36 42 17 17 17
25 35 24 153 102 51
25 35 25 153 102 51
25 35 26 153 102 51
32 33 25 153 102 51
32 33 24 153 102 51
32 33 23 153 102 51
0 1 26 153 102 51
0 1 25 153 102 51
0 1 24 153 102 51
0 1 23 153 102 51
1 0 26 153 102 51
1 0 25 153 102 51
1 0 24 153 102 51
1 0 23 153 102 51
35 29 26 153 102 51
35 29 25 153 102 51
6 15 27 153 102 51
6 14 27 153 102 51
25 35 42 17 17 17
0 15 24 153 102 51
0 14 24 153 102 51
0 13 24 153 102 51
14 24 26 153 102 51
14 24 25 153 102 51
14 24 24 153 102 51
14 24 23 153 102 51
10 24 26 153 102 51
10 24 25 153 102 51
10 24 24 153 102 51
10 24 23 153 102 51
13 25 26 153 102 51
13 25 25 153 102 51
13 25 24 153 102 51
13 25 23 153 102 51
11 25 26 153 102 51
0 12 24 153 102 51
4 27 23 153 102 51
4 26 23 153 102 51
27 38 24 153 102 51
27 38 25 153 102 51
27 38 26 153 102 51
8 9 23 153 102 51
20 28 26 153 102 51
20 28 25 153 102 51
20 28 24 153 102 51
20 28 23 153 102 51
16 29 26 51 204 255
19 29 25 153 102 51
19 29 24 153 102 51
19 29 23 153 102 51
16 29 25 51 204 255
18 30 25 153 102 51
18 30 24 153 102 51
18 30 23 153 102 51
6 13 27 153 102 51
6 12 27 153 102 51
38 39 37 153 102 51
26 37 24 153 102 51
26 37 25 153 102 51
26 37 26 153 102 51
1 11 26 153 102 51
1 11 25 153 102 51
1 11 24 153 102 51
1 11 23 153 102 51
2 10 26 153 102 51
2 10 25 153 102 51
2 10 24 153 102 51
2 10 23 153 102 51
3 9 26 153 102 51
3 9 25 153 102 51
3 9 24 153 102 51
3 9 23 153 102 51
4 8 26 153 102 51
33 39 41 153 102 51
34 39 40 0 153 0
26 37 42 17 17 17
25 36 24 153 102 51
25 36 25 153 102 51
25 36 26 153 102 51
3 4 25 153 102 51
3 4 24 153 102 51
3 4 23 153 102 51
4 3 26 153 102 51
4 3 25 153 102 51
4 3 24 153 102 51
4 3 23 153 102 51
30 28 26 153 102 51
30 28 25 153 102 51
30 28 24 153 102 51
30 28 23 153 102 51
29 29 26 153 102 51
29 29 25 153 102 51
35 39 39 153 102 51
36 39 38 153 102 51
25 36 42 17 17 17
4 25 23 153 102 51
4 24 23 153 102 51
4 23 23 153 102 51
11 25 25 153 102 51
11 25 24 153 102 51
11 25 23 153 102 51
9 19 23 153 102 51
10 18 26 153 102 51
10 18 25 153 102 51
10 18 24 153 102 51
10 18 23 153 102 51
13 17 26 153 102 51
13 17 25 153 102 51
13 17 24 153 102 51
13 17 23 153 102 51
11 17 26 153 102 51
4 22 23 153 102 51
4 21 23 153 102 51
4 20 23 153 102 51
26 38 24 153 102 51
26 38 25 153 102 51
26 38 26 153 102 51
16 30 25 51 204 255
17 31 25 153 102 51
17 31 24 153 102 51
17 31 23 153 102 51
16 32 26 153 102 51
16 32 25 153 102 51
16 32 24 153 102 51
16 32 23 153 102 51
15 33 26 153 102 51
15 33 25 153 102 51
15 33 24 153 102 51
15 33 23 153 102 51
7 11 26 153 102 51
7 22 42 153 102 51
7 21 42 153 102 51
7 20 42 153 102 51
25 37 24 153 102 51
25 37 25 153 102 51
25 37 26 153 102 51
4 8 25 153 102 51
4 8 24 153 102 51
4 8 23 153 102 51
5 7 26 153 102 51
5 7 25 153 102 51
5 7 24 153 102 51
5 7 23 153 102 51
25 28 26 153 102 51
25 28 25 153 102 51
25 28 24 153 102 51
25 28 23 153 102 51
24 29 26 153 102 51
24 29 25 153 102 51
7 19 42 153 102 51
7 18 42 153 102 51
25 37 42 17 17 17
4 19 23 153 102 51
4 18 23 153 102 51
4 17 23 153 102 51
11 17 25 153 102 51
11 17 24 153 102 51
11 17 23 153 102 51
12 16 26 153 102 51
12 16 25 153 102 51
12 16 24 153 102 51
12 16 23 153 102 51
9 22 23 153 102 51
14 23 26 153 102 51
14 23 25 153 102 51
14 23 24 153 102 51
14 23 23 153 102 51
10 23 26 153 102 51
4 16 23 153 102 51
4 15 23 153 102 51
4 14 23 153 102 51
25 38 24 153 102 51
25 38 25 153 102 51
25 38 26 153 102 51
7 11 25 153 102 51
7 11 24 153 102 51
7 11 23 153 102 51
8 10 26 153 102 51
8 10 25 153 102 51
8 10 24 153 102 51
8 10 23 153 102 51
9 9 26 153 102 51
9 9 25 153 102 51
9 9 24 153 102 51
9 9 23 153 102 51
19 28 26 51 204 255
19 28 25 153 102 51
7 17 42 153 102 51
7 16 42 153 102 51
7 15 42 153 102 51
4 13 23 153 102 51
4 12 23 153 102 51
5 27 24 153 102 51
10 23 25 153 102 51
10 23 24 153 102 51
10 23 23 153 102 51
13 24 26 153 102 51
13 24 25 153 102 51
13 24 24 153 102 51
13 24 23 153 102 51
11 24 26 153 102 51
11 24 25 153 102 51
11 24 24 153 102 51
11 24 23 153 102 51
12 25 26 153 102 51
12 25 25 153 102 51
5 26 24 153 102 51
5 25 24 153 102 51
5 24 24 153 102 51
0 36 28 153 102 51
1 36 28 153 102 51
2 36 28 153 102 51
3 36 28 153 102 51
4 36 28 153 102 51
5 36 28 153 102 51
6 36 28 153 102 51
7 36 28 153 102 51
8 36 28 153 102 51
9 36 28 153 102 51
10 36 28 153 102 51
11 36 28 153 102 51
12 36 28 153 102 51
13 36 28 153 102 51
14 36 28 153 102 51
29 29 24 153 102 51
29 29 23 153 102 51
28 30 26 153 102 51
28 30 25 153 102 51
28 30 24 153 102 51
28 30 23 153 102 51
27 31 26 153 102 51
27 31 25 153 102 51
27 31 24 153 102 51
27 31 23 153 102 51
0 36 27 153 102 51
1 36 27 153 102 51
2 36 27 153 102 51
3 36 27 153 102 51
4 36 27 153 102 51
5 36 27 153 102 51
6 36 27 153 102 51
7 36 27 153 102 51
8 36 27 153 102 51
9 36 27 153 102 51
10 36 27 153 102 51
11 36 27 153 102 51
12 36 27 153 102 51
13 36 27 153 102 51
14 36 27 153 102 51
26 32 26 153 102 51
26 32 25 153 102 51
26 32 24 153 102 51
26 32 23 153 102 51
25 33 26 153 102 51
25 33 25 153 102 51
25 33 24 153 102 51
25 33 23 153 102 51
0 8 26 153 102 51
0 8 25 153 102 51
0 36 29 153 102 51
1 36 29 153 102 51
2 36 29 153 102 51
3 36 29 153 102 51
4 36 29 153 102 51
5 36 29 153 102 51
6 36 29 153 102 51
7 36 29 153 102 51
8 36 29 153 102 51
9 36 29 153 102 51
10 36 29 153 102 51
11 36 29 153 102 51
12 36 29 153 102 51
13 36 29 153 102 51
14 36 29 153 102 51
0 8 24 153 102 51
0 8 23 153 102 51
1 7 26 153 102 51
1 7 25 153 102 51
1 7 24 153 102 51
1 7 23 153 102 51
2 6 26 153 102 51
2 6 25 153 102 51
2 6 24 153 102 51
2 6 23 153 102 51
0 35 28 153 102 51
1 35 28 153 102 51
2 35 28 153 102 51
3 35 28 153 102 51
4 35 28 153 102 51
5 35 28 153 102 51
6 35 28 153 102 51
7 35 28 153 102 51
8 35 28 153 102 51
9 35 28 153 102 51
10 35 28 153 102 51
11 35 28 153 102 51
12 35 28 153 102 51
13 35 28 153 102 51
14 35 28 153 102 51
35 29 24 153 102 51
35 29 23 153 102 51
34 30 26 153 102 51
34 30 25 153 102 51
34 30 24 153 102 51
34 30 23 153 102 51
32 32 26 153 102 51
32 32 25 153 102 51
32 32 24 153 102 51
32 32 23 153 102 51
0 37 28 153 102 51
1 37 28 153 102 51
2 37 28 153 102 51
3 37 28 153 102 51
4 37 28 153 102 51
5 37 28 153 102 51
6 37 28 153 102 51
7 37 28 153 102 51
8 37 28 153 102 51
9 37 28 153 102 51
10 37 28 153 102 51
11 37 28 153 102 51
12 37 28 153 102 51
13 37 28 153 102 51
14 37 28 153 102 51
24 29 24 153 102 51
24 29 23 153 102 51
23 30 26 153 102 51
23 30 25 153 102 51
23 30 24 153 102 51
23 30 23 153 102 51
22 31 26 153 102 51
22 31 25 153 102 51
22 31 24 153 102 51
22 31 23 153 102 51
0 36 26 153 102 51
1 36 26 153 102 51
2 36 26 153 102 51
3 36 26 153 102 51
4 36 26 153 102 51
5 36 26 153 102 51
6 36 26 153 102 51
7 36 26 153 102 51
8 36 26 153 102 51
9 36 26 153 102 51
10 36 26 153 102 51
11 36 26 153 102 51
12 36 26 153 102 51
13 36 26 153 102 51
14 36 26 153 102 51
15 36 26 153 102 51
16 36 26 153 102 51
17 36 26 153 102 51
18 36 26 153 102 51
19 36 26 153 102 51
20 36 26 153 102 51
21 36 26 153 102 51
22 36 26 153 102 51
23 36 26 153 102 51
24 36 26 153 102 51
0 35 27 153 102 51
1 35 27 153 102 51
2 35 27 153 102 51
3 35 27 153 102 51
4 35 27 153 102 51
5 35 27 153 102 51
6 35 27 153 102 51
7 35 27 153 102 51
8 35 27 153 102 51
9 35 27 153 102 51
10 35 27 153 102 51
11 35 27 153 102 51
12 35 27 153 102 51
13 35 27 153 102 51
14 35 27 153 102 51
31 33 26 153 102 51
31 33 25 153 102 51
31 33 24 153 102 51
31 33 23 153 102 51
0 2 26 153 102 51
0 2 25 153 102 51
0 2 24 153 102 51
0 2 23 153 102 51
1 1 26 153 102 51
1 1 25 153 102 51
0 37 27 153 102 51
1 37 27 153 102 51
2 37 27 153 102 51
3 37 27 153 102 51
4 37 27 153 102 51
5 37 27 153 102 51
6 37 27 153 102 51
7 37 27 153 102 51
8 37 27 153 102 51
9 37 27 153 102 51
10 37 27 153 102 51
11 37 27 153 102 51
12 37 27 153 102 51
13 37 27 153 102 51
14 37 27 153 102 51
21 32 26 153 102 51
21 32 25 153 102 51
21 32 24 153 102 51
21 32 23 153 102 51
20 33 26 153 102 51
20 33 25 153 102 51
20 33 24 153 102 51
20 33 23 153 102 51
2 11 26 153 102 51
2 11 25 153 102 51
0 36 30 153 102 51
1 36 30 153 102 51
2 36 30 153 102 51
3 36 30 153 102 51
4 36 30 153 102 51
5 36 30 153 102 51
6 36 30 153 102 51
7 36 30 153 102 51
8 36 30 153 102 51
9 36 30 153 102 51
10 36 30 153 102 51
11 36 30 153 102 51
12 36 30 153 102 51
13 36 30 153 102 51
14 36 30 153 102 51
3 5 26 153 102 51
3 5 25 153 102 51
3 5 24 153 102 51
3 5 23 153 102 51
4 4 26 153 102 51
4 4 25 153 102 51
4 4 24 153 102 51
4 4 23 153 102 51
29 28 26 153 102 51
29 28 25 153 102 51
0 35 29 153 102 51
1 35 29 153 102 51
2 35 29 153 102 51
3 35 29 153 102 51
4 35 29 153 102 51
5 35 29 153 102 51
6 35 29 153 102 51
7 35 29 153 102 51
8 35 29 153 102 51
9 35 29 153 102 51
10 35 29 153 102 51
11 35 29 153 102 51
12 35 29 153 102 51
13 35 29 153 102 51
14 35 29 153 102 51
1 1 24 153 102 51
1 1 23 153 102 51
2 0 26 153 102 51
2 0 25 153 102 51
2 0 24 153 102 51
2 0 23 153 102 51
34 29 26 153 102 51
34 29 25 153 102 51
34 29 24 153 102 51
34 29 23 153 102 51
0 37 29 153 102 51
1 37 29 153 102 51
2 37 29 153 102 51
3 37 29 153 102 51
4 37 29 153 102 51
5 37 29 153 102 51
6 37 29 153 102 51
7 37 29 153 102 51
8 37 29 153 102 51
9 37 29 153 102 51
10 37 29 153 102 51
11 37 29 153 102 51
12 37 29 153 102 51
13 37 29 153 102 51
14 37 29 153 102 51
2 11 24 153 102 51
2 11 23 153 102 51
3 10 26 153 102 51
3 10 25 153 102 51
3 10 24 153 102 51
3 10 23 153 102 51
4 9 26 153 102 51
4 9 25 153 102 51
4 9 24 153 102 51
4 9 23 153 102 51
0 34 28 153 102 51
1 34 28 153 102 51
2 34 28 153 102 51
3 34 28 153 102 51
4 34 28 153 102 51
5 34 28 153 102 51
6 34 28 153 102 51
7 34 28 153 102 51
8 34 28 153 102 51
9 34 28 153 102 51
10 34 28 153 102 51
11 34 28 153 102 51
12 34 28 153 102 51
13 34 28 153 102 51
14 34 28 153 102 51
23 26 22 153 102 51
7 6 24 153 102 51
7 6 23 153 102 51
7 6 22 153 102 51
23 27 24 153 102 51
23 27 23 153 102 51
23 27 22 153 102 51
7 7 24 153 102 51
7 7 23 153 102 51
7 7 22 153 102 51
0 38 28 153 102 51
1 38 28 153 102 51
2 38 28 153 102 51
3 38 28 153 102 51
4 38 28 153 102 51
5 38 28 153 102 51
6 38 28 153 102 51
7 38 28 153 102 51
8 38 28 153 102 51
9 38 28 153 102 51
10 38 28 153 102 51
11 38 28 153 102 51
12 38 28 153 102 51
13 38 28 153 102 51
14 38 28 153 102 51
19 28 24 153 102 51
19 28 23 153 102 51
16 31 26 51 204 255
19 29 26 51 204 255
18 29 24 153 102 51
18 29 23 153 102 51
17 31 26 51 204 255
19 30 26 51 204 255
17 30 24 153 102 51
17 30 23 153 102 51
0 36 25 153 102 51
1 36 25 153 102 51
2 36 25 153 102 51
3 36 25 153 102 51
4 36 25 153 102 51
5 36 25 153 102 51
6 36 25 153 102 51
7 36 25 153 102 51
8 36 25 153 102 51
9 36 25 153 102 51
10 36 25 153 102 51
11 36 25 153 102 51
12 36 25 153 102 51
13 36 25 153 102 51
