ply
format ascii 1.0
comment : MagicaVoxel @ Ephtracy
element vertex 2324
property float x
property float y
property float z
property uchar red
property uchar green
property uchar blue
end_header
19 19 37 255 102 0
18 19 37 255 102 0
17 19 37 255 102 0
16 19 37 255 102 0
15 19 37 255 102 0
14 19 37 255 102 0
13 19 37 255 102 0
12 19 37 255 102 0
11 19 37 255 102 0
10 19 37 255 102 0
19 19 20 255 102 0
18 19 20 255 102 0
17 19 20 255 102 0
16 19 20 255 102 0
15 19 20 255 102 0
14 19 20 255 102 0
13 19 20 255 102 0
12 19 20 255 102 0
11 19 20 255 102 0
10 19 20 255 102 0
9 19 20 255 102 0
8 19 20 255 102 0
7 19 20 255 102 0
6 19 20 255 102 0
5 19 20 255 102 0
4 19 20 255 102 0
3 19 20 255 102 0
2 19 20 255 102 0
1 19 20 255 102 0
0 19 20 255 102 0
9 19 37 255 102 0
8 19 37 255 102 0
7 19 37 255 102 0
6 19 37 255 102 0
5 19 37 255 102 0
4 19 37 255 102 0
3 19 37 255 102 0
2 19 37 255 102 0
1 19 37 255 102 0
0 19 37 255 102 0
19 18 37 255 102 0
18 18 37 255 102 0
17 18 37 255 102 0
16 18 37 255 102 0
15 18 37 255 102 0
14 18 37 255 102 0
13 18 37 0 102 0
12 18 37 0 102 0
11 18 37 255 102 0
19 18 33 255 102 0
19 18 20 255 102 0
18 18 20 255 102 0
17 18 20 255 102 0
16 18 20 255 102 0
15 18 20 255 102 0
14 18 20 255 102 0
13 18 20 255 102 0
12 18 20 255 102 0
11 18 20 255 102 0
19 19 32 255 102 0
19 18 39 255 102 0
19 19 39 0 102 0
18 18 39 255 102 0
0 18 39 0 102 0
18 19 39 0 102 0
0 19 39 0 102 0
17 18 39 0 102 0
1 18 39 0 102 0
17 19 39 0 102 0
1 19 39 0 102 0
16 18 39 0 102 0
2 18 39 255 102 0
16 19 39 0 102 0
2 19 39 0 102 0
15 18 39 255 102 0
3 18 39 255 102 0
15 19 39 0 102 0
3 19 39 0 102 0
14 18 39 255 102 0
4 18 39 0 102 0
0 18 25 255 102 0
1 18 25 0 102 0
2 18 25 0 102 0
3 18 25 0 102 0
4 18 25 255 102 0
5 18 25 0 102 0
6 18 25 0 102 0
7 18 25 255 102 0
8 18 25 255 102 0
0 18 33 255 102 0
18 19 32 255 102 0
11 18 25 255 102 0
12 18 25 255 102 0
13 18 25 0 102 0
14 18 25 255 102 0
15 18 25 255 102 0
16 18 25 255 102 0
17 18 25 255 102 0
18 18 25 255 102 0
19 18 25 255 102 0
0 19 25 255 102 0
1 19 25 255 102 0
2 19 25 255 102 0
3 19 25 255 102 0
4 19 25 255 102 0
5 19 25 255 102 0
6 19 25 255 102 0
7 19 25 255 102 0
8 19 25 255 102 0
9 19 25 255 102 0
10 19 25 255 102 0
11 19 25 255 102 0
12 19 25 255 102 0
13 19 25 255 102 0
14 19 25 255 102 0
15 19 25 255 102 0
16 19 25 255 102 0
17 19 25 255 102 0
18 19 25 255 102 0
19 19 25 255 102 0
19 19 24 255 102 0
18 19 24 255 102 0
17 19 24 255 102 0
16 19 24 255 102 0
15 19 24 255 102 0
14 19 24 255 102 0
13 19 24 255 102 0
12 19 24 255 102 0
11 19 24 255 102 0
10 19 24 255 102 0
9 19 24 255 102 0
8 19 24 255 102 0
7 19 24 255 102 0
6 19 24 255 102 0
5 19 24 255 102 0
4 19 24 255 102 0
3 19 24 255 102 0
2 19 24 255 102 0
1 19 24 255 102 0
0 19 24 255 102 0
19 18 24 255 102 0
18 18 24 0 102 0
17 18 24 0 102 0
16 18 24 255 102 0
15 18 24 255 102 0
14 18 24 255 102 0
13 18 24 0 102 0
12 18 24 255 102 0
11 18 24 255 102 0
17 19 32 255 102 0
1 18 33 255 102 0
8 18 24 255 102 0
7 18 24 255 102 0
6 18 24 255 102 0
5 18 24 0 102 0
4 18 24 0 102 0
3 18 24 0 102 0
2 18 24 0 102 0
1 18 24 0 102 0
0 18 24 255 102 0
14 19 39 0 102 0
4 19 39 0 102 0
13 18 39 0 102 0
5 18 39 0 102 0
13 19 39 0 102 0
5 19 39 0 102 0
12 18 39 0 102 0
6 18 39 255 102 0
12 19 39 0 102 0
6 19 39 0 102 0
11 18 39 0 102 0
7 18 39 255 102 0
11 19 39 0 102 0
7 19 39 0 102 0
10 18 39 0 153 255
8 18 39 255 102 0
10 19 39 0 153 255
8 19 39 0 102 0
9 18 39 0 153 255
9 19 39 0 153 255
2 18 33 255 102 0
8 18 20 255 102 0
7 18 20 255 102 0
6 18 20 255 102 0
5 18 20 255 102 0
4 18 20 255 102 0
3 18 20 255 102 0
2 18 20 255 102 0
1 18 20 255 102 0
0 18 20 255 102 0
3 18 33 255 102 0
8 18 37 255 102 0
7 18 37 0 102 0
6 18 37 0 102 0
5 18 37 255 102 0
4 18 37 255 102 0
3 18 37 255 102 0
2 18 37 255 102 0
1 18 37 255 102 0
0 18 37 255 102 0
0 18 26 255 102 0
1 18 26 0 102 0
2 18 26 0 102 0
3 18 26 0 102 0
4 18 26 255 102 0
5 18 26 255 102 0
6 18 26 255 102 0
7 18 26 255 102 0
8 18 26 255 102 0
4 18 33 255 102 0
16 19 32 255 102 0
11 18 26 255 102 0
12 18 26 0 102 0
13 18 26 0 102 0
14 18 26 255 102 0
15 18 26 255 102 0
16 18 26 255 102 0
17 18 26 255 102 0
18 18 26 255 102 0
19 18 26 255 102 0
0 19 26 255 102 0
1 19 26 255 102 0
2 19 26 255 102 0
3 19 26 255 102 0
4 19 26 255 102 0
5 19 26 255 102 0
6 19 26 255 102 0
7 19 26 255 102 0
8 19 26 255 102 0
9 19 26 255 102 0
10 19 26 255 102 0
11 19 26 255 102 0
12 19 26 255 102 0
13 19 26 255 102 0
14 19 26 255 102 0
15 19 26 255 102 0
16 19 26 255 102 0
17 19 26 255 102 0
18 19 26 255 102 0
19 19 26 255 102 0
19 19 36 255 102 0
18 19 36 255 102 0
17 19 36 255 102 0
16 19 36 255 102 0
15 19 36 255 102 0
14 19 36 255 102 0
13 19 36 255 102 0
12 19 36 255 102 0
11 19 36 255 102 0
10 19 36 255 102 0
9 19 36 255 102 0
8 19 36 255 102 0
7 19 36 255 102 0
6 19 36 255 102 0
5 19 36 255 102 0
4 19 36 255 102 0
3 19 36 255 102 0
2 19 36 255 102 0
1 19 36 255 102 0
0 19 36 255 102 0
0 18 27 255 102 0
1 18 27 0 102 0
2 18 27 0 102 0
3 18 27 0 102 0
4 18 27 255 102 0
5 18 27 255 102 0
6 18 27 255 102 0
7 18 27 255 102 0
8 18 27 255 102 0
5 18 33 255 102 0
15 19 32 255 102 0
11 18 27 255 102 0
12 18 27 0 102 0
13 18 27 0 102 0
14 18 27 255 102 0
15 18 27 255 102 0
16 18 27 255 102 0
17 18 27 255 102 0
18 18 27 255 102 0
19 18 27 255 102 0
0 19 27 255 102 0
1 19 27 255 102 0
2 19 27 255 102 0
3 19 27 255 102 0
4 19 27 255 102 0
5 19 27 255 102 0
6 19 27 255 102 0
7 19 27 255 102 0
8 19 27 255 102 0
9 19 27 255 102 0
10 19 27 255 102 0
11 19 27 255 102 0
12 19 27 255 102 0
13 19 27 255 102 0
14 19 27 255 102 0
15 19 27 255 102 0
16 19 27 255 102 0
17 19 27 255 102 0
18 19 27 255 102 0
19 19 27 255 102 0
19 18 36 255 102 0
18 18 36 255 102 0
17 18 36 255 102 0
16 18 36 255 102 0
15 18 36 255 102 0
14 18 36 255 102 0
13 18 36 255 102 0
12 18 36 0 102 0
11 18 36 255 102 0
14 19 32 255 102 0
6 18 33 255 102 0
8 18 36 255 102 0
7 18 36 0 102 0
6 18 36 255 102 0
5 18 36 255 102 0
4 18 36 255 102 0
3 18 36 255 102 0
2 18 36 255 102 0
1 18 36 255 102 0
0 18 36 255 102 0
0 18 28 255 102 0
1 18 28 0 102 0
2 18 28 255 102 0
3 18 28 255 102 0
4 18 28 255 102 0
5 18 28 255 102 0
6 18 28 255 102 0
7 18 28 255 102 0
8 18 28 255 102 0
7 18 33 0 102 0
13 19 32 255 102 0
11 18 28 255 102 0
12 18 28 0 102 0
13 18 28 255 102 0
14 18 28 0 102 0
15 18 28 255 102 0
16 18 28 255 102 0
17 18 28 255 102 0
18 18 28 255 102 0
19 18 28 255 102 0
0 19 28 255 102 0
1 19 28 255 102 0
2 19 28 255 102 0
3 19 28 255 102 0
4 19 28 255 102 0
5 19 28 255 102 0
6 19 28 255 102 0
7 19 28 255 102 0
8 19 28 255 102 0
9 19 28 255 102 0
10 19 28 255 102 0
11 19 28 255 102 0
12 19 28 255 102 0
13 19 28 255 102 0
14 19 28 255 102 0
15 19 28 255 102 0
16 19 28 255 102 0
17 19 28 255 102 0
18 19 28 255 102 0
19 19 28 255 102 0
19 19 23 255 102 0
18 19 23 255 102 0
17 19 23 255 102 0
16 19 23 255 102 0
15 19 23 255 102 0
14 19 23 255 102 0
13 19 23 255 102 0
12 19 23 255 102 0
11 19 23 255 102 0
10 19 23 255 102 0
9 19 23 255 102 0
8 19 23 255 102 0
7 19 23 255 102 0
6 19 23 255 102 0
5 19 23 255 102 0
4 19 23 255 102 0
3 19 23 255 102 0
2 19 23 255 102 0
1 19 23 255 102 0
0 19 23 255 102 0
19 18 23 255 102 0
18 18 23 0 102 0
17 18 23 0 102 0
16 18 23 0 102 0
15 18 23 255 102 0
14 18 23 255 102 0
13 18 23 255 102 0
12 18 23 0 102 0
11 18 23 0 102 0
12 19 32 255 102 0
8 18 33 0 102 0
8 18 23 0 102 0
7 18 23 255 102 0
6 18 23 255 102 0
5 18 23 0 102 0
4 18 23 0 102 0
3 18 23 0 102 0
2 18 23 0 102 0
1 18 23 0 102 0
0 18 23 255 102 0
19 19 38 255 102 0
18 19 38 255 102 0
17 19 38 0 102 0
16 19 38 0 102 0
15 19 38 0 102 0
14 19 38 0 102 0
13 19 38 0 102 0
12 19 38 0 102 0
11 19 38 0 102 0
10 19 38 0 102 0
19 19 35 255 102 0
18 19 35 255 102 0
17 19 35 255 102 0
16 19 35 255 102 0
15 19 35 255 102 0
14 19 35 255 102 0
13 19 35 255 102 0
12 19 35 255 102 0
11 19 35 255 102 0
10 19 35 255 102 0
9 19 35 255 102 0
8 19 35 255 102 0
7 19 35 255 102 0
6 19 35 255 102 0
5 19 35 255 102 0
4 19 35 255 102 0
3 19 35 255 102 0
2 19 35 255 102 0
1 19 35 255 102 0
0 19 35 255 102 0
9 19 38 0 102 0
8 19 38 0 102 0
7 19 38 0 102 0
6 19 38 0 102 0
5 19 38 0 102 0
4 19 38 0 102 0
3 19 38 0 102 0
2 19 38 0 102 0
1 19 38 0 102 0
0 19 38 255 102 0
19 18 38 255 102 0
18 18 38 0 102 0
17 18 38 0 102 0
16 18 38 255 102 0
15 18 38 255 102 0
14 18 38 255 102 0
13 18 38 0 102 0
12 18 38 0 102 0
11 18 38 255 102 0
11 19 32 255 102 0
19 18 35 255 102 0
18 18 35 255 102 0
17 18 35 255 102 0
16 18 35 0 102 0
15 18 35 0 102 0
14 18 35 255 102 0
13 18 35 255 102 0
12 18 35 0 102 0
11 18 35 255 102 0
10 19 32 255 102 0
9 19 32 255 102 0
8 18 35 0 102 0
7 18 35 255 102 0
6 18 35 255 102 0
5 18 35 255 102 0
4 18 35 255 102 0
3 18 35 255 102 0
2 18 35 255 102 0
1 18 35 255 102 0
0 18 35 255 102 0
11 18 33 255 102 0
8 18 38 255 102 0
7 18 38 0 102 0
6 18 38 0 102 0
5 18 38 0 102 0
4 18 38 255 102 0
3 18 38 255 102 0
2 18 38 255 102 0
1 18 38 255 102 0
0 18 38 255 102 0
0 18 21 255 102 0
1 18 21 0 102 0
2 18 21 0 102 0
3 18 21 0 102 0
4 18 21 0 102 0
5 18 21 0 102 0
6 18 21 0 102 0
7 18 21 0 102 0
8 18 21 0 102 0
12 18 33 255 102 0
0 18 29 255 102 0
1 18 29 255 102 0
2 18 29 255 102 0
3 18 29 255 102 0
4 18 29 255 102 0
5 18 29 255 102 0
6 18 29 255 102 0
7 18 29 255 102 0
8 18 29 255 102 0
13 18 33 255 102 0
8 19 32 255 102 0
11 18 29 255 102 0
12 18 29 0 102 0
13 18 29 255 102 0
14 18 29 0 102 0
15 18 29 255 102 0
16 18 29 255 102 0
17 18 29 255 102 0
18 18 29 255 102 0
19 18 29 255 102 0
7 19 32 255 102 0
11 18 21 0 102 0
12 18 21 0 102 0
13 18 21 0 102 0
14 18 21 0 102 0
15 18 21 0 102 0
16 18 21 0 102 0
17 18 21 0 102 0
18 18 21 0 102 0
19 18 21 255 102 0
0 19 29 255 102 0
1 19 29 255 102 0
2 19 29 255 102 0
3 19 29 255 102 0
4 19 29 255 102 0
5 19 29 255 102 0
6 19 29 255 102 0
7 19 29 255 102 0
8 19 29 255 102 0
9 19 29 255 102 0
10 19 29 255 102 0
11 19 29 255 102 0
12 19 29 255 102 0
13 19 29 255 102 0
14 19 29 255 102 0
15 19 29 255 102 0
16 19 29 255 102 0
17 19 29 255 102 0
18 19 29 255 102 0
19 19 29 255 102 0
0 19 21 255 102 0
1 19 21 255 102 0
2 19 21 255 102 0
3 19 21 255 102 0
4 19 21 255 102 0
5 19 21 255 102 0
6 19 21 255 102 0
7 19 21 255 102 0
8 19 21 255 102 0
9 19 21 255 102 0
10 19 21 255 102 0
11 19 21 255 102 0
12 19 21 255 102 0
13 19 21 255 102 0
14 19 21 255 102 0
15 19 21 255 102 0
16 19 21 255 102 0
17 19 21 255 102 0
18 19 21 255 102 0
19 19 21 255 102 0
0 18 30 255 102 0
1 18 30 255 102 0
2 18 30 255 102 0
3 18 30 255 102 0
4 18 30 255 102 0
5 18 30 255 102 0
6 18 30 255 102 0
7 18 30 0 102 0
8 18 30 255 102 0
14 18 33 255 102 0
6 19 32 255 102 0
11 18 30 255 102 0
12 18 30 0 102 0
13 18 30 255 102 0
14 18 30 0 102 0
15 18 30 0 102 0
16 18 30 255 102 0
17 18 30 255 102 0
18 18 30 255 102 0
19 18 30 255 102 0
0 19 30 255 102 0
1 19 30 255 102 0
2 19 30 255 102 0
3 19 30 255 102 0
4 19 30 255 102 0
5 19 30 255 102 0
6 19 30 255 102 0
7 19 30 255 102 0
8 19 30 255 102 0
9 19 30 255 102 0
10 19 30 255 102 0
11 19 30 255 102 0
12 19 30 255 102 0
13 19 30 255 102 0
14 19 30 255 102 0
15 19 30 255 102 0
16 19 30 255 102 0
17 19 30 255 102 0
18 19 30 255 102 0
19 19 30 255 102 0
19 19 34 255 102 0
18 19 34 255 102 0
17 19 34 255 102 0
16 19 34 255 102 0
15 19 34 255 102 0
14 19 34 255 102 0
13 19 34 255 102 0
12 19 34 255 102 0
11 19 34 255 102 0
10 19 34 255 102 0
9 19 34 255 102 0
8 19 34 255 102 0
7 19 34 255 102 0
6 19 34 255 102 0
5 19 34 255 102 0
4 19 34 255 102 0
3 19 34 255 102 0
2 19 34 255 102 0
1 19 34 255 102 0
0 19 34 255 102 0
0 18 31 255 102 0
1 18 31 255 102 0
2 18 31 255 102 0
3 18 31 255 102 0
4 18 31 255 102 0
5 18 31 255 102 0
6 18 31 255 102 0
7 18 31 0 102 0
8 18 31 255 102 0
15 18 33 0 102 0
5 19 32 255 102 0
11 18 31 255 102 0
12 18 31 255 102 0
13 18 31 255 102 0
14 18 31 0 102 0
15 18 31 0 102 0
16 18 31 255 102 0
17 18 31 255 102 0
18 18 31 255 102 0
19 18 31 255 102 0
0 19 31 255 102 0
1 19 31 255 102 0
2 19 31 255 102 0
3 19 31 255 102 0
4 19 31 255 102 0
5 19 31 255 102 0
6 19 31 255 102 0
7 19 31 255 102 0
8 19 31 255 102 0
9 19 31 255 102 0
10 19 31 255 102 0
11 19 31 255 102 0
12 19 31 255 102 0
13 19 31 255 102 0
14 19 31 255 102 0
15 19 31 255 102 0
16 19 31 255 102 0
17 19 31 255 102 0
18 19 31 255 102 0
19 19 31 255 102 0
19 19 22 255 102 0
18 19 22 255 102 0
17 19 22 255 102 0
16 19 22 255 102 0
15 19 22 255 102 0
14 19 22 255 102 0
13 19 22 255 102 0
12 19 22 255 102 0
11 19 22 255 102 0
10 19 22 255 102 0
9 19 22 255 102 0
8 19 22 255 102 0
7 19 22 255 102 0
6 19 22 255 102 0
5 19 22 255 102 0
4 19 22 255 102 0
3 19 22 255 102 0
2 19 22 255 102 0
1 19 22 255 102 0
0 19 22 255 102 0
19 18 22 255 102 0
18 18 22 0 102 0
17 18 22 0 102 0
16 18 22 0 102 0
15 18 22 0 102 0
14 18 22 0 102 0
13 18 22 0 102 0
12 18 22 0 102 0
11 18 22 0 102 0
4 19 32 255 102 0
16 18 33 255 102 0
8 18 22 0 102 0
7 18 22 0 102 0
6 18 22 0 102 0
5 18 22 0 102 0
4 18 22 0 102 0
3 18 22 0 102 0
2 18 22 0 102 0
1 18 22 0 102 0
0 18 22 255 102 0
19 18 34 255 102 0
18 18 34 255 102 0
17 18 34 255 102 0
16 18 34 0 102 0
15 18 34 0 102 0
14 18 34 255 102 0
13 18 34 255 102 0
12 18 34 255 102 0
11 18 34 255 102 0
3 19 32 255 102 0
17 18 33 255 102 0
8 18 34 0 102 0
7 18 34 255 102 0
6 18 34 255 102 0
5 18 34 255 102 0
4 18 34 255 102 0
3 18 34 255 102 0
2 18 34 255 102 0
1 18 34 255 102 0
0 18 34 255 102 0
19 19 33 255 102 0
18 19 33 255 102 0
17 19 33 255 102 0
16 19 33 255 102 0
15 19 33 255 102 0
14 19 33 255 102 0
13 19 33 255 102 0
12 19 33 255 102 0
11 19 33 255 102 0
10 19 33 255 102 0
9 19 33 255 102 0
8 19 33 255 102 0
7 19 33 255 102 0
6 19 33 255 102 0
5 19 33 255 102 0
4 19 33 255 102 0
3 19 33 255 102 0
2 19 33 255 102 0
1 19 33 255 102 0
0 19 33 255 102 0
0 18 32 255 102 0
1 18 32 255 102 0
2 18 32 255 102 0
3 18 32 255 102 0
4 18 32 255 102 0
5 18 32 255 102 0
6 18 32 255 102 0
7 18 32 0 102 0
8 18 32 255 102 0
18 18 33 255 102 0
2 19 32 255 102 0
11 18 32 255 102 0
12 18 32 255 102 0
13 18 32 255 102 0
14 18 32 0 102 0
15 18 32 0 102 0
16 18 32 255 102 0
17 18 32 255 102 0
18 18 32 255 102 0
19 18 32 255 102 0
0 19 32 255 102 0
1 19 32 255 102 0
10 18 28 0 153 255
9 18 28 0 153 255
10 18 27 0 153 255
10 18 29 0 153 255
9 18 27 0 153 255
9 18 29 0 153 255
1 1 23 255 102 0
10 18 30 0 153 255
9 18 26 0 153 255
3 0 23 0 102 0
0 12 26 255 102 0
10 18 31 0 153 255
9 18 25 0 153 255
1 9 23 255 102 0
10 18 24 0 153 255
13 6 23 0 102 0
9 18 24 0 153 255
14 5 23 0 102 0
10 18 23 0 153 255
14 6 23 0 102 0
9 18 23 0 153 255
9 18 33 0 153 255
10 18 22 0 153 255
10 18 34 0 153 255
9 18 22 0 153 255
9 18 34 0 153 255
10 18 21 0 153 255
10 18 35 0 153 255
9 18 21 0 153 255
9 18 35 0 153 255
10 18 20 0 153 255
10 18 36 0 153 255
9 18 20 0 153 255
1 2 23 255 102 0
10 18 37 0 153 255
2 1 23 255 102 0
10 18 38 0 153 255
9 18 38 0 153 255
10 5 20 255 102 0
10 4 20 255 102 0
13 15 21 255 102 0
9 5 20 255 102 0
11 5 20 255 102 0
10 3 20 255 102 0
9 4 20 255 102 0
11 4 20 255 102 0
14 14 21 255 102 0
0 16 21 255 102 0
11 6 20 255 102 0
4 15 22 255 102 0
12 5 20 255 102 0
10 2 20 255 102 0
9 3 20 255 102 0
11 3 20 255 102 0
8 4 20 255 102 0
12 4 20 255 102 0
16 12 21 255 102 0
2 10 22 0 102 0
11 7 20 255 102 0
1 9 22 255 102 0
12 6 20 255 102 0
1 15 22 255 102 0
13 5 20 255 102 0
10 1 20 255 102 0
9 2 20 255 102 0
11 2 20 255 102 0
8 3 20 255 102 0
12 3 20 255 102 0
0 8 22 255 102 0
13 4 20 255 102 0
1 1 22 255 102 0
1 17 21 255 102 0
19 8 21 255 102 0
0 14 22 255 102 0
12 7 20 255 102 0
5 15 22 255 102 0
13 6 20 255 102 0
18 9 21 255 102 0
14 5 20 255 102 0
10 0 20 255 102 0
9 1 20 255 102 0
11 1 20 255 102 0
8 2 20 255 102 0
12 2 20 255 102 0
7 3 20 255 102 0
13 3 20 255 102 0
3 16 22 255 102 0
14 4 20 255 102 0
2 17 22 255 102 0
17 10 21 255 102 0
3 0 22 255 102 0
5 14 22 255 102 0
12 8 20 255 102 0
1 6 22 255 102 0
13 7 20 255 102 0
16 11 21 255 102 0
14 6 20 255 102 0
2 1 22 255 102 0
15 5 20 255 102 0
9 0 20 255 102 0
11 0 20 255 102 0
8 1 20 255 102 0
12 1 20 255 102 0
7 2 20 255 102 0
13 2 20 255 102 0
6 3 20 255 102 0
14 3 20 255 102 0
5 4 20 255 102 0
15 4 20 255 102 0
17 11 21 255 102 0
18 10 21 255 102 0
13 14 21 255 102 0
1 16 22 255 102 0
4 13 22 255 102 0
0 2 22 255 102 0
13 8 20 255 102 0
19 9 21 255 102 0
14 7 20 255 102 0
5 6 20 255 102 0
15 6 20 255 102 0
4 5 20 255 102 0
16 5 20 255 102 0
8 0 20 255 102 0
12 0 20 255 102 0
7 1 20 255 102 0
13 1 20 255 102 0
6 2 20 255 102 0
14 2 20 255 102 0
5 3 20 255 102 0
15 3 20 255 102 0
4 4 20 255 102 0
16 4 20 255 102 0
10 12 20 255 102 0
1 13 22 255 102 0
0 15 21 255 102 0
1 11 22 255 102 0
12 10 20 255 102 0
7 9 20 255 102 0
13 9 20 255 102 0
6 8 20 255 102 0
14 8 20 255 102 0
5 7 20 255 102 0
15 7 20 255 102 0
4 6 20 255 102 0
16 6 20 255 102 0
3 5 20 255 102 0
17 5 20 255 102 0
7 0 20 255 102 0
13 0 20 255 102 0
6 1 20 255 102 0
14 1 20 255 102 0
5 2 20 255 102 0
15 2 20 255 102 0
4 3 20 255 102 0
16 3 20 255 102 0
3 4 20 255 102 0
17 4 20 255 102 0
10 13 20 255 102 0
3 12 22 255 102 0
11 12 20 255 102 0
0 5 22 255 102 0
1 2 22 255 102 0
7 10 20 255 102 0
13 10 20 255 102 0
6 9 20 255 102 0
14 9 20 255 102 0
5 8 20 255 102 0
15 8 20 255 102 0
4 7 20 255 102 0
16 7 20 255 102 0
3 6 20 255 102 0
17 6 20 255 102 0
2 5 20 255 102 0
18 5 20 255 102 0
6 0 20 255 102 0
14 0 20 255 102 0
5 1 20 255 102 0
15 1 20 255 102 0
4 2 20 255 102 0
16 2 20 255 102 0
3 3 20 255 102 0
17 3 20 255 102 0
2 4 20 255 102 0
18 4 20 255 102 0
10 14 20 255 102 0
0 17 21 255 102 0
11 13 20 255 102 0
1 16 21 255 102 0
12 12 20 255 102 0
7 11 20 255 102 0
13 11 20 255 102 0
6 10 20 255 102 0
14 10 20 255 102 0
5 9 20 255 102 0
15 9 20 255 102 0
4 8 20 255 102 0
16 8 20 255 102 0
3 7 20 255 102 0
17 7 20 255 102 0
2 6 20 255 102 0
18 6 20 255 102 0
1 5 20 255 102 0
19 5 20 255 102 0
5 0 20 255 102 0
15 0 20 255 102 0
4 1 20 255 102 0
16 1 20 255 102 0
3 2 20 255 102 0
17 2 20 255 102 0
2 3 20 255 102 0
18 3 20 255 102 0
1 4 20 255 102 0
19 4 20 255 102 0
3 5 21 255 102 0
2 11 22 255 102 0
11 14 20 255 102 0
8 13 20 255 102 0
12 13 20 255 102 0
7 12 20 255 102 0
13 12 20 255 102 0
6 11 20 255 102 0
14 11 20 255 102 0
5 10 20 255 102 0
15 10 20 255 102 0
4 9 20 255 102 0
16 9 20 255 102 0
3 8 20 255 102 0
17 8 20 255 102 0
2 7 20 255 102 0
18 7 20 255 102 0
1 6 20 255 102 0
19 6 20 255 102 0
0 5 20 255 102 0
4 0 20 255 102 0
16 0 20 255 102 0
3 1 20 255 102 0
17 1 20 255 102 0
2 2 20 255 102 0
18 2 20 255 102 0
1 3 20 255 102 0
19 3 20 255 102 0
0 4 20 255 102 0
4 7 21 255 102 0
2 4 21 255 102 0
11 15 20 255 102 0
8 14 20 255 102 0
12 14 20 255 102 0
7 13 20 255 102 0
13 13 20 255 102 0
6 12 20 255 102 0
14 12 20 255 102 0
5 11 20 255 102 0
15 11 20 255 102 0
4 10 20 255 102 0
16 10 20 255 102 0
3 9 20 255 102 0
17 9 20 255 102 0
2 8 20 255 102 0
18 8 20 255 102 0
1 7 20 255 102 0
19 7 20 255 102 0
0 6 20 255 102 0
3 0 20 255 102 0
17 0 20 255 102 0
2 1 20 255 102 0
18 1 20 255 102 0
1 2 20 255 102 0
19 2 20 255 102 0
0 3 20 255 102 0
5 7 21 0 153 255
3 6 21 255 102 0
5 4 21 255 102 0
8 15 20 255 102 0
12 15 20 255 102 0
7 14 20 255 102 0
13 14 20 255 102 0
6 13 20 255 102 0
14 13 20 255 102 0
5 12 20 255 102 0
15 12 20 255 102 0
4 11 20 255 102 0
16 11 20 255 102 0
3 10 20 255 102 0
17 10 20 255 102 0
2 9 20 255 102 0
18 9 20 255 102 0
1 8 20 255 102 0
19 8 20 255 102 0
0 7 20 255 102 0
2 0 20 255 102 0
18 0 20 255 102 0
1 1 20 255 102 0
19 1 20 255 102 0
0 2 20 255 102 0
2 6 21 255 102 0
4 6 21 255 102 0
3 7 21 255 102 0
12 16 20 255 102 0
7 15 20 255 102 0
13 15 20 255 102 0
6 14 20 255 102 0
14 14 20 255 102 0
5 13 20 255 102 0
15 13 20 255 102 0
4 12 20 255 102 0
16 12 20 255 102 0
3 11 20 255 102 0
17 11 20 255 102 0
2 10 20 255 102 0
18 10 20 255 102 0
1 9 20 255 102 0
19 9 20 255 102 0
0 8 20 255 102 0
1 0 20 255 102 0
19 0 20 255 102 0
0 1 20 255 102 0
4 8 21 255 102 0
12 17 20 255 102 0
7 16 20 255 102 0
13 16 20 255 102 0
6 15 20 255 102 0
14 15 20 255 102 0
5 14 20 255 102 0
15 14 20 255 102 0
4 13 20 255 102 0
16 13 20 255 102 0
3 12 20 255 102 0
17 12 20 255 102 0
2 11 20 255 102 0
18 11 20 255 102 0
1 10 20 255 102 0
19 10 20 255 102 0
0 9 20 255 102 0
0 0 20 255 102 0
7 17 20 255 102 0
13 17 20 255 102 0
6 16 20 255 102 0
14 16 20 255 102 0
5 15 20 255 102 0
15 15 20 255 102 0
4 14 20 255 102 0
16 14 20 255 102 0
3 13 20 255 102 0
17 13 20 255 102 0
2 12 20 255 102 0
18 12 20 255 102 0
1 11 20 255 102 0
19 11 20 255 102 0
0 10 20 255 102 0
6 17 20 255 102 0
14 17 20 255 102 0
5 16 20 255 102 0
15 16 20 255 102 0
4 15 20 255 102 0
16 15 20 255 102 0
3 14 20 255 102 0
17 14 20 255 102 0
2 13 20 255 102 0
18 13 20 255 102 0
1 12 20 255 102 0
19 12 20 255 102 0
0 11 20 255 102 0
5 17 20 255 102 0
15 17 20 255 102 0
4 16 20 255 102 0
16 16 20 255 102 0
3 15 20 255 102 0
17 15 20 255 102 0
2 14 20 255 102 0
18 14 20 255 102 0
1 13 20 255 102 0
19 13 20 255 102 0
0 12 20 255 102 0
4 17 20 255 102 0
16 17 20 255 102 0
3 16 20 255 102 0
17 16 20 255 102 0
2 15 20 255 102 0
18 15 20 255 102 0
1 14 20 255 102 0
19 14 20 255 102 0
0 13 20 255 102 0
3 17 20 255 102 0
17 17 20 255 102 0
2 16 20 255 102 0
18 16 20 255 102 0
1 15 20 255 102 0
19 15 20 255 102 0
0 14 20 255 102 0
2 17 20 255 102 0
18 17 20 255 102 0
1 16 20 255 102 0
19 16 20 255 102 0
0 15 20 255 102 0
1 17 20 255 102 0
19 17 20 255 102 0
0 16 20 255 102 0
0 17 20 255 102 0
2 17 21 255 102 0
5 5 20 255 102 0
3 13 22 255 102 0
6 4 20 255 102 0
2 12 22 255 102 0
6 5 20 255 102 0
7 4 20 255 102 0
6 6 20 255 102 0
1 5 22 255 102 0
7 5 20 255 102 0
19 7 21 255 102 0
6 7 20 255 102 0
18 8 21 255 102 0
7 6 20 255 102 0
8 5 20 255 102 0
7 7 20 255 102 0
8 6 20 255 102 0
0 4 22 255 102 0
3 9 22 0 102 0
2 3 21 255 102 0
1 3 22 255 102 0
9 14 20 255 102 0
13 16 21 255 102 0
7 8 20 255 102 0
3 1 22 255 102 0
8 7 20 255 102 0
9 6 20 255 102 0
8 12 20 255 102 0
9 13 20 255 102 0
8 8 20 255 102 0
9 7 20 255 102 0
14 15 21 255 102 0
4 0 22 255 102 0
15 14 21 255 102 0
10 6 20 255 102 0
16 13 21 255 102 0
12 11 20 255 102 0
0 3 22 255 102 0
8 11 20 255 102 0
17 12 21 255 102 0
4 0 21 255 102 0
9 12 20 255 102 0
3 1 21 255 102 0
12 9 20 255 102 0
8 9 20 255 102 0
11 8 20 255 102 0
0 14 21 255 102 0
10 7 20 255 102 0
18 11 21 255 102 0
8 10 20 255 102 0
1 15 21 255 102 0
11 11 20 255 102 0
2 15 22 255 102 0
9 11 20 255 102 0
1 7 22 255 102 0
1 3 21 255 102 0
11 9 20 255 102 0
3 0 21 255 102 0
9 9 20 255 102 0
2 1 21 255 102 0
10 8 20 255 102 0
1 2 21 255 102 0
11 10 20 255 102 0
1 14 22 255 102 0
9 10 20 255 102 0
2 9 22 0 102 0
10 11 20 255 102 0
0 13 22 255 102 0
10 9 20 255 102 0
1 12 22 255 102 0
2 5 21 255 102 0
2 13 22 255 102 0
1 4 21 255 102 0
2 16 21 255 102 0
0 3 21 255 102 0
10 10 20 255 102 0
2 0 21 255 102 0
9 8 20 255 102 0
1 1 21 255 102 0
3 17 21 255 102 0
0 2 21 255 102 0
19 6 21 255 102 0
1 8 22 255 102 0
18 7 21 255 102 0
3 14 22 255 102 0
0 15 22 255 102 0
19 10 21 255 102 0
13 17 21 255 102 0
0 6 22 255 102 0
0 0 22 255 102 0
14 16 21 255 102 0
1 5 21 255 102 0
15 15 21 255 102 0
0 4 21 255 102 0
1 10 22 255 102 0
16 14 21 255 102 0
1 0 21 255 102 0
11 0 21 255 102 0
0 1 21 255 102 0
5 16 22 0 102 0
0 9 22 255 102 0
1 4 22 255 102 0
17 13 21 255 102 0
0 7 22 255 102 0
1 17 22 255 102 0
0 13 21 255 102 0
0 16 22 255 102 0
18 12 21 255 102 0
1 14 21 255 102 0
2 15 21 255 102 0
1 6 21 255 102 0
3 16 21 255 102 0
0 5 21 255 102 0
0 11 22 255 102 0
3 10 22 0 102 0
0 17 22 255 102 0
0 0 21 255 102 0
12 0 21 255 102 0
19 17 21 255 102 0
19 16 21 255 102 0
4 17 21 255 102 0
5 11 21 255 102 0
19 0 21 255 102 0
18 17 21 255 102 0
0 12 22 255 102 0
3 9 21 255 102 0
19 5 21 255 102 0
19 15 21 255 102 0
18 6 21 255 102 0
1 7 21 255 102 0
19 11 21 255 102 0
0 6 21 255 102 0
14 17 21 255 102 0
5 17 22 0 102 0
18 16 21 255 102 0
17 17 21 255 102 0
13 0 21 255 102 0
14 1 21 255 102 0
19 14 21 255 102 0
6 13 21 255 102 0
5 12 21 255 102 0
15 16 21 255 102 0
4 11 21 255 102 0
4 17 22 255 102 0
3 10 21 255 102 0
1 0 22 255 102 0
2 9 21 255 102 0
16 15 21 255 102 0
1 8 21 255 102 0
5 13 22 255 102 0
0 7 21 255 102 0
0 12 21 255 102 0
1 13 21 255 102 0
18 15 21 255 102 0
17 16 21 255 102 0
16 3 21 255 102 0
14 0 21 255 102 0
15 1 21 255 102 0
16 2 21 255 102 0
6 14 21 255 102 0
5 13 21 255 102 0
0 1 22 255 102 0
4 12 21 255 102 0
2 14 21 255 102 0
3 11 21 255 102 0
2 14 22 255 102 0
2 10 21 255 102 0
3 15 21 255 102 0
1 9 21 255 102 0
4 16 21 255 102 0
0 8 21 255 102 0
0 10 22 255 102 0
2 0 22 255 102 0
16 17 21 255 102 0
19 13 21 255 102 0
18 14 21 255 102 0
17 3 21 255 102 0
15 0 21 255 102 0
16 1 21 255 102 0
17 2 21 255 102 0
6 15 21 255 102 0
5 14 21 255 102 0
5 17 21 255 102 0
4 13 21 255 102 0
19 1 21 255 102 0
3 12 21 255 102 0
18 0 21 255 102 0
2 11 21 255 102 0
19 4 21 255 102 0
1 10 21 255 102 0
18 5 21 255 102 0
0 9 21 255 102 0
4 12 22 0 102 0
17 6 21 255 102 0
17 14 21 255 102 0
17 15 21 255 102 0
16 16 21 255 102 0
17 4 21 255 102 0
18 3 21 255 102 0
16 0 21 255 102 0
17 1 21 255 102 0
18 2 21 255 102 0
6 16 21 255 102 0
5 15 21 255 102 0
7 15 21 255 102 0
4 14 21 255 102 0
4 16 22 255 102 0
3 13 21 255 102 0
18 13 21 255 102 0
2 12 21 255 102 0
2 16 22 255 102 0
1 11 21 255 102 0
4 14 22 255 102 0
0 10 21 255 102 0
2 5 22 255 102 0
3 17 22 255 102 0
3 11 22 0 102 0
15 17 21 255 102 0
19 12 21 255 102 0
17 5 21 255 102 0
18 4 21 255 102 0
19 3 21 255 102 0
17 0 21 255 102 0
18 1 21 255 102 0
19 2 21 255 102 0
6 17 21 255 102 0
5 16 21 255 102 0
3 15 22 255 102 0
4 15 21 255 102 0
5 12 22 0 102 0
3 14 21 255 102 0
0 11 21 255 102 0
2 13 21 255 102 0
4 11 22 0 102 0
1 12 21 255 102 0
2 8 21 255 102 0
3 4 21 255 102 0
4 5 21 255 102 0
14 17 22 255 102 0
4 10 21 255 102 0
14 16 22 0 102 0
15 17 22 255 102 0
2 7 21 255 102 0
2 2 21 255 102 0
15 16 22 255 102 0
16 17 22 255 102 0
3 3 21 255 102 0
15 15 22 0 102 0
16 16 22 255 102 0
17 17 22 255 102 0
15 14 22 0 102 0
16 15 22 255 102 0
17 16 22 255 102 0
18 17 22 255 102 0
16 14 22 0 102 0
17 15 22 255 102 0
18 16 22 255 102 0
19 17 22 255 102 0
16 13 22 0 102 0
17 14 22 255 102 0
18 15 22 255 102 0
19 16 22 255 102 0
16 12 22 255 102 0
17 13 22 255 102 0
18 14 22 255 102 0
19 15 22 255 102 0
16 11 22 255 102 0
17 12 22 255 102 0
18 13 22 255 102 0
19 14 22 255 102 0
17 11 22 255 102 0
18 12 22 255 102 0
19 13 22 255 102 0
17 10 22 255 102 0
18 11 22 0 102 0
19 12 22 255 102 0
18 10 22 255 102 0
19 11 22 255 102 0
18 9 22 255 102 0
19 10 22 255 102 0
18 8 22 255 102 0
19 9 22 255 102 0
18 7 22 255 102 0
19 8 22 255 102 0
18 6 22 255 102 0
19 7 22 255 102 0
18 5 22 255 102 0
17 6 22 255 102 0
19 6 22 255 102 0
18 4 22 0 102 0
17 5 22 255 102 0
19 5 22 255 102 0
18 3 22 255 102 0
17 4 22 255 102 0
19 4 22 255 102 0
18 2 22 255 102 0
17 3 22 0 102 0
19 3 22 255 102 0
18 1 22 255 102 0
17 2 22 255 102 0
19 2 22 255 102 0
16 3 22 255 102 0
18 0 22 255 102 0
17 1 22 255 102 0
19 1 22 255 102 0
16 2 22 0 102 0
17 0 22 255 102 0
19 0 22 255 102 0
16 1 22 0 102 0
16 0 22 255 102 0
15 1 22 255 102 0
15 0 22 255 102 0
14 1 22 255 102 0
14 0 22 0 102 0
13 0 22 0 102 0
12 0 22 0 102 0
11 0 22 0 102 0
5 8 21 255 102 0
3 8 21 255 102 0
4 9 21 255 102 0
4 4 21 255 102 0
3 2 21 255 102 0
4 3 21 255 102 0
12 14 21 255 102 0
12 13 21 255 102 0
13 13 21 255 102 0
13 12 21 0 153 255
14 13 21 255 102 0
14 12 21 255 102 0
15 13 21 255 102 0
14 11 21 255 102 0
15 12 21 255 102 0
14 10 21 255 102 0
15 11 21 255 102 0
15 10 21 255 102 0
15 9 21 255 102 0
16 10 21 255 102 0
15 8 21 255 102 0
16 9 21 255 102 0
15 7 21 255 102 0
16 8 21 255 102 0
17 9 21 255 102 0
15 6 21 255 102 0
16 7 21 255 102 0
17 8 21 255 102 0
15 5 21 255 102 0
14 6 21 255 102 0
16 6 21 255 102 0
17 7 21 255 102 0
15 4 21 255 102 0
14 5 21 255 102 0
16 5 21 255 102 0
15 3 21 255 102 0
14 4 21 255 102 0
16 4 21 255 102 0
15 2 21 255 102 0
14 3 21 255 102 0
13 4 21 255 102 0
14 2 21 255 102 0
13 3 21 255 102 0
12 4 21 255 102 0
13 2 21 255 102 0
12 3 21 255 102 0
13 1 21 255 102 0
12 2 21 255 102 0
11 3 21 255 102 0
12 1 21 255 102 0
11 2 21 255 102 0
11 1 21 255 102 0
10 2 21 255 102 0
10 1 21 255 102 0
9 2 21 255 102 0
10 0 21 255 102 0
9 1 21 255 102 0
9 0 21 255 102 0
8 1 21 255 102 0
8 0 21 255 102 0
7 1 21 255 102 0
7 0 21 255 102 0
7 2 21 255 102 0
6 1 21 255 102 0
6 0 21 255 102 0
6 2 21 255 102 0
5 1 21 255 102 0
5 0 21 255 102 0
5 2 21 255 102 0
4 1 21 255 102 0
5 3 21 255 102 0
4 2 21 255 102 0
10 17 20 0 153 255
10 16 20 0 153 255
9 17 20 0 153 255
11 17 20 0 153 255
10 15 20 0 153 255
9 16 20 0 153 255
11 16 20 0 153 255
8 17 20 0 153 255
9 15 20 0 153 255
8 16 20 0 153 255
8 9 21 0 153 255
8 8 21 0 153 255
8 10 21 0 153 255
7 9 21 0 153 255
9 9 21 0 153 255
8 7 21 0 153 255
7 8 21 0 153 255
9 8 21 0 153 255
8 11 21 0 153 255
7 10 21 0 153 255
9 10 21 0 153 255
6 9 21 0 153 255
10 9 21 0 153 255
8 6 21 0 153 255
7 7 21 0 153 255
9 7 21 0 153 255
6 8 21 0 153 255
10 8 21 0 153 255
8 12 21 0 153 255
7 11 21 0 153 255
9 11 21 0 153 255
6 10 21 0 153 255
10 10 21 0 153 255
5 9 21 0 153 255
11 9 21 0 153 255
8 5 21 0 153 255
7 6 21 0 153 255
9 6 21 0 153 255
6 7 21 0 153 255
10 7 21 0 153 255
11 8 21 0 153 255
8 13 21 0 153 255
7 12 21 0 153 255
9 12 21 0 153 255
6 11 21 0 153 255
10 11 21 0 153 255
5 10 21 0 153 255
11 10 21 0 153 255
12 9 21 0 153 255
8 4 21 0 153 255
7 5 21 0 153 255
9 5 21 0 153 255
6 6 21 0 153 255
10 6 21 0 153 255
11 7 21 0 153 255
12 8 21 0 153 255
8 14 21 0 153 255
7 13 21 0 153 255
9 13 21 0 153 255
6 12 21 0 153 255
10 12 21 0 153 255
11 11 21 0 153 255
12 10 21 0 153 255
13 9 21 0 153 255
8 3 21 0 153 255
7 4 21 0 153 255
9 4 21 0 153 255
6 5 21 0 153 255
10 5 21 0 153 255
5 6 21 0 153 255
11 6 21 0 153 255
12 7 21 0 153 255
13 8 21 0 153 255
8 15 21 0 153 255
7 14 21 0 153 255
9 14 21 0 153 255
10 13 21 0 153 255
11 12 21 0 153 255
12 11 21 0 153 255
13 10 21 0 153 255
14 9 21 0 153 255
8 2 21 0 153 255
7 3 21 0 153 255
9 3 21 0 153 255
6 4 21 0 153 255
10 4 21 0 153 255
5 5 21 0 153 255
11 5 21 0 153 255
12 6 21 0 153 255
13 7 21 0 153 255
14 8 21 0 153 255
10 14 21 0 153 255
11 13 21 0 153 255
12 12 21 0 153 255
13 11 21 0 153 255
6 3 21 0 153 255
10 3 21 0 153 255
11 4 21 0 153 255
12 5 21 0 153 255
13 6 21 0 153 255
14 7 21 0 153 255
11 14 21 0 153 255
13 5 21 0 153 255
11 15 21 0 153 255
12 15 21 0 153 255
12 16 21 0 153 255
12 17 21 0 153 255
17 16 27 255 102 0
17 16 26 255 102 0
17 16 25 255 102 0
17 16 24 255 102 0
16 17 31 255 102 0
16 17 26 255 102 0
16 17 25 255 102 0
19 10 30 255 102 0
19 10 29 255 102 0
19 10 28 255 102 0
19 10 27 255 102 0
19 10 26 0 102 0
15 6 22 0 102 0
19 10 25 255 102 0
19 10 24 255 102 0
17 15 33 255 102 0
14 6 22 255 102 0
17 15 32 255 102 0
17 15 31 255 102 0
17 15 30 255 102 0
14 5 22 255 102 0
17 15 29 255 102 0
17 15 28 255 102 0
17 15 27 255 102 0
17 15 26 255 102 0
17 15 25 255 102 0
17 15 24 255 102 0
16 17 32 255 102 0
19 11 32 255 102 0
19 11 31 255 102 0
19 11 30 255 102 0
17 16 29 255 102 0
19 11 29 255 102 0
19 11 28 255 102 0
19 11 27 255 102 0
19 11 26 0 102 0
19 11 25 0 102 0
19 11 24 0 102 0
17 14 33 255 102 0
14 15 22 0 102 0
17 14 32 0 102 0
17 14 31 0 102 0
17 14 30 0 102 0
17 14 29 0 102 0
17 14 28 0 102 0
17 14 27 0 102 0
17 14 26 255 102 0
17 14 25 255 102 0
17 14 24 255 102 0
18 13 33 255 102 0
18 13 32 255 102 0
18 13 31 255 102 0
18 13 30 255 102 0
18 13 29 0 102 0
18 13 28 0 102 0
18 13 27 0 102 0
18 13 26 0 102 0
18 13 25 0 102 0
18 13 24 255 102 0
16 17 24 255 102 0
19 12 32 255 102 0
19 12 31 255 102 0
19 12 30 255 102 0
19 12 29 255 102 0
19 12 28 255 102 0
19 12 27 255 102 0
19 12 26 255 102 0
19 12 25 0 102 0
19 12 24 0 102 0
18 14 33 255 102 0
18 14 32 255 102 0
18 14 31 255 102 0
18 14 30 255 102 0
18 14 29 255 102 0
18 14 28 255 102 0
18 14 27 255 102 0
18 14 26 255 102 0
18 14 25 255 102 0
18 14 24 255 102 0
19 13 33 255 102 0
19 13 32 255 102 0
19 13 31 255 102 0
19 13 30 255 102 0
19 13 29 255 102 0
19 13 28 255 102 0
19 13 27 255 102 0
19 13 26 255 102 0
19 13 25 255 102 0
17 16 33 255 102 0
19 13 24 255 102 0
19 14 33 255 102 0
19 14 32 255 102 0
19 14 31 255 102 0
19 14 30 255 102 0
19 14 29 255 102 0
19 14 28 255 102 0
9 17 21 0 153 255
9 16 21 0 153 255
8 17 21 0 153 255
10 17 21 0 153 255
9 15 21 0 153 255
8 16 21 0 153 255
10 16 21 0 153 255
11 17 21 0 153 255
10 15 21 0 153 255
11 16 21 0 153 255
7 17 21 0 153 255
7 16 21 0 153 255
19 14 27 255 102 0
19 14 26 255 102 0
19 14 25 255 102 0
19 14 24 255 102 0
16 16 26 255 102 0
17 17 36 255 102 0
19 9 25 255 102 0
17 17 35 0 102 0
17 17 34 0 102 0
17 17 33 255 102 0
17 17 32 255 102 0
17 17 31 255 102 0
17 17 30 255 102 0
17 17 29 255 102 0
19 9 26 255 102 0
17 17 28 255 102 0
17 17 27 255 102 0
17 17 26 255 102 0
17 17 25 255 102 0
18 17 37 0 102 0
18 17 36 255 102 0
18 17 35 255 102 0
18 17 34 255 102 0
18 17 33 255 102 0
18 17 32 255 102 0
18 17 31 255 102 0
19 9 27 255 102 0
18 17 30 255 102 0
16 17 27 255 102 0
18 17 29 255 102 0
18 17 28 255 102 0
18 17 27 255 102 0
0 13 25 255 102 0
18 17 26 255 102 0
0 13 31 255 102 0
18 17 25 255 102 0
16 16 31 255 102 0
17 16 31 255 102 0
17 16 28 255 102 0
16 16 30 255 102 0
16 16 29 255 102 0
18 15 34 255 102 0
18 15 33 255 102 0
16 17 28 255 102 0
18 15 32 255 102 0
18 15 31 255 102 0
18 15 30 255 102 0
18 15 29 255 102 0
18 15 28 255 102 0
0 12 25 255 102 0
18 15 27 255 102 0
0 13 30 255 102 0
18 15 26 255 102 0
17 16 30 255 102 0
18 15 25 255 102 0
16 16 28 255 102 0
16 16 27 255 102 0
18 16 35 255 102 0
18 16 34 255 102 0
19 9 28 255 102 0
18 16 33 255 102 0
18 16 32 255 102 0
18 16 31 255 102 0
18 16 30 255 102 0
18 16 29 255 102 0
18 16 28 255 102 0
18 16 27 255 102 0
0 13 26 255 102 0
0 13 28 0 102 0
18 16 26 255 102 0
17 16 32 255 102 0
18 16 25 255 102 0
19 17 37 0 102 0
19 17 36 255 102 0
19 17 35 255 102 0
19 17 34 255 102 0
19 17 33 255 102 0
19 17 32 255 102 0
13 6 22 255 102 0
19 17 31 255 102 0
19 17 30 255 102 0
19 17 29 255 102 0
0 11 24 255 102 0
0 13 27 255 102 0
19 17 28 255 102 0
19 17 27 255 102 0
19 17 26 255 102 0
19 17 25 255 102 0
16 16 33 255 102 0
16 16 32 255 102 0
19 15 35 255 102 0
19 15 34 255 102 0
19 15 33 255 102 0
19 15 32 255 102 0
0 11 25 255 102 0
0 13 29 0 102 0
19 15 31 255 102 0
19 15 30 255 102 0
19 15 29 255 102 0
19 9 24 255 102 0
0 10 24 255 102 0
19 15 28 255 102 0
19 15 27 255 102 0
19 15 26 255 102 0
19 15 25 255 102 0
19 16 37 255 102 0
19 16 36 255 102 0
19 16 35 255 102 0
19 16 34 255 102 0
19 16 33 255 102 0
19 16 32 255 102 0
19 16 31 255 102 0
19 16 30 255 102 0
19 16 29 255 102 0
19 16 28 255 102 0
19 16 27 255 102 0
4 17 23 0 102 0
4 16 23 255 102 0
4 15 23 255 102 0
3 14 23 255 102 0
3 13 23 255 102 0
2 13 23 255 102 0
2 12 23 255 102 0
1 12 23 255 102 0
1 11 23 255 102 0
1 10 23 255 102 0
0 10 23 255 102 0
0 9 23 255 102 0
0 8 23 255 102 0
0 7 23 255 102 0
0 6 23 255 102 0
0 5 23 255 102 0
0 4 23 255 102 0
0 3 23 255 102 0
0 2 23 255 102 0
0 1 23 255 102 0
0 0 23 255 102 0
1 0 23 255 102 0
2 0 23 255 102 0
16 0 23 0 102 0
17 0 23 255 102 0
18 0 23 255 102 0
19 0 23 255 102 0
19 1 23 255 102 0
19 2 23 255 102 0
18 2 23 255 102 0
17 2 23 0 102 0
18 1 23 255 102 0
17 1 23 255 102 0
18 3 23 0 102 0
19 3 23 255 102 0
19 4 23 255 102 0
19 4 24 255 102 0
19 4 25 255 102 0
19 4 26 255 102 0
19 5 26 255 102 0
19 5 25 255 102 0
19 6 25 255 102 0
19 7 25 255 102 0
19 7 24 255 102 0
19 8 24 255 102 0
19 9 23 255 102 0
19 10 23 255 102 0
19 11 23 0 102 0
19 12 23 0 102 0
19 13 23 255 102 0
18 13 23 255 102 0
18 14 23 255 102 0
17 14 23 255 102 0
17 15 23 255 102 0
17 16 23 255 102 0
16 16 23 255 102 0
16 17 23 255 102 0
17 17 23 255 102 0
18 17 23 255 102 0
19 17 23 255 102 0
19 16 23 255 102 0
19 15 23 255 102 0
18 16 23 255 102 0
18 5 23 255 102 0
19 5 23 255 102 0
19 6 23 255 102 0
19 7 23 255 102 0
18 7 23 255 102 0
19 8 23 255 102 0
18 8 23 255 102 0
2 11 23 255 102 0
19 6 24 255 102 0
19 5 24 255 102 0
19 14 23 255 102 0
18 15 23 255 102 0
19 17 24 255 102 0
18 17 24 255 102 0
18 16 24 255 102 0
18 15 24 255 102 0
19 15 24 255 102 0
19 16 24 255 102 0
17 17 24 255 102 0
0 16 23 255 102 0
0 15 23 255 102 0
0 17 23 255 102 0
1 16 23 255 102 0
0 14 23 255 102 0
1 15 23 255 102 0
1 17 23 255 102 0
2 16 23 255 102 0
0 13 23 255 102 0
1 14 23 255 102 0
2 15 23 255 102 0
2 17 23 255 102 0
3 16 23 255 102 0
0 12 23 255 102 0
1 13 23 255 102 0
2 14 23 255 102 0
3 15 23 255 102 0
3 17 23 255 102 0
0 11 23 255 102 0
3 17 24 255 102 0
2 17 24 255 102 0
2 16 24 255 102 0
2 15 24 255 102 0
1 15 24 255 102 0
1 14 24 255 102 0
0 14 24 255 102 0
0 13 24 255 102 0
0 12 24 255 102 0
0 15 24 255 102 0
0 16 24 255 102 0
0 17 24 255 102 0
1 17 24 255 102 0
2 17 25 255 102 0
1 16 24 255 102 0
1 17 25 255 102 0
0 16 25 255 102 0
0 15 25 255 102 0
0 14 25 0 102 0
1 15 25 255 102 0
1 16 25 255 102 0
2 16 25 255 102 0
2 17 26 255 102 0
3 17 26 255 102 0
2 17 27 255 102 0
1 17 27 255 102 0
1 17 26 255 102 0
0 17 27 255 102 0
0 17 26 255 102 0
0 17 25 255 102 0
3 17 25 255 102 0
3 17 27 255 102 0
1 17 28 255 102 0
0 17 28 255 102 0
0 17 29 255 102 0
0 17 30 255 102 0
0 17 31 255 102 0
3 17 32 255 102 0
3 16 32 255 102 0
3 17 31 255 102 0
3 17 30 0 102 0
4 17 30 255 102 0
4 17 31 255 102 0
4 17 32 255 102 0
5 17 32 255 102 0
5 17 33 255 102 0
5 17 34 255 102 0
5 17 35 255 102 0
4 17 35 255 102 0
4 17 36 255 102 0
4 17 37 255 102 0
3 17 37 255 102 0
16 16 24 255 102 0
16 16 25 255 102 0
2 17 37 255 102 0
2 17 36 255 102 0
1 17 36 255 102 0
0 17 36 255 102 0
0 17 37 255 102 0
1 17 37 255 102 0
2 17 35 255 102 0
3 17 35 255 102 0
3 17 34 255 102 0
3 17 33 255 102 0
4 17 33 255 102 0
4 17 34 255 102 0
5 17 36 255 102 0
6 17 36 255 102 0
16 17 33 255 102 0
2 17 38 255 102 0
1 17 38 255 102 0
0 17 38 255 102 0
3 17 36 255 102 0
0 17 33 255 102 0
1 17 33 255 102 0
1 17 34 255 102 0
0 17 34 255 102 0
0 17 35 255 102 0
1 17 35 255 102 0
2 17 33 255 102 0
1 16 33 255 102 0
1 17 32 255 102 0
1 17 31 255 102 0
1 17 30 255 102 0
2 17 30 255 102 0
2 17 31 255 102 0
2 17 32 255 102 0
1 16 34 255 102 0
2 17 34 255 102 0
0 17 32 255 102 0
4 17 29 255 102 0
3 17 28 0 102 0
2 17 29 255 102 0
1 17 29 255 102 0
3 17 29 0 102 0
2 17 28 255 102 0
0 16 26 255 102 0
0 16 27 255 102 0
0 16 28 255 102 0
0 16 29 255 102 0
0 16 30 255 102 0
0 16 31 255 102 0
0 16 32 255 102 0
0 16 33 255 102 0
0 16 34 255 102 0
0 16 35 255 102 0
0 16 36 255 102 0
0 15 26 255 102 0
0 15 27 255 102 0
0 15 28 255 102 0
0 15 29 255 102 0
0 15 30 255 102 0
0 15 31 255 102 0
0 15 32 255 102 0
0 15 33 255 102 0
0 15 34 255 102 0
0 15 35 255 102 0
0 15 36 255 102 0
1 16 26 255 102 0
1 16 27 255 102 0
1 16 28 255 102 0
1 16 29 255 102 0
1 16 30 255 102 0
1 16 31 255 102 0
1 16 32 255 102 0
1 16 35 255 102 0
1 16 36 255 102 0
0 14 26 0 102 0
0 14 27 0 102 0
0 14 28 0 102 0
0 14 29 255 102 0
0 14 30 255 102 0
0 14 31 255 102 0
0 14 32 255 102 0
0 14 33 255 102 0
0 14 34 255 102 0
16 17 30 255 102 0
16 17 29 255 102 0
1 15 26 0 102 0
1 15 27 255 102 0
1 15 28 255 102 0
1 15 29 0 102 0
1 15 30 0 102 0
1 15 31 0 102 0
1 15 32 0 102 0
1 15 33 255 102 0
1 15 34 255 102 0
1 15 35 255 102 0
1 15 36 255 102 0
2 16 26 0 102 0
2 16 27 0 102 0
2 16 28 0 102 0
2 16 29 0 102 0
2 16 30 0 102 0
2 16 31 255 102 0
2 16 32 255 102 0
2 16 33 255 102 0
2 16 34 255 102 0
2 16 35 255 102 0
2 16 36 255 102 0
19 16 25 255 102 0
19 16 26 255 102 0
2 2 22 0 153 255
13 9 22 0 153 255
12 10 22 0 153 255
14 10 22 0 153 255
13 8 22 0 153 255
12 9 22 0 153 255
14 9 22 0 153 255
12 11 22 0 153 255
11 10 22 0 153 255
14 11 22 0 153 255
15 10 22 0 153 255
13 7 22 0 153 255
12 8 22 0 153 255
14 8 22 0 153 255
11 9 22 0 153 255
15 9 22 0 153 255
12 12 22 0 153 255
11 11 22 0 153 255
10 10 22 0 153 255
14 12 22 0 153 255
15 11 22 0 153 255
16 10 22 0 153 255
12 7 22 0 153 255
14 7 22 0 153 255
11 8 22 0 153 255
15 8 22 0 153 255
10 9 22 0 153 255
16 9 22 0 153 255
12 13 22 0 153 255
11 12 22 0 153 255
10 11 22 0 153 255
9 10 22 0 153 255
14 13 22 0 153 255
15 12 22 0 153 255
12 6 22 0 153 255
11 7 22 0 153 255
15 7 22 0 153 255
10 8 22 0 153 255
16 8 22 0 153 255
17 9 22 0 153 255
12 14 22 0 153 255
13 13 22 0 153 255
10 12 22 0 153 255
9 11 22 0 153 255
8 10 22 0 153 255
14 14 22 0 153 255
15 13 22 0 153 255
12 5 22 0 153 255
11 6 22 0 153 255
10 7 22 0 153 255
16 7 22 0 153 255
17 8 22 0 153 255
12 15 22 0 153 255
13 14 22 0 153 255
10 13 22 0 153 255
9 12 22 0 153 255
8 11 22 0 153 255
8 9 22 0 153 255
7 10 22 0 153 255
12 4 22 0 153 255
11 5 22 0 153 255
13 5 22 0 153 255
10 6 22 0 153 255
16 6 22 0 153 255
17 7 22 0 153 255
13 15 22 0 153 255
9 13 22 0 153 255
8 12 22 0 153 255
7 9 22 0 153 255
6 10 22 0 153 255
12 3 22 0 153 255
11 4 22 0 153 255
13 4 22 0 153 255
10 5 22 0 153 255
9 6 22 0 153 255
16 5 22 0 153 255
13 16 22 0 153 255
9 14 22 0 153 255
8 13 22 0 153 255
7 8 22 0 153 255
6 9 22 0 153 255
6 11 22 0 153 255
5 10 22 0 153 255
12 2 22 0 153 255
11 3 22 0 153 255
13 3 22 0 153 255
10 4 22 0 153 255
14 4 22 0 153 255
9 5 22 0 153 255
16 4 22 0 153 255
15 5 22 0 153 255
13 17 22 0 153 255
8 14 22 0 153 255
7 7 22 0 153 255
6 8 22 0 153 255
5 9 22 0 153 255
6 12 22 0 153 255
5 11 22 0 153 255
4 10 22 0 153 255
12 1 22 0 153 255
11 2 22 0 153 255
13 2 22 0 153 255
10 3 22 0 153 255
14 3 22 0 153 255
9 4 22 0 153 255
15 4 22 0 153 255
8 5 22 0 153 255
12 17 22 0 153 255
8 15 22 0 153 255
7 14 22 0 153 255
7 6 22 0 153 255
6 7 22 0 153 255
5 8 22 0 153 255
4 9 22 0 153 255
6 13 22 0 153 255
11 1 22 0 153 255
13 1 22 0 153 255
10 2 22 0 153 255
14 2 22 0 153 255
9 3 22 0 153 255
15 3 22 0 153 255
8 4 22 0 153 255
7 5 22 0 153 255
11 17 22 0 153 255
7 15 22 0 153 255
6 14 22 0 153 255
6 6 22 0 153 255
4 8 22 0 153 255
10 1 22 0 153 255
9 2 22 0 153 255
15 2 22 0 153 255
8 3 22 0 153 255
7 4 22 0 153 255
6 5 22 0 153 255
10 17 22 0 153 255
7 16 22 0 153 255
6 15 22 0 153 255
4 7 22 0 153 255
3 8 22 0 153 255
10 0 22 0 153 255
9 1 22 0 153 255
8 2 22 0 153 255
7 3 22 0 153 255
6 4 22 0 153 255
2 3 22 0 153 255
10 16 22 0 153 255
9 17 22 0 153 255
7 17 22 0 153 255
6 16 22 0 153 255
4 6 22 0 153 255
3 7 22 0 153 255
2 8 22 0 153 255
9 0 22 0 153 255
8 1 22 0 153 255
7 2 22 0 153 255
6 3 22 0 153 255
5 4 22 0 153 255
4 5 22 0 153 255
6 17 22 0 153 255
3 6 22 0 153 255
2 7 22 0 153 255
8 0 22 0 153 255
7 1 22 0 153 255
6 2 22 0 153 255
5 3 22 0 153 255
4 4 22 0 153 255
3 5 22 0 153 255
2 6 22 0 153 255
7 0 22 0 153 255
6 1 22 0 153 255
5 2 22 0 153 255
4 3 22 0 153 255
3 4 22 0 153 255
6 0 22 0 153 255
5 1 22 0 153 255
4 2 22 0 153 255
3 3 22 0 153 255
2 4 22 0 153 255
5 0 22 0 153 255
4 1 22 0 153 255
3 2 22 0 153 255
