ply
format ascii 1.0
comment : MagicaVoxel @ Ephtracy
element vertex 13922
property float x
property float y
property float z
property uchar red
property uchar green
property uchar blue
end_header
35 38 26 248 229 106
19 7 20 248 229 106
17 25 20 248 229 106
18 34 29 248 229 106
13 7 20 248 229 106
30 17 22 248 229 106
24 9 29 248 229 106
18 6 20 248 229 106
14 6 20 248 229 106
28 30 26 248 229 106
17 5 20 248 229 106
15 5 20 248 229 106
3 22 20 248 229 106
30 16 22 248 229 106
29 17 22 248 229 106
31 17 22 248 229 106
4 23 20 248 229 106
15 35 21 248 229 106
27 24 20 248 229 106
18 33 29 248 229 106
13 28 21 248 229 106
35 36 42 7 146 0
19 28 21 248 229 106
27 19 22 248 229 106
7 14 22 248 229 106
30 15 22 248 229 106
29 16 22 248 229 106
31 16 22 248 229 106
28 17 22 248 229 106
32 17 22 248 229 106
27 18 22 248 229 106
15 8 22 248 229 106
5 24 20 248 229 106
28 34 29 248 229 106
12 27 21 248 229 106
9 15 20 248 229 106
34 36 42 7 146 0
27 20 22 248 229 106
11 26 22 248 229 106
26 19 22 248 229 106
8 13 22 248 229 106
30 14 22 248 229 106
29 15 22 248 229 106
31 15 22 248 229 106
28 16 22 248 229 106
32 16 22 248 229 106
27 17 22 248 229 106
16 7 22 248 229 106
26 18 22 248 229 106
3 28 22 248 229 106
30 24 22 248 229 106
7 32 26 248 229 106
26 25 20 248 229 106
15 25 20 248 229 106
6 25 20 248 229 106
27 21 22 248 229 106
3 21 22 248 229 106
26 20 22 248 229 106
4 29 22 248 229 106
25 19 22 248 229 106
4 22 22 248 229 106
30 13 22 248 229 106
29 14 22 248 229 106
31 14 22 248 229 106
28 15 22 248 229 106
32 15 22 248 229 106
27 16 22 248 229 106
9 12 22 248 229 106
26 17 22 248 229 106
5 30 22 248 229 106
25 18 22 248 229 106
7 26 22 248 229 106
30 25 22 248 229 106
29 24 22 248 229 106
31 24 22 248 229 106
25 26 20 248 229 106
12 7 27 248 229 106
27 22 22 248 229 106
9 28 21 248 229 106
26 21 22 248 229 106
6 31 22 248 229 106
25 20 22 248 229 106
9 35 22 248 229 106
24 19 22 248 229 106
5 23 22 248 229 106
30 12 22 248 229 106
29 13 22 248 229 106
31 13 22 248 229 106
28 14 22 248 229 106
32 14 22 248 229 106
27 15 22 248 229 106
3 11 22 248 229 106
26 16 22 248 229 106
7 32 22 248 229 106
25 17 22 248 229 106
3 8 22 248 229 106
24 18 22 248 229 106
3 13 22 248 229 106
30 26 22 248 229 106
29 25 22 248 229 106
31 25 22 248 229 106
28 24 22 248 229 106
32 24 22 248 229 106
27 23 22 248 229 106
4 10 22 248 229 106
26 22 22 248 229 106
8 33 22 248 229 106
25 21 22 248 229 106
4 7 22 248 229 106
24 20 22 248 229 106
4 11 22 248 229 106
23 19 22 248 229 106
13 33 22 248 229 106
30 11 22 248 229 106
29 12 22 248 229 106
31 12 22 248 229 106
28 13 22 248 229 106
32 13 22 248 229 106
27 14 22 248 229 106
5 9 22 248 229 106
26 15 22 248 229 106
9 34 22 248 229 106
25 16 22 248 229 106
5 6 22 248 229 106
24 17 22 248 229 106
6 24 22 248 229 106
23 18 22 248 229 106
4 12 22 248 229 106
30 27 22 248 229 106
29 26 22 248 229 106
31 26 22 248 229 106
28 25 22 248 229 106
32 25 22 248 229 106
27 24 22 248 229 106
6 8 22 248 229 106
26 23 22 248 229 106
9 16 22 248 229 106
25 22 22 248 229 106
10 29 22 248 229 106
24 21 22 248 229 106
7 20 22 248 229 106
23 20 22 248 229 106
5 10 22 248 229 106
22 19 22 248 229 106
12 9 22 248 229 106
30 10 22 248 229 106
29 11 22 248 229 106
31 11 22 248 229 106
28 12 22 248 229 106
32 12 22 248 229 106
27 13 22 248 229 106
7 7 22 248 229 106
26 14 22 248 229 106
8 21 22 248 229 106
25 15 22 248 229 106
9 22 22 248 229 106
24 16 22 248 229 106
13 8 22 248 229 106
23 17 22 248 229 106
7 25 22 248 229 106
22 18 22 248 229 106
10 23 22 248 229 106
30 28 22 248 229 106
29 27 22 248 229 106
31 27 22 248 229 106
28 26 22 248 229 106
32 26 22 248 229 106
27 25 22 248 229 106
8 6 22 248 229 106
26 24 22 248 229 106
13 10 22 248 229 106
25 23 22 248 229 106
14 7 22 248 229 106
24 22 22 248 229 106
3 31 22 248 229 106
23 21 22 248 229 106
12 27 22 248 229 106
22 20 22 248 229 106
13 7 22 248 229 106
21 19 22 248 229 106
8 26 22 248 229 106
30 9 22 248 229 106
29 10 22 248 229 106
31 10 22 248 229 106
28 11 22 248 229 106
32 11 22 248 229 106
27 12 22 248 229 106
11 30 22 248 229 106
26 13 22 248 229 106
17 6 22 248 229 106
25 14 22 248 229 106
5 11 22 248 229 106
24 15 22 248 229 106
4 32 22 248 229 106
23 16 22 248 229 106
15 6 22 248 229 106
22 17 22 248 229 106
9 28 22 248 229 106
21 18 22 248 229 106
9 27 22 248 229 106
30 29 22 248 229 106
29 28 22 248 229 106
31 28 22 248 229 106
28 27 22 248 229 106
32 27 22 248 229 106
27 26 22 248 229 106
12 11 22 248 229 106
26 25 22 248 229 106
13 28 22 248 229 106
25 24 22 248 229 106
6 9 22 248 229 106
24 23 22 248 229 106
5 33 22 248 229 106
23 22 22 248 229 106
3 33 22 248 229 106
22 21 22 248 229 106
14 29 22 248 229 106
21 20 22 248 229 106
15 30 22 248 229 106
20 19 22 248 229 106
30 8 22 248 229 106
29 9 22 248 229 106
31 9 22 248 229 106
28 10 22 248 229 106
32 10 22 248 229 106
27 11 22 248 229 106
3 14 22 248 229 106
26 12 22 248 229 106
4 18 22 248 229 106
25 13 22 248 229 106
10 28 22 248 229 106
24 14 22 248 229 106
6 34 22 248 229 106
23 15 22 248 229 106
4 34 22 248 229 106
22 16 22 248 229 106
5 17 22 248 229 106
21 17 22 248 229 106
11 29 22 248 229 106
20 18 22 248 229 106
30 30 22 248 229 106
29 29 22 248 229 106
31 29 22 248 229 106
28 28 22 248 229 106
32 28 22 248 229 106
27 27 22 248 229 106
6 10 22 248 229 106
26 26 22 248 229 106
12 30 22 248 229 106
25 25 22 248 229 106
3 20 22 248 229 106
24 24 22 248 229 106
10 15 22 248 229 106
23 23 22 248 229 106
17 34 21 248 229 106
22 22 22 248 229 106
12 31 22 248 229 106
21 21 22 248 229 106
4 21 22 248 229 106
20 20 22 248 229 106
19 19 22 248 229 106
30 7 22 248 229 106
29 8 22 248 229 106
31 8 22 248 229 106
28 9 22 248 229 106
32 9 22 248 229 106
27 10 22 248 229 106
7 8 22 248 229 106
26 11 22 248 229 106
5 22 22 248 229 106
25 12 22 248 229 106
5 24 22 248 229 106
24 13 22 248 229 106
11 24 22 248 229 106
23 14 22 248 229 106
12 25 22 248 229 106
22 15 22 248 229 106
9 29 22 248 229 106
21 16 22 248 229 106
12 32 22 248 229 106
20 17 22 248 229 106
19 18 22 248 229 106
30 31 22 248 229 106
29 30 22 248 229 106
31 30 22 248 229 106
28 29 22 248 229 106
32 29 22 248 229 106
27 28 22 248 229 106
13 31 22 248 229 106
26 27 22 248 229 106
13 26 22 248 229 106
25 26 22 248 229 106
3 29 22 248 229 106
24 25 22 248 229 106
14 27 22 248 229 106
23 24 22 248 229 106
7 22 22 248 229 106
22 23 22 248 229 106
4 13 22 248 229 106
21 22 22 248 229 106
14 32 22 248 229 106
20 21 22 248 229 106
19 20 22 248 229 106
18 19 22 248 229 106
30 6 22 248 229 106
29 7 22 248 229 106
31 7 22 248 229 106
28 8 22 248 229 106
32 8 22 248 229 106
27 9 22 248 229 106
6 23 22 248 229 106
26 10 22 248 229 106
3 10 22 248 229 106
25 11 22 248 229 106
4 30 22 248 229 106
24 12 22 248 229 106
9 24 22 248 229 106
23 13 22 248 229 106
12 33 22 248 229 106
22 14 22 248 229 106
7 9 22 248 229 106
21 15 22 248 229 106
7 24 22 248 229 106
20 16 22 248 229 106
19 17 22 248 229 106
18 18 22 248 229 106
28 34 23 248 229 106
29 31 22 248 229 106
31 31 22 248 229 106
28 30 22 248 229 106
32 30 22 248 229 106
27 29 22 248 229 106
6 18 22 248 229 106
26 28 22 248 229 106
4 9 22 248 229 106
25 27 22 248 229 106
5 31 22 248 229 106
24 26 22 248 229 106
16 31 22 248 229 106
23 25 22 248 229 106
17 32 22 248 229 106
22 24 22 248 229 106
8 7 22 248 229 106
21 23 22 248 229 106
3 19 22 248 229 106
20 22 22 248 229 106
19 21 22 248 229 106
18 20 22 248 229 106
17 19 22 248 229 106
13 32 22 248 229 106
29 6 22 248 229 106
31 6 22 248 229 106
28 7 22 248 229 106
32 7 22 248 229 106
27 8 22 248 229 106
3 26 22 248 229 106
26 9 22 248 229 106
5 8 22 248 229 106
25 10 22 248 229 106
6 32 22 248 229 106
24 11 22 248 229 106
6 16 22 248 229 106
23 12 22 248 229 106
7 15 22 248 229 106
22 13 22 248 229 106
15 33 22 248 229 106
21 14 22 248 229 106
8 14 22 248 229 106
20 15 22 248 229 106
19 16 22 248 229 106
18 17 22 248 229 106
17 18 22 248 229 106
33 32 21 248 229 106
28 31 24 248 229 106
28 34 22 248 229 106
28 31 22 248 229 106
32 31 22 248 229 106
27 30 22 248 229 106
4 27 22 248 229 106
26 29 22 248 229 106
6 7 22 248 229 106
25 28 22 248 229 106
7 33 22 248 229 106
24 27 22 248 229 106
16 34 22 248 229 106
23 26 22 248 229 106
13 32 21 248 229 106
22 25 22 248 229 106
8 25 22 248 229 106
21 24 22 248 229 106
9 6 22 248 229 106
20 23 22 248 229 106
19 22 22 248 229 106
18 21 22 248 229 106
17 20 22 248 229 106
16 19 22 248 229 106
18 33 22 248 229 106
14 33 22 248 229 106
15 34 22 248 229 106
28 6 22 248 229 106
32 6 22 248 229 106
27 7 22 248 229 106
5 28 22 248 229 106
26 8 22 248 229 106
7 6 22 248 229 106
25 9 22 248 229 106
8 34 22 248 229 106
24 10 22 248 229 106
9 26 22 248 229 106
23 11 22 248 229 106
10 27 22 248 229 106
22 12 22 248 229 106
4 20 22 248 229 106
21 13 22 248 229 106
15 28 22 248 229 106
20 14 22 248 229 106
19 15 22 248 229 106
18 16 22 248 229 106
17 17 22 248 229 106
16 18 22 248 229 106
34 36 21 248 229 106
34 37 46 7 146 0
33 35 22 248 229 106
28 30 24 248 229 106
32 32 22 248 229 106
27 31 22 248 229 106
6 29 22 248 229 106
26 30 22 248 229 106
13 12 22 248 229 106
25 29 22 248 229 106
14 11 22 248 229 106
24 28 22 248 229 106
5 21 22 248 229 106
23 27 22 248 229 106
6 22 22 248 229 106
22 26 22 248 229 106
15 10 22 248 229 106
21 25 22 248 229 106
11 28 22 248 229 106
20 24 22 248 229 106
19 23 22 248 229 106
18 22 22 248 229 106
17 21 22 248 229 106
16 20 22 248 229 106
15 19 22 248 229 106
5 12 22 248 229 106
9 13 22 248 229 106
7 17 22 248 229 106
16 29 22 248 229 106
8 16 22 248 229 106
27 6 22 248 229 106
7 30 22 248 229 106
26 7 22 248 229 106
12 29 22 248 229 106
25 8 22 248 229 106
17 30 22 248 229 106
24 9 22 248 229 106
3 7 22 248 229 106
23 10 22 248 229 106
8 23 22 248 229 106
22 11 22 248 229 106
18 31 22 248 229 106
21 12 22 248 229 106
7 23 22 248 229 106
20 13 22 248 229 106
19 14 22 248 229 106
18 15 22 248 229 106
17 16 22 248 229 106
16 17 22 248 229 106
15 18 22 248 229 106
16 9 22 248 229 106
35 36 46 7 146 0
33 32 22 248 229 106
34 39 24 248 229 106
33 34 23 248 229 106
27 32 22 248 229 106
8 31 22 248 229 106
26 31 22 248 229 106
6 11 22 248 229 106
25 30 22 248 229 106
9 15 22 248 229 106
24 29 22 248 229 106
4 6 22 248 229 106
23 28 22 248 229 106
8 24 22 248 229 106
22 27 22 248 229 106
10 7 20 248 229 106
21 26 22 248 229 106
19 34 22 248 229 106
20 25 22 248 229 106
19 24 22 248 229 106
18 23 22 248 229 106
17 22 22 248 229 106
16 21 22 248 229 106
15 20 22 248 229 106
14 19 22 248 229 106
8 8 22 248 229 106
7 10 22 248 229 106
8 9 22 248 229 106
3 15 22 248 229 106
4 14 22 248 229 106
17 8 22 248 229 106
9 32 22 248 229 106
26 6 22 248 229 106
9 7 22 248 229 106
25 7 22 248 229 106
18 7 22 248 229 106
24 8 22 248 229 106
13 30 22 248 229 106
23 9 22 248 229 106
9 8 22 248 229 106
22 10 22 248 229 106
5 19 22 248 229 106
21 11 22 248 229 106
29 35 22 248 229 106
20 12 22 248 229 106
19 13 22 248 229 106
18 14 22 248 229 106
17 15 22 248 229 106
16 16 22 248 229 106
15 17 22 248 229 106
14 18 22 248 229 106
19 32 22 248 229 106
19 6 22 248 229 106
12 7 22 248 229 106
37 39 23 248 229 106
33 33 23 248 229 106
26 34 23 248 229 106
10 33 22 248 229 106
26 32 22 248 229 106
11 14 20 248 229 106
25 31 22 248 229 106
3 22 22 248 229 106
24 30 22 248 229 106
5 13 22 248 229 106
23 29 22 248 229 106
10 6 22 248 229 106
22 28 22 248 229 106
20 33 22 248 229 106
21 27 22 248 229 106
14 31 22 248 229 106
20 26 22 248 229 106
19 25 22 248 229 106
18 24 22 248 229 106
17 23 22 248 229 106
16 22 22 248 229 106
15 21 22 248 229 106
14 20 22 248 229 106
13 19 22 248 229 106
6 12 22 248 229 106
7 11 22 248 229 106
10 7 22 248 229 106
11 6 22 248 229 106
9 25 22 248 229 106
8 10 22 248 229 106
11 34 22 248 229 106
3 16 22 248 229 106
6 20 22 248 229 106
25 6 22 248 229 106
12 10 22 248 229 106
24 7 22 248 229 106
9 9 22 248 229 106
23 8 22 248 229 106
13 9 22 248 229 106
22 9 22 248 229 106
14 8 22 248 229 106
21 10 22 248 229 106
10 26 22 248 229 106
20 11 22 248 229 106
19 12 22 248 229 106
18 13 22 248 229 106
17 14 22 248 229 106
16 15 22 248 229 106
15 16 22 248 229 106
14 17 22 248 229 106
13 18 22 248 229 106
19 32 21 248 229 106
6 19 22 248 229 106
21 34 22 248 229 106
14 9 22 248 229 106
4 26 20 248 229 106
27 34 22 248 229 106
8 17 22 248 229 106
26 33 22 248 229 106
15 32 22 248 229 106
25 32 22 248 229 106
14 6 22 248 229 106
24 31 22 248 229 106
8 27 22 248 229 106
23 30 22 248 229 106
15 7 22 248 229 106
22 29 22 248 229 106
11 27 22 248 229 106
21 28 22 248 229 106
3 17 22 248 229 106
20 27 22 248 229 106
19 26 22 248 229 106
18 25 22 248 229 106
17 24 22 248 229 106
16 23 22 248 229 106
15 22 22 248 229 106
14 21 22 248 229 106
13 20 22 248 229 106
12 19 22 248 229 106
4 16 22 248 229 106
16 33 22 248 229 106
17 34 22 248 229 106
12 28 22 248 229 106
7 27 22 248 229 106
12 34 22 248 229 106
27 27 20 248 229 106
13 29 22 248 229 106
4 15 22 248 229 106
5 20 22 248 229 106
24 6 22 248 229 106
14 30 22 248 229 106
23 7 22 248 229 106
12 12 22 248 229 106
22 8 22 248 229 106
5 14 22 248 229 106
21 9 22 248 229 106
7 21 22 248 229 106
20 10 22 248 229 106
19 11 22 248 229 106
18 12 22 248 229 106
17 13 22 248 229 106
16 14 22 248 229 106
15 15 22 248 229 106
14 16 22 248 229 106
13 17 22 248 229 106
12 18 22 248 229 106
8 22 22 248 229 106
13 11 22 248 229 106
14 10 22 248 229 106
12 8 22 248 229 106
4 17 22 248 229 106
10 31 22 248 229 106
15 9 22 248 229 106
26 34 22 248 229 106
3 27 22 248 229 106
25 33 22 248 229 106
15 31 22 248 229 106
24 32 22 248 229 106
5 15 22 248 229 106
23 31 22 248 229 106
16 32 22 248 229 106
22 30 22 248 229 106
11 7 22 248 229 106
21 29 22 248 229 106
17 33 22 248 229 106
20 28 22 248 229 106
19 27 22 248 229 106
18 26 22 248 229 106
17 25 22 248 229 106
16 24 22 248 229 106
15 23 22 248 229 106
14 22 22 248 229 106
13 21 22 248 229 106
12 20 22 248 229 106
11 19 22 248 229 106
3 25 22 248 229 106
4 26 22 248 229 106
3 24 22 248 229 106
9 23 22 248 229 106
6 14 22 248 229 106
4 28 22 248 229 106
12 6 22 248 229 106
3 9 22 248 229 106
6 13 22 248 229 106
10 24 22 248 229 106
23 6 22 248 229 106
3 32 22 248 229 106
22 7 22 248 229 106
16 8 22 248 229 106
21 8 22 248 229 106
11 25 22 248 229 106
20 9 22 248 229 106
19 10 22 248 229 106
18 11 22 248 229 106
17 12 22 248 229 106
16 13 22 248 229 106
15 14 22 248 229 106
14 15 22 248 229 106
13 16 22 248 229 106
12 17 22 248 229 106
11 18 22 248 229 106
3 6 22 248 229 106
12 26 22 248 229 106
13 27 22 248 229 106
17 7 22 248 229 106
18 6 22 248 229 106
11 32 22 248 229 106
14 28 22 248 229 106
7 18 22 248 229 106
5 29 22 248 229 106
25 34 22 248 229 106
4 8 22 248 229 106
24 33 22 248 229 106
18 34 22 248 229 106
23 32 22 248 229 106
4 33 22 248 229 106
22 31 22 248 229 106
4 25 22 248 229 106
21 30 22 248 229 106
6 15 22 248 229 106
20 29 22 248 229 106
19 28 22 248 229 106
18 27 22 248 229 106
17 26 22 248 229 106
16 25 22 248 229 106
15 24 22 248 229 106
14 23 22 248 229 106
13 22 22 248 229 106
12 21 22 248 229 106
11 20 22 248 229 106
10 19 22 248 229 106
5 27 22 248 229 106
16 6 22 248 229 106
5 26 22 248 229 106
6 30 22 248 229 106
10 32 22 248 229 106
5 7 22 248 229 106
7 12 22 248 229 106
3 30 22 248 229 106
8 11 22 248 229 106
5 34 22 248 229 106
22 6 22 248 229 106
6 28 22 248 229 106
21 7 22 248 229 106
14 34 22 248 229 106
20 8 22 248 229 106
19 9 22 248 229 106
18 10 22 248 229 106
17 11 22 248 229 106
16 12 22 248 229 106
15 13 22 248 229 106
15 19 21 248 229 106
13 15 22 248 229 106
12 16 22 248 229 106
11 17 22 248 229 106
10 18 22 248 229 106
4 23 22 248 229 106
10 25 22 248 229 106
5 18 22 248 229 106
15 29 22 248 229 106
16 30 22 248 229 106
13 6 22 248 229 106
7 13 22 248 229 106
11 33 22 248 229 106
7 31 22 248 229 106
7 19 22 248 229 106
6 6 22 248 229 106
24 34 22 248 229 106
4 31 22 248 229 106
23 33 22 248 229 106
8 20 22 248 229 106
22 32 22 248 229 106
8 12 22 248 229 106
21 31 22 248 229 106
3 23 22 248 229 106
20 30 22 248 229 106
19 29 22 248 229 106
18 28 22 248 229 106
17 27 22 248 229 106
16 26 22 248 229 106
15 25 22 248 229 106
14 24 22 248 229 106
13 23 22 248 229 106
12 22 22 248 229 106
11 21 22 248 229 106
10 20 22 248 229 106
9 19 22 248 229 106
7 29 22 248 229 106
8 32 22 248 229 106
6 27 22 248 229 106
9 10 22 248 229 106
4 24 22 248 229 106
5 32 22 248 229 106
9 21 22 248 229 106
20 34 22 248 229 106
20 17 21 248 229 106
6 25 22 248 229 106
21 6 22 248 229 106
7 28 22 248 229 106
20 7 22 248 229 106
19 8 22 248 229 106
18 9 22 248 229 106
17 10 22 248 229 106
16 11 22 248 229 106
15 12 22 248 229 106
27 29 20 248 229 106
14 33 21 248 229 106
12 15 22 248 229 106
11 16 22 248 229 106
10 17 22 248 229 106
9 18 22 248 229 106
11 31 22 248 229 106
13 34 22 248 229 106
6 17 22 248 229 106
7 16 22 248 229 106
17 31 22 248 229 106
10 30 22 248 229 106
5 16 22 248 229 106
9 33 22 248 229 106
10 22 22 248 229 106
8 15 22 248 229 106
11 23 22 248 229 106
6 33 22 248 229 106
23 34 22 248 229 106
12 24 22 248 229 106
22 33 22 248 229 106
29 35 24 248 229 106
21 32 22 248 229 106
8 30 22 248 229 106
20 31 22 248 229 106
19 30 22 248 229 106
18 29 22 248 229 106
17 28 22 248 229 106
16 27 22 248 229 106
15 26 22 248 229 106
14 25 22 248 229 106
13 24 22 248 229 106
12 23 22 248 229 106
11 22 22 248 229 106
10 21 22 248 229 106
9 20 22 248 229 106
8 19 22 248 229 106
9 31 22 248 229 106
5 25 22 248 229 106
8 29 22 248 229 106
7 34 22 248 229 106
6 26 22 248 229 106
18 32 22 248 229 106
9 11 22 248 229 106
3 34 22 248 229 106
10 20 20 248 229 106
18 9 21 248 229 106
20 6 22 248 229 106
19 7 22 248 229 106
18 8 22 248 229 106
17 9 22 248 229 106
16 10 22 248 229 106
15 11 22 248 229 106
14 12 22 248 229 106
18 33 21 248 229 106
37 38 26 248 229 106
11 15 22 248 229 106
10 16 22 248 229 106
9 17 22 248 229 106
8 18 22 248 229 106
3 12 22 248 229 106
4 19 22 248 229 106
9 14 22 248 229 106
13 25 22 248 229 106
19 33 22 248 229 106
10 34 22 248 229 106
8 28 22 248 229 106
9 30 22 248 229 106
6 21 22 248 229 106
14 26 22 248 229 106
15 27 22 248 229 106
12 31 21 248 229 106
22 34 22 248 229 106
16 28 22 248 229 106
21 33 22 248 229 106
3 18 22 248 229 106
20 32 22 248 229 106
19 31 22 248 229 106
18 30 22 248 229 106
17 29 22 248 229 106
20 16 23 248 229 106
20 15 23 248 229 106
20 17 23 248 229 106
19 16 23 248 229 106
21 16 23 248 229 106
20 14 23 248 229 106
19 15 23 248 229 106
21 15 23 248 229 106
20 18 23 248 229 106
19 17 23 248 229 106
21 17 23 248 229 106
18 16 23 248 229 106
22 16 23 248 229 106
20 13 23 248 229 106
19 14 23 248 229 106
21 14 23 248 229 106
18 15 23 248 229 106
22 15 23 248 229 106
20 19 23 248 229 106
19 18 23 248 229 106
21 18 23 248 229 106
18 17 23 248 229 106
22 17 23 248 229 106
17 16 23 248 229 106
23 16 23 248 229 106
20 12 23 248 229 106
19 13 23 248 229 106
21 13 23 248 229 106
18 14 23 248 229 106
22 14 23 248 229 106
17 15 23 248 229 106
23 15 23 248 229 106
20 20 23 248 229 106
19 19 23 248 229 106
21 19 23 248 229 106
18 18 23 248 229 106
22 18 23 248 229 106
17 17 23 248 229 106
23 17 23 248 229 106
16 16 23 248 229 106
24 16 23 248 229 106
20 11 23 248 229 106
19 12 23 248 229 106
21 12 23 248 229 106
18 13 23 248 229 106
22 13 23 248 229 106
17 14 23 248 229 106
23 14 23 248 229 106
16 15 23 248 229 106
24 15 23 248 229 106
20 21 23 248 229 106
19 20 23 248 229 106
21 20 23 248 229 106
18 19 23 248 229 106
22 19 23 248 229 106
17 18 23 248 229 106
23 18 23 248 229 106
16 17 23 248 229 106
24 17 23 248 229 106
15 16 23 248 229 106
25 16 23 248 229 106
20 10 23 248 229 106
19 11 23 248 229 106
21 11 23 248 229 106
18 12 23 248 229 106
22 12 23 248 229 106
17 13 23 248 229 106
23 13 23 248 229 106
3 18 21 248 229 106
24 14 23 248 229 106
15 15 23 248 229 106
25 15 23 248 229 106
20 22 23 248 229 106
19 21 23 248 229 106
21 21 23 248 229 106
18 20 23 248 229 106
22 20 23 248 229 106
17 19 23 248 229 106
23 19 23 248 229 106
16 18 23 248 229 106
24 18 23 248 229 106
15 17 23 248 229 106
25 17 23 248 229 106
14 16 23 248 229 106
26 16 23 248 229 106
20 9 23 248 229 106
19 10 23 248 229 106
21 10 23 248 229 106
18 11 23 248 229 106
22 11 23 248 229 106
17 12 23 248 229 106
23 12 23 248 229 106
16 35 21 248 229 106
24 13 23 248 229 106
14 19 21 248 229 106
25 14 23 248 229 106
14 15 23 248 229 106
26 15 23 248 229 106
20 23 23 248 229 106
19 22 23 248 229 106
21 22 23 248 229 106
18 21 23 248 229 106
22 21 23 248 229 106
17 20 23 248 229 106
23 20 23 248 229 106
16 19 23 248 229 106
24 19 23 248 229 106
15 18 23 248 229 106
25 18 23 248 229 106
14 17 23 248 229 106
26 17 23 248 229 106
13 16 23 248 229 106
27 16 23 248 229 106
20 8 23 248 229 106
19 9 23 248 229 106
21 9 23 248 229 106
18 10 23 248 229 106
22 10 23 248 229 106
17 11 23 248 229 106
23 11 23 248 229 106
16 12 23 248 229 106
24 12 23 248 229 106
17 18 21 248 229 106
25 13 23 248 229 106
15 18 21 248 229 106
26 14 23 248 229 106
13 15 23 248 229 106
27 15 23 248 229 106
20 24 23 248 229 106
19 23 23 248 229 106
21 23 23 248 229 106
18 22 23 248 229 106
22 22 23 248 229 106
17 21 23 248 229 106
23 21 23 248 229 106
16 20 23 248 229 106
24 20 23 248 229 106
15 19 23 248 229 106
25 19 23 248 229 106
14 18 23 248 229 106
26 18 23 248 229 106
13 17 23 248 229 106
27 17 23 248 229 106
12 16 23 248 229 106
28 16 23 248 229 106
20 7 23 248 229 106
19 8 23 248 229 106
21 8 23 248 229 106
18 9 23 248 229 106
22 9 23 248 229 106
17 10 23 248 229 106
23 10 23 248 229 106
16 11 23 248 229 106
24 11 23 248 229 106
15 12 23 248 229 106
25 12 23 248 229 106
16 17 21 248 229 106
26 13 23 248 229 106
16 18 21 248 229 106
27 14 23 248 229 106
12 15 23 248 229 106
28 15 23 248 229 106
20 25 23 248 229 106
19 24 23 248 229 106
21 24 23 248 229 106
18 23 23 248 229 106
22 23 23 248 229 106
17 22 23 248 229 106
23 22 23 248 229 106
16 21 23 248 229 106
24 21 23 248 229 106
15 20 23 248 229 106
25 20 23 248 229 106
14 19 23 248 229 106
26 19 23 248 229 106
13 18 23 248 229 106
27 18 23 248 229 106
12 17 23 248 229 106
28 17 23 248 229 106
11 16 23 248 229 106
29 16 23 248 229 106
20 6 23 248 229 106
19 7 23 248 229 106
21 7 23 248 229 106
18 8 23 248 229 106
22 8 23 248 229 106
17 9 23 248 229 106
23 9 23 248 229 106
16 10 23 248 229 106
24 10 23 248 229 106
15 11 23 248 229 106
25 11 23 248 229 106
14 12 23 248 229 106
26 12 23 248 229 106
17 20 21 248 229 106
27 13 23 248 229 106
15 20 21 248 229 106
28 14 23 248 229 106
11 15 23 248 229 106
29 15 23 248 229 106
20 26 23 248 229 106
19 25 23 248 229 106
21 25 23 248 229 106
18 24 23 248 229 106
22 24 23 248 229 106
17 23 23 248 229 106
23 23 23 248 229 106
16 22 23 248 229 106
24 22 23 248 229 106
15 21 23 248 229 106
25 21 23 248 229 106
14 20 23 248 229 106
26 20 23 248 229 106
13 19 23 248 229 106
27 19 23 248 229 106
12 18 23 248 229 106
7 26 20 248 229 106
11 17 23 248 229 106
29 17 23 248 229 106
10 16 23 248 229 106
30 16 23 248 229 106
19 6 23 248 229 106
21 6 23 248 229 106
18 7 23 248 229 106
22 7 23 248 229 106
17 8 23 248 229 106
23 8 23 248 229 106
16 9 23 248 229 106
24 9 23 248 229 106
15 10 23 248 229 106
25 10 23 248 229 106
14 11 23 248 229 106
26 11 23 248 229 106
13 12 23 248 229 106
27 12 23 248 229 106
16 21 21 248 229 106
28 13 23 248 229 106
16 19 21 248 229 106
29 14 23 248 229 106
10 15 23 248 229 106
30 15 23 248 229 106
20 27 23 248 229 106
19 26 23 248 229 106
21 26 23 248 229 106
18 25 23 248 229 106
22 25 23 248 229 106
17 24 23 248 229 106
23 24 23 248 229 106
16 23 23 248 229 106
24 23 23 248 229 106
15 22 23 248 229 106
25 22 23 248 229 106
14 21 23 248 229 106
26 21 23 248 229 106
13 20 23 248 229 106
27 20 23 248 229 106
12 19 23 248 229 106
24 27 20 248 229 106
11 18 23 248 229 106
25 8 29 248 229 106
10 17 23 248 229 106
30 17 23 248 229 106
9 16 23 248 229 106
31 16 23 248 229 106
18 6 23 248 229 106
22 6 23 248 229 106
17 7 23 248 229 106
23 7 23 248 229 106
16 8 23 248 229 106
24 8 23 248 229 106
15 9 23 248 229 106
25 9 23 248 229 106
14 10 23 248 229 106
26 10 23 248 229 106
13 11 23 248 229 106
27 11 23 248 229 106
12 12 23 248 229 106
28 12 23 248 229 106
16 20 21 248 229 106
29 13 23 248 229 106
15 17 25 248 229 106
30 14 23 248 229 106
9 15 23 248 229 106
31 15 23 248 229 106
20 28 23 248 229 106
19 27 23 248 229 106
21 27 23 248 229 106
18 26 23 248 229 106
22 26 23 248 229 106
17 25 23 248 229 106
23 25 23 248 229 106
16 24 23 248 229 106
24 24 23 248 229 106
15 23 23 248 229 106
25 23 23 248 229 106
14 22 23 248 229 106
26 22 23 248 229 106
13 21 23 248 229 106
27 21 23 248 229 106
12 20 23 248 229 106
8 27 20 248 229 106
11 19 23 248 229 106
17 34 29 248 229 106
10 18 23 248 229 106
23 28 20 248 229 106
9 17 23 248 229 106
31 17 23 248 229 106
8 16 23 248 229 106
32 16 23 248 229 106
17 6 23 248 229 106
23 6 23 248 229 106
16 7 23 248 229 106
24 7 23 248 229 106
15 8 23 248 229 106
25 8 23 248 229 106
14 9 23 248 229 106
26 9 23 248 229 106
13 10 23 248 229 106
27 10 23 248 229 106
12 11 23 248 229 106
28 11 23 248 229 106
8 35 22 248 229 106
29 12 23 248 229 106
15 34 21 248 229 106
30 13 23 248 229 106
9 14 23 248 229 106
31 14 23 248 229 106
8 15 23 248 229 106
32 15 23 248 229 106
20 29 23 248 229 106
19 28 23 248 229 106
21 28 23 248 229 106
18 27 23 248 229 106
22 27 23 248 229 106
17 26 23 248 229 106
23 26 23 248 229 106
16 25 23 248 229 106
24 25 23 248 229 106
15 24 23 248 229 106
25 24 23 248 229 106
14 23 23 248 229 106
26 23 23 248 229 106
13 22 23 248 229 106
27 22 23 248 229 106
12 21 23 248 229 106
9 28 20 248 229 106
11 20 23 248 229 106
28 34 26 248 229 106
10 19 23 248 229 106
13 7 27 97 38 6
9 18 23 248 229 106
22 29 20 248 229 106
8 17 23 248 229 106
32 17 23 248 229 106
7 16 23 248 229 106
16 6 23 248 229 106
24 6 23 248 229 106
15 7 23 248 229 106
25 7 23 248 229 106
14 8 23 248 229 106
26 8 23 248 229 106
13 9 23 248 229 106
27 9 23 248 229 106
12 10 23 248 229 106
28 10 23 248 229 106
19 4 20 248 229 106
29 11 23 248 229 106
20 22 20 248 229 106
30 12 23 248 229 106
9 13 23 248 229 106
31 13 23 248 229 106
8 14 23 248 229 106
32 14 23 248 229 106
7 15 23 248 229 106
20 30 23 248 229 106
19 29 23 248 229 106
21 29 23 248 229 106
18 28 23 248 229 106
22 28 23 248 229 106
17 27 23 248 229 106
23 27 23 248 229 106
16 26 23 248 229 106
24 26 23 248 229 106
15 25 23 248 229 106
25 25 23 248 229 106
14 24 23 248 229 106
26 24 23 248 229 106
13 23 23 248 229 106
27 23 23 248 229 106
12 22 23 248 229 106
10 29 20 248 229 106
11 21 23 248 229 106
17 33 29 248 229 106
10 20 23 248 229 106
29 17 21 248 229 106
9 19 23 248 229 106
21 30 20 248 229 106
8 18 23 248 229 106
35 37 26 248 229 106
7 17 23 248 229 106
6 16 23 248 229 106
15 6 23 248 229 106
25 6 23 248 229 106
14 7 23 248 229 106
26 7 23 248 229 106
13 8 23 248 229 106
27 8 23 248 229 106
12 9 23 248 229 106
28 9 23 248 229 106
18 15 21 248 229 106
29 10 23 248 229 106
7 35 23 248 229 106
30 11 23 248 229 106
9 12 23 248 229 106
31 12 23 248 229 106
8 13 23 248 229 106
32 13 23 248 229 106
7 14 23 248 229 106
6 15 23 248 229 106
20 31 23 248 229 106
19 30 23 248 229 106
8 32 26 248 229 106
18 29 23 248 229 106
22 29 23 248 229 106
17 28 23 248 229 106
23 28 23 248 229 106
16 27 23 248 229 106
24 27 23 248 229 106
15 26 23 248 229 106
25 26 23 248 229 106
14 25 23 248 229 106
26 25 23 248 229 106
13 24 23 248 229 106
27 24 23 248 229 106
12 23 23 248 229 106
11 30 20 248 229 106
11 22 23 248 229 106
16 34 29 248 229 106
10 21 23 248 229 106
16 26 20 248 229 106
9 20 23 248 229 106
20 31 20 248 229 106
8 19 23 248 229 106
6 31 21 248 229 106
7 18 23 248 229 106
6 17 23 248 229 106
5 16 23 248 229 106
14 6 23 248 229 106
26 6 23 248 229 106
13 7 23 248 229 106
27 7 23 248 229 106
12 8 23 248 229 106
28 8 23 248 229 106
13 16 21 248 229 106
29 9 23 248 229 106
30 24 20 248 229 106
30 10 23 248 229 106
9 11 23 248 229 106
31 11 23 248 229 106
8 12 23 248 229 106
32 12 23 248 229 106
7 13 23 248 229 106
6 14 23 248 229 106
5 15 23 248 229 106
20 32 23 248 229 106
19 31 23 248 229 106
7 32 29 248 229 106
18 30 23 248 229 106
7 32 27 248 229 106
17 29 23 248 229 106
23 29 23 248 229 106
16 28 23 248 229 106
24 28 23 248 229 106
15 27 23 248 229 106
25 27 23 248 229 106
14 26 23 248 229 106
26 26 23 248 229 106
13 25 23 248 229 106
27 25 23 248 229 106
12 24 23 248 229 106
28 24 23 248 229 106
11 23 23 248 229 106
28 33 29 248 229 106
10 22 23 248 229 106
12 31 20 248 229 106
9 21 23 248 229 106
19 32 20 248 229 106
8 20 23 248 229 106
13 32 20 248 229 106
7 19 23 248 229 106
6 18 23 248 229 106
5 17 23 248 229 106
4 16 23 248 229 106
13 6 23 248 229 106
27 6 23 248 229 106
12 7 23 248 229 106
28 7 23 248 229 106
28 26 20 248 229 106
29 8 23 248 229 106
19 16 21 248 229 106
30 9 23 248 229 106
9 10 23 248 229 106
31 10 23 248 229 106
8 11 23 248 229 106
32 11 23 248 229 106
7 12 23 248 229 106
6 13 23 248 229 106
5 14 23 248 229 106
4 15 23 248 229 106
20 33 23 248 229 106
19 32 23 248 229 106
21 32 23 248 229 106
18 31 23 248 229 106
9 32 26 248 229 106
17 30 23 248 229 106
8 32 29 248 229 106
16 29 23 248 229 106
24 29 23 248 229 106
15 28 23 248 229 106
25 28 23 248 229 106
14 27 23 248 229 106
26 27 23 248 229 106
13 26 23 248 229 106
27 26 23 248 229 106
12 25 23 248 229 106
28 25 23 248 229 106
11 24 23 248 229 106
29 24 23 248 229 106
10 23 23 248 229 106
18 33 20 248 229 106
9 22 23 248 229 106
14 33 20 248 229 106
8 21 23 248 229 106
17 34 20 248 229 106
7 20 23 248 229 106
6 19 23 248 229 106
5 18 23 248 229 106
4 17 23 248 229 106
3 16 23 248 229 106
12 6 23 248 229 106
28 6 23 248 229 106
11 7 23 248 229 106
29 7 23 248 229 106
12 17 21 248 229 106
30 8 23 248 229 106
29 35 23 248 229 106
31 9 23 248 229 106
8 10 23 248 229 106
32 10 23 248 229 106
7 11 23 248 229 106
6 12 23 248 229 106
5 13 23 248 229 106
4 14 23 248 229 106
3 15 23 248 229 106
20 34 23 248 229 106
19 33 23 248 229 106
21 33 23 248 229 106
18 32 23 248 229 106
22 32 23 248 229 106
17 31 23 248 229 106
8 32 27 248 229 106
16 30 23 248 229 106
7 32 28 248 229 106
15 29 23 248 229 106
25 29 23 248 229 106
14 28 23 248 229 106
26 28 23 248 229 106
13 27 23 248 229 106
27 27 23 248 229 106
12 26 23 248 229 106
28 26 23 248 229 106
11 25 23 248 229 106
29 25 23 248 229 106
10 24 23 248 229 106
30 24 23 248 229 106
9 23 23 248 229 106
15 34 20 248 229 106
8 22 23 248 229 106
20 27 21 248 229 106
7 21 23 248 229 106
6 20 23 248 229 106
5 19 23 248 229 106
4 18 23 248 229 106
3 17 23 248 229 106
11 6 23 248 229 106
29 6 23 248 229 106
10 7 23 248 229 106
30 7 23 248 229 106
14 20 25 248 229 106
31 8 23 248 229 106
17 20 25 248 229 106
32 9 23 248 229 106
7 10 23 248 229 106
6 11 23 248 229 106
5 12 23 248 229 106
4 13 23 248 229 106
3 14 23 248 229 106
19 34 23 248 229 106
21 34 23 248 229 106
18 33 23 248 229 106
22 33 23 248 229 106
17 32 23 248 229 106
23 32 23 248 229 106
16 31 23 248 229 106
10 32 26 248 229 106
15 30 23 248 229 106
9 32 29 248 229 106
14 29 23 248 229 106
26 29 23 248 229 106
13 28 23 248 229 106
27 28 23 248 229 106
12 27 23 248 229 106
28 27 23 248 229 106
11 26 23 248 229 106
29 26 23 248 229 106
10 25 23 248 229 106
30 25 23 248 229 106
9 24 23 248 229 106
31 24 23 248 229 106
8 23 23 248 229 106
16 35 20 248 229 106
7 22 23 248 229 106
6 21 23 248 229 106
5 20 23 248 229 106
4 19 23 248 229 106
3 18 23 248 229 106
10 6 23 248 229 106
30 6 23 248 229 106
9 7 23 248 229 106
31 7 23 248 229 106
15 20 25 248 229 106
32 8 23 248 229 106
26 28 20 248 229 106
6 10 23 248 229 106
5 11 23 248 229 106
4 12 23 248 229 106
3 13 23 248 229 106
18 34 23 248 229 106
22 34 23 248 229 106
17 33 23 248 229 106
23 33 23 248 229 106
16 32 23 248 229 106
24 32 23 248 229 106
15 31 23 248 229 106
9 32 27 248 229 106
14 30 23 248 229 106
8 32 28 248 229 106
13 29 23 248 229 106
27 29 23 248 229 106
12 28 23 248 229 106
28 28 23 248 229 106
11 27 23 248 229 106
29 27 23 248 229 106
10 26 23 248 229 106
30 26 23 248 229 106
9 25 23 248 229 106
31 25 23 248 229 106
8 24 23 248 229 106
32 24 23 248 229 106
7 23 23 248 229 106
6 22 23 248 229 106
5 21 23 248 229 106
4 20 23 248 229 106
3 19 23 248 229 106
9 6 23 248 229 106
31 6 23 248 229 106
8 7 23 248 229 106
32 7 23 248 229 106
16 20 25 248 229 106
6 28 20 248 229 106
5 10 23 248 229 106
4 11 23 248 229 106
3 12 23 248 229 106
17 34 23 248 229 106
23 34 23 248 229 106
16 33 23 248 229 106
24 33 23 248 229 106
15 32 23 248 229 106
25 32 23 248 229 106
14 31 23 248 229 106
11 32 26 248 229 106
13 30 23 248 229 106
10 32 29 248 229 106
12 29 23 248 229 106
28 29 23 248 229 106
11 28 23 248 229 106
29 28 23 248 229 106
10 27 23 248 229 106
30 27 23 248 229 106
9 26 23 248 229 106
31 26 23 248 229 106
8 25 23 248 229 106
32 25 23 248 229 106
7 24 23 248 229 106
6 23 23 248 229 106
5 22 23 248 229 106
4 21 23 248 229 106
3 20 23 248 229 106
8 6 23 248 229 106
32 6 23 248 229 106
7 7 23 248 229 106
16 13 20 248 229 106
5 9 23 248 229 106
4 10 23 248 229 106
3 11 23 248 229 106
16 34 23 248 229 106
24 34 23 248 229 106
15 33 23 248 229 106
25 33 23 248 229 106
14 32 23 248 229 106
10 32 27 248 229 106
13 31 23 248 229 106
9 32 28 248 229 106
12 30 23 248 229 106
12 32 26 248 229 106
11 29 23 248 229 106
29 29 23 248 229 106
10 28 23 248 229 106
30 28 23 248 229 106
9 27 23 248 229 106
31 27 23 248 229 106
8 26 23 248 229 106
32 26 23 248 229 106
7 25 23 248 229 106
6 24 23 248 229 106
5 23 23 248 229 106
4 22 23 248 229 106
3 21 23 248 229 106
7 6 23 248 229 106
6 7 23 248 229 106
5 8 23 248 229 106
4 9 23 248 229 106
3 10 23 248 229 106
15 34 23 248 229 106
25 34 23 248 229 106
14 33 23 248 229 106
29 34 21 248 229 106
13 32 23 248 229 106
11 32 29 248 229 106
12 31 23 248 229 106
20 17 29 248 229 106
11 30 23 248 229 106
11 32 27 248 229 106
10 29 23 248 229 106
30 29 23 248 229 106
9 28 23 248 229 106
31 28 23 248 229 106
8 27 23 248 229 106
32 27 23 248 229 106
7 26 23 248 229 106
6 25 23 248 229 106
5 24 23 248 229 106
4 23 23 248 229 106
3 22 23 248 229 106
6 6 23 248 229 106
5 7 23 248 229 106
4 8 23 248 229 106
3 9 23 248 229 106
14 34 23 248 229 106
29 33 21 248 229 106
13 33 23 248 229 106
9 29 29 248 229 106
12 32 23 248 229 106
21 16 29 248 229 106
11 31 23 248 229 106
11 7 29 248 229 106
10 30 23 248 229 106
10 32 28 248 229 106
9 29 23 248 229 106
31 29 23 248 229 106
8 28 23 248 229 106
32 28 23 248 229 106
7 27 23 248 229 106
6 26 23 248 229 106
5 25 23 248 229 106
4 24 23 248 229 106
3 23 23 248 229 106
5 6 23 248 229 106
4 7 23 248 229 106
3 8 23 248 229 106
13 34 23 248 229 106
25 13 28 248 229 106
12 33 23 248 229 106
28 11 29 248 229 106
11 32 23 248 229 106
18 16 29 248 229 106
10 31 23 248 229 106
19 15 29 248 229 106
9 30 23 248 229 106
14 32 25 248 229 106
8 29 23 248 229 106
32 29 23 248 229 106
7 28 23 248 229 106
6 27 23 248 229 106
5 26 23 248 229 106
4 25 23 248 229 106
3 24 23 248 229 106
4 6 23 248 229 106
3 7 23 248 229 106
12 34 23 248 229 106
16 33 29 248 229 106
11 33 23 248 229 106
27 26 29 248 229 106
10 32 23 248 229 106
28 9 29 248 229 106
9 31 23 248 229 106
18 17 29 248 229 106
8 30 23 248 229 106
13 32 26 248 229 106
7 29 23 248 229 106
6 28 23 248 229 106
5 27 23 248 229 106
4 26 23 248 229 106
3 25 23 248 229 106
3 6 23 248 229 106
11 34 23 248 229 106
19 16 29 248 229 106
10 33 23 248 229 106
20 15 29 248 229 106
9 32 23 248 229 106
15 34 29 248 229 106
8 31 23 248 229 106
28 25 29 248 229 106
7 30 23 248 229 106
6 29 23 248 229 106
5 28 23 248 229 106
4 27 23 248 229 106
3 26 23 248 229 106
10 34 23 248 229 106
28 10 29 248 229 106
9 33 23 248 229 106
19 17 29 248 229 106
8 32 23 248 229 106
20 16 29 248 229 106
7 31 23 248 229 106
6 30 23 248 229 106
5 29 23 248 229 106
4 28 23 248 229 106
3 27 23 248 229 106
9 34 23 248 229 106
21 15 29 248 229 106
8 33 23 248 229 106
24 14 28 248 229 106
7 32 23 248 229 106
6 31 23 248 229 106
5 30 23 248 229 106
4 29 23 248 229 106
3 28 23 248 229 106
8 34 23 248 229 106
28 32 29 248 229 106
7 33 23 248 229 106
6 32 23 248 229 106
5 31 23 248 229 106
4 30 23 248 229 106
3 29 23 248 229 106
7 34 23 248 229 106
6 33 23 248 229 106
5 32 23 248 229 106
4 31 23 248 229 106
3 30 23 248 229 106
6 34 23 248 229 106
5 33 23 248 229 106
4 32 23 248 229 106
3 31 23 248 229 106
5 34 23 248 229 106
4 33 23 248 229 106
3 32 23 248 229 106
4 34 23 248 229 106
3 33 23 248 229 106
3 34 23 248 229 106
21 16 24 248 229 106
21 15 24 248 229 106
21 17 24 248 229 106
20 16 24 248 229 106
22 16 24 248 229 106
21 14 24 248 229 106
20 15 24 248 229 106
22 15 24 248 229 106
21 18 24 248 229 106
20 17 24 248 229 106
22 17 24 248 229 106
19 16 24 248 229 106
23 16 24 248 229 106
21 13 24 248 229 106
20 14 24 248 229 106
22 14 24 248 229 106
19 15 24 248 229 106
23 15 24 248 229 106
21 19 24 248 229 106
20 18 24 248 229 106
22 18 24 248 229 106
19 17 24 248 229 106
23 17 24 248 229 106
18 16 24 248 229 106
24 16 24 248 229 106
21 12 24 248 229 106
20 13 24 248 229 106
22 13 24 248 229 106
19 14 24 248 229 106
23 14 24 248 229 106
18 15 24 248 229 106
24 15 24 248 229 106
21 20 24 248 229 106
20 19 24 248 229 106
22 19 24 248 229 106
19 18 24 248 229 106
23 18 24 248 229 106
18 17 24 248 229 106
24 17 24 248 229 106
17 16 24 248 229 106
25 16 24 248 229 106
21 11 24 248 229 106
20 12 24 248 229 106
22 12 24 248 229 106
19 13 24 248 229 106
23 13 24 248 229 106
15 22 21 248 229 106
24 14 24 248 229 106
17 15 24 248 229 106
25 15 24 248 229 106
21 21 24 248 229 106
20 20 24 248 229 106
22 20 24 248 229 106
19 19 24 248 229 106
23 19 24 248 229 106
18 18 24 248 229 106
24 18 24 248 229 106
17 17 24 248 229 106
25 17 24 248 229 106
16 16 24 248 229 106
26 16 24 248 229 106
21 10 24 248 229 106
20 11 24 248 229 106
22 11 24 248 229 106
19 12 24 248 229 106
23 12 24 248 229 106
6 15 21 248 229 106
24 13 24 248 229 106
16 23 21 248 229 106
25 14 24 248 229 106
16 15 24 248 229 106
26 15 24 248 229 106
21 22 24 248 229 106
20 21 24 248 229 106
22 21 24 248 229 106
19 20 24 248 229 106
23 20 24 248 229 106
18 19 24 248 229 106
24 19 24 248 229 106
17 18 24 248 229 106
25 18 24 248 229 106
16 17 24 248 229 106
26 17 24 248 229 106
15 16 24 248 229 106
27 16 24 248 229 106
21 9 24 248 229 106
20 10 24 248 229 106
22 10 24 248 229 106
19 11 24 248 229 106
23 11 24 248 229 106
18 12 24 248 229 106
24 12 24 248 229 106
26 15 21 248 229 106
25 13 24 248 229 106
18 19 21 248 229 106
26 14 24 248 229 106
15 15 24 248 229 106
27 15 24 248 229 106
21 23 24 248 229 106
20 22 24 248 229 106
22 22 24 248 229 106
19 21 24 248 229 106
23 21 24 248 229 106
18 20 24 248 229 106
24 20 24 248 229 106
17 19 24 248 229 106
25 19 24 248 229 106
16 18 24 248 229 106
26 18 24 248 229 106
15 17 24 248 229 106
27 17 24 248 229 106
14 16 24 248 229 106
28 16 24 248 229 106
21 8 24 248 229 106
20 9 24 248 229 106
22 9 24 248 229 106
19 10 24 248 229 106
23 10 24 248 229 106
18 11 24 248 229 106
24 11 24 248 229 106
17 12 24 248 229 106
25 12 24 248 229 106
5 16 21 248 229 106
26 13 24 248 229 106
24 16 20 248 229 106
27 14 24 248 229 106
14 15 24 248 229 106
28 15 24 248 229 106
21 24 24 248 229 106
20 23 24 248 229 106
22 23 24 248 229 106
19 22 24 248 229 106
23 22 24 248 229 106
18 21 24 248 229 106
24 21 24 248 229 106
17 20 24 248 229 106
25 20 24 248 229 106
16 19 24 248 229 106
26 19 24 248 229 106
15 18 24 248 229 106
27 18 24 248 229 106
14 17 24 248 229 106
28 17 24 248 229 106
13 16 24 248 229 106
29 16 24 248 229 106
21 7 24 248 229 106
20 8 24 248 229 106
22 8 24 248 229 106
19 9 24 248 229 106
23 9 24 248 229 106
18 10 24 248 229 106
24 10 24 248 229 106
17 11 24 248 229 106
25 11 24 248 229 106
16 12 24 248 229 106
26 12 24 248 229 106
27 16 21 248 229 106
27 13 24 248 229 106
4 17 21 248 229 106
28 14 24 248 229 106
13 15 24 248 229 106
29 15 24 248 229 106
21 25 24 248 229 106
20 24 24 248 229 106
22 24 24 248 229 106
19 23 24 248 229 106
23 23 24 248 229 106
18 22 24 248 229 106
24 22 24 248 229 106
17 21 24 248 229 106
25 21 24 248 229 106
16 20 24 248 229 106
26 20 24 248 229 106
15 19 24 248 229 106
27 19 24 248 229 106
14 18 24 248 229 106
11 26 21 248 229 106
13 17 24 248 229 106
29 17 24 248 229 106
12 16 24 248 229 106
30 16 24 248 229 106
21 6 24 248 229 106
20 7 24 248 229 106
22 7 24 248 229 106
19 8 24 248 229 106
23 8 24 248 229 106
18 9 24 248 229 106
24 9 24 248 229 106
17 10 24 248 229 106
25 10 24 248 229 106
16 11 24 248 229 106
26 11 24 248 229 106
15 12 24 248 229 106
27 12 24 248 229 106
28 17 21 248 229 106
28 13 24 248 229 106
18 20 21 248 229 106
29 14 24 248 229 106
12 15 24 248 229 106
30 15 24 248 229 106
21 26 24 248 229 106
20 25 24 248 229 106
22 25 24 248 229 106
19 24 24 248 229 106
23 24 24 248 229 106
18 23 24 248 229 106
24 23 24 248 229 106
17 22 24 248 229 106
25 22 24 248 229 106
16 21 24 248 229 106
26 21 24 248 229 106
15 20 24 248 229 106
27 20 24 248 229 106
14 19 24 248 229 106
3 18 20 248 229 106
13 18 24 248 229 106
28 30 25 248 229 106
12 17 24 248 229 106
30 17 24 248 229 106
11 16 24 248 229 106
31 16 24 248 229 106
20 6 24 248 229 106
22 6 24 248 229 106
19 7 24 248 229 106
23 7 24 248 229 106
18 8 24 248 229 106
24 8 24 248 229 106
17 9 24 248 229 106
25 9 24 248 229 106
16 10 24 248 229 106
26 10 24 248 229 106
15 11 24 248 229 106
27 11 24 248 229 106
14 12 24 248 229 106
28 12 24 248 229 106
14 20 21 248 229 106
29 13 24 248 229 106
17 21 21 248 229 106
30 14 24 248 229 106
11 15 24 248 229 106
31 15 24 248 229 106
21 27 24 248 229 106
20 26 24 248 229 106
22 26 24 248 229 106
19 25 24 248 229 106
23 25 24 248 229 106
18 24 24 248 229 106
24 24 24 248 229 106
17 23 24 248 229 106
25 23 24 248 229 106
16 22 24 248 229 106
26 22 24 248 229 106
15 21 24 248 229 106
27 21 24 248 229 106
14 20 24 248 229 106
21 26 21 248 229 106
13 19 24 248 229 106
28 31 25 248 229 106
12 18 24 248 229 106
23 15 20 248 229 106
11 17 24 248 229 106
31 17 24 248 229 106
10 16 24 248 229 106
32 16 24 248 229 106
19 6 24 248 229 106
23 6 24 248 229 106
18 7 24 248 229 106
24 7 24 248 229 106
17 8 24 248 229 106
25 8 24 248 229 106
16 9 24 248 229 106
26 9 24 248 229 106
15 10 24 248 229 106
27 10 24 248 229 106
14 11 24 248 229 106
28 11 24 248 229 106
13 12 24 248 229 106
29 12 24 248 229 106
15 21 21 248 229 106
30 13 24 248 229 106
16 22 21 248 229 106
31 14 24 248 229 106
10 15 24 248 229 106
32 15 24 248 229 106
21 28 24 248 229 106
20 27 24 248 229 106
22 27 24 248 229 106
19 26 24 248 229 106
23 26 24 248 229 106
18 25 24 248 229 106
24 25 24 248 229 106
17 24 24 248 229 106
25 24 24 248 229 106
16 23 24 248 229 106
26 23 24 248 229 106
15 22 24 248 229 106
27 22 24 248 229 106
14 21 24 248 229 106
10 25 21 248 229 106
13 20 24 248 229 106
30 30 24 248 229 106
12 19 24 248 229 106
22 25 21 248 229 106
11 18 24 248 229 106
28 17 20 248 229 106
10 17 24 248 229 106
32 17 24 248 229 106
9 16 24 248 229 106
18 6 24 248 229 106
24 6 24 248 229 106
17 7 24 248 229 106
25 7 24 248 229 106
16 8 24 248 229 106
26 8 24 248 229 106
15 9 24 248 229 106
27 9 24 248 229 106
14 10 24 248 229 106
28 10 24 248 229 106
13 11 24 248 229 106
29 11 24 248 229 106
12 12 24 248 229 106
30 12 24 248 229 106
17 19 21 248 229 106
31 13 24 248 229 106
14 17 25 248 229 106
32 14 24 248 229 106
9 15 24 248 229 106
21 29 24 248 229 106
20 28 24 248 229 106
22 28 24 248 229 106
19 27 24 248 229 106
23 27 24 248 229 106
18 26 24 248 229 106
24 26 24 248 229 106
17 25 24 248 229 106
25 25 24 248 229 106
16 24 24 248 229 106
26 24 24 248 229 106
15 23 24 248 229 106
27 23 24 248 229 106
14 22 24 248 229 106
4 17 20 248 229 106
13 21 24 248 229 106
10 7 29 248 229 106
12 20 24 248 229 106
27 16 20 248 229 106
11 19 24 248 229 106
5 16 20 248 229 106
10 18 24 248 229 106
26 15 20 248 229 106
9 17 24 248 229 106
8 16 24 248 229 106
17 6 24 248 229 106
25 6 24 248 229 106
16 7 24 248 229 106
26 7 24 248 229 106
15 8 24 248 229 106
27 8 24 248 229 106
14 9 24 248 229 106
28 9 24 248 229 106
13 10 24 248 229 106
29 10 24 248 229 106
12 11 24 248 229 106
30 11 24 248 229 106
21 6 20 248 229 106
31 12 24 248 229 106
17 17 25 248 229 106
32 13 24 248 229 106
9 14 24 248 229 106
8 15 24 248 229 106
12 32 29 248 229 106
20 29 24 248 229 106
22 29 24 248 229 106
19 28 24 248 229 106
23 28 24 248 229 106
18 27 24 248 229 106
24 27 24 248 229 106
17 26 24 248 229 106
25 26 24 248 229 106
16 25 24 248 229 106
26 25 24 248 229 106
15 24 24 248 229 106
27 24 24 248 229 106
14 23 24 248 229 106
6 15 20 248 229 106
13 22 24 248 229 106
29 30 24 248 229 106
12 21 24 248 229 106
26 30 20 248 229 106
11 20 24 248 229 106
25 14 20 248 229 106
10 19 24 248 229 106
25 32 21 248 229 106
9 18 24 248 229 106
8 17 24 248 229 106
7 16 24 248 229 106
16 6 24 248 229 106
26 6 24 248 229 106
15 7 24 248 229 106
27 7 24 248 229 106
14 8 24 248 229 106
28 8 24 248 229 106
13 9 24 248 229 106
29 9 24 248 229 106
12 10 24 248 229 106
30 10 24 248 229 106
12 22 20 248 229 106
31 11 24 248 229 106
16 17 25 248 229 106
32 12 24 248 229 106
9 13 24 248 229 106
8 14 24 248 229 106
7 15 24 248 229 106
13 32 25 248 229 106
20 30 24 248 229 106
12 32 27 248 229 106
19 29 24 248 229 106
23 29 24 248 229 106
18 28 24 248 229 106
24 28 24 248 229 106
17 27 24 248 229 106
25 27 24 248 229 106
16 26 24 248 229 106
26 26 24 248 229 106
15 25 24 248 229 106
27 25 24 248 229 106
14 24 24 248 229 106
28 24 24 248 229 106
13 23 24 248 229 106
7 14 20 248 229 106
12 22 24 248 229 106
24 13 20 248 229 106
11 21 24 248 229 106
8 13 20 248 229 106
10 20 24 248 229 106
23 12 20 248 229 106
9 19 24 248 229 106
8 18 24 248 229 106
7 17 24 248 229 106
6 16 24 248 229 106
15 6 24 248 229 106
27 6 24 248 229 106
14 7 24 248 229 106
28 7 24 248 229 106
13 8 24 248 229 106
29 8 24 248 229 106
12 9 24 248 229 106
30 9 24 248 229 106
15 14 21 248 229 106
31 10 24 248 229 106
11 6 20 248 229 106
32 11 24 248 229 106
9 12 24 248 229 106
8 13 24 248 229 106
7 14 24 248 229 106
6 15 24 248 229 106
12 32 25 248 229 106
20 31 24 248 229 106
13 31 25 248 229 106
19 30 24 248 229 106
11 32 28 248 229 106
18 29 24 248 229 106
24 29 24 248 229 106
17 28 24 248 229 106
25 28 24 248 229 106
16 27 24 248 229 106
26 27 24 248 229 106
15 26 24 248 229 106
27 26 24 248 229 106
14 25 24 248 229 106
28 25 24 248 229 106
13 24 24 248 229 106
29 24 24 248 229 106
12 23 24 248 229 106
9 12 20 248 229 106
11 22 24 248 229 106
22 11 20 248 229 106
10 21 24 248 229 106
10 11 20 248 229 106
9 20 24 248 229 106
8 19 24 248 229 106
7 18 24 248 229 106
6 17 24 248 229 106
5 16 24 248 229 106
14 6 24 248 229 106
28 6 24 248 229 106
13 7 24 248 229 106
29 7 24 248 229 106
12 8 24 248 229 106
30 8 24 248 229 106
14 15 21 248 229 106
31 9 24 248 229 106
17 14 21 248 229 106
32 10 24 248 229 106
9 11 24 248 229 106
8 12 24 248 229 106
7 13 24 248 229 106
6 14 24 248 229 106
5 15 24 248 229 106
21 33 24 248 229 106
20 32 24 248 229 106
12 31 25 248 229 106
19 31 24 248 229 106
12 31 24 248 229 106
18 30 24 248 229 106
15 32 25 248 229 106
17 29 24 248 229 106
25 29 24 248 229 106
16 28 24 248 229 106
26 28 24 248 229 106
15 27 24 248 229 106
27 27 24 248 229 106
14 26 24 248 229 106
28 26 24 248 229 106
13 25 24 248 229 106
29 25 24 248 229 106
12 24 24 248 229 106
30 24 24 248 229 106
11 23 24 248 229 106
21 10 20 248 229 106
10 22 24 248 229 106
11 10 20 248 229 106
9 21 24 248 229 106
8 20 24 248 229 106
7 19 24 248 229 106
6 18 24 248 229 106
5 17 24 248 229 106
4 16 24 248 229 106
13 6 24 248 229 106
29 6 24 248 229 106
12 7 24 248 229 106
30 7 24 248 229 106
11 21 20 248 229 106
31 8 24 248 229 106
18 3 20 248 229 106
32 9 24 248 229 106
9 10 24 248 229 106
8 11 24 248 229 106
7 12 24 248 229 106
6 13 24 248 229 106
5 14 24 248 229 106
4 15 24 248 229 106
21 34 24 248 229 106
20 33 24 248 229 106
22 33 24 248 229 106
19 32 24 248 229 106
18 12 26 248 229 106
18 31 24 248 229 106
17 12 26 248 229 106
17 30 24 248 229 106
14 32 26 248 229 106
16 29 24 248 229 106
26 29 24 248 229 106
15 28 24 248 229 106
27 28 24 248 229 106
14 27 24 248 229 106
28 27 24 248 229 106
13 26 24 248 229 106
29 26 24 248 229 106
12 25 24 248 229 106
30 25 24 248 229 106
11 24 24 248 229 106
31 24 24 248 229 106
10 23 24 248 229 106
20 9 20 248 229 106
9 22 24 248 229 106
8 21 24 248 229 106
7 20 24 248 229 106
6 19 24 248 229 106
5 18 24 248 229 106
4 17 24 248 229 106
3 16 24 248 229 106
12 6 24 248 229 106
30 6 24 248 229 106
11 7 24 248 229 106
31 7 24 248 229 106
29 25 20 248 229 106
32 8 24 248 229 106
5 27 20 248 229 106
8 10 24 248 229 106
7 11 24 248 229 106
6 12 24 248 229 106
5 13 24 248 229 106
4 14 24 248 229 106
3 15 24 248 229 106
20 34 24 248 229 106
22 34 24 248 229 106
19 33 24 248 229 106
23 33 24 248 229 106
18 32 24 248 229 106
16 12 26 248 229 106
17 31 24 248 229 106
15 12 26 248 229 106
16 30 24 248 229 106
13 32 29 248 229 106
15 29 24 248 229 106
27 29 24 248 229 106
14 28 24 248 229 106
28 28 24 248 229 106
13 27 24 248 229 106
29 27 24 248 229 106
12 26 24 248 229 106
30 26 24 248 229 106
11 25 24 248 229 106
31 25 24 248 229 106
10 24 24 248 229 106
32 24 24 248 229 106
9 23 24 248 229 106
8 22 24 248 229 106
7 21 24 248 229 106
6 20 24 248 229 106
5 19 24 248 229 106
4 18 24 248 229 106
3 17 24 248 229 106
11 6 24 248 229 106
31 6 24 248 229 106
10 7 24 248 229 106
32 7 24 248 229 106
23 28 21 248 229 106
8 27 21 248 229 106
7 10 24 248 229 106
6 11 24 248 229 106
5 12 24 248 229 106
4 13 24 248 229 106
3 14 24 248 229 106
19 34 24 248 229 106
23 34 24 248 229 106
18 33 24 248 229 106
24 33 24 248 229 106
17 32 24 248 229 106
13 8 26 248 229 106
16 31 24 248 229 106
14 12 26 248 229 106
15 30 24 248 229 106
13 32 27 248 229 106
14 29 24 248 229 106
28 29 24 248 229 106
13 28 24 248 229 106
29 28 24 248 229 106
12 27 24 248 229 106
30 27 24 248 229 106
11 26 24 248 229 106
31 26 24 248 229 106
10 25 24 248 229 106
32 25 24 248 229 106
9 24 24 248 229 106
8 23 24 248 229 106
7 22 24 248 229 106
6 21 24 248 229 106
5 20 24 248 229 106
4 19 24 248 229 106
3 18 24 248 229 106
10 6 24 248 229 106
32 6 24 248 229 106
9 7 24 248 229 106
24 27 21 248 229 106
7 26 21 248 229 106
6 10 24 248 229 106
5 11 24 248 229 106
4 12 24 248 229 106
3 13 24 248 229 106
18 34 24 248 229 106
24 34 24 248 229 106
17 33 24 248 229 106
25 33 24 248 229 106
16 32 24 248 229 106
13 9 26 248 229 106
15 31 24 248 229 106
12 8 26 248 229 106
14 30 24 248 229 106
12 32 28 248 229 106
13 29 24 248 229 106
29 29 24 248 229 106
12 28 24 248 229 106
30 28 24 248 229 106
11 27 24 248 229 106
31 27 24 248 229 106
10 26 24 248 229 106
32 26 24 248 229 106
9 25 24 248 229 106
8 24 24 248 229 106
7 23 24 248 229 106
6 22 24 248 229 106
5 21 24 248 229 106
4 20 24 248 229 106
3 19 24 248 229 106
9 6 24 248 229 106
8 7 24 248 229 106
25 26 21 248 229 106
28 35 24 248 229 106
5 10 24 248 229 106
4 11 24 248 229 106
3 12 24 248 229 106
17 34 24 248 229 106
25 34 24 248 229 106
16 33 24 248 229 106
28 34 21 248 229 106
15 32 24 248 229 106
13 12 26 248 229 106
14 31 24 248 229 106
17 15 29 248 229 106
13 30 24 248 229 106
16 32 25 248 229 106
12 29 24 248 229 106
30 29 24 248 229 106
11 28 24 248 229 106
31 28 24 248 229 106
10 27 24 248 229 106
32 27 24 248 229 106
9 26 24 248 229 106
8 25 24 248 229 106
7 24 24 248 229 106
6 23 24 248 229 106
5 22 24 248 229 106
4 21 24 248 229 106
3 20 24 248 229 106
8 6 24 248 229 106
7 7 24 248 229 106
28 35 22 248 229 106
5 9 24 248 229 106
4 10 24 248 229 106
3 11 24 248 229 106
16 34 24 248 229 106
28 33 21 248 229 106
15 33 24 248 229 106
28 31 29 248 229 106
14 32 24 248 229 106
26 9 29 248 229 106
13 31 24 248 229 106
20 28 29 248 229 106
12 30 24 248 229 106
20 18 29 248 229 106
11 29 24 248 229 106
31 29 24 248 229 106
10 28 24 248 229 106
32 28 24 248 229 106
9 27 24 248 229 106
8 26 24 248 229 106
7 25 24 248 229 106
6 24 24 248 229 106
5 23 24 248 229 106
4 22 24 248 229 106
3 21 24 248 229 106
7 6 24 248 229 106
6 7 24 248 229 106
5 8 24 248 229 106
4 9 24 248 229 106
3 10 24 248 229 106
15 34 24 248 229 106
27 8 29 248 229 106
14 33 24 248 229 106
28 7 29 248 229 106
13 32 24 248 229 106
16 17 29 248 229 106
19 12 26 248 229 106
17 16 29 248 229 106
11 30 24 248 229 106
30 31 24 248 229 106
10 29 24 248 229 106
32 29 24 248 229 106
9 28 24 248 229 106
8 27 24 248 229 106
7 26 24 248 229 106
6 25 24 248 229 106
5 24 24 248 229 106
4 23 24 248 229 106
3 22 24 248 229 106
6 6 24 248 229 106
5 7 24 248 229 106
4 8 24 248 229 106
3 9 24 248 229 106
14 34 24 248 229 106
18 15 29 248 229 106
13 33 24 248 229 106
15 33 29 248 229 106
12 32 24 248 229 106
25 29 29 248 229 106
11 31 24 248 229 106
27 34 29 248 229 106
10 30 24 248 229 106
27 34 23 248 229 106
9 29 24 248 229 106
8 28 24 248 229 106
7 27 24 248 229 106
6 26 24 248 229 106
5 25 24 248 229 106
4 24 24 248 229 106
3 23 24 248 229 106
5 6 24 248 229 106
4 7 24 248 229 106
3 8 24 248 229 106
13 34 24 248 229 106
27 9 29 248 229 106
12 33 24 248 229 106
28 8 29 248 229 106
11 32 24 248 229 106
27 33 29 248 229 106
10 31 24 248 229 106
27 34 27 248 229 106
9 30 24 248 229 106
8 29 24 248 229 106
7 28 24 248 229 106
6 27 24 248 229 106
5 26 24 248 229 106
4 25 24 248 229 106
3 24 24 248 229 106
4 6 24 248 229 106
3 7 24 248 229 106
12 34 24 248 229 106
17 17 29 248 229 106
11 33 24 248 229 106
27 34 28 248 229 106
10 32 24 248 229 106
27 33 27 248 229 106
9 31 24 248 229 106
8 30 24 248 229 106
7 29 24 248 229 106
6 28 24 248 229 106
5 27 24 248 229 106
4 26 24 248 229 106
3 25 24 248 229 106
3 6 24 248 229 106
11 34 24 248 229 106
27 33 28 248 229 106
10 33 24 248 229 106
27 34 26 248 229 106
9 32 24 248 229 106
8 31 24 248 229 106
7 30 24 248 229 106
6 29 24 248 229 106
5 28 24 248 229 106
4 27 24 248 229 106
3 26 24 248 229 106
10 34 24 248 229 106
27 33 26 248 229 106
9 33 24 248 229 106
8 32 24 248 229 106
7 31 24 248 229 106
6 30 24 248 229 106
5 29 24 248 229 106
4 28 24 248 229 106
3 27 24 248 229 106
9 34 24 248 229 106
8 33 24 248 229 106
7 32 24 248 229 106
6 31 24 248 229 106
5 30 24 248 229 106
4 29 24 248 229 106
3 28 24 248 229 106
8 34 24 248 229 106
7 33 24 248 229 106
6 32 24 248 229 106
5 31 24 248 229 106
4 30 24 248 229 106
3 29 24 248 229 106
7 34 24 248 229 106
6 33 24 248 229 106
5 32 24 248 229 106
4 31 24 248 229 106
3 30 24 248 229 106
6 34 24 248 229 106
5 33 24 248 229 106
4 32 24 248 229 106
3 31 24 248 229 106
5 34 24 248 229 106
4 33 24 248 229 106
3 32 24 248 229 106
4 34 24 248 229 106
3 33 24 248 229 106
3 34 24 248 229 106
15 12 25 248 229 106
15 15 25 248 229 106
16 15 25 248 229 106
21 15 25 248 229 106
14 12 25 248 229 106
15 16 25 248 229 106
14 16 25 248 229 106
27 9 25 248 229 106
22 17 25 248 229 106
21 16 25 248 229 106
26 9 25 248 229 106
20 15 25 248 229 106
17 12 25 248 229 106
22 12 25 248 229 106
16 16 25 248 229 106
14 15 25 248 229 106
25 9 25 248 229 106
24 14 25 248 229 106
22 18 25 248 229 106
21 17 25 248 229 106
23 17 25 248 229 106
20 16 25 248 229 106
16 12 25 248 229 106
19 15 25 248 229 106
24 9 25 248 229 106
22 7 20 248 229 106
21 12 25 248 229 106
23 12 25 248 229 106
23 9 25 248 229 106
24 13 25 248 229 106
22 9 25 248 229 106
25 14 25 248 229 106
22 19 25 248 229 106
21 18 25 248 229 106
23 18 25 248 229 106
20 17 25 248 229 106
24 17 25 248 229 106
19 16 25 248 229 106
21 9 25 248 229 106
18 15 25 248 229 106
18 13 21 248 229 106
9 8 20 248 229 106
21 24 21 248 229 106
11 24 21 248 229 106
20 12 25 248 229 106
24 12 25 248 229 106
20 9 25 248 229 106
25 13 25 248 229 106
19 9 25 248 229 106
14 13 21 248 229 106
22 20 25 248 229 106
21 19 25 248 229 106
23 19 25 248 229 106
20 18 25 248 229 106
24 18 25 248 229 106
19 17 25 248 229 106
25 17 25 248 229 106
18 16 25 248 229 106
17 16 25 248 229 106
27 33 20 248 229 106
17 12 21 248 229 106
20 25 21 248 229 106
12 25 21 248 229 106
19 26 21 248 229 106
13 26 21 248 229 106
22 28 21 248 229 106
19 12 25 248 229 106
25 12 25 248 229 106
18 9 25 248 229 106
15 12 21 248 229 106
34 36 46 7 146 0
16 11 21 248 229 106
22 21 25 248 229 106
21 20 25 248 229 106
23 20 25 248 229 106
20 19 25 248 229 106
24 19 25 248 229 106
4 22 21 248 229 106
25 18 25 248 229 106
18 17 25 248 229 106
26 17 25 248 229 106
33 2 23 248 229 106
17 15 25 248 229 106
37 34 21 248 229 106
28 15 25 248 229 106
22 8 25 248 229 106
18 27 21 248 229 106
9 27 21 248 229 106
14 27 21 248 229 106
23 27 21 248 229 106
17 28 21 248 229 106
8 26 21 248 229 106
18 12 25 248 229 106
24 20 21 248 229 106
37 37 21 248 229 106
8 20 21 248 229 106
35 37 21 248 229 106
28 14 25 248 229 106
22 22 25 248 229 106
21 21 25 248 229 106
23 21 25 248 229 106
20 20 25 248 229 106
24 20 25 248 229 106
18 25 21 248 229 106
25 19 25 248 229 106
3 21 21 248 229 106
26 18 25 248 229 106
34 3 20 248 229 106
27 17 25 248 229 106
33 3 23 248 229 106
28 16 25 248 229 106
36 37 21 248 229 106
26 28 29 248 229 106
22 7 25 248 229 106
21 8 25 248 229 106
23 8 25 248 229 106
15 28 21 248 229 106
24 26 21 248 229 106
16 29 21 248 229 106
24 19 21 248 229 106
8 19 21 248 229 106
23 18 21 248 229 106
36 39 23 248 229 106
23 21 21 248 229 106
28 32 20 248 229 106
28 13 25 248 229 106
37 36 21 248 229 106
14 34 29 248 229 106
22 23 25 248 229 106
21 22 25 248 229 106
23 22 25 248 229 106
20 21 25 248 229 106
24 21 25 248 229 106
16 13 21 248 229 106
25 20 25 248 229 106
14 25 21 248 229 106
26 19 25 248 229 106
30 35 20 248 229 106
27 18 25 248 229 106
33 2 20 248 229 106
28 17 25 248 229 106
34 4 23 248 229 106
27 27 29 248 229 106
36 36 21 248 229 106
12 9 20 248 229 106
4 28 25 248 229 106
21 7 25 248 229 106
23 7 25 248 229 106
20 8 25 248 229 106
24 8 25 248 229 106
9 18 21 248 229 106
22 17 21 248 229 106
10 17 21 248 229 106
21 16 21 248 229 106
34 32 20 248 229 106
11 16 21 248 229 106
34 31 20 248 229 106
28 12 25 248 229 106
35 36 21 248 229 106
28 26 29 248 229 106
37 35 21 248 229 106
19 8 20 248 229 106
22 24 25 248 229 106
21 23 25 248 229 106
23 23 25 248 229 106
20 22 25 248 229 106
24 22 25 248 229 106
22 20 21 248 229 106
25 21 25 248 229 106
10 20 21 248 229 106
26 20 25 248 229 106
32 7 20 248 229 106
27 19 25 248 229 106
31 6 20 248 229 106
13 8 20 248 229 106
34 4 20 248 229 106
19 29 29 248 229 106
34 2 23 248 229 106
18 7 20 248 229 106
13 15 25 248 229 106
14 7 20 248 229 106
5 29 25 248 229 106
6 30 25 248 229 106
20 7 25 248 229 106
24 7 25 248 229 106
19 8 25 248 229 106
25 8 25 248 229 106
20 15 21 248 229 106
12 15 21 248 229 106
36 35 21 248 229 106
19 14 21 248 229 106
35 35 21 248 229 106
28 11 25 248 229 106
37 32 21 248 229 106
24 30 23 248 229 106
36 32 21 248 229 106
9 24 21 248 229 106
9 21 21 248 229 106
17 6 20 248 229 106
22 25 25 248 229 106
21 24 25 248 229 106
23 24 25 248 229 106
20 23 25 248 229 106
24 23 25 248 229 106
21 21 21 248 229 106
25 22 25 248 229 106
11 21 21 248 229 106
26 21 25 248 229 106
32 32 20 248 229 106
27 20 25 248 229 106
31 33 20 248 229 106
23 24 21 248 229 106
30 34 20 248 229 106
15 6 20 248 229 106
33 3 20 248 229 106
8 23 21 248 229 106
13 16 25 248 229 106
36 37 26 248 229 106
12 15 25 248 229 106
5 26 25 248 229 106
18 23 21 248 229 106
14 23 21 248 229 106
19 7 25 248 229 106
25 7 25 248 229 106
18 8 25 248 229 106
26 8 25 248 229 106
35 32 21 248 229 106
13 14 21 248 229 106
34 34 23 248 229 106
28 10 25 248 229 106
34 33 23 248 229 106
26 29 29 248 229 106
34 31 23 248 229 106
24 23 21 248 229 106
22 22 21 248 229 106
7 22 21 248 229 106
10 22 21 248 229 106
6 27 25 248 229 106
22 26 25 248 229 106
21 25 25 248 229 106
23 25 25 248 229 106
20 24 25 248 229 106
24 24 25 248 229 106
20 22 21 248 229 106
25 23 25 248 229 106
12 22 21 248 229 106
26 22 25 248 229 106
17 21 25 248 229 106
27 21 25 248 229 106
33 4 20 248 229 106
25 22 21 248 229 106
29 35 20 248 229 106
6 21 21 248 229 106
3 35 20 248 229 106
16 5 20 248 229 106
13 17 25 248 229 106
3 21 20 248 229 106
12 16 25 248 229 106
4 23 25 248 229 106
11 15 25 248 229 106
9 33 25 248 229 106
5 24 25 248 229 106
18 7 25 97 38 6
26 7 25 248 229 106
34 32 23 248 229 106
27 8 25 248 229 106
33 36 46 7 146 0
28 9 25 248 229 106
4 32 20 248 229 106
9 7 29 248 229 106
30 31 20 248 229 106
3 17 21 248 229 106
13 12 25 248 229 106
4 22 20 248 229 106
21 23 21 248 229 106
19 22 21 248 229 106
11 23 21 248 229 106
22 27 25 248 229 106
21 26 25 248 229 106
23 26 25 248 229 106
20 25 25 248 229 106
24 25 25 248 229 106
19 23 21 248 229 106
25 24 25 248 229 106
15 7 29 97 38 6
26 23 25 248 229 106
17 22 25 248 229 106
27 22 25 248 229 106
16 21 25 248 229 106
27 23 20 248 229 106
35 4 21 248 229 106
5 23 20 248 229 106
32 8 20 248 229 106
26 24 20 248 229 106
16 5 21 248 229 106
6 24 20 248 229 106
12 17 25 248 229 106
4 33 25 248 229 106
11 16 25 248 229 106
10 15 25 248 229 106
17 24 21 248 229 106
4 27 25 248 229 106
13 7 25 97 38 6
27 7 25 248 229 106
34 35 23 248 229 106
28 8 25 248 229 106
29 32 20 248 229 106
27 28 29 248 229 106
3 32 20 248 229 106
25 25 20 248 229 106
13 11 25 248 229 106
7 25 20 248 229 106
12 12 25 248 229 106
6 25 25 248 229 106
20 24 21 248 229 106
12 24 21 248 229 106
22 28 25 248 229 106
21 27 25 248 229 106
23 27 25 248 229 106
20 26 25 248 229 106
24 26 25 248 229 106
13 23 21 248 229 106
25 25 25 248 229 106
18 24 21 248 229 106
26 24 25 248 229 106
17 23 25 248 229 106
27 23 25 248 229 106
16 22 25 248 229 106
24 26 20 248 229 106
15 21 25 248 229 106
34 32 22 248 229 106
31 7 20 248 229 106
8 26 20 248 229 106
17 26 21 248 229 106
23 27 20 248 229 106
15 6 21 248 229 106
9 30 25 248 229 106
11 17 25 248 229 106
10 16 25 248 229 106
9 15 25 248 229 106
5 28 25 248 229 106
6 29 25 248 229 106
28 33 20 248 229 106
28 7 25 248 229 106
34 32 21 248 229 106
28 27 29 248 229 106
4 33 20 248 229 106
9 27 20 248 229 106
13 10 25 248 229 106
22 28 20 248 229 106
12 11 25 248 229 106
4 32 25 248 229 106
7 25 21 248 229 106
19 25 21 248 229 106
9 14 25 248 229 106
22 29 25 248 229 106
21 28 25 248 229 106
23 28 25 248 229 106
20 27 25 248 229 106
24 27 25 248 229 106
14 24 21 248 229 106
25 26 25 248 229 106
17 25 21 248 229 106
26 25 25 248 229 106
17 24 25 248 229 106
27 24 25 248 229 106
16 23 25 248 229 106
10 28 20 248 229 106
15 22 25 248 229 106
21 29 20 248 229 106
14 21 25 248 229 106
11 29 20 248 229 106
13 20 25 248 229 106
20 30 20 248 229 106
15 26 21 248 229 106
5 33 25 248 229 106
17 6 21 248 229 106
10 17 25 248 229 106
9 16 25 248 229 106
8 15 25 248 229 106
15 24 21 248 229 106
16 25 21 248 229 106
34 37 22 248 229 106
30 34 24 248 229 106
34 36 22 248 229 106
12 30 20 248 229 106
13 9 25 248 229 106
19 31 20 248 229 106
12 10 25 248 229 106
21 19 21 248 229 106
25 25 21 248 229 106
13 25 21 248 229 106
9 13 25 248 229 106
8 14 25 248 229 106
28 12 29 248 229 106
21 29 25 248 229 106
23 29 25 248 229 106
20 28 25 248 229 106
24 28 25 248 229 106
15 25 21 248 229 106
25 27 25 248 229 106
16 26 21 248 229 106
26 26 25 248 229 106
17 25 25 248 229 106
27 25 25 248 229 106
16 24 25 248 229 106
28 24 25 248 229 106
15 23 25 248 229 106
35 36 26 248 229 106
14 22 25 248 229 106
13 31 20 248 229 106
13 21 25 248 229 106
26 21 21 248 229 106
12 20 25 248 229 106
19 18 21 248 229 106
16 27 21 248 229 106
14 7 21 248 229 106
9 17 25 248 229 106
8 16 25 248 229 106
20 16 21 248 229 106
13 18 21 248 229 106
10 33 25 248 229 106
34 35 22 248 229 106
18 32 20 248 229 106
13 8 25 248 229 106
5 20 21 248 229 106
12 9 25 248 229 106
4 31 25 248 229 106
6 24 21 248 229 106
18 26 21 248 229 106
9 12 25 248 229 106
8 13 25 248 229 106
12 16 21 248 229 106
18 17 21 248 229 106
21 17 29 248 229 106
10 29 29 248 229 106
20 29 25 248 229 106
24 29 25 248 229 106
19 28 25 248 229 106
25 28 25 248 229 106
18 7 21 248 229 106
26 27 25 248 229 106
13 8 21 248 229 106
27 26 25 248 229 106
16 25 25 248 229 106
28 25 25 248 229 106
15 24 25 248 229 106
14 33 29 248 229 106
14 23 25 248 229 106
14 32 20 248 229 106
13 22 25 248 229 106
27 20 21 248 229 106
12 21 25 248 229 106
5 32 25 248 229 106
11 20 25 248 229 106
13 18 20 248 229 106
22 19 21 248 229 106
8 17 25 248 229 106
19 15 21 248 229 106
13 15 21 248 229 106
11 19 21 248 229 106
14 17 21 248 229 106
34 31 22 248 229 106
36 38 26 248 229 106
12 8 25 248 229 106
6 33 25 248 229 106
26 24 21 248 229 106
14 26 21 248 229 106
9 11 25 248 229 106
8 12 25 248 229 106
18 14 21 248 229 106
14 14 21 248 229 106
3 25 20 248 229 106
17 16 21 248 229 106
22 11 21 248 229 106
25 14 28 248 229 106
20 19 29 248 229 106
19 29 25 248 229 106
25 29 25 248 229 106
18 28 25 248 229 106
26 28 25 248 229 106
19 8 21 248 229 106
27 27 25 248 229 106
20 18 21 248 229 106
28 26 25 248 229 106
15 25 25 248 229 106
13 34 29 248 229 106
14 24 25 248 229 106
16 8 21 248 229 106
13 23 25 248 229 106
15 9 21 248 229 106
12 22 25 248 229 106
9 28 25 248 229 106
11 21 25 248 229 106
10 20 25 248 229 106
10 19 21 248 229 106
21 18 21 248 229 106
17 13 21 248 229 106
15 13 21 248 229 106
5 15 25 248 229 106
4 26 25 248 229 106
5 27 25 248 229 106
12 7 25 248 229 106
10 29 25 248 229 106
5 23 21 248 229 106
17 27 21 248 229 106
9 10 25 248 229 106
8 11 25 248 229 106
16 12 21 248 229 106
23 20 21 248 229 106
5 14 25 248 229 106
22 33 25 248 229 106
15 16 21 248 229 106
9 12 21 248 229 106
16 15 21 248 229 106
23 12 21 248 229 106
27 30 23 248 229 106
28 30 29 248 229 106
18 29 25 248 229 106
26 29 25 248 229 106
17 28 25 248 229 106
27 28 25 248 229 106
12 9 21 248 229 106
28 27 25 248 229 106
12 18 21 248 229 106
8 7 29 248 229 106
14 25 25 248 229 106
17 9 21 248 229 106
13 24 25 248 229 106
14 10 21 248 229 106
12 23 25 248 229 106
4 30 25 248 229 106
11 22 25 248 229 106
10 21 25 248 229 106
9 20 25 248 229 106
11 18 21 248 229 106
9 20 21 248 229 106
22 21 21 248 229 106
5 16 25 248 229 106
4 15 25 248 229 106
6 28 25 248 229 106
5 31 25 248 229 106
11 7 25 248 229 106
27 23 21 248 229 106
15 27 21 248 229 106
8 10 25 248 229 106
10 21 21 248 229 106
21 22 21 248 229 106
5 13 25 248 229 106
4 14 25 248 229 106
11 30 25 248 229 106
21 33 25 248 229 106
23 33 25 248 229 106
8 16 20 248 229 106
8 13 21 248 229 106
24 13 21 248 229 106
7 14 21 248 229 106
18 32 25 248 229 106
28 13 29 248 229 106
17 29 25 248 229 106
27 29 25 248 229 106
16 28 25 248 229 106
28 28 25 248 229 106
20 9 21 248 229 106
13 33 29 248 229 106
19 18 20 248 229 106
18 10 21 248 229 106
13 25 25 248 229 106
13 11 21 248 229 106
12 24 25 248 229 106
6 32 25 248 229 106
11 23 25 248 229 106
10 22 25 248 229 106
9 21 25 248 229 106
8 20 25 248 229 106
14 7 29 97 38 6
11 22 21 248 229 106
5 17 25 248 229 106
4 16 25 248 229 106
12 33 25 248 229 106
16 7 29 97 38 6
10 7 25 248 229 106
16 28 21 248 229 106
23 19 21 248 229 106
20 23 21 248 229 106
12 23 21 248 229 106
5 12 25 248 229 106
4 13 25 248 229 106
20 19 21 248 229 106
25 14 21 248 229 106
17 33 20 248 229 106
20 33 25 248 229 106
24 33 25 248 229 106
20 20 21 248 229 106
12 20 21 248 229 106
19 21 21 248 229 106
13 21 21 248 229 106
22 17 29 248 229 106
11 29 29 248 229 106
16 29 25 248 229 106
28 29 25 248 229 106
15 28 25 248 229 106
12 34 29 248 229 106
8 35 23 248 229 106
15 33 20 248 229 106
21 10 21 248 229 106
16 34 20 248 229 106
12 25 25 248 229 106
7 33 25 248 229 106
11 24 25 248 229 106
10 23 25 248 229 106
9 22 25 248 229 106
8 21 25 248 229 106
7 20 25 248 229 106
19 24 21 248 229 106
5 18 25 248 229 106
4 17 25 248 229 106
18 22 21 248 229 106
12 19 21 248 229 106
9 7 25 248 229 106
9 19 21 248 229 106
22 18 21 248 229 106
13 24 21 248 229 106
5 11 25 248 229 106
4 12 25 248 229 106
4 25 25 248 229 106
3 19 20 248 229 106
14 33 25 248 229 106
19 33 25 248 229 106
25 33 25 248 229 106
14 22 21 248 229 106
17 23 21 248 229 106
15 23 21 248 229 106
16 24 21 248 229 106
13 10 29 248 229 106
20 20 29 248 229 106
15 29 25 248 229 106
7 7 29 248 229 106
14 28 25 248 229 106
4 18 20 248 229 106
19 17 21 248 229 106
27 17 20 248 229 106
13 17 21 248 229 106
13 33 25 248 229 106
11 25 25 248 229 106
10 24 25 248 229 106
9 23 25 248 229 106
8 22 25 248 229 106
7 21 25 248 229 106
6 20 25 248 229 106
5 19 25 248 229 106
4 18 25 248 229 106
4 24 25 248 229 106
19 19 21 248 229 106
8 7 25 248 229 106
10 18 21 248 229 106
21 17 21 248 229 106
5 10 25 248 229 106
4 11 25 248 229 106
5 25 25 248 229 106
4 7 25 248 229 106
5 17 20 248 229 106
18 33 25 248 229 106
26 33 25 248 229 106
13 19 21 248 229 106
18 18 21 248 229 106
14 18 21 248 229 106
29 31 24 248 229 106
26 25 29 248 229 106
24 25 29 248 229 106
14 29 25 248 229 106
26 16 20 248 229 106
13 28 25 248 229 106
6 16 20 248 229 106
18 16 21 248 229 106
6 26 25 248 229 106
14 16 21 248 229 106
10 25 25 248 229 106
9 24 25 248 229 106
8 23 25 248 229 106
7 22 25 248 229 106
6 21 25 248 229 106
5 20 25 248 229 106
4 19 25 248 229 106
17 15 21 248 229 106
17 17 21 248 229 106
7 7 25 248 229 106
11 17 21 248 229 106
5 9 25 248 229 106
4 10 25 248 229 106
13 22 21 248 229 106
4 22 25 248 229 106
5 23 25 248 229 106
17 33 25 248 229 106
26 7 29 248 229 106
15 17 21 248 229 106
14 17 29 248 229 106
16 16 21 248 229 106
15 16 29 248 229 106
12 33 29 248 229 106
25 15 20 248 229 106
13 29 25 248 229 106
7 15 20 248 229 106
12 28 25 248 229 106
4 29 25 248 229 106
15 15 21 248 229 106
16 14 21 248 229 106
9 25 25 248 229 106
8 24 25 248 229 106
7 23 25 248 229 106
6 22 25 248 229 106
5 21 25 248 229 106
4 20 25 248 229 106
9 29 25 248 229 106
11 33 25 248 229 106
6 7 25 248 229 106
5 8 25 248 229 106
4 9 25 248 229 106
10 30 25 248 229 106
6 24 25 248 229 106
7 25 25 248 229 106
16 33 25 248 229 106
16 15 29 248 229 106
17 7 29 97 38 6
25 9 29 248 229 106
19 20 21 248 229 106
24 14 20 248 229 106
13 30 25 248 229 106
8 14 20 248 229 106
12 29 25 248 229 106
5 30 25 248 229 106
11 28 25 248 229 106
21 20 21 248 229 106
11 20 21 248 229 106
8 25 25 248 229 106
7 24 25 248 229 106
6 23 25 248 229 106
5 22 25 248 229 106
4 21 25 248 229 106
13 20 21 248 229 106
8 33 25 248 229 106
5 7 25 248 229 106
4 8 25 248 229 106
18 21 21 248 229 106
20 21 21 248 229 106
12 21 21 248 229 106
15 33 25 248 229 106
28 34 28 248 229 106
14 21 21 248 229 106
23 13 20 248 229 106
17 22 21 248 229 106
9 13 20 248 229 106
12 30 25 248 229 106
6 31 25 248 229 106
11 29 25 248 229 106
10 28 25 248 229 106
36 31 26 248 229 106
19 10 21 248 229 106
37 31 26 248 229 106
30 6 20 248 229 106
12 8 20 248 229 106
38 31 26 248 229 106
34 3 23 248 229 106
17 35 21 248 229 106
5 15 20 248 229 106
33 4 21 248 229 106
20 8 20 248 229 106
36 35 46 7 146 0
13 10 21 248 229 106
32 30 21 248 229 106
35 2 24 44 185 36
10 23 21 248 229 106
35 4 23 248 229 106
26 31 21 248 229 106
35 31 26 248 229 106
32 35 20 248 229 106
3 6 21 248 229 106
9 3 20 248 229 106
39 31 26 248 229 106
32 34 20 248 229 106
11 9 20 248 229 106
3 35 24 248 229 106
35 31 22 248 229 106
29 6 21 248 229 106
33 2 24 44 185 36
23 8 20 248 229 106
35 2 23 248 229 106
37 32 26 248 229 106
21 9 20 248 229 106
9 2 20 248 229 106
3 35 22 248 229 106
10 3 20 248 229 106
30 7 21 248 229 106
10 2 20 248 229 106
8 9 20 248 229 106
35 2 21 248 229 106
38 32 26 248 229 106
10 10 20 248 229 106
36 31 22 248 229 106
4 35 24 248 229 106
37 31 22 248 229 106
31 8 21 248 229 106
35 3 24 44 185 36
12 11 21 248 229 106
35 3 23 248 229 106
24 9 20 248 229 106
20 11 21 248 229 106
17 34 25 248 229 106
21 21 20 248 229 106
13 3 20 248 229 106
4 28 20 248 229 106
11 3 20 248 229 106
15 5 23 248 229 106
13 2 20 248 229 106
38 38 26 248 229 106
22 10 20 248 229 106
4 35 22 248 229 106
32 9 21 248 229 106
35 39 23 248 229 106
7 10 20 248 229 106
34 39 23 248 229 106
16 34 25 248 229 106
37 39 22 248 229 106
14 5 23 248 229 106
33 3 24 44 185 36
39 32 26 248 229 106
9 11 20 248 229 106
3 35 23 248 229 106
4 35 21 248 229 106
25 10 20 248 229 106
18 34 25 248 229 106
13 5 23 248 229 106
39 33 26 248 229 106
11 2 20 248 229 106
36 36 26 248 229 106
12 3 20 248 229 106
5 35 24 248 229 106
28 35 21 248 229 106
6 11 20 248 229 106
15 34 25 248 229 106
18 5 22 248 229 106
23 29 20 248 229 106
27 34 20 248 229 106
21 12 21 248 229 106
36 39 22 248 229 106
23 11 20 248 229 106
26 34 20 248 229 106
10 29 21 248 229 106
35 35 46 7 146 0
5 35 22 248 229 106
22 13 21 248 229 106
28 28 20 248 229 106
9 14 21 248 229 106
23 14 21 248 229 106
3 34 21 248 229 106
26 11 20 248 229 106
19 34 25 248 229 106
17 5 22 248 229 106
30 13 21 248 229 106
5 30 21 248 229 106
4 35 23 248 229 106
12 2 20 248 229 106
37 38 22 248 229 106
36 34 42 7 146 0
14 34 25 248 229 106
16 5 22 248 229 106
39 34 26 248 229 106
8 12 20 248 229 106
32 35 24 248 229 106
35 38 22 248 229 106
6 34 20 248 229 106
5 12 20 248 229 106
5 34 20 248 229 106
20 34 25 248 229 106
35 39 22 248 229 106
15 5 22 248 229 106
34 35 46 7 146 0
22 10 21 248 229 106
27 30 21 248 229 106
32 35 22 248 229 106
8 15 21 248 229 106
21 30 23 248 229 106
24 15 21 248 229 106
7 16 21 248 229 106
4 16 20 248 229 106
25 16 21 248 229 106
6 17 21 248 229 106
26 17 21 248 229 106
5 18 21 248 229 106
27 12 20 248 229 106
13 34 25 248 229 106
14 5 22 248 229 106
39 35 26 248 229 106
24 12 20 248 229 106
6 35 24 248 229 106
32 31 21 248 229 106
4 13 20 248 229 106
21 34 25 248 229 106
13 5 22 248 229 106
39 36 26 248 229 106
7 13 20 248 229 106
6 35 22 248 229 106
34 39 22 248 229 106
30 6 21 248 229 106
33 35 46 7 146 0
28 13 20 248 229 106
26 35 20 248 229 106
12 34 25 248 229 106
6 35 20 248 229 106
35 4 22 248 229 106
39 37 26 248 229 106
25 13 20 248 229 106
5 35 23 248 229 106
31 7 21 248 229 106
27 18 21 248 229 106
4 19 21 248 229 106
3 14 20 248 229 106
16 33 21 248 229 106
28 16 20 248 229 106
15 32 21 248 229 106
17 32 21 248 229 106
14 31 21 248 229 106
18 31 21 248 229 106
13 30 21 248 229 106
19 30 21 248 229 106
22 34 25 248 229 106
34 4 22 248 229 106
39 38 26 248 229 106
18 29 21 248 229 106
31 35 24 248 229 106
32 8 21 248 229 106
29 14 20 248 229 106
11 34 25 248 229 106
33 4 22 248 229 106
39 39 26 248 229 106
14 24 20 248 229 106
31 35 22 248 229 106
18 7 26 97 38 6
32 11 20 248 229 106
3 35 21 248 229 106
37 39 21 248 229 106
30 15 20 248 229 106
35 34 46 7 146 0
23 34 25 248 229 106
34 35 21 248 229 106
35 3 22 248 229 106
34 32 26 248 229 106
14 29 21 248 229 106
32 35 23 248 229 106
29 35 21 248 229 106
12 29 21 248 229 106
31 16 20 248 229 106
20 29 21 248 229 106
30 26 21 248 229 106
11 28 21 248 229 106
21 28 21 248 229 106
10 27 21 248 229 106
22 27 21 248 229 106
9 26 21 248 229 106
23 26 21 248 229 106
8 25 21 248 229 106
24 25 21 248 229 106
10 34 25 248 229 106
34 3 22 248 229 106
8 28 20 248 229 106
6 14 20 248 229 106
7 35 24 248 229 106
34 36 45 7 146 0
32 17 20 248 229 106
24 34 25 248 229 106
33 3 22 248 229 106
11 27 20 248 229 106
18 24 20 248 229 106
7 35 22 248 229 106
33 35 21 248 229 106
12 35 20 248 229 106
9 34 25 248 229 106
31 10 20 248 229 106
19 7 26 248 229 106
30 9 20 248 229 106
35 2 22 248 229 106
29 8 20 248 229 106
26 14 20 248 229 106
36 39 21 248 229 106
6 35 23 248 229 106
32 32 21 248 229 106
20 35 20 248 229 106
7 24 21 248 229 106
31 25 21 248 229 106
25 24 21 248 229 106
6 23 21 248 229 106
26 23 21 248 229 106
5 22 21 248 229 106
27 22 21 248 229 106
4 21 21 248 229 106
3 20 21 248 229 106
16 6 21 248 229 106
15 7 21 248 229 106
25 34 25 248 229 106
34 2 22 248 229 106
6 9 20 248 229 106
13 23 20 248 229 106
30 35 24 248 229 106
31 6 21 248 229 106
11 34 20 248 229 106
8 34 25 248 229 106
33 2 22 248 229 106
30 35 22 248 229 106
32 7 21 248 229 106
21 34 20 248 229 106
26 34 25 248 229 106
33 35 43 7 146 0
19 23 20 248 229 106
31 35 23 248 229 106
30 35 21 248 229 106
10 33 20 248 229 106
17 7 21 248 229 106
22 12 20 248 229 106
14 8 21 248 229 106
18 8 21 248 229 106
3 8 20 248 229 106
13 9 21 248 229 106
28 7 20 248 229 106
19 9 21 248 229 106
4 7 20 248 229 106
12 10 21 248 229 106
20 10 21 248 229 106
9 35 24 248 229 106
21 11 21 248 229 106
7 34 25 248 229 106
7 17 20 248 229 106
22 33 20 248 229 106
26 8 29 248 229 106
25 17 20 248 229 106
8 35 24 248 229 106
33 35 20 248 229 106
9 32 20 248 229 106
6 34 25 248 229 106
12 19 20 248 229 106
34 37 21 248 229 106
11 34 29 248 229 106
20 19 20 248 229 106
23 32 20 248 229 106
5 34 25 248 229 106
32 24 21 248 229 106
5 29 20 248 229 106
22 12 21 248 229 106
9 13 21 248 229 106
23 13 21 248 229 106
8 14 21 248 229 106
24 14 21 248 229 106
7 15 21 248 229 106
34 36 20 248 229 106
4 34 25 248 229 106
9 6 21 248 229 106
36 32 20 248 229 106
22 30 21 248 229 106
10 30 21 248 229 106
21 31 21 248 229 106
11 31 21 248 229 106
10 12 20 248 229 106
20 32 21 248 229 106
31 32 24 248 229 106
12 32 21 248 229 106
21 11 20 248 229 106
37 31 21 248 229 106
19 33 21 248 229 106
27 6 20 248 229 106
13 33 21 248 229 106
18 34 21 248 229 106
14 34 21 248 229 106
17 16 20 248 229 106
15 16 20 248 229 106
16 15 20 248 229 106
25 15 21 248 229 106
6 16 21 248 229 106
26 16 21 248 229 106
5 17 21 248 229 106
27 17 21 248 229 106
20 20 20 248 229 106
12 20 20 248 229 106
19 21 20 248 229 106
13 21 20 248 229 106
18 22 20 248 229 106
11 11 20 248 229 106
14 22 20 248 229 106
17 23 20 248 229 106
15 23 20 248 229 106
16 24 20 248 229 106
19 19 20 248 229 106
13 19 20 248 229 106
18 18 20 248 229 106
14 18 20 248 229 106
17 17 20 248 229 106
15 17 20 248 229 106
4 18 21 248 229 106
3 19 21 248 229 106
16 34 21 248 229 106
16 16 20 248 229 106
19 20 20 248 229 106
13 20 20 248 229 106
18 21 20 248 229 106
14 21 20 248 229 106
17 22 20 248 229 106
15 22 20 248 229 106
20 10 20 248 229 106
16 23 20 248 229 106
12 10 20 248 229 106
18 19 20 248 229 106
19 9 20 248 229 106
14 19 20 248 229 106
13 9 20 248 229 106
36 31 21 248 229 106
17 18 20 248 229 106
15 18 20 248 229 106
16 17 20 248 229 106
15 33 21 248 229 106
18 20 20 248 229 106
14 20 20 248 229 106
17 21 20 248 229 106
15 21 20 248 229 106
16 22 20 248 229 106
17 19 20 248 229 106
15 19 20 248 229 106
16 18 20 248 229 106
17 20 20 248 229 106
15 20 20 248 229 106
16 21 20 248 229 106
16 19 20 248 229 106
19 11 21 248 229 106
16 20 20 248 229 106
18 8 20 248 229 106
32 35 21 248 229 106
33 35 23 248 229 106
31 35 21 248 229 106
32 6 21 248 229 106
33 32 23 248 229 106
31 14 21 248 229 106
34 33 26 248 229 106
34 34 26 248 229 106
34 35 26 248 229 106
34 36 26 248 229 106
9 11 21 248 229 106
23 11 21 248 229 106
24 28 20 248 229 106
8 12 21 248 229 106
34 37 26 248 229 106
34 38 26 248 229 106
34 39 26 248 229 106
14 16 20 248 229 106
24 12 21 248 229 106
35 39 26 248 229 106
12 12 21 248 229 106
36 39 26 248 229 106
33 34 43 7 146 0
7 13 21 248 229 106
20 12 21 248 229 106
26 9 20 248 229 106
11 30 21 248 229 106
5 10 20 248 229 106
13 7 26 97 38 6
27 10 20 248 229 106
4 11 20 248 229 106
28 11 20 248 229 106
3 12 20 248 229 106
29 12 20 248 229 106
30 13 20 248 229 106
31 14 20 248 229 106
32 15 20 248 229 106
10 35 20 248 229 106
22 35 20 248 229 106
9 34 20 248 229 106
23 34 20 248 229 106
8 33 20 248 229 106
24 33 20 248 229 106
21 13 21 248 229 106
7 32 20 248 229 106
21 30 21 248 229 106
25 32 20 248 229 106
6 31 20 248 229 106
26 31 20 248 229 106
5 30 20 248 229 106
27 30 20 248 229 106
4 29 20 248 229 106
28 29 20 248 229 106
3 28 20 248 229 106
29 28 20 248 229 106
30 27 20 248 229 106
31 26 20 248 229 106
32 25 20 248 229 106
8 6 20 248 229 106
24 6 20 248 229 106
7 7 20 248 229 106
25 7 20 248 229 106
6 8 20 248 229 106
26 8 20 248 229 106
5 9 20 248 229 106
27 9 20 248 229 106
4 10 20 248 229 106
22 14 21 248 229 106
28 10 20 248 229 106
9 15 21 248 229 106
3 11 20 248 229 106
23 15 21 248 229 106
29 11 20 248 229 106
8 16 21 248 229 106
30 12 20 248 229 106
12 7 26 248 229 106
31 13 20 248 229 106
32 14 20 248 229 106
9 35 20 248 229 106
23 35 20 248 229 106
8 34 20 248 229 106
24 34 20 248 229 106
7 33 20 248 229 106
25 33 20 248 229 106
6 32 20 248 229 106
26 32 20 248 229 106
5 31 20 248 229 106
27 31 20 248 229 106
14 8 20 248 229 106
4 30 20 248 229 106
17 7 20 248 229 106
28 30 20 248 229 106
3 29 20 248 229 106
29 29 20 248 229 106
30 28 20 248 229 106
31 27 20 248 229 106
32 26 20 248 229 106
7 6 20 248 229 106
25 6 20 248 229 106
6 7 20 248 229 106
26 7 20 248 229 106
5 8 20 248 229 106
27 8 20 248 229 106
4 9 20 248 229 106
28 9 20 248 229 106
3 10 20 248 229 106
29 10 20 248 229 106
30 11 20 248 229 106
31 12 20 248 229 106
32 13 20 248 229 106
8 35 20 248 229 106
24 35 20 248 229 106
15 7 20 248 229 106
7 34 20 248 229 106
16 6 20 248 229 106
25 34 20 248 229 106
3 20 20 248 229 106
6 33 20 248 229 106
4 21 20 248 229 106
26 33 20 248 229 106
5 32 20 248 229 106
27 32 20 248 229 106
4 31 20 248 229 106
28 31 20 248 229 106
3 30 20 248 229 106
29 30 20 248 229 106
30 29 20 248 229 106
31 28 20 248 229 106
32 27 20 248 229 106
6 6 20 248 229 106
26 6 20 248 229 106
27 22 20 248 229 106
5 7 20 248 229 106
5 22 20 248 229 106
27 7 20 248 229 106
4 8 20 248 229 106
28 8 20 248 229 106
3 9 20 248 229 106
29 9 20 248 229 106
30 10 20 248 229 106
31 11 20 248 229 106
32 12 20 248 229 106
7 35 20 248 229 106
25 35 20 248 229 106
37 34 22 248 229 106
36 34 43 7 146 0
37 35 22 248 229 106
37 36 22 248 229 106
35 37 22 248 229 106
36 37 22 248 229 106
37 37 22 248 229 106
37 33 21 248 229 106
37 32 22 248 229 106
36 32 22 248 229 106
37 33 22 248 229 106
35 32 22 248 229 106
27 7 29 248 229 106
33 36 45 7 146 0
26 23 20 248 229 106
34 37 23 248 229 106
6 23 20 248 229 106
34 36 23 248 229 106
18 16 20 248 229 106
36 35 45 7 146 0
35 35 45 7 146 0
34 35 45 7 146 0
34 38 21 248 229 106
36 38 22 248 229 106
37 38 21 248 229 106
35 38 21 248 229 106
34 38 20 248 229 106
25 24 20 248 229 106
36 38 21 248 229 106
7 24 20 248 229 106
37 38 20 248 229 106
37 31 23 248 229 106
36 31 23 248 229 106
35 31 23 248 229 106
34 35 39 179 83 0
34 35 40 179 83 0
32 35 46 7 146 0
34 33 46 7 146 0
32 15 21 248 229 106
36 33 43 7 146 0
36 33 44 7 146 0
25 13 21 248 229 106
33 33 42 7 146 0
34 33 42 7 146 0
35 34 43 7 146 0
35 33 42 7 146 0
32 34 42 7 146 0
32 35 42 7 146 0
36 35 26 248 229 106
32 36 42 7 146 0
32 33 43 7 146 0
33 33 43 7 146 0
24 25 20 248 229 106
34 33 43 7 146 0
8 25 20 248 229 106
35 33 43 7 146 0
6 14 21 248 229 106
32 34 43 7 146 0
37 39 26 248 229 106
10 35 21 248 229 106
26 14 21 248 229 106
32 35 43 7 146 0
32 36 43 7 146 0
23 26 20 248 229 106
32 37 43 7 146 0
9 26 20 248 229 106
32 33 44 7 146 0
33 33 44 7 146 0
34 33 44 7 146 0
32 34 44 7 146 0
32 35 44 7 146 0
32 36 44 7 146 0
13 17 20 248 229 106
32 37 44 7 146 0
22 35 21 248 229 106
9 34 21 248 229 106
23 34 21 248 229 106
33 33 45 7 146 0
34 33 45 7 146 0
35 33 45 7 146 0
32 34 45 7 146 0
32 35 45 7 146 0
32 36 45 7 146 0
35 33 44 7 146 0
21 27 20 248 229 106
33 34 41 7 146 0
22 27 20 248 229 106
5 15 21 248 229 106
10 27 20 248 229 106
19 17 20 248 229 106
8 33 21 248 229 106
34 34 41 7 146 0
35 34 41 7 146 0
33 35 41 7 146 0
34 35 41 179 83 0
21 28 20 248 229 106
35 35 41 7 146 0
11 28 20 248 229 106
7 27 20 248 229 106
17 33 21 248 229 106
33 36 41 7 146 0
25 27 20 248 229 106
12 18 20 248 229 106
20 18 20 248 229 106
34 36 41 7 146 0
35 36 41 7 146 0
33 34 42 7 146 0
34 34 42 7 146 0
10 26 20 248 229 106
22 26 20 248 229 106
35 34 42 7 146 0
38 39 26 248 229 106
6 26 20 248 229 106
26 26 20 248 229 106
5 25 20 248 229 106
27 25 20 248 229 106
20 29 20 248 229 106
4 24 20 248 229 106
12 29 20 248 229 106
28 24 20 248 229 106
3 23 20 248 229 106
14 5 20 248 229 106
18 5 20 248 229 106
19 30 20 248 229 106
13 6 20 248 229 106
24 16 21 248 229 106
19 6 20 248 229 106
12 7 20 248 229 106
20 7 20 248 229 106
11 8 20 248 229 106
21 8 20 248 229 106
10 9 20 248 229 106
22 9 20 248 229 106
9 10 20 248 229 106
23 10 20 248 229 106
14 32 21 248 229 106
8 11 20 248 229 106
18 32 21 248 229 106
24 11 20 248 229 106
7 12 20 248 229 106
25 12 20 248 229 106
6 13 20 248 229 106
34 34 43 7 146 0
26 13 20 248 229 106
7 17 21 248 229 106
5 14 20 248 229 106
27 14 20 248 229 106
25 17 21 248 229 106
4 15 20 248 229 106
6 18 21 248 229 106
28 15 20 248 229 106
3 16 20 248 229 106
29 16 20 248 229 106
30 17 20 248 229 106
14 35 20 248 229 106
18 35 20 248 229 106
13 34 20 248 229 106
19 34 20 248 229 106
12 33 20 248 229 106
20 33 20 248 229 106
11 32 20 248 229 106
21 32 20 248 229 106
10 31 20 248 229 106
22 31 20 248 229 106
26 18 21 248 229 106
9 30 20 248 229 106
5 19 21 248 229 106
23 30 20 248 229 106
8 29 20 248 229 106
27 19 21 248 229 106
24 29 20 248 229 106
7 28 20 248 229 106
25 28 20 248 229 106
6 27 20 248 229 106
26 27 20 248 229 106
5 26 20 248 229 106
13 31 21 248 229 106
27 26 20 248 229 106
19 31 21 248 229 106
4 25 20 248 229 106
12 30 21 248 229 106
28 25 20 248 229 106
16 32 21 248 229 106
3 24 20 248 229 106
15 31 21 248 229 106
29 24 20 248 229 106
13 5 20 248 229 106
18 4 20 248 229 106
12 6 20 248 229 106
20 6 20 248 229 106
11 7 20 248 229 106
21 7 20 248 229 106
10 8 20 248 229 106
22 8 20 248 229 106
9 9 20 248 229 106
23 9 20 248 229 106
17 31 21 248 229 106
8 10 20 248 229 106
13 30 20 248 229 106
24 10 20 248 229 106
7 11 20 248 229 106
25 11 20 248 229 106
6 12 20 248 229 106
26 12 20 248 229 106
5 13 20 248 229 106
27 13 20 248 229 106
4 14 20 248 229 106
18 31 20 248 229 106
28 14 20 248 229 106
14 31 20 248 229 106
3 15 20 248 229 106
29 15 20 248 229 106
30 16 20 248 229 106
31 17 20 248 229 106
13 35 20 248 229 106
19 35 20 248 229 106
17 32 20 248 229 106
12 34 20 248 229 106
15 32 20 248 229 106
20 34 20 248 229 106
20 30 21 248 229 106
11 33 20 248 229 106
11 29 21 248 229 106
16 33 20 248 229 106
21 33 20 248 229 106
4 19 20 248 229 106
21 29 21 248 229 106
10 32 20 248 229 106
27 18 20 248 229 106
10 28 21 248 229 106
5 18 20 248 229 106
22 32 20 248 229 106
9 31 20 248 229 106
26 17 20 248 229 106
23 31 20 248 229 106
8 30 20 248 229 106
6 17 20 248 229 106
25 16 20 248 229 106
7 16 20 248 229 106
24 15 20 248 229 106
8 15 20 248 229 106
23 14 20 248 229 106
9 14 20 248 229 106
22 13 20 248 229 106
10 13 20 248 229 106
21 12 20 248 229 106
11 12 20 248 229 106
9 2 21 248 229 106
14 30 21 248 229 106
18 30 21 248 229 106
13 29 21 248 229 106
19 29 21 248 229 106
33 2 21 248 229 106
12 28 21 248 229 106
20 28 21 248 229 106
11 27 21 248 229 106
21 27 21 248 229 106
9 3 21 248 229 106
10 26 21 248 229 106
34 34 46 7 146 0
20 11 20 248 229 106
12 11 20 248 229 106
19 10 20 248 229 106
13 10 20 248 229 106
31 35 20 248 229 106
18 9 20 248 229 106
10 2 21 248 229 106
14 9 20 248 229 106
17 8 20 248 229 106
15 8 20 248 229 106
16 7 20 248 229 106
4 20 20 248 229 106
27 21 20 248 229 106
10 3 21 248 229 106
5 21 20 248 229 106
13 2 21 248 229 106
26 22 20 248 229 106
6 22 20 248 229 106
25 23 20 248 229 106
7 23 20 248 229 106
35 3 21 248 229 106
24 24 20 248 229 106
32 6 20 248 229 106
21 19 20 248 229 106
11 2 21 248 229 106
6 30 20 248 229 106
22 26 21 248 229 106
9 25 21 248 229 106
23 25 21 248 229 106
8 24 21 248 229 106
24 24 21 248 229 106
7 23 21 248 229 106
25 23 21 248 229 106
13 3 21 248 229 106
7 32 21 248 229 106
11 3 21 248 229 106
25 31 20 248 229 106
35 35 26 248 229 106
7 31 20 248 229 106
24 32 20 248 229 106
34 2 24 44 185 36
8 32 20 248 229 106
33 34 46 7 146 0
28 16 21 248 229 106
32 31 20 248 229 106
33 36 42 7 146 0
12 2 21 248 229 106
4 16 21 248 229 106
23 33 20 248 229 106
8 24 20 248 229 106
9 33 20 248 229 106
22 34 20 248 229 106
10 34 20 248 229 106
21 35 20 248 229 106
11 35 20 248 229 106
27 15 21 248 229 106
6 22 21 248 229 106
12 3 21 248 229 106
26 22 21 248 229 106
5 21 21 248 229 106
27 21 21 248 229 106
4 20 21 248 229 106
36 35 42 7 146 0
23 25 20 248 229 106
5 6 20 248 229 106
32 16 20 248 229 106
35 4 24 44 185 36
35 34 26 248 229 106
32 33 20 248 229 106
31 15 20 248 229 106
31 32 20 248 229 106
30 14 20 248 229 106
29 13 20 248 229 106
3 13 20 248 229 106
28 12 20 248 229 106
4 12 20 248 229 106
27 11 20 248 229 106
5 11 20 248 229 106
35 33 26 248 229 106
24 33 21 248 229 106
26 10 20 248 229 106
16 7 21 248 229 106
15 8 21 248 229 106
17 8 21 248 229 106
6 10 20 248 229 106
25 9 20 248 229 106
7 9 20 248 229 106
24 8 20 248 229 106
8 8 20 248 229 106
23 7 20 248 229 106
9 7 20 248 229 106
22 6 20 248 229 106
35 31 21 248 229 106
10 6 20 248 229 106
34 31 21 248 229 106
19 3 20 248 229 106
33 4 24 44 185 36
35 35 42 7 146 0
31 34 20 248 229 106
36 32 26 248 229 106
11 19 20 248 229 106
14 9 21 248 229 106
31 24 20 248 229 106
34 35 42 7 146 0
30 25 20 248 229 106
29 26 20 248 229 106
3 26 20 248 229 106
28 27 20 248 229 106
4 27 20 248 229 106
27 28 20 248 229 106
5 28 20 248 229 106
26 29 20 248 229 106
6 29 20 248 229 106
25 30 20 248 229 106
7 30 20 248 229 106
24 31 20 248 229 106
9 25 20 248 229 106
35 32 26 248 229 106
8 31 20 248 229 106
33 35 42 7 146 0
33 37 42 7 146 0
9 3 24 248 229 106
9 2 24 248 229 106
10 3 24 248 229 106
35 33 20 248 229 106
10 2 24 248 229 106
32 28 20 248 229 106
13 3 24 248 229 106
35 34 20 248 229 106
11 3 24 248 229 106
34 3 24 248 229 106
13 2 24 248 229 106
11 2 24 248 229 106
12 3 24 248 229 106
12 2 24 248 229 106
13 3 23 248 229 106
13 2 23 248 229 106
12 3 23 248 229 106
12 2 23 248 229 106
11 3 23 248 229 106
9 3 23 248 229 106
11 2 23 248 229 106
9 2 23 248 229 106
10 3 23 248 229 106
10 2 23 248 229 106
19 3 23 248 229 106
19 4 23 248 229 106
18 3 23 248 229 106
18 4 23 248 229 106
19 4 22 248 229 106
18 4 22 248 229 106
19 3 22 248 229 106
18 3 22 248 229 106
13 3 22 248 229 106
36 36 42 7 146 0
12 3 22 248 229 106
11 3 22 248 229 106
10 3 22 248 229 106
9 3 22 248 229 106
13 2 22 248 229 106
34 33 20 248 229 106
12 2 22 248 229 106
34 34 20 248 229 106
11 2 22 248 229 106
31 29 20 248 229 106
10 2 22 248 229 106
33 33 20 248 229 106
9 2 22 248 229 106
18 5 24 248 229 106
17 5 24 248 229 106
16 5 24 248 229 106
15 5 24 248 229 106
14 5 24 248 229 106
13 5 24 248 229 106
18 5 23 248 229 106
6 7 29 248 229 106
17 5 23 248 229 106
16 5 23 248 229 106
28 28 21 248 229 106
4 28 21 248 229 106
27 29 21 248 229 106
5 29 21 248 229 106
26 30 21 248 229 106
6 30 21 248 229 106
25 31 21 248 229 106
7 31 21 248 229 106
24 32 21 248 229 106
8 32 21 248 229 106
23 33 21 248 229 106
9 33 21 248 229 106
22 34 21 248 229 106
10 34 21 248 229 106
21 35 21 248 229 106
11 35 21 248 229 106
32 16 21 248 229 106
31 15 21 248 229 106
30 14 21 248 229 106
29 13 21 248 229 106
3 13 21 248 229 106
28 12 21 248 229 106
33 34 20 248 229 106
4 12 21 248 229 106
37 37 20 248 229 106
27 11 21 248 229 106
35 37 45 7 146 0
5 11 21 248 229 106
30 30 20 248 229 106
26 10 21 248 229 106
6 10 21 248 229 106
25 9 21 248 229 106
7 9 21 248 229 106
24 8 21 248 229 106
8 8 21 248 229 106
23 7 21 248 229 106
9 7 21 248 229 106
22 6 21 248 229 106
10 6 21 248 229 106
19 3 21 248 229 106
31 24 21 248 229 106
30 25 21 248 229 106
29 26 21 248 229 106
3 26 21 248 229 106
28 27 21 248 229 106
4 27 21 248 229 106
27 28 21 248 229 106
5 28 21 248 229 106
26 29 21 248 229 106
6 29 21 248 229 106
25 30 21 248 229 106
7 30 21 248 229 106
24 31 21 248 229 106
8 31 21 248 229 106
23 32 21 248 229 106
9 32 21 248 229 106
22 33 21 248 229 106
10 33 21 248 229 106
21 34 21 248 229 106
11 34 21 248 229 106
20 35 21 248 229 106
12 35 21 248 229 106
32 17 21 248 229 106
19 7 27 248 229 106
31 16 21 248 229 106
30 15 21 248 229 106
29 31 20 248 229 106
29 14 21 248 229 106
35 39 21 248 229 106
3 14 21 248 229 106
37 36 20 248 229 106
28 13 21 248 229 106
3 31 20 248 229 106
4 13 21 248 229 106
27 12 21 248 229 106
5 12 21 248 229 106
26 11 21 248 229 106
6 11 21 248 229 106
25 10 21 248 229 106
7 10 21 248 229 106
24 9 21 248 229 106
8 9 21 248 229 106
23 8 21 248 229 106
9 8 21 248 229 106
22 7 21 248 229 106
10 7 21 248 229 106
21 6 21 248 229 106
11 6 21 248 229 106
19 4 21 248 229 106
18 3 21 248 229 106
30 24 21 248 229 106
29 25 21 248 229 106
3 25 21 248 229 106
28 26 21 248 229 106
4 26 21 248 229 106
27 27 21 248 229 106
5 27 21 248 229 106
26 28 21 248 229 106
6 28 21 248 229 106
25 29 21 248 229 106
7 29 21 248 229 106
24 30 21 248 229 106
8 30 21 248 229 106
23 31 21 248 229 106
9 31 21 248 229 106
22 32 21 248 229 106
10 32 21 248 229 106
21 33 21 248 229 106
11 33 21 248 229 106
20 34 21 248 229 106
12 34 21 248 229 106
18 7 27 97 38 6
19 35 21 248 229 106
36 37 20 248 229 106
13 35 21 248 229 106
5 33 20 248 229 106
31 17 21 248 229 106
24 30 20 248 229 106
30 16 21 248 229 106
34 37 45 7 146 0
29 15 21 248 229 106
3 15 21 248 229 106
28 14 21 248 229 106
4 14 21 248 229 106
27 13 21 248 229 106
5 13 21 248 229 106
26 12 21 248 229 106
6 12 21 248 229 106
25 11 21 248 229 106
7 11 21 248 229 106
24 10 21 248 229 106
8 10 21 248 229 106
23 9 21 248 229 106
9 9 21 248 229 106
22 8 21 248 229 106
10 8 21 248 229 106
21 7 21 248 229 106
11 7 21 248 229 106
20 6 21 248 229 106
12 6 21 248 229 106
18 4 21 248 229 106
13 5 21 248 229 106
29 24 21 248 229 106
3 24 21 248 229 106
28 25 21 248 229 106
4 25 21 248 229 106
27 26 21 248 229 106
5 26 21 248 229 106
26 27 21 248 229 106
6 27 21 248 229 106
25 28 21 248 229 106
7 28 21 248 229 106
24 29 21 248 229 106
28 33 28 248 229 106
8 29 21 248 229 106
23 30 21 248 229 106
9 30 21 248 229 106
22 31 21 248 229 106
10 31 21 248 229 106
21 32 21 248 229 106
11 32 21 248 229 106
34 39 21 248 229 106
20 33 21 248 229 106
37 39 20 248 229 106
12 33 21 248 229 106
37 35 20 248 229 106
19 34 21 248 229 106
36 36 20 248 229 106
13 34 21 248 229 106
18 35 21 248 229 106
14 35 21 248 229 106
30 17 21 248 229 106
29 16 21 248 229 106
3 16 21 248 229 106
28 15 21 248 229 106
4 15 21 248 229 106
27 14 21 248 229 106
5 14 21 248 229 106
26 13 21 248 229 106
6 13 21 248 229 106
25 12 21 248 229 106
7 12 21 248 229 106
24 11 21 248 229 106
8 11 21 248 229 106
23 10 21 248 229 106
9 10 21 248 229 106
22 9 21 248 229 106
10 9 21 248 229 106
21 8 21 248 229 106
11 8 21 248 229 106
20 7 21 248 229 106
12 7 21 248 229 106
19 6 21 248 229 106
13 6 21 248 229 106
18 5 21 248 229 106
14 5 21 248 229 106
3 23 21 248 229 106
28 24 21 248 229 106
4 24 21 248 229 106
27 25 21 248 229 106
5 25 21 248 229 106
26 26 21 248 229 106
6 26 21 248 229 106
25 27 21 248 229 106
7 27 21 248 229 106
24 28 21 248 229 106
8 28 21 248 229 106
23 29 21 248 229 106
9 29 21 248 229 106
19 35 23 248 229 106
18 35 23 248 229 106
35 37 20 248 229 106
20 35 23 248 229 106
36 39 20 248 229 106
19 35 22 248 229 106
37 31 20 248 229 106
19 35 24 248 229 106
17 35 23 248 229 106
18 35 22 248 229 106
18 35 24 248 229 106
21 35 23 248 229 106
20 35 22 248 229 106
20 35 24 248 229 106
16 35 23 248 229 106
17 35 22 248 229 106
17 35 24 248 229 106
22 35 23 248 229 106
21 35 22 248 229 106
21 35 24 248 229 106
15 35 23 248 229 106
16 35 22 248 229 106
16 35 24 248 229 106
23 35 23 248 229 106
22 35 22 248 229 106
22 35 24 248 229 106
14 35 23 248 229 106
15 35 22 248 229 106
15 35 24 248 229 106
24 35 23 248 229 106
23 35 22 248 229 106
23 35 24 248 229 106
13 35 23 248 229 106
14 35 22 248 229 106
14 35 24 248 229 106
25 35 23 248 229 106
24 35 22 248 229 106
24 35 24 248 229 106
12 35 23 248 229 106
13 35 22 248 229 106
13 35 24 248 229 106
26 35 23 248 229 106
25 35 22 248 229 106
25 35 24 248 229 106
11 35 23 248 229 106
12 35 22 248 229 106
12 35 24 248 229 106
27 35 23 248 229 106
26 35 22 248 229 106
26 35 24 248 229 106
10 35 23 248 229 106
35 39 20 248 229 106
11 35 22 248 229 106
15 17 29 248 229 106
11 35 24 248 229 106
28 35 23 248 229 106
27 35 22 248 229 106
9 29 20 248 229 106
25 8 20 248 229 106
34 31 26 248 229 106
39 38 25 248 229 106
39 37 25 248 229 106
38 37 26 248 229 106
39 36 25 248 229 106
39 35 25 248 229 106
26 31 42 97 38 6
26 32 42 97 38 6
27 31 42 97 38 6
27 32 42 97 38 6
26 31 41 97 38 6
20 28 20 248 229 106
17 15 20 248 229 106
7 8 20 248 229 106
26 32 41 97 38 6
27 31 41 97 38 6
27 32 41 97 38 6
39 39 25 248 229 106
38 39 25 248 229 106
37 39 25 248 229 106
36 39 25 248 229 106
35 39 25 248 229 106
22 23 21 248 229 106
27 15 20 248 229 106
9 22 21 248 229 106
23 22 21 248 229 106
39 34 25 248 229 106
38 34 25 248 229 106
37 34 25 248 229 106
39 33 25 248 229 106
38 33 25 248 229 106
37 33 25 248 229 106
39 32 25 248 229 106
38 32 25 248 229 106
37 32 25 248 229 106
39 31 25 248 229 106
38 31 25 248 229 106
30 33 20 248 229 106
37 31 25 248 229 106
36 31 25 248 229 106
35 31 25 248 229 106
34 39 25 248 229 106
34 38 25 248 229 106
34 37 25 248 229 106
36 34 26 248 229 106
34 36 25 248 229 106
34 4 24 44 185 36
34 35 25 248 229 106
34 34 25 248 229 106
34 33 25 248 229 106
34 32 25 248 229 106
34 31 25 248 229 106
38 36 24 248 229 106
37 36 24 248 229 106
8 21 21 248 229 106
29 34 20 248 229 106
35 37 42 7 146 0
3 34 20 248 229 106
24 21 21 248 229 106
7 20 21 248 229 106
25 20 21 248 229 106
16 10 21 248 229 106
38 35 24 248 229 106
37 35 24 248 229 106
38 34 24 248 229 106
37 34 24 248 229 106
16 16 29 248 229 106
38 33 24 248 229 106
33 4 23 248 229 106
37 33 24 248 229 106
38 32 24 248 229 106
36 33 26 248 229 106
37 32 24 248 229 106
35 32 23 248 229 106
36 32 23 248 229 106
37 32 23 248 229 106
37 33 23 248 229 106
35 2 20 248 229 106
38 32 23 248 229 106
28 35 20 248 229 106
37 36 23 248 229 106
37 34 23 248 229 106
38 33 23 248 229 106
37 35 23 248 229 106
38 36 23 248 229 106
38 34 23 248 229 106
38 35 23 248 229 106
33 34 24 248 229 106
34 35 24 248 229 106
33 33 24 248 229 106
35 31 20 248 229 106
15 11 21 248 229 106
37 34 20 248 229 106
3 27 21 248 229 106
17 11 21 248 229 106
14 12 21 248 229 106
18 12 21 248 229 106
13 13 21 248 229 106
19 13 21 248 229 106
30 35 23 248 229 106
34 34 24 248 229 106
33 32 24 248 229 106
34 33 24 248 229 106
35 3 20 248 229 106
34 32 24 248 229 106
34 2 20 248 229 106
34 31 24 248 229 106
35 31 24 248 229 106
34 38 24 248 229 106
36 31 24 248 229 106
34 36 24 248 229 106
34 37 24 248 229 106
37 31 24 248 229 106
33 35 24 248 229 106
39 38 24 248 229 106
38 31 24 248 229 106
39 37 24 248 229 106
39 31 24 248 229 106
36 35 20 248 229 106
39 36 24 248 229 106
36 33 20 248 229 106
39 32 24 248 229 106
39 35 24 248 229 106
39 33 24 248 229 106
39 34 24 248 229 106
39 39 24 248 229 106
20 14 21 248 229 106
29 27 21 248 229 106
11 15 21 248 229 106
21 15 21 248 229 106
10 16 21 248 229 106
22 16 21 248 229 106
9 17 21 248 229 106
33 3 21 248 229 106
23 17 21 248 229 106
35 4 20 248 229 106
8 18 21 248 229 106
24 18 21 248 229 106
38 39 24 248 229 106
37 39 24 248 229 106
36 39 24 248 229 106
35 39 24 248 229 106
38 37 23 248 229 106
38 38 23 248 229 106
37 38 23 248 229 106
37 37 23 248 229 106
38 39 23 248 229 106
38 39 22 248 229 106
38 39 20 248 229 106
38 39 21 248 229 106
35 36 20 248 229 106
38 38 22 248 229 106
34 37 20 248 229 106
38 38 20 248 229 106
38 38 21 248 229 106
38 37 22 248 229 106
38 37 20 248 229 106
38 37 21 248 229 106
38 36 22 248 229 106
38 36 20 248 229 106
38 36 21 248 229 106
7 19 21 248 229 106
14 17 20 248 229 106
25 19 21 248 229 106
16 30 21 248 229 106
15 29 21 248 229 106
17 29 21 248 229 106
14 28 21 248 229 106
18 28 21 248 229 106
34 4 21 248 229 106
13 27 21 248 229 106
19 27 21 248 229 106
12 26 21 248 229 106
20 26 21 248 229 106
38 35 22 248 229 106
38 35 20 248 229 106
38 35 21 248 229 106
38 34 22 248 229 106
19 7 28 97 38 6
38 34 20 248 229 106
38 34 21 248 229 106
38 33 22 248 229 106
38 33 20 248 229 106
38 33 21 248 229 106
37 32 20 248 229 106
38 32 22 248 229 106
34 39 20 248 229 106
38 31 23 248 229 106
38 32 20 248 229 106
38 32 21 248 229 106
38 31 22 248 229 106
38 31 20 248 229 106
38 31 21 248 229 106
35 38 20 248 229 106
36 38 20 248 229 106
33 35 45 7 146 0
36 34 45 7 146 0
35 34 45 7 146 0
11 25 21 248 229 106
18 17 20 248 229 106
21 25 21 248 229 106
10 24 21 248 229 106
22 24 21 248 229 106
9 23 21 248 229 106
23 23 21 248 229 106
8 22 21 248 229 106
24 22 21 248 229 106
7 21 21 248 229 106
25 21 21 248 229 106
34 34 45 7 146 0
33 34 45 7 146 0
36 37 44 7 146 0
35 37 44 7 146 0
18 7 28 97 38 6
34 37 44 7 146 0
33 37 44 7 146 0
36 36 44 7 146 0
36 31 20 248 229 106
35 36 44 7 146 0
34 35 20 248 229 106
34 36 44 7 146 0
33 36 44 7 146 0
36 35 44 7 146 0
35 35 44 7 146 0
34 35 44 7 146 0
33 35 44 7 146 0
36 34 44 7 146 0
35 34 44 7 146 0
34 34 44 7 146 0
33 34 44 7 146 0
36 37 43 7 146 0
35 37 43 7 146 0
34 37 43 7 146 0
6 20 21 248 229 106
26 20 21 248 229 106
16 9 21 248 229 106
15 10 21 248 229 106
17 10 21 248 229 106
14 11 21 248 229 106
18 11 21 248 229 106
13 12 21 248 229 106
19 12 21 248 229 106
33 37 43 7 146 0
22 20 20 248 229 106
12 28 20 248 229 106
19 29 20 248 229 106
22 30 20 248 229 106
10 30 20 248 229 106
17 7 28 97 38 6
15 15 20 248 229 106
35 32 20 248 229 106
21 31 20 248 229 106
37 33 20 248 229 106
24 7 20 248 229 106
11 31 20 248 229 106
36 36 43 7 146 0
16 14 20 248 229 106
20 32 20 248 229 106
21 20 20 248 229 106
29 12 21 248 229 106
11 20 20 248 229 106
20 21 20 248 229 106
13 29 20 248 229 106
18 30 20 248 229 106
20 31 21 248 229 106
20 13 21 248 229 106
37 37 26 248 229 106
21 14 21 248 229 106
10 15 21 248 229 106
22 15 21 248 229 106
9 16 21 248 229 106
