ply
format ascii 1.0
comment : MagicaVoxel @ Ephtracy
element vertex 22494
property float x
property float y
property float z
property uchar red
property uchar green
property uchar blue
end_header
-5 13 5 18 148 223
18 21 -5 255 217 165
18 20 -5 255 217 165
17 21 -5 255 217 165
18 21 -4 255 217 165
18 19 -5 255 217 165
17 20 -5 255 217 165
18 20 -4 255 217 165
16 21 -5 255 217 165
17 21 -4 255 217 165
18 21 -3 255 217 165
18 18 -5 255 217 165
17 19 -5 255 217 165
18 19 -4 255 217 165
16 20 -5 255 217 165
17 20 -4 255 217 165
18 20 -3 255 217 165
15 21 -5 255 217 165
16 21 -4 255 217 165
17 21 -3 255 217 165
18 21 -2 255 217 165
14 21 -5 255 217 165
18 17 -5 255 217 165
17 18 -5 255 217 165
18 18 -4 255 217 165
16 19 -5 255 217 165
17 19 -4 255 217 165
18 19 -3 255 217 165
15 20 -5 255 217 165
16 20 -4 255 217 165
17 20 -3 255 217 165
18 20 -2 255 217 165
15 21 -4 255 217 165
16 21 -3 255 217 165
17 21 -2 255 217 165
18 21 -1 255 217 165
-5 12 5 18 148 223
24 -24 -5 255 217 165
13 21 -5 255 217 165
14 20 -5 255 217 165
14 21 -4 255 217 165
18 16 -5 255 217 165
17 17 -5 255 217 165
18 17 -4 255 217 165
16 18 -5 255 217 165
17 18 -4 255 217 165
18 18 -3 255 217 165
15 19 -5 255 217 165
16 19 -4 255 217 165
17 19 -3 255 217 165
18 19 -2 255 217 165
15 20 -4 255 217 165
16 20 -3 255 217 165
17 20 -2 255 217 165
18 20 -1 255 217 165
15 21 -3 255 217 165
16 21 -2 255 217 165
17 21 -1 255 217 165
18 21 0 255 217 165
23 -24 -5 255 217 165
24 -23 -5 255 217 165
24 -24 2 174 202 48
24 -24 -4 255 217 165
12 21 -5 255 217 165
13 20 -5 255 217 165
13 21 -4 255 217 165
14 19 -5 255 217 165
14 20 -4 255 217 165
14 21 -3 255 217 165
18 15 -5 255 217 165
17 16 -5 255 217 165
18 16 -4 255 217 165
16 17 -5 255 217 165
17 17 -4 255 217 165
4 13 5 18 148 223
18 17 -3 255 217 165
15 18 -5 255 217 165
16 18 -4 255 217 165
17 18 -3 255 217 165
18 18 -2 255 217 165
15 19 -4 255 217 165
16 19 -3 255 217 165
17 19 -2 255 217 165
18 19 -1 255 217 165
-4 13 5 18 148 223
15 20 -3 255 217 165
16 20 -2 255 217 165
17 20 -1 255 217 165
18 20 0 255 217 165
15 21 -2 255 217 165
16 21 -1 255 217 165
17 21 0 255 217 165
18 21 1 92 109 23
22 -24 -5 255 217 165
23 -24 2 174 202 48
23 -23 -5 255 217 165
23 -24 -4 255 217 165
24 -22 -5 255 217 165
24 -23 2 174 202 48
24 -23 -4 255 217 165
24 -24 1 255 217 165
24 -24 -3 255 217 165
11 21 -5 255 217 165
12 20 -5 255 217 165
12 21 -4 255 217 165
13 19 -5 255 217 165
13 20 -4 255 217 165
13 21 -3 255 217 165
14 18 -5 255 217 165
14 19 -4 255 217 165
14 20 -3 255 217 165
14 21 -2 255 217 165
18 14 -5 255 217 165
17 15 -5 255 217 165
18 15 -4 255 217 165
-5 11 5 18 148 223
16 16 -5 255 217 165
17 16 -4 255 217 165
18 16 -3 255 217 165
15 17 -5 255 217 165
16 17 -4 255 217 165
17 17 -3 255 217 165
18 17 -2 255 217 165
15 18 -4 255 217 165
16 18 -3 255 217 165
17 18 -2 255 217 165
18 18 -1 255 217 165
15 19 -3 255 217 165
16 19 -2 255 217 165
17 19 -1 255 217 165
18 19 0 255 217 165
15 20 -2 255 217 165
16 20 -1 255 217 165
17 20 0 255 217 165
18 20 1 92 109 23
15 21 -1 255 217 165
4 12 5 18 148 223
16 21 0 255 217 165
17 21 1 92 109 23
18 21 2 174 202 48
-4 12 5 18 148 223
23 -24 1 255 217 165
21 -24 -5 255 217 165
22 -24 2 174 202 48
22 -23 -5 255 217 165
22 -24 -4 255 217 165
23 -23 2 255 217 165
23 -22 -5 255 217 165
23 -23 -4 255 217 165
23 -24 -3 255 217 165
24 -21 -5 255 217 165
24 -22 2 174 202 48
24 -22 -4 255 217 165
11 -6 9 255 217 165
-2 9 7 18 148 223
3 13 5 18 148 223
-5 9 12 18 148 223
-4 9 7 18 148 223
0 9 6 18 148 223
8 -6 8 255 217 165
-3 9 10 18 148 223
7 -6 9 255 217 165
-5 9 9 18 148 223
-5 9 11 18 148 223
-3 9 6 18 148 223
24 -23 1 255 217 165
-1 9 10 18 148 223
8 -7 10 255 217 165
7 -7 10 255 217 165
3 9 10 18 148 223
2 9 9 18 148 223
2 9 11 18 148 223
1 9 8 18 148 223
1 9 12 18 148 223
-5 9 6 18 148 223
0 9 7 18 148 223
6 -7 10 255 217 165
4 9 9 18 148 223
4 9 11 18 148 223
-2 9 9 18 148 223
4 9 6 18 148 223
3 9 8 18 148 223
3 9 12 18 148 223
2 9 7 18 148 223
6 -6 10 255 217 165
9 -6 8 255 217 165
-2 9 11 18 148 223
1 9 6 18 148 223
-1 9 6 18 148 223
-4 9 10 18 148 223
-4 9 8 18 148 223
-3 13 5 18 148 223
5 -7 10 174 202 48
4 9 8 18 148 223
8 -6 6 255 217 165
-3 9 9 18 148 223
-4 9 12 18 148 223
4 9 12 18 148 223
-5 9 7 18 148 223
-3 9 11 18 148 223
10 -6 9 255 217 165
0 9 10 18 148 223
-3 9 7 18 148 223
-4 9 6 18 148 223
-1 9 9 18 148 223
7 -6 5 255 217 165
2 9 10 18 148 223
1 9 9 18 148 223
3 9 7 18 148 223
7 -6 7 255 217 165
1 9 11 18 148 223
-1 9 11 18 148 223
8 -6 9 255 217 165
4 9 10 18 148 223
0 9 8 18 148 223
-2 9 8 18 148 223
2 9 6 18 148 223
8 -6 7 255 217 165
4 9 7 18 148 223
3 9 9 18 148 223
0 9 12 18 148 223
-2 9 12 18 148 223
7 -6 10 255 217 165
-5 10 5 18 148 223
3 9 11 18 148 223
-1 9 7 18 148 223
-5 9 10 18 148 223
3 9 6 18 148 223
2 9 8 18 148 223
4 11 5 18 148 223
9 -6 9 255 217 165
-4 11 5 18 148 223
-4 9 9 18 148 223
3 12 5 18 148 223
7 -6 8 255 217 165
-3 12 5 18 148 223
2 9 12 18 148 223
-2 9 6 18 148 223
-4 9 11 18 148 223
-3 9 8 18 148 223
9 -6 7 255 217 165
10 -6 8 255 217 165
1 9 7 18 148 223
-5 9 8 18 148 223
-2 9 10 18 148 223
-1 9 12 18 148 223
-1 9 8 18 148 223
0 9 11 18 148 223
0 9 9 18 148 223
1 9 10 18 148 223
-3 9 12 18 148 223
10 8 20 92 109 23
8 11 15 156 111 55
7 11 15 156 111 55
7 8 15 156 111 55
6 9 15 156 111 55
9 10 15 156 111 55
6 10 15 156 111 55
8 8 15 156 111 55
8 8 16 92 109 23
7 8 16 92 109 23
6 9 16 92 109 23
6 10 16 92 109 23
7 11 16 92 109 23
8 11 16 92 109 23
9 10 16 92 109 23
9 10 17 92 109 23
8 8 17 92 109 23
7 8 17 92 109 23
6 9 17 92 109 23
5 9 20 92 109 23
6 12 20 92 109 23
10 12 20 92 109 23
5 11 20 92 109 23
6 7 20 92 109 23
10 7 20 92 109 23
9 10 18 92 109 23
5 8 20 92 109 23
5 12 20 92 109 23
5 7 20 92 109 23
8 9 21 92 109 23
8 8 18 92 109 23
8 8 21 92 109 23
8 10 21 92 109 23
7 9 21 92 109 23
9 9 21 92 109 23
8 7 21 92 109 23
16 5 -5 156 111 55
9 9 18 92 109 23
7 8 21 92 109 23
9 8 21 92 109 23
8 11 21 92 109 23
7 10 21 92 109 23
9 10 21 92 109 23
6 9 21 92 109 23
10 9 21 92 109 23
9 8 18 92 109 23
7 7 21 92 109 23
9 7 21 92 109 23
6 8 21 92 109 23
10 8 21 92 109 23
8 12 21 92 109 23
7 11 21 92 109 23
9 11 21 92 109 23
6 10 21 92 109 23
10 10 21 92 109 23
5 9 21 92 109 23
6 7 21 92 109 23
10 7 21 92 109 23
6 12 18 92 109 23
16 7 -5 156 111 55
5 8 21 92 109 23
7 12 21 92 109 23
9 12 21 92 109 23
6 11 21 92 109 23
10 11 21 92 109 23
7 12 18 92 109 23
5 10 21 92 109 23
5 7 21 92 109 23
6 12 21 92 109 23
10 12 21 92 109 23
5 11 21 92 109 23
5 12 21 92 109 23
8 12 18 92 109 23
8 10 22 92 109 23
8 9 22 92 109 23
8 11 22 92 109 23
7 10 22 92 109 23
9 10 22 92 109 23
8 8 22 92 109 23
7 9 22 92 109 23
9 12 18 92 109 23
9 9 22 92 109 23
8 12 22 92 109 23
7 11 22 92 109 23
9 11 22 92 109 23
6 10 22 92 109 23
10 10 22 92 109 23
8 7 22 92 109 23
7 8 22 92 109 23
9 8 22 92 109 23
6 9 22 92 109 23
10 9 22 92 109 23
7 12 22 92 109 23
9 12 22 92 109 23
6 11 22 92 109 23
10 11 22 92 109 23
5 10 22 92 109 23
5 8 18 92 109 23
7 7 22 92 109 23
5 9 18 92 109 23
5 10 18 92 109 23
9 7 22 92 109 23
5 11 18 92 109 23
6 8 22 92 109 23
6 7 22 92 109 23
10 8 22 92 109 23
6 12 22 92 109 23
6 7 18 92 109 23
7 7 18 92 109 23
8 7 18 92 109 23
9 7 18 92 109 23
5 11 22 92 109 23
10 8 18 92 109 23
10 9 18 92 109 23
10 10 18 92 109 23
2 13 5 18 148 223
5 9 22 92 109 23
10 11 18 92 109 23
5 8 22 92 109 23
7 9 18 92 109 23
7 10 18 92 109 23
8 9 18 92 109 23
8 10 18 92 109 23
8 9 19 92 109 23
8 8 19 92 109 23
8 10 19 92 109 23
7 9 19 92 109 23
9 9 19 92 109 23
8 7 19 92 109 23
7 8 19 92 109 23
9 8 19 92 109 23
8 11 19 92 109 23
7 10 19 92 109 23
-5 2 -5 156 111 55
9 10 19 92 109 23
6 9 19 92 109 23
16 3 -5 156 111 55
10 9 19 92 109 23
7 7 19 92 109 23
9 7 19 92 109 23
6 8 19 92 109 23
10 8 19 92 109 23
8 12 19 92 109 23
7 11 19 92 109 23
-4 -8 -4 18 148 223
-5 -8 3 18 148 223
-5 -8 -3 18 148 223
4 -8 -5 18 148 223
-2 -8 -5 18 148 223
-3 -8 4 18 148 223
-3 -8 -4 18 148 223
-4 -8 3 18 148 223
-4 -8 -3 18 148 223
-5 -8 2 18 148 223
-5 -8 -2 18 148 223
3 -8 -5 18 148 223
4 -8 4 18 148 223
4 -8 -4 18 148 223
-1 -8 -5 18 148 223
-2 -8 4 18 148 223
-2 -8 -4 18 148 223
-3 -8 3 18 148 223
-3 -8 -3 18 148 223
16 9 -5 156 111 55
-4 -8 2 18 148 223
-4 -8 -2 18 148 223
-5 -8 1 18 148 223
-5 -8 -1 18 148 223
2 -8 -5 18 148 223
3 -8 4 18 148 223
3 -8 -4 18 148 223
4 -8 3 18 148 223
4 -8 -3 18 148 223
-2 13 5 18 148 223
0 -8 -5 18 148 223
-1 -8 4 18 148 223
-1 -8 -4 18 148 223
-2 -8 3 18 148 223
-2 -8 -3 18 148 223
-3 -8 2 18 148 223
-3 -8 -2 18 148 223
-4 -8 1 18 148 223
-4 -8 -1 18 148 223
-5 -8 0 18 148 223
1 -8 -5 18 148 223
2 -8 4 18 148 223
2 -8 -4 18 148 223
3 -8 3 18 148 223
3 -8 -3 18 148 223
4 -8 2 18 148 223
4 -8 -2 18 148 223
0 -8 4 18 148 223
0 -8 -4 18 148 223
-1 -8 3 18 148 223
-1 -8 -3 18 148 223
-2 -8 2 18 148 223
-2 -8 -2 18 148 223
-3 -8 1 18 148 223
-3 -8 -1 18 148 223
-4 -8 0 18 148 223
1 -8 4 18 148 223
1 -8 -4 18 148 223
2 -8 3 18 148 223
2 -8 -3 18 148 223
3 -8 2 18 148 223
3 -8 -2 18 148 223
4 -8 1 18 148 223
4 -8 -1 18 148 223
0 -8 3 18 148 223
0 -8 -3 18 148 223
-1 -8 2 18 148 223
-1 -8 -2 18 148 223
-2 -8 1 18 148 223
-2 -8 -1 18 148 223
-3 -8 0 18 148 223
8 20 2 156 111 55
1 -8 3 18 148 223
7 20 2 156 111 55
1 -8 -3 18 148 223
2 -8 2 18 148 223
2 -8 -2 18 148 223
3 -8 1 18 148 223
3 -8 -1 18 148 223
4 -8 0 18 148 223
0 -8 2 18 148 223
0 -8 -2 18 148 223
-1 -8 1 18 148 223
-1 -8 -1 18 148 223
-2 -8 0 18 148 223
1 -8 2 18 148 223
1 -8 -2 18 148 223
2 -8 1 18 148 223
6 20 2 156 111 55
2 -8 -1 18 148 223
3 -8 0 18 148 223
-5 9 5 18 148 223
0 -8 1 18 148 223
0 -8 -1 18 148 223
-1 -8 0 18 148 223
1 -8 1 18 148 223
1 -8 -1 18 148 223
2 -8 0 18 148 223
0 -8 0 18 148 223
1 -8 0 18 148 223
2 4 5 18 148 223
-2 4 5 18 148 223
1 5 5 18 148 223
-1 5 5 18 148 223
0 6 5 18 148 223
-5 -7 5 18 148 223
-5 0 5 18 148 223
4 1 5 18 148 223
16 1 -5 156 111 55
-7 2 -5 156 111 55
-4 1 5 18 148 223
3 2 5 18 148 223
-3 2 5 18 148 223
2 3 5 18 148 223
-2 3 5 18 148 223
1 4 5 18 148 223
-1 4 5 18 148 223
0 5 5 18 148 223
-5 -6 5 18 148 223
4 -7 5 18 148 223
-4 -7 5 18 148 223
-5 -1 5 18 148 223
4 0 5 18 148 223
-4 0 5 18 148 223
3 1 5 18 148 223
-3 1 5 18 148 223
2 2 5 18 148 223
-2 2 5 18 148 223
1 3 5 18 148 223
-1 3 5 18 148 223
0 4 5 18 148 223
-5 -5 5 18 148 223
4 -6 5 18 148 223
-4 -6 5 18 148 223
3 -7 5 18 148 223
-3 -7 5 18 148 223
-5 -2 5 18 148 223
4 -1 5 18 148 223
-4 -1 5 18 148 223
16 11 -5 156 111 55
3 0 5 18 148 223
-3 0 5 18 148 223
2 1 5 18 148 223
-2 1 5 18 148 223
1 2 5 18 148 223
-1 2 5 18 148 223
0 3 5 18 148 223
-5 -4 5 18 148 223
-11 6 -5 156 111 55
4 -5 5 18 148 223
-4 -5 5 18 148 223
3 -6 5 18 148 223
-3 -6 5 18 148 223
2 -7 5 18 148 223
-2 -7 5 18 148 223
-5 -3 5 18 148 223
4 -2 5 18 148 223
4 10 5 18 148 223
-4 -2 5 18 148 223
3 -1 5 18 148 223
-3 -1 5 18 148 223
2 0 5 18 148 223
-2 0 5 18 148 223
1 1 5 18 148 223
8 19 2 156 111 55
-1 1 5 18 148 223
7 19 2 156 111 55
0 2 5 18 148 223
6 19 2 156 111 55
4 -4 5 18 148 223
-4 -4 5 18 148 223
3 -5 5 18 148 223
-3 -5 5 18 148 223
2 -6 5 18 148 223
-2 -6 5 18 148 223
1 -7 5 18 148 223
-1 -7 5 18 148 223
4 -3 5 18 148 223
-4 -3 5 18 148 223
3 -2 5 18 148 223
-3 -2 5 18 148 223
2 -1 5 18 148 223
-2 -1 5 18 148 223
1 0 5 18 148 223
-1 0 5 18 148 223
0 1 5 18 148 223
3 -4 5 18 148 223
-3 -4 5 18 148 223
2 -5 5 18 148 223
-2 -5 5 18 148 223
1 -6 5 18 148 223
-1 -6 5 18 148 223
0 -7 5 18 148 223
3 -3 5 18 148 223
-3 -3 5 18 148 223
2 -2 5 18 148 223
-2 -2 5 18 148 223
1 -1 5 18 148 223
-1 -1 5 18 148 223
0 0 5 18 148 223
2 -4 5 18 148 223
-2 -4 5 18 148 223
1 -5 5 18 148 223
-1 -5 5 18 148 223
0 -6 5 18 148 223
16 12 -5 156 111 55
2 -3 5 18 148 223
-2 -3 5 18 148 223
1 -2 5 18 148 223
-1 -2 5 18 148 223
0 -1 5 18 148 223
1 -4 5 18 148 223
-1 -4 5 18 148 223
0 -5 5 18 148 223
1 -3 5 18 148 223
-1 -3 5 18 148 223
0 -2 5 18 148 223
0 -4 5 18 148 223
0 -3 5 18 148 223
13 9 -1 255 0 0
13 9 -3 255 0 0
13 9 -2 255 0 0
13 8 1 255 0 0
13 8 -1 255 0 0
13 -1 1 255 0 0
13 -3 1 255 0 0
13 -4 1 255 0 0
-4 10 5 18 148 223
13 -5 1 255 0 0
13 -7 1 255 0 0
13 -9 1 255 0 0
13 -8 1 255 0 0
13 5 0 255 0 0
13 3 0 255 0 0
13 1 0 255 0 0
13 -1 0 255 0 0
13 -3 0 255 0 0
13 -7 0 255 0 0
13 7 -1 255 0 0
13 5 -1 255 0 0
16 -1 -5 156 111 55
13 4 -1 255 0 0
13 3 -1 255 0 0
13 1 -1 255 0 0
13 0 -1 255 0 0
-9 2 -5 156 111 55
13 -1 -1 255 0 0
13 -3 -1 255 0 0
13 -9 -1 255 0 0
-11 4 -5 156 111 55
13 -8 -1 255 0 0
13 -7 -1 255 0 0
13 5 -2 255 0 0
13 3 -2 255 0 0
13 1 -2 255 0 0
13 -1 -2 255 0 0
13 -3 -2 255 0 0
13 -7 -2 255 0 0
13 5 -3 255 0 0
13 3 -3 255 0 0
13 1 -3 255 0 0
13 -1 -3 255 0 0
13 -3 -3 255 0 0
13 -4 -3 255 0 0
13 -5 -3 255 0 0
13 -7 -3 255 0 0
13 -8 -3 255 0 0
13 -9 -3 255 0 0
7 9 -4 156 111 55
13 0 1 255 0 0
13 1 1 255 0 0
13 3 1 255 0 0
13 4 1 255 0 0
13 5 1 255 0 0
13 7 1 255 0 0
6 12 -3 156 111 55
7 12 -3 156 111 55
13 9 0 255 0 0
13 9 1 255 0 0
16 -10 -4 156 111 55
16 -13 -4 156 111 55
2 -2 -1 113 58 30
2 -1 -1 113 58 30
2 -1 0 113 58 30
-11 8 -5 156 111 55
2 -2 0 113 58 30
1 -2 -1 113 58 30
1 -1 -1 113 58 30
1 -1 0 113 58 30
1 -2 0 113 58 30
0 -3 -2 113 58 30
0 0 -2 113 58 30
0 0 1 113 58 30
0 -3 1 113 58 30
0 -1 -1 113 58 30
0 -2 -1 113 58 30
0 -1 0 113 58 30
0 -2 0 113 58 30
-1 -1 -1 113 58 30
-1 -2 -1 113 58 30
-1 -1 0 113 58 30
3 11 5 18 148 223
-1 -2 0 113 58 30
-1 0 -2 113 58 30
-1 -3 -2 113 58 30
-1 0 1 113 58 30
-1 -3 1 113 58 30
-1 -5 -3 113 58 30
-1 2 2 113 58 30
-1 -5 2 113 58 30
-1 2 -3 113 58 30
6 10 17 92 109 23
7 11 17 92 109 23
11 12 -5 156 111 55
13 12 -5 156 111 55
8 11 17 92 109 23
9 9 17 92 109 23
4 17 -1 156 111 55
3 17 -1 156 111 55
2 17 -1 156 111 55
1 17 -1 156 111 55
4 16 -1 156 111 55
3 16 -1 156 111 55
2 16 -1 156 111 55
7 17 1 156 111 55
1 16 -1 156 111 55
4 15 -1 156 111 55
3 15 -1 156 111 55
2 15 -1 156 111 55
1 15 -1 156 111 55
4 17 -2 156 111 55
3 17 -2 156 111 55
2 17 -2 156 111 55
1 17 -2 156 111 55
0 17 -2 156 111 55
-1 17 -2 156 111 55
-2 17 -2 156 111 55
4 16 -2 156 111 55
3 16 -2 156 111 55
7 15 1 156 111 55
2 16 -2 156 111 55
1 16 -2 156 111 55
0 16 -2 156 111 55
-1 16 -2 156 111 55
-2 16 -2 156 111 55
4 15 -2 156 111 55
3 15 -2 156 111 55
2 15 -2 156 111 55
1 15 -2 156 111 55
0 15 -2 156 111 55
-1 15 -2 156 111 55
-2 15 -2 156 111 55
-10 20 8 156 111 55
-11 20 8 156 111 55
-11 18 8 156 111 55
-11 19 8 156 111 55
-12 20 8 156 111 55
-10 19 8 156 111 55
-3 3 5 18 148 223
3 3 5 18 148 223
-4 2 5 18 148 223
4 2 5 18 148 223
-12 19 8 156 111 55
-10 18 8 156 111 55
-12 18 8 156 111 55
5 17 0 156 111 55
5 16 0 156 111 55
5 15 0 156 111 55
1 8 -3 255 0 0
9 -8 -5 156 111 55
16 -7 -5 156 111 55
14 12 -5 156 111 55
9 8 17 92 109 23
6 8 17 92 109 23
6 11 17 92 109 23
9 11 17 92 109 23
6 11 18 92 109 23
6 10 18 92 109 23
-3 11 5 18 148 223
8 18 2 156 111 55
7 9 23 92 109 23
7 18 2 156 111 55
7 10 23 92 109 23
6 18 2 156 111 55
7 11 18 92 109 23
6 9 18 92 109 23
11 2 -5 156 111 55
16 -3 -5 156 111 55
16 -19 -5 156 111 55
7 16 1 156 111 55
8 17 1 156 111 55
8 11 18 92 109 23
8 15 1 156 111 55
-5 1 5 18 148 223
0 7 5 18 148 223
-1 6 5 18 148 223
-11 2 -5 156 111 55
1 6 5 18 148 223
6 8 18 92 109 23
8 10 23 92 109 23
8 9 23 92 109 23
9 11 18 92 109 23
9 11 19 92 109 23
7 8 18 92 109 23
6 8 23 92 109 23
6 9 23 92 109 23
6 10 19 92 109 23
10 10 19 92 109 23
6 10 23 92 109 23
6 11 23 92 109 23
7 8 23 92 109 23
8 8 23 92 109 23
9 8 23 92 109 23
9 9 23 92 109 23
-4 -8 4 18 148 223
-5 -8 -5 18 148 223
-3 -8 -5 18 148 223
-1 -8 5 18 148 223
-16 12 8 156 111 55
-16 10 8 156 111 55
-16 9 8 156 111 55
-16 8 8 156 111 55
-16 7 8 156 111 55
-16 6 8 156 111 55
-16 4 8 156 111 55
-5 -8 -4 18 148 223
-2 -8 5 18 148 223
-16 11 7 156 111 55
-16 10 7 156 111 55
-16 9 7 156 111 55
-16 8 7 156 111 55
-16 7 7 156 111 55
-16 6 7 156 111 55
-16 5 7 156 111 55
-5 -8 4 18 148 223
0 -8 5 18 148 223
-13 8 -5 156 111 55
-9 18 7 156 111 55
-4 20 6 156 111 55
-5 20 6 156 111 55
-6 20 6 156 111 55
-9 19 7 156 111 55
-9 20 7 156 111 55
-8 18 7 156 111 55
-7 18 7 156 111 55
-4 19 6 156 111 55
-5 19 6 156 111 55
-6 19 6 156 111 55
-8 19 7 156 111 55
-7 19 7 156 111 55
-8 20 7 156 111 55
-7 20 7 156 111 55
-4 18 6 156 111 55
-5 18 6 156 111 55
-6 18 6 156 111 55
3 15 0 156 111 55
2 12 5 18 148 223
4 15 0 156 111 55
3 16 0 156 111 55
4 16 0 156 111 55
3 17 0 156 111 55
4 17 0 156 111 55
-16 10 6 156 111 55
-16 6 6 156 111 55
8 16 1 156 111 55
-4 -8 -5 18 148 223
-3 -8 5 18 148 223
-1 20 5 156 111 55
-2 20 5 156 111 55
-3 20 5 156 111 55
-1 19 5 156 111 55
-2 19 5 156 111 55
-3 19 5 156 111 55
-1 18 5 156 111 55
-2 18 5 156 111 55
-3 18 5 156 111 55
-16 10 5 156 111 55
-16 6 5 156 111 55
1 -8 5 18 148 223
-4 -8 5 18 148 223
0 20 4 156 111 55
0 19 4 156 111 55
0 18 4 156 111 55
-1 12 -3 255 0 0
0 11 -3 255 0 0
-16 10 4 156 111 55
-16 6 4 156 111 55
9 10 23 92 109 23
9 11 23 92 109 23
2 -8 5 18 148 223
-5 -8 5 18 148 223
0 6 -3 255 0 0
-16 10 3 156 111 55
-16 6 3 156 111 55
-2 5 5 18 148 223
2 5 5 18 148 223
-3 4 5 18 148 223
3 4 5 18 148 223
-4 3 5 18 148 223
4 3 5 18 148 223
3 -8 5 18 148 223
4 -8 5 18 148 223
7 11 23 92 109 23
8 11 23 92 109 23
-10 8 2 156 111 55
-11 8 2 156 111 55
-10 7 2 156 111 55
-10 5 2 156 111 55
5 9 19 92 109 23
6 7 19 92 109 23
10 7 19 92 109 23
5 8 19 92 109 23
7 12 19 92 109 23
9 12 19 92 109 23
-10 3 2 156 111 55
-10 1 2 156 111 55
-10 0 2 156 111 55
-11 0 2 156 111 55
-5 2 5 18 148 223
0 8 5 18 148 223
-1 7 5 18 148 223
1 7 5 18 148 223
-2 6 5 18 148 223
2 6 5 18 148 223
0 12 -3 255 0 0
1 11 -3 255 0 0
2 10 -3 255 0 0
3 9 -3 255 0 0
1 6 -3 255 0 0
2 7 -3 255 0 0
-1 6 -3 255 0 0
-14 0 1 156 111 55
-14 -1 1 156 111 55
6 15 1 156 111 55
-2 12 5 18 148 223
-14 -3 1 156 111 55
-14 -5 1 156 111 55
-3 5 5 18 148 223
3 5 5 18 148 223
-4 4 5 18 148 223
4 4 5 18 148 223
-5 3 5 18 148 223
0 9 5 18 148 223
-14 -7 1 156 111 55
3 8 -3 255 0 0
6 11 19 92 109 23
-1 8 5 18 148 223
1 8 5 18 148 223
-2 7 5 18 148 223
2 7 5 18 148 223
-3 6 5 18 148 223
3 6 5 18 148 223
-11 -7 0 156 111 55
-11 16 -1 156 111 55
-11 15 -1 156 111 55
11 8 -5 156 111 55
-4 8 -3 255 0 0
-3 7 -3 255 0 0
-13 19 -2 156 111 55
6 16 1 156 111 55
11 -4 -5 156 111 55
-15 19 -2 156 111 55
1 18 4 156 111 55
2 18 4 156 111 55
10 11 19 92 109 23
5 10 19 92 109 23
5 7 19 92 109 23
6 12 19 92 109 23
10 12 19 92 109 23
5 11 19 92 109 23
5 12 19 92 109 23
8 10 20 92 109 23
-11 19 -2 156 111 55
1 19 4 156 111 55
2 19 4 156 111 55
8 9 20 92 109 23
8 11 20 92 109 23
7 10 20 92 109 23
9 10 20 92 109 23
8 8 20 92 109 23
7 9 20 92 109 23
9 9 20 92 109 23
8 12 20 92 109 23
1 20 4 156 111 55
2 20 4 156 111 55
7 11 20 92 109 23
9 11 20 92 109 23
6 10 20 92 109 23
10 10 20 92 109 23
8 7 20 92 109 23
-15 8 -5 156 111 55
7 8 20 92 109 23
9 8 20 92 109 23
6 9 20 92 109 23
10 9 20 92 109 23
-4 5 5 18 148 223
-2 8 -3 255 0 0
4 5 5 18 148 223
-11 12 -2 156 111 55
-5 4 5 18 148 223
0 10 5 18 148 223
-1 9 5 18 148 223
1 9 5 18 148 223
-2 8 5 18 148 223
2 8 5 18 148 223
-3 7 5 18 148 223
-15 16 -3 156 111 55
-8 -4 -2 156 111 55
3 7 5 18 148 223
7 -8 -5 156 111 55
-15 13 -4 156 111 55
11 4 -5 156 111 55
1 13 5 18 148 223
7 12 20 92 109 23
9 12 20 92 109 23
6 11 20 92 109 23
10 11 20 92 109 23
11 -6 -5 156 111 55
5 10 20 92 109 23
7 7 20 92 109 23
9 7 20 92 109 23
6 8 20 92 109 23
11 -2 -5 156 111 55
-15 20 9 156 111 55
-15 19 9 156 111 55
-14 20 9 156 111 55
-15 18 9 156 111 55
-14 19 9 156 111 55
-13 20 9 156 111 55
-14 18 9 156 111 55
-13 19 9 156 111 55
-13 18 9 156 111 55
11 10 -5 156 111 55
-4 6 5 18 148 223
4 6 5 18 148 223
-5 5 5 18 148 223
0 11 5 18 148 223
-1 10 5 18 148 223
-8 12 -3 156 111 55
1 10 5 18 148 223
-7 12 -3 156 111 55
-2 9 5 18 148 223
2 9 5 18 148 223
-3 8 5 18 148 223
3 8 5 18 148 223
-4 7 5 18 148 223
6 17 1 156 111 55
4 7 5 18 148 223
-5 6 5 18 148 223
0 12 5 18 148 223
-1 11 5 18 148 223
-5 -4 -3 156 111 55
-2 11 -3 255 0 0
-8 -7 -1 156 111 55
1 11 5 18 148 223
-2 10 5 18 148 223
11 -8 -5 156 111 55
2 10 5 18 148 223
-3 9 5 18 148 223
3 9 5 18 148 223
-4 8 5 18 148 223
-3 10 -3 255 0 0
-1 10 -3 255 0 0
4 8 5 18 148 223
-5 7 5 18 148 223
-4 9 -3 255 0 0
0 13 5 18 148 223
-5 -1 -4 156 111 55
-1 12 5 18 148 223
1 12 5 18 148 223
-2 11 5 18 148 223
11 6 -5 156 111 55
2 11 5 18 148 223
7 6 -5 156 111 55
-3 10 5 18 148 223
3 10 5 18 148 223
-4 9 5 18 148 223
4 9 5 18 148 223
-1 11 -3 255 0 0
16 -16 -5 156 111 55
16 -5 -5 156 111 55
-5 8 5 18 148 223
-1 13 5 18 148 223
11 0 -5 156 111 55
3 18 3 156 111 55
4 18 3 156 111 55
5 18 3 156 111 55
3 19 3 156 111 55
4 19 3 156 111 55
5 19 3 156 111 55
3 20 3 156 111 55
4 20 3 156 111 55
5 20 3 156 111 55
0 10 -3 255 0 0
-2 6 -3 255 0 0
-15 10 -5 156 111 55
-15 -10 5 255 217 165
-16 -10 5 92 109 23
-14 -10 5 255 217 165
-15 -9 5 255 217 165
-15 -10 4 255 217 165
-15 -10 6 255 217 165
-16 -9 5 255 217 165
-16 -10 4 92 109 23
-16 -10 6 92 109 23
-13 -10 5 255 217 165
-14 -9 5 255 217 165
-14 -10 4 255 217 165
-14 -10 6 255 217 165
-15 -9 4 255 217 165
-15 -9 6 255 217 165
-15 -10 3 255 217 165
-15 -10 7 255 217 165
-16 -8 5 255 217 165
-16 -9 4 255 217 165
-16 -9 6 174 202 48
-16 -10 3 255 217 165
-16 -10 7 92 109 23
-12 -10 5 255 217 165
-13 -9 5 255 217 165
-13 -10 4 255 217 165
-13 -10 6 255 217 165
-14 -9 4 255 217 165
-14 -9 6 255 217 165
-14 -10 3 255 217 165
-14 -10 7 255 217 165
-15 -9 3 255 217 165
-15 -9 7 255 217 165
-15 -10 2 255 217 165
-15 -10 8 174 202 48
-16 -7 5 255 217 165
-16 -8 4 255 217 165
-16 -8 6 255 217 165
-16 -9 3 255 217 165
-16 -9 7 92 109 23
-16 -10 2 255 217 165
-16 -10 8 92 109 23
-11 -10 5 255 217 165
-12 -9 5 255 217 165
-12 -10 4 255 217 165
-12 -10 6 255 217 165
-13 -9 4 255 217 165
-13 -9 6 255 217 165
-13 -10 3 255 217 165
-13 -10 7 255 217 165
-14 -9 3 255 217 165
-14 -9 7 255 217 165
-14 -10 2 255 217 165
-14 -10 8 255 217 165
-15 -9 2 255 217 165
-15 -8 7 255 217 165
-15 -9 8 255 217 165
-15 -11 2 255 217 165
-15 -10 1 255 217 165
-15 -10 9 174 202 48
-16 -6 5 255 217 165
-16 -7 4 255 217 165
-16 -7 6 255 217 165
-16 -8 3 255 217 165
-16 -8 7 174 202 48
-16 -9 2 255 217 165
-16 -9 8 92 109 23
-17 -10 2 255 217 165
-16 -11 2 255 217 165
-16 -10 1 255 217 165
-16 -10 9 174 202 48
-10 -10 5 255 217 165
-11 -9 5 255 217 165
-11 -10 4 255 217 165
-11 -10 6 255 217 165
-12 -9 4 255 217 165
-12 -9 6 255 217 165
-12 -10 3 255 217 165
-12 -10 7 255 217 165
-13 -9 3 255 217 165
-13 -9 7 255 217 165
-13 -10 2 255 217 165
-13 -10 8 255 217 165
-14 -9 2 255 217 165
-14 -8 7 255 217 165
-14 -9 8 255 217 165
-14 -11 2 255 217 165
-14 -10 1 255 217 165
-14 -10 9 174 202 48
-15 -9 1 255 217 165
-15 -7 7 255 217 165
-15 -8 8 255 217 165
-15 -9 9 255 217 165
-15 -12 2 255 217 165
-15 -11 1 255 217 165
-15 -10 0 255 217 165
-15 -10 10 174 202 48
-16 -5 5 255 217 165
-16 -6 4 255 217 165
-16 -6 6 255 217 165
-16 -7 3 255 217 165
-16 -7 7 174 202 48
-16 -8 2 255 217 165
-16 -8 8 174 202 48
-17 -9 2 255 217 165
-16 -9 1 255 217 165
-16 -9 9 92 109 23
-18 -10 2 255 217 165
-17 -11 2 255 217 165
-17 -10 1 255 217 165
-16 -12 2 255 217 165
-16 -11 1 255 217 165
-16 -10 0 255 217 165
-16 -10 10 174 202 48
-9 -10 5 255 217 165
-10 -9 5 255 217 165
-10 -10 4 255 217 165
-10 -10 6 255 217 165
-11 -9 4 255 217 165
-11 -9 6 255 217 165
-11 -10 3 255 217 165
-11 -10 7 255 217 165
-12 -9 3 255 217 165
-12 -8 6 255 217 165
-12 -9 7 255 217 165
-12 -10 2 255 217 165
-12 -10 8 255 217 165
-13 -9 2 255 217 165
-13 -8 7 255 217 165
-13 -9 8 255 217 165
-13 -11 2 255 217 165
-13 -10 1 255 217 165
-13 -10 9 255 217 165
-14 -9 1 255 217 165
-14 -7 7 255 217 165
-14 -8 8 255 217 165
-14 -9 9 255 217 165
-14 -12 2 255 217 165
-14 -11 1 255 217 165
-14 -10 0 255 217 165
-14 -10 10 174 202 48
-15 -8 1 255 217 165
-15 -9 0 255 217 165
-15 -6 7 255 217 165
-15 -7 8 255 217 165
-15 -8 9 255 217 165
-15 -9 10 255 217 165
-15 -13 2 255 217 165
-15 -12 1 255 217 165
-15 -11 0 255 217 165
-15 -10 -1 255 217 165
-16 -4 5 174 202 48
-16 -5 4 255 217 165
-16 -5 6 255 217 165
-16 -6 3 255 217 165
-16 -6 7 255 217 165
-16 -7 2 255 217 165
-16 -7 8 174 202 48
-17 -8 2 255 217 165
-16 -8 1 255 217 165
-16 -8 9 92 109 23
-18 -9 2 255 217 165
-17 -9 1 255 217 165
-16 -9 0 255 217 165
-16 -9 10 174 202 48
-19 -10 2 174 202 48
-18 -11 2 255 217 165
-18 -10 1 255 217 165
-17 -12 2 255 217 165
-17 -11 1 255 217 165
-17 -10 0 255 217 165
-16 -13 2 255 217 165
-16 -12 1 255 217 165
-16 -11 0 255 217 165
-16 -10 -1 255 217 165
-8 -10 5 255 217 165
-9 -9 5 255 217 165
-9 -10 4 255 217 165
-9 -10 6 92 109 23
-10 -9 4 255 217 165
-10 -9 6 255 217 165
-10 -10 3 255 217 165
-10 -10 7 255 217 165
-11 -9 3 255 217 165
-11 -8 6 255 217 165
-11 -9 7 255 217 165
-11 -10 2 255 217 165
-11 -10 8 255 217 165
-12 -9 2 255 217 165
-12 -7 6 255 217 165
-12 -8 7 255 217 165
-12 -9 8 255 217 165
-12 -11 2 255 217 165
-12 -10 1 255 217 165
-12 -10 9 255 217 165
-13 -9 1 255 217 165
-13 -7 7 255 217 165
-13 -8 8 255 217 165
-13 -9 9 255 217 165
-13 -12 2 255 217 165
-13 -11 1 255 217 165
-13 -10 0 255 217 165
-13 -10 10 174 202 48
-14 -8 1 255 217 165
-14 -9 0 255 217 165
-14 -6 7 255 217 165
-14 -7 8 255 217 165
-14 -8 9 255 217 165
-14 -9 10 255 217 165
-14 -13 2 255 217 165
-14 -12 1 255 217 165
-14 -11 0 255 217 165
-14 -10 -1 255 217 165
-15 -7 1 255 217 165
-15 -8 0 255 217 165
-15 -9 -1 255 217 165
-15 -5 7 255 217 165
-15 -6 8 255 217 165
-15 -7 9 255 217 165
-15 -8 10 255 217 165
-15 -14 2 92 109 23
-15 -13 1 255 217 165
-15 -12 0 255 217 165
-15 -11 -1 255 217 165
-15 -10 -2 255 217 165
-16 -3 5 255 217 165
-16 -4 4 255 217 165
-16 -4 6 174 202 48
-16 -5 3 255 217 165
-16 -5 7 174 202 48
-16 -6 2 255 217 165
-16 -6 8 255 217 165
-17 -7 2 255 217 165
-16 -7 1 255 217 165
-16 -7 9 92 109 23
-18 -8 2 255 217 165
-17 -8 1 255 217 165
-16 -8 0 255 217 165
-16 -8 10 174 202 48
-19 -9 2 174 202 48
-18 -9 1 255 217 165
-17 -9 0 255 217 165
-16 -9 -1 255 217 165
-19 -11 2 174 202 48
-19 -10 1 92 109 23
-18 -12 2 255 217 165
-18 -11 1 255 217 165
-18 -10 0 255 217 165
-17 -13 2 255 217 165
-17 -12 1 255 217 165
-17 -11 0 255 217 165
-17 -10 -1 255 217 165
-16 -14 2 92 109 23
-16 -13 1 255 217 165
-16 -12 0 255 217 165
-16 -11 -1 255 217 165
-16 -10 -2 255 217 165
-7 -10 5 255 217 165
-8 -9 5 255 217 165
-8 -10 4 255 217 165
-8 -10 6 92 109 23
-9 -8 5 255 217 165
-9 -9 4 255 217 165
-9 -9 6 255 217 165
-9 -10 3 255 217 165
-9 -10 7 92 109 23
-10 -9 3 255 217 165
-10 -8 6 255 217 165
-10 -9 7 255 217 165
-10 -10 2 255 217 165
-10 -10 8 92 109 23
-11 -9 2 255 217 165
-11 -7 6 255 217 165
-11 -8 7 255 217 165
-11 -9 8 255 217 165
-11 -11 2 255 217 165
-11 -10 1 255 217 165
-11 -10 9 255 217 165
-12 -9 1 255 217 165
-12 -6 6 255 217 165
-12 -7 7 255 217 165
-12 -8 8 255 217 165
-12 -9 9 255 217 165
-12 -12 2 255 217 165
-12 -11 1 255 217 165
-12 -10 0 255 217 165
-12 -10 10 174 202 48
-13 -8 1 255 217 165
-13 -9 0 255 217 165
-13 -6 7 255 217 165
-13 -7 8 255 217 165
-13 -8 9 255 217 165
-13 -9 10 255 217 165
-13 -13 2 255 217 165
-13 -12 1 255 217 165
-13 -11 0 255 217 165
-13 -10 -1 255 217 165
-14 -8 0 255 217 165
-14 -9 -1 255 217 165
-14 -5 7 255 217 165
-14 -6 8 255 217 165
-14 -7 9 255 217 165
-14 -8 10 255 217 165
-14 -14 2 174 202 48
-14 -13 1 255 217 165
-14 -12 0 255 217 165
-14 -11 -1 255 217 165
-14 -10 -2 255 217 165
-15 -6 1 255 217 165
-15 -7 0 255 217 165
-15 -8 -1 255 217 165
-15 -9 -2 255 217 165
-15 -4 7 255 217 165
-15 -5 8 255 217 165
-15 -6 9 255 217 165
-15 -7 10 255 217 165
-15 -14 1 92 109 23
-15 -13 0 255 217 165
-15 -12 -1 255 217 165
-15 -11 -2 255 217 165
-15 -10 -3 255 217 165
-16 -2 5 255 217 165
-16 -3 4 255 217 165
-16 -3 6 255 217 165
-16 -4 3 255 217 165
-16 -4 7 174 202 48
-16 -5 2 255 217 165
-16 -5 8 174 202 48
-17 -6 2 255 217 165
-16 -6 1 255 217 165
-16 -6 9 255 217 165
-18 -7 2 255 217 165
-17 -7 1 255 217 165
-16 -7 0 255 217 165
-16 -7 10 174 202 48
-19 -8 2 174 202 48
-18 -8 1 255 217 165
-17 -8 0 255 217 165
-16 -8 -1 255 217 165
-19 -9 1 92 109 23
-18 -9 0 255 217 165
-17 -9 -1 255 217 165
-16 -9 -2 255 217 165
-19 -12 2 174 202 48
-19 -11 1 92 109 23
-19 -10 0 255 217 165
-18 -13 2 255 217 165
-18 -12 1 255 217 165
-18 -11 0 255 217 165
-18 -10 -1 255 217 165
-17 -14 2 174 202 48
-17 -13 1 255 217 165
-17 -12 0 255 217 165
-17 -11 -1 255 217 165
-17 -10 -2 255 217 165
-16 -14 1 255 217 165
-16 -13 0 255 217 165
-16 -12 -1 255 217 165
-16 -11 -2 255 217 165
-16 -10 -3 255 217 165
-6 -10 5 92 109 23
-7 -9 5 255 217 165
-7 -10 4 255 217 165
-7 -10 6 255 217 165
-8 -8 5 255 217 165
-8 -9 4 255 217 165
-8 -9 6 255 217 165
-8 -10 3 255 217 165
-8 -10 7 255 217 165
-9 -7 5 255 217 165
-9 -8 6 255 217 165
-9 -9 3 255 217 165
-9 -9 7 255 217 165
-9 -10 2 255 217 165
-9 -10 8 92 109 23
-10 -9 2 255 217 165
-10 -7 6 255 217 165
-10 -8 7 255 217 165
-10 -9 8 255 217 165
-10 -11 2 255 217 165
-10 -10 1 255 217 165
-10 -10 9 255 217 165
-11 -9 1 255 217 165
-11 -6 6 255 217 165
-11 -7 7 255 217 165
-11 -8 8 255 217 165
-11 -9 9 255 217 165
-11 -12 2 255 217 165
-11 -11 1 255 217 165
-11 -10 0 255 217 165
-11 -10 10 174 202 48
-12 -9 0 255 217 165
-12 -5 6 255 217 165
-12 -6 7 255 217 165
-12 -7 8 255 217 165
-12 -8 9 255 217 165
-12 -9 10 255 217 165
-12 -13 2 255 217 165
-12 -12 1 255 217 165
-12 -11 0 255 217 165
-12 -10 -1 255 217 165
-13 -7 1 255 217 165
-13 -8 0 255 217 165
-13 -9 -1 255 217 165
-13 -5 7 255 217 165
-13 -6 8 255 217 165
-13 -7 9 255 217 165
-13 -8 10 255 217 165
-13 -14 2 174 202 48
-13 -13 1 255 217 165
-13 -12 0 255 217 165
-13 -11 -1 255 217 165
-13 -10 -2 255 217 165
-14 -7 0 255 217 165
-14 -8 -1 255 217 165
-14 -9 -2 255 217 165
-14 -4 7 255 217 165
-14 -5 8 255 217 165
-14 -6 9 255 217 165
-14 -7 10 255 217 165
-14 -14 1 92 109 23
-14 -13 0 255 217 165
-14 -12 -1 255 217 165
-14 -11 -2 255 217 165
-14 -10 -3 255 217 165
-14 -6 1 255 217 165
-15 -5 1 255 217 165
-15 -6 0 255 217 165
-15 -7 -1 255 217 165
-15 -8 -2 255 217 165
-15 -9 -3 255 217 165
-15 -3 7 255 217 165
-15 -4 8 255 217 165
-15 -5 9 255 217 165
-15 -6 10 255 217 165
-15 -14 0 255 217 165
-15 -13 -1 255 217 165
-15 -12 -2 255 217 165
-15 -11 -3 255 217 165
-15 -10 -4 255 217 165
-16 -1 5 255 217 165
-16 -2 4 255 217 165
-16 -2 6 255 217 165
-16 -3 3 255 217 165
-16 -3 7 255 217 165
-16 -4 2 255 217 165
-16 -4 8 174 202 48
-17 -5 2 255 217 165
-16 -5 1 255 217 165
-16 -5 9 255 217 165
-18 -6 2 255 217 165
-17 -6 1 255 217 165
-16 -6 0 255 217 165
-16 -6 10 174 202 48
-19 -7 2 174 202 48
-18 -7 1 255 217 165
-17 -7 0 255 217 165
-16 -7 -1 255 217 165
-19 -8 1 92 109 23
-18 -8 0 255 217 165
-17 -8 -1 255 217 165
-16 -8 -2 255 217 165
-19 -9 0 255 217 165
-18 -9 -1 255 217 165
-17 -9 -2 255 217 165
-16 -9 -3 255 217 165
-19 -13 2 174 202 48
-19 -12 1 92 109 23
-19 -11 0 255 217 165
-19 -10 -1 255 217 165
-18 -14 2 174 202 48
-18 -13 1 255 217 165
-18 -12 0 255 217 165
-18 -11 -1 255 217 165
-18 -10 -2 255 217 165
-17 -14 1 255 217 165
-17 -13 0 255 217 165
-17 -12 -1 255 217 165
-17 -11 -2 255 217 165
-17 -10 -3 255 217 165
-16 -14 0 255 217 165
-16 -13 -1 255 217 165
-16 -12 -2 255 217 165
-16 -11 -3 255 217 165
-16 -10 -4 255 217 165
-6 -9 5 255 217 165
-6 -10 4 255 217 165
-6 -10 6 92 109 23
-7 -8 5 255 217 165
-7 -9 4 255 217 165
-7 -9 6 255 217 165
-7 -10 3 255 217 165
-7 -10 7 92 109 23
-8 -7 5 255 217 165
-8 -8 6 255 217 165
-8 -9 3 255 217 165
-8 -9 7 255 217 165
-8 -10 2 255 217 165
-8 -10 8 92 109 23
-9 -6 5 255 217 165
-9 -7 6 255 217 165
-9 -8 7 255 217 165
-9 -9 2 255 217 165
-9 -9 8 255 217 165
-9 -11 2 255 217 165
-9 -10 1 255 217 165
-9 -10 9 255 217 165
-10 -9 1 255 217 165
-10 -6 6 255 217 165
-10 -7 7 255 217 165
-10 -8 8 255 217 165
-10 -9 9 255 217 165
-10 -12 2 255 217 165
-10 -11 1 255 217 165
-10 -10 0 255 217 165
-10 -10 10 174 202 48
-11 -9 0 255 217 165
-11 -5 6 255 217 165
-11 -6 7 255 217 165
-11 -7 8 255 217 165
-11 -8 9 255 217 165
-11 -9 10 255 217 165
-11 -13 2 255 217 165
-11 -12 1 255 217 165
-11 -11 0 255 217 165
-11 -10 -1 255 217 165
-12 -8 0 255 217 165
-12 -9 -1 255 217 165
-12 -4 6 255 217 165
-12 -5 5 255 217 165
-12 -5 7 255 217 165
-12 -6 8 255 217 165
-12 -7 9 255 217 165
-12 -8 10 255 217 165
-12 -14 2 174 202 48
-12 -13 1 255 217 165
-12 -12 0 255 217 165
-12 -11 -1 255 217 165
-12 -10 -2 255 217 165
-13 -6 1 255 217 165
-13 -7 0 255 217 165
-13 -8 -1 255 217 165
-13 -9 -2 255 217 165
-13 -4 7 255 217 165
-13 -5 8 255 217 165
-13 -6 9 255 217 165
-13 -7 10 255 217 165
-13 -14 1 92 109 23
-13 -13 0 255 217 165
-13 -12 -1 255 217 165
-13 -11 -2 255 217 165
-13 -10 -3 255 217 165
-14 -6 0 255 217 165
-14 -7 -1 255 217 165
-14 -8 -2 255 217 165
-14 -9 -3 255 217 165
-14 -3 7 255 217 165
-14 -4 8 255 217 165
-14 -5 9 255 217 165
-14 -6 10 255 217 165
-14 -14 0 255 217 165
-14 -13 -1 255 217 165
-14 -12 -2 255 217 165
-14 -11 -3 255 217 165
-14 -10 -4 255 217 165
-15 -4 1 255 217 165
-15 -5 0 255 217 165
-15 -6 -1 255 217 165
-15 -7 -2 255 217 165
-15 -8 -3 255 217 165
-15 -9 -4 255 217 165
-15 -2 7 255 217 165
-15 -3 8 255 217 165
-15 -4 9 255 217 165
-15 -5 10 255 217 165
-15 -14 -1 255 217 165
-15 -13 -2 255 217 165
-15 -12 -3 255 217 165
-15 -11 -4 255 217 165
-15 -10 -5 255 217 165
-16 0 5 255 217 165
-16 -1 4 255 217 165
-16 -1 6 255 217 165
-16 -2 3 255 217 165
-16 -2 7 255 217 165
-16 -3 2 255 217 165
-16 -3 8 255 217 165
-17 -4 2 255 217 165
-16 -4 1 255 217 165
-16 -4 9 174 202 48
-18 -5 2 255 217 165
-17 -5 1 255 217 165
-16 -5 0 255 217 165
-16 -5 10 174 202 48
-19 -6 2 174 202 48
-18 -6 1 255 217 165
-17 -6 0 255 217 165
-16 -6 -1 255 217 165
-19 -7 1 255 217 165
-18 -7 0 255 217 165
-17 -7 -1 255 217 165
-16 -7 -2 255 217 165
-19 -8 0 255 217 165
-18 -8 -1 255 217 165
-17 -8 -2 255 217 165
-16 -8 -3 255 217 165
-19 -9 -1 255 217 165
-18 -9 -2 255 217 165
-17 -9 -3 255 217 165
-16 -9 -4 255 217 165
-19 -14 2 174 202 48
-19 -13 1 255 217 165
-19 -12 0 255 217 165
-19 -11 -1 255 217 165
-19 -10 -2 255 217 165
-18 -14 1 255 217 165
-18 -13 0 255 217 165
-18 -12 -1 255 217 165
-18 -11 -2 255 217 165
-18 -10 -3 255 217 165
-17 -14 0 255 217 165
-17 -13 -1 255 217 165
-17 -12 -2 255 217 165
-17 -11 -3 255 217 165
-17 -10 -4 255 217 165
-16 -14 -1 255 217 165
-16 -13 -2 255 217 165
-16 -12 -3 255 217 165
-16 -11 -4 255 217 165
-16 -10 -5 255 217 165
-6 -8 5 255 217 165
-6 -9 4 255 217 165
-6 -9 6 255 217 165
-6 -10 3 255 217 165
-6 -10 7 92 109 23
-7 -7 5 255 217 165
-7 -8 6 255 217 165
-7 -9 3 255 217 165
-7 -9 7 255 217 165
-7 -10 2 255 217 165
-7 -10 8 92 109 23
-8 -6 5 255 217 165
-8 -7 6 255 217 165
-8 -8 7 255 217 165
-8 -9 2 255 217 165
-8 -9 8 255 217 165
-8 -11 2 255 217 165
-8 -10 1 255 217 165
-8 -10 9 92 109 23
-9 -5 5 255 217 165
-9 -6 6 255 217 165
-9 -7 7 255 217 165
-9 -8 8 255 217 165
-9 -9 1 255 217 165
-9 -9 9 255 217 165
-9 -12 2 255 217 165
-9 -11 1 255 217 165
-9 -10 0 255 217 165
-9 -10 10 174 202 48
-10 -9 0 255 217 165
-10 -5 6 255 217 165
-10 -6 7 255 217 165
-10 -7 8 255 217 165
-10 -8 9 255 217 165
-10 -9 10 255 217 165
-10 -13 2 255 217 165
-10 -12 1 255 217 165
-10 -11 0 255 217 165
-10 -10 -1 255 217 165
-11 -8 0 255 217 165
-11 -9 -1 255 217 165
-11 -4 6 255 217 165
-11 -5 5 255 217 165
-11 -5 7 255 217 165
-11 -6 8 255 217 165
-11 -7 9 255 217 165
-11 -8 10 255 217 165
-11 -14 2 92 109 23
-11 -13 1 255 217 165
-11 -12 0 255 217 165
-11 -11 -1 255 217 165
-11 -10 -2 255 217 165
-12 -7 0 255 217 165
-12 -8 -1 255 217 165
-12 -9 -2 255 217 165
-12 -3 6 255 217 165
-12 -4 5 255 217 165
-12 -4 7 255 217 165
-12 -5 4 255 217 165
-12 -5 8 255 217 165
-12 -6 9 255 217 165
-12 -7 10 255 217 165
-12 -14 1 255 217 165
-12 -13 0 255 217 165
-12 -12 -1 255 217 165
-12 -11 -2 255 217 165
-12 -10 -3 255 217 165
-13 -5 1 255 217 165
-13 -6 0 255 217 165
-13 -7 -1 255 217 165
-13 -8 -2 255 217 165
-13 -9 -3 255 217 165
-13 -3 7 255 217 165
-13 -4 8 255 217 165
-13 -5 9 255 217 165
-13 -6 10 255 217 165
-13 -14 0 255 217 165
-13 -13 -1 255 217 165
-13 -12 -2 255 217 165
-13 -11 -3 255 217 165
-13 -10 -4 255 217 165
-14 -5 0 255 217 165
-14 -6 -1 255 217 165
-14 -7 -2 255 217 165
-14 -8 -3 255 217 165
-14 -9 -4 255 217 165
-14 -2 7 255 217 165
-14 -3 8 255 217 165
-14 -4 9 255 217 165
-14 -5 10 255 217 165
-14 -14 -1 255 217 165
-14 -13 -2 255 217 165
-14 -12 -3 255 217 165
-14 -11 -4 255 217 165
-14 -10 -5 255 217 165
-14 -4 1 255 217 165
-15 -3 1 255 217 165
-15 -4 0 255 217 165
-15 -5 -1 255 217 165
-15 -6 -2 255 217 165
-15 -7 -3 255 217 165
-15 -8 -4 255 217 165
-15 -9 -5 255 217 165
-15 -1 7 255 217 165
-15 -2 8 255 217 165
-15 -3 9 255 217 165
-15 -4 10 255 217 165
-15 -14 -2 255 217 165
-15 -13 -3 255 217 165
-15 -12 -4 255 217 165
-15 -11 -5 255 217 165
-16 1 5 255 217 165
-16 0 4 255 217 165
-16 0 6 174 202 48
-16 -1 3 255 217 165
-16 -1 7 174 202 48
-16 -2 2 255 217 165
-16 -2 8 255 217 165
-17 -3 2 255 217 165
-16 -3 1 255 217 165
-16 -3 9 255 217 165
-18 -4 2 255 217 165
-17 -4 1 255 217 165
-16 -4 0 255 217 165
-16 -4 10 174 202 48
-19 -5 2 174 202 48
-18 -5 1 255 217 165
-17 -5 0 255 217 165
-16 -5 -1 255 217 165
-19 -6 1 255 217 165
-18 -6 0 255 217 165
-17 -6 -1 255 217 165
-16 -6 -2 255 217 165
-19 -7 0 255 217 165
-18 -7 -1 255 217 165
-17 -7 -2 255 217 165
-16 -7 -3 255 217 165
-19 -8 -1 255 217 165
-18 -8 -2 255 217 165
-17 -8 -3 255 217 165
-16 -8 -4 255 217 165
-19 -9 -2 255 217 165
-18 -9 -3 255 217 165
-17 -9 -4 255 217 165
-16 -9 -5 255 217 165
-19 -14 1 255 217 165
-19 -13 0 255 217 165
-19 -12 -1 255 217 165
-19 -11 -2 255 217 165
-19 -10 -3 255 217 165
-18 -14 0 255 217 165
-18 -13 -1 255 217 165
-18 -12 -2 255 217 165
-18 -11 -3 255 217 165
-18 -10 -4 255 217 165
-17 -14 -1 255 217 165
-17 -13 -2 255 217 165
-17 -12 -3 255 217 165
-17 -11 -4 255 217 165
-17 -10 -5 255 217 165
-16 -14 -2 255 217 165
-16 -13 -3 255 217 165
-16 -12 -4 255 217 165
-16 -11 -5 255 217 165
-6 -7 5 255 217 165
-6 -8 4 255 217 165
-6 -8 6 255 217 165
-6 -9 3 255 217 165
-6 -9 7 92 109 23
-6 -10 2 174 202 48
-6 -10 8 92 109 23
-7 -6 5 255 217 165
-7 -7 6 255 217 165
-7 -8 7 255 217 165
-7 -9 2 255 217 165
-7 -9 8 255 217 165
-7 -11 2 255 217 165
-7 -10 1 255 217 165
-7 -10 9 174 202 48
-8 -5 5 255 217 165
-8 -6 6 255 217 165
-8 -7 7 255 217 165
-8 -8 8 255 217 165
-8 -9 1 255 217 165
-8 -9 9 255 217 165
-8 -12 2 255 217 165
-8 -11 1 255 217 165
-8 -10 0 255 217 165
-8 -10 10 92 109 23
-10 -5 5 255 217 165
-9 -4 5 255 217 165
-9 -5 4 255 217 165
-9 -5 6 255 217 165
-9 -6 7 255 217 165
-9 -7 8 255 217 165
-9 -8 9 255 217 165
-9 -9 0 255 217 165
-9 -9 10 255 217 165
-9 -13 2 255 217 165
-9 -12 1 255 217 165
-9 -11 0 255 217 165
-9 -10 -1 255 217 165
-10 -8 0 255 217 165
-10 -9 -1 255 217 165
-10 -4 6 255 217 165
-10 -5 7 255 217 165
-10 -6 8 255 217 165
-10 -7 9 255 217 165
-10 -8 10 255 217 165
-10 -14 2 174 202 48
-10 -13 1 255 217 165
-10 -12 0 255 217 165
-10 -11 -1 255 217 165
-10 -10 -2 255 217 165
-11 -8 -1 255 217 165
-11 -9 -2 255 217 165
-11 -3 6 255 217 165
-11 -4 5 255 217 165
-11 -4 7 255 217 165
-11 -5 4 255 217 165
-11 -5 8 255 217 165
-11 -6 9 255 217 165
-11 -7 10 255 217 165
-11 -14 1 92 109 23
-11 -13 0 255 217 165
-11 -12 -1 255 217 165
-11 -11 -2 255 217 165
-11 -10 -3 255 217 165
-12 -6 0 255 217 165
-12 -7 -1 255 217 165
-12 -8 -2 255 217 165
-12 -9 -3 255 217 165
-12 -2 6 255 217 165
-12 -3 5 255 217 165
-12 -3 7 255 217 165
-12 -4 4 255 217 165
-12 -4 8 255 217 165
-12 -5 3 255 217 165
-12 -5 9 255 217 165
-12 -6 10 255 217 165
-12 -14 0 255 217 165
-12 -13 -1 255 217 165
-12 -12 -2 255 217 165
-12 -11 -3 255 217 165
-12 -10 -4 255 217 165
-12 -5 1 255 217 165
-13 -4 1 255 217 165
-13 -5 0 255 217 165
-13 -6 -1 255 217 165
-13 -7 -2 255 217 165
-13 -8 -3 255 217 165
-13 -9 -4 255 217 165
-13 -2 7 255 217 165
-13 -3 8 255 217 165
-13 -4 9 255 217 165
-13 -5 10 255 217 165
-13 -14 -1 255 217 165
-13 -13 -2 255 217 165
-13 -12 -3 255 217 165
-13 -11 -4 255 217 165
-13 -10 -5 255 217 165
-14 -4 0 255 217 165
-14 -5 -1 255 217 165
-14 -6 -2 255 217 165
-14 -7 -3 255 217 165
-14 -8 -4 255 217 165
-14 -9 -5 255 217 165
-14 -1 7 255 217 165
-14 -2 8 255 217 165
-14 -3 9 255 217 165
-14 -4 10 255 217 165
-14 -14 -2 255 217 165
-14 -13 -3 255 217 165
-14 -12 -4 255 217 165
-14 -11 -5 255 217 165
-15 -2 1 255 217 165
-15 -3 0 255 217 165
-15 -4 -1 255 217 165
-15 -5 -2 255 217 165
-15 -6 -3 255 217 165
-15 -7 -4 255 217 165
-15 -8 -5 255 217 165
-15 0 7 255 217 165
-15 -1 8 255 217 165
-15 -2 9 255 217 165
-15 -3 10 255 217 165
-15 -14 -3 255 217 165
-15 -13 -4 255 217 165
-15 -12 -5 255 217 165
-16 2 5 255 217 165
-16 1 4 255 217 165
-16 1 6 255 217 165
-16 0 3 255 217 165
-16 0 7 174 202 48
-16 -1 2 255 217 165
-16 -1 8 174 202 48
-17 -2 2 255 217 165
-16 -2 1 255 217 165
-16 -2 9 255 217 165
-18 -3 2 255 217 165
-17 -3 1 255 217 165
-16 -3 0 255 217 165
-16 -3 10 174 202 48
-19 -4 2 174 202 48
-18 -4 1 255 217 165
-17 -4 0 255 217 165
-16 -4 -1 255 217 165
-19 -5 1 255 217 165
-18 -5 0 255 217 165
-17 -5 -1 255 217 165
-16 -5 -2 255 217 165
-19 -6 0 255 217 165
-18 -6 -1 255 217 165
-17 -6 -2 255 217 165
-16 -6 -3 255 217 165
-19 -7 -1 255 217 165
-18 -7 -2 255 217 165
-17 -7 -3 255 217 165
-16 -7 -4 255 217 165
-19 -8 -2 255 217 165
-18 -8 -3 255 217 165
-17 -8 -4 255 217 165
-16 -8 -5 255 217 165
-19 -9 -3 255 217 165
-18 -9 -4 255 217 165
-17 -9 -5 255 217 165
-19 -14 0 255 217 165
-19 -13 -1 255 217 165
-19 -12 -2 255 217 165
-19 -11 -3 255 217 165
-19 -10 -4 255 217 165
-18 -14 -1 255 217 165
-18 -13 -2 255 217 165
-18 -12 -3 255 217 165
-18 -11 -4 255 217 165
-18 -10 -5 255 217 165
-17 -14 -2 255 217 165
-17 -13 -3 255 217 165
-17 -12 -4 255 217 165
-17 -11 -5 255 217 165
-16 -14 -3 255 217 165
-16 -13 -4 255 217 165
-16 -12 -5 255 217 165
-6 -6 5 255 217 165
-6 -7 4 255 217 165
-6 -7 6 255 217 165
-6 -8 3 255 217 165
-6 -8 7 255 217 165
-6 -9 2 255 217 165
-6 -9 8 92 109 23
-6 -11 2 174 202 48
-6 -10 1 174 202 48
-6 -10 9 92 109 23
-7 -5 5 255 217 165
-7 -6 6 255 217 165
-7 -7 7 255 217 165
-7 -8 8 255 217 165
-7 -9 1 255 217 165
-7 -9 9 255 217 165
-7 -12 2 255 217 165
-7 -11 1 255 217 165
-7 -10 0 255 217 165
-7 -10 10 174 202 48
-8 -4 5 255 217 165
-8 -5 4 255 217 165
-8 -5 6 255 217 165
-8 -6 7 255 217 165
-8 -7 8 255 217 165
-8 -8 9 255 217 165
-8 -9 0 255 217 165
-8 -9 10 255 217 165
-8 -13 2 255 217 165
-8 -12 1 255 217 165
-8 -11 0 255 217 165
-8 -10 -1 255 217 165
-10 -4 5 255 217 165
-10 -5 4 255 217 165
-9 -3 5 255 217 165
-9 -4 4 255 217 165
-9 -4 6 255 217 165
-9 -5 7 255 217 165
-9 -6 8 255 217 165
-9 -7 9 255 217 165
-9 -8 10 255 217 165
-9 -9 -1 255 217 165
-9 -14 2 174 202 48
-9 -13 1 255 217 165
-9 -12 0 255 217 165
-9 -11 -1 255 217 165
-9 -10 -2 255 217 165
-10 -7 0 255 217 165
-10 -8 -1 255 217 165
-10 -9 -2 255 217 165
-10 -3 6 255 217 165
-10 -4 7 255 217 165
-10 -5 8 255 217 165
-10 -6 9 255 217 165
-10 -7 10 255 217 165
-10 -14 1 92 109 23
-10 -13 0 255 217 165
-10 -12 -1 255 217 165
-10 -11 -2 255 217 165
-10 -10 -3 255 217 165
-11 -7 -1 255 217 165
-11 -8 -2 255 217 165
-11 -9 -3 255 217 165
-11 -2 6 255 217 165
-11 -3 5 255 217 165
-11 -3 7 255 217 165
-11 -4 4 255 217 165
-11 -4 8 255 217 165
-11 -5 3 255 217 165
-11 -5 9 255 217 165
-11 -6 10 255 217 165
-11 -14 0 255 217 165
-11 -13 -1 255 217 165
-11 -12 -2 255 217 165
-11 -11 -3 255 217 165
-11 -10 -4 255 217 165
-11 -6 0 255 217 165
-12 -5 0 255 217 165
-12 -6 -1 255 217 165
-12 -7 -2 255 217 165
-12 -8 -3 255 217 165
-12 -9 -4 255 217 165
-12 -2 5 255 217 165
-12 -2 7 255 217 165
-12 -3 4 255 217 165
-12 -3 8 255 217 165
-12 -4 3 255 217 165
-12 -4 9 255 217 165
-12 -5 2 255 217 165
-12 -5 10 255 217 165
-12 -14 -1 255 217 165
-12 -13 -2 255 217 165
-12 -12 -3 255 217 165
-12 -11 -4 255 217 165
-12 -10 -5 255 217 165
-11 -5 1 255 217 165
-12 -4 1 255 217 165
-13 -3 1 255 217 165
-13 -4 0 255 217 165
-13 -5 -1 255 217 165
-13 -6 -2 255 217 165
-13 -7 -3 255 217 165
-13 -8 -4 255 217 165
-13 -9 -5 255 217 165
-13 -1 7 255 217 165
-13 -2 8 255 217 165
-13 -3 9 255 217 165
-13 -4 10 255 217 165
-13 -14 -2 255 217 165
-13 -13 -3 255 217 165
-13 -12 -4 255 217 165
-13 -11 -5 255 217 165
-14 -3 0 255 217 165
-14 -4 -1 255 217 165
-14 -5 -2 255 217 165
-14 -6 -3 255 217 165
-14 -7 -4 255 217 165
-14 -8 -5 255 217 165
-14 0 7 255 217 165
-14 -1 8 255 217 165
-14 -2 9 255 217 165
-14 -3 10 255 217 165
-14 -14 -3 255 217 165
-14 -13 -4 255 217 165
-14 -12 -5 255 217 165
-14 -2 1 255 217 165
-15 -1 1 255 217 165
-15 -2 0 255 217 165
-15 -3 -1 255 217 165
-15 -4 -2 255 217 165
-15 -5 -3 255 217 165
-15 -6 -4 255 217 165
-15 -7 -5 255 217 165
-15 1 7 255 217 165
-15 0 8 255 217 165
-15 -1 9 255 217 165
-15 -2 10 255 217 165
-15 -14 -4 255 217 165
-15 -13 -5 255 217 165
-15 2 5 255 217 165
-16 3 5 255 217 165
-16 2 4 255 217 165
-16 2 6 255 217 165
-16 1 3 255 217 165
-16 1 7 255 217 165
-16 0 2 255 217 165
-16 0 8 174 202 48
-17 -1 2 255 217 165
-16 -1 1 255 217 165
-16 -1 9 174 202 48
-18 -2 2 255 217 165
-17 -2 1 255 217 165
-16 -2 0 255 217 165
-16 -2 10 174 202 48
-19 -3 2 174 202 48
-18 -3 1 255 217 165
-17 -3 0 255 217 165
-16 -3 -1 255 217 165
-19 -4 1 255 217 165
-18 -4 0 255 217 165
-17 -4 -1 255 217 165
-16 -4 -2 255 217 165
-19 -5 0 255 217 165
-18 -5 -1 255 217 165
-17 -5 -2 255 217 165
-16 -5 -3 255 217 165
-19 -6 -1 255 217 165
-18 -6 -2 255 217 165
-17 -6 -3 255 217 165
-16 -6 -4 255 217 165
-19 -7 -2 255 217 165
-18 -7 -3 255 217 165
-17 -7 -4 255 217 165
-16 -7 -5 255 217 165
-19 -8 -3 255 217 165
-18 -8 -4 255 217 165
-17 -8 -5 255 217 165
-19 -9 -4 255 217 165
-18 -9 -5 255 217 165
-19 -14 -1 255 217 165
-19 -13 -2 255 217 165
-19 -12 -3 255 217 165
-19 -11 -4 255 217 165
-19 -10 -5 255 217 165
-18 -14 -2 255 217 165
-18 -13 -3 255 217 165
-18 -12 -4 255 217 165
-18 -11 -5 255 217 165
-17 -14 -3 255 217 165
-17 -13 -4 255 217 165
-17 -12 -5 255 217 165
-16 -14 -4 255 217 165
-16 -13 -5 255 217 165
-6 -5 5 255 217 165
-6 -6 4 255 217 165
-6 -6 6 255 217 165
-5 -7 4 255 217 165
-6 -7 3 255 217 165
-6 -7 7 255 217 165
-6 -8 2 255 217 165
-6 -8 8 92 109 23
-6 -9 1 255 217 165
-6 -9 9 255 217 165
-6 -12 2 174 202 48
-6 -11 1 174 202 48
-6 -10 0 255 217 165
-6 -10 10 174 202 48
-7 -4 5 255 217 165
-7 -5 4 255 217 165
-7 -5 6 255 217 165
-7 -6 7 255 217 165
-7 -7 8 255 217 165
-7 -8 9 255 217 165
-7 -9 0 255 217 165
-7 -9 10 255 217 165
-7 -13 2 255 217 165
-7 -12 1 255 217 165
-7 -11 0 255 217 165
-7 -10 -1 255 217 165
-8 -3 5 255 217 165
-8 -4 4 255 217 165
-8 -4 6 255 217 165
-8 -5 7 255 217 165
-8 -6 8 255 217 165
-8 -7 9 255 217 165
-8 -8 10 255 217 165
-8 -9 -1 255 217 165
-8 -14 2 174 202 48
-8 -13 1 255 217 165
-8 -12 0 255 217 165
-8 -11 -1 255 217 165
-8 -10 -2 255 217 165
-10 -3 5 255 217 165
-10 -4 4 255 217 165
-10 -5 3 255 217 165
-9 -2 5 255 217 165
-9 -3 4 255 217 165
-9 -3 6 255 217 165
-9 -4 7 255 217 165
-9 -5 8 255 217 165
-9 -6 9 255 217 165
-9 -7 10 255 217 165
-9 -8 -1 255 217 165
-9 -9 -2 255 217 165
-9 -14 1 255 217 165
-9 -13 0 255 217 165
-9 -12 -1 255 217 165
-9 -11 -2 255 217 165
-9 -10 -3 255 217 165
-10 -6 0 255 217 165
-10 -7 -1 255 217 165
-10 -8 -2 255 217 165
-10 -9 -3 255 217 165
-10 -2 6 255 217 165
-10 -3 7 255 217 165
-10 -4 8 255 217 165
-10 -5 9 255 217 165
-10 -6 10 255 217 165
-10 -14 0 255 217 165
-10 -13 -1 255 217 165
-10 -12 -2 255 217 165
-10 -11 -3 255 217 165
-10 -10 -4 255 217 165
-11 -6 -1 255 217 165
-11 -7 -2 255 217 165
-11 -8 -3 255 217 165
-11 -9 -4 255 217 165
-11 -2 5 255 217 165
-11 -2 7 255 217 165
-11 -3 4 255 217 165
-11 -3 8 255 217 165
-11 -4 3 255 217 165
-11 -4 9 255 217 165
-11 -5 2 255 217 165
-11 -5 10 255 217 165
-11 -14 -1 255 217 165
-11 -13 -2 255 217 165
-11 -12 -3 255 217 165
-11 -11 -4 255 217 165
-11 -10 -5 255 217 165
-11 -5 0 255 217 165
-12 -4 0 255 217 165
-12 -5 -1 255 217 165
-12 -6 -2 255 217 165
-12 -7 -3 255 217 165
-12 -8 -4 255 217 165
-12 -9 -5 255 217 165
-12 -2 4 255 217 165
-12 -2 8 255 217 165
-12 -3 3 255 217 165
-12 -3 9 255 217 165
-12 -4 2 255 217 165
-12 -4 10 255 217 165
-12 -14 -2 255 217 165
-12 -13 -3 255 217 165
-12 -12 -4 255 217 165
-12 -11 -5 255 217 165
-10 -5 1 255 217 165
-11 -4 1 255 217 165
-12 -3 1 255 217 165
-13 -2 1 255 217 165
-13 -3 0 255 217 165
-13 -4 -1 255 217 165
-13 -5 -2 255 217 165
-13 -6 -3 255 217 165
-13 -7 -4 255 217 165
-13 -8 -5 255 217 165
-13 0 7 255 217 165
-13 -1 8 255 217 165
-13 -2 9 255 217 165
-13 -3 10 255 217 165
-13 -14 -3 255 217 165
-13 -13 -4 255 217 165
-13 -12 -5 255 217 165
-14 -2 0 255 217 165
-14 -3 -1 255 217 165
-14 -4 -2 255 217 165
-14 -5 -3 255 217 165
-14 -6 -4 255 217 165
-14 -7 -5 255 217 165
-14 1 7 255 217 165
-14 0 8 255 217 165
-14 -1 9 255 217 165
-14 -2 10 255 217 165
-14 -14 -4 255 217 165
-14 -13 -5 255 217 165
-15 0 1 255 217 165
-15 -1 0 255 217 165
-15 -2 -1 255 217 165
-15 -3 -2 255 217 165
-15 -4 -3 255 217 165
-15 -5 -4 255 217 165
-15 -6 -5 255 217 165
-15 2 7 255 217 165
-15 1 8 255 217 165
-15 0 9 255 217 165
-15 -1 10 255 217 165
-15 -14 -5 255 217 165
-14 2 5 255 217 165
-15 3 5 255 217 165
-15 2 4 255 217 165
-15 2 6 255 217 165
-16 4 5 255 217 165
-16 3 4 255 217 165
-16 3 6 255 217 165
-16 2 3 255 217 165
-16 2 7 255 217 165
-16 1 2 255 217 165
-16 1 8 255 217 165
-17 0 2 255 217 165
-16 0 1 255 217 165
-16 0 9 174 202 48
-18 -1 2 255 217 165
-17 -1 1 255 217 165
-16 -1 0 255 217 165
-16 -1 10 174 202 48
-19 -2 2 174 202 48
-18 -2 1 255 217 165
-17 -2 0 255 217 165
-16 -2 -1 255 217 165
-19 -3 1 255 217 165
-18 -3 0 255 217 165
-17 -3 -1 255 217 165
-16 -3 -2 255 217 165
-19 -4 0 255 217 165
-18 -4 -1 255 217 165
-17 -4 -2 255 217 165
-16 -4 -3 255 217 165
-19 -5 -1 255 217 165
-18 -5 -2 255 217 165
-17 -5 -3 255 217 165
-16 -5 -4 255 217 165
-19 -6 -2 255 217 165
-18 -6 -3 255 217 165
-17 -6 -4 255 217 165
-16 -6 -5 255 217 165
-19 -7 -3 255 217 165
-18 -7 -4 255 217 165
-17 -7 -5 255 217 165
-19 -8 -4 255 217 165
-18 -8 -5 255 217 165
-19 -9 -5 255 217 165
-19 -14 -2 255 217 165
-19 -13 -3 255 217 165
-19 -12 -4 255 217 165
-19 -11 -5 255 217 165
-18 -14 -3 255 217 165
-18 -13 -4 255 217 165
-18 -12 -5 255 217 165
-17 -14 -4 255 217 165
-17 -13 -5 255 217 165
-16 -14 -5 255 217 165
-6 -4 5 255 217 165
-6 -5 4 255 217 165
-6 -5 6 255 217 165
-5 -6 4 255 217 165
-6 -6 3 255 217 165
-6 -6 7 255 217 165
-4 -7 4 255 217 165
-5 -7 3 255 217 165
-6 -7 2 255 217 165
-6 -7 8 255 217 165
-6 -8 1 255 217 165
-6 -8 9 92 109 23
-6 -9 0 255 217 165
-6 -9 10 255 217 165
-6 -13 2 174 202 48
-6 -12 1 174 202 48
-6 -11 0 255 217 165
-6 -10 -1 255 217 165
-7 -3 5 255 217 165
-7 -4 4 255 217 165
-7 -4 6 255 217 165
-7 -5 7 255 217 165
-7 -6 8 255 217 165
-7 -7 9 255 217 165
-7 -8 10 255 217 165
-7 -9 -1 255 217 165
-7 -14 2 174 202 48
-7 -13 1 255 217 165
-7 -12 0 255 217 165
-7 -11 -1 255 217 165
-7 -10 -2 255 217 165
-8 -2 5 255 217 165
-8 -3 4 255 217 165
-8 -3 6 255 217 165
-8 -4 7 255 217 165
-8 -5 8 255 217 165
-8 -6 9 255 217 165
-8 -7 10 255 217 165
-8 -8 -1 255 217 165
-8 -9 -2 255 217 165
-8 -14 1 255 217 165
-8 -13 0 255 217 165
-8 -12 -1 255 217 165
-8 -11 -2 255 217 165
-8 -10 -3 255 217 165
-10 -2 5 255 217 165
-10 -3 4 255 217 165
-10 -4 3 255 217 165
-10 -5 2 255 217 165
-9 -2 4 255 217 165
-9 -2 6 255 217 165
-9 -3 7 255 217 165
-9 -4 8 255 217 165
-9 -5 9 255 217 165
-9 -6 10 255 217 165
-9 -7 -1 255 217 165
-9 -8 -2 255 217 165
-9 -9 -3 255 217 165
-9 -14 0 255 217 165
-9 -13 -1 255 217 165
-9 -12 -2 255 217 165
-9 -11 -3 255 217 165
-9 -10 -4 255 217 165
-10 -5 0 255 217 165
-10 -6 -1 255 217 165
-10 -7 -2 255 217 165
-10 -8 -3 255 217 165
-10 -9 -4 255 217 165
-10 -2 7 255 217 165
-10 -3 8 255 217 165
-10 -4 9 255 217 165
-10 -5 10 255 217 165
-10 -14 -1 255 217 165
-10 -13 -2 255 217 165
-10 -12 -3 255 217 165
-10 -11 -4 255 217 165
-10 -10 -5 255 217 165
-11 -5 -1 255 217 165
-11 -6 -2 255 217 165
-11 -7 -3 255 217 165
-11 -8 -4 255 217 165
-11 -9 -5 255 217 165
-11 -2 4 255 217 165
-11 -2 8 255 217 165
-11 -3 3 255 217 165
-11 -3 9 255 217 165
-11 -4 2 255 217 165
-11 -4 10 255 217 165
-11 -14 -2 255 217 165
-11 -13 -3 255 217 165
-11 -12 -4 255 217 165
-11 -11 -5 255 217 165
-11 -4 0 255 217 165
-12 -3 0 255 217 165
-12 -4 -1 255 217 165
-12 -5 -2 255 217 165
-12 -6 -3 255 217 165
-12 -7 -4 255 217 165
-12 -8 -5 255 217 165
-12 -2 3 255 217 165
-12 -1 8 255 217 165
-12 -2 9 255 217 165
-12 -3 2 255 217 165
-12 -3 10 255 217 165
-12 -14 -3 255 217 165
-12 -13 -4 255 217 165
-12 -12 -5 255 217 165
-10 -4 1 255 217 165
-11 -3 1 255 217 165
-12 -2 1 255 217 165
-13 -1 1 255 217 165
-13 -2 0 255 217 165
-13 -3 -1 255 217 165
-13 -4 -2 255 217 165
-13 -5 -3 255 217 165
-13 -6 -4 255 217 165
-13 -7 -5 255 217 165
-13 1 7 255 217 165
-13 0 8 255 217 165
-13 -1 9 255 217 165
-13 -2 10 255 217 165
-13 -14 -4 255 217 165
-13 -13 -5 255 217 165
-14 -1 0 255 217 165
-14 -2 -1 255 217 165
-14 -3 -2 255 217 165
-14 -4 -3 255 217 165
-14 -5 -4 255 217 165
-14 -6 -5 255 217 165
-14 2 7 255 217 165
-14 1 8 255 217 165
-14 0 9 255 217 165
-14 -1 10 255 217 165
-14 -14 -5 255 217 165
-15 1 1 255 217 165
-15 0 0 255 217 165
-15 -1 -1 255 217 165
-15 -2 -2 255 217 165
-15 -3 -3 255 217 165
-15 -4 -4 255 217 165
-15 -5 -5 255 217 165
-15 3 7 255 217 165
-15 2 8 255 217 165
-15 1 9 255 217 165
-15 0 10 174 202 48
-13 2 5 255 217 165
-14 3 5 255 217 165
-14 2 4 255 217 165
-14 2 6 255 217 165
-15 4 5 255 217 165
-15 3 4 255 217 165
-15 3 6 255 217 165
-15 2 3 255 217 165
-16 5 5 255 217 165
-16 4 4 255 217 165
-16 4 6 255 217 165
-16 3 3 255 217 165
-16 3 7 255 217 165
-16 2 2 255 217 165
-16 2 8 255 217 165
-17 1 2 255 217 165
-16 1 1 255 217 165
-16 1 9 174 202 48
-18 0 2 255 217 165
-17 0 1 255 217 165
-16 0 0 255 217 165
-16 0 10 174 202 48
-19 -1 2 174 202 48
-18 -1 1 255 217 165
-17 -1 0 255 217 165
-16 -1 -1 255 217 165
-19 -2 1 255 217 165
-18 -2 0 255 217 165
-17 -2 -1 255 217 165
-16 -2 -2 255 217 165
-19 -3 0 255 217 165
-18 -3 -1 255 217 165
-17 -3 -2 255 217 165
-16 -3 -3 255 217 165
-19 -4 -1 255 217 165
-18 -4 -2 255 217 165
-17 -4 -3 255 217 165
-16 -4 -4 255 217 165
-19 -5 -2 255 217 165
-18 -5 -3 255 217 165
-17 -5 -4 255 217 165
-16 -5 -5 255 217 165
-19 -6 -3 255 217 165
-18 -6 -4 255 217 165
-17 -6 -5 255 217 165
-19 -7 -4 255 217 165
-18 -7 -5 255 217 165
-19 -8 -5 255 217 165
-19 -14 -3 255 217 165
-19 -13 -4 255 217 165
-19 -12 -5 255 217 165
-18 -14 -4 255 217 165
-18 -13 -5 255 217 165
-17 -14 -5 255 217 165
-6 -3 5 255 217 165
-6 -4 4 255 217 165
-6 -4 6 255 217 165
-5 -5 4 255 217 165
-6 -5 3 255 217 165
-6 -5 7 255 217 165
-4 -6 4 255 217 165
-5 -6 3 255 217 165
-6 -6 2 255 217 165
-6 -6 8 255 217 165
-3 -7 4 255 217 165
-4 -7 3 255 217 165
-5 -7 2 255 217 165
-6 -7 1 255 217 165
-6 -7 9 92 109 23
-6 -8 0 255 217 165
-6 -8 10 255 217 165
-6 -9 -1 255 217 165
-6 -14 2 174 202 48
-6 -13 1 174 202 48
-6 -12 0 255 217 165
-6 -11 -1 255 217 165
-6 -10 -2 255 217 165
-7 -2 5 255 217 165
-7 -3 4 255 217 165
-7 -3 6 255 217 165
-7 -4 7 255 217 165
-7 -5 8 255 217 165
-7 -6 9 255 217 165
-7 -7 10 255 217 165
-7 -8 -1 255 217 165
-7 -9 -2 255 217 165
-7 -14 1 255 217 165
-7 -13 0 255 217 165
-7 -12 -1 255 217 165
-7 -11 -2 255 217 165
-7 -10 -3 255 217 165
-8 -1 5 255 217 165
-8 -2 4 255 217 165
-8 -2 6 255 217 165
-8 -3 7 255 217 165
-8 -4 8 255 217 165
-8 -5 9 255 217 165
-8 -6 10 255 217 165
-8 -8 -2 255 217 165
-8 -9 -3 255 217 165
-8 -14 0 255 217 165
-8 -13 -1 255 217 165
-8 -12 -2 255 217 165
-8 -11 -3 255 217 165
-8 -10 -4 255 217 165
-10 -2 4 255 217 165
-10 -3 3 255 217 165
-10 -4 2 255 217 165
-9 -2 3 255 217 165
-9 -2 7 255 217 165
-9 -3 8 255 217 165
-9 -4 9 255 217 165
-9 -5 10 255 217 165
-9 -6 -1 255 217 165
-9 -7 -2 255 217 165
-9 -8 -3 255 217 165
-9 -9 -4 255 217 165
-9 -14 -1 255 217 165
-9 -13 -2 255 217 165
-9 -12 -3 255 217 165
-9 -11 -4 255 217 165
-9 -10 -5 255 217 165
-10 -4 0 255 217 165
-10 -5 -1 255 217 165
-10 -6 -2 255 217 165
-10 -7 -3 255 217 165
-10 -8 -4 255 217 165
-10 -9 -5 255 217 165
-10 -2 8 255 217 165
-10 -3 9 255 217 165
-10 -4 10 255 217 165
-10 -14 -2 255 217 165
-10 -13 -3 255 217 165
-10 -12 -4 255 217 165
-10 -11 -5 255 217 165
-11 -4 -1 255 217 165
-11 -5 -2 255 217 165
-11 -6 -3 255 217 165
-11 -7 -4 255 217 165
-11 -8 -5 255 217 165
-11 -2 3 255 217 165
-11 -1 8 255 217 165
-11 -2 9 255 217 165
-11 -3 2 255 217 165
-11 -3 10 255 217 165
-11 -14 -3 255 217 165
-11 -13 -4 255 217 165
-11 -12 -5 255 217 165
-11 -3 0 255 217 165
-12 -2 0 255 217 165
-12 -3 -1 255 217 165
-12 -4 -2 255 217 165
-12 -5 -3 255 217 165
-12 -6 -4 255 217 165
-12 -7 -5 255 217 165
-12 -2 2 255 217 165
-12 0 8 255 217 165
-12 -1 9 255 217 165
-12 -2 10 255 217 165
-12 -14 -4 255 217 165
-12 -13 -5 255 217 165
-10 -3 1 255 217 165
-11 -2 1 255 217 165
-12 -1 1 255 217 165
-13 0 1 255 217 165
-13 -1 0 255 217 165
-13 -2 -1 255 217 165
-13 -3 -2 255 217 165
-13 -4 -3 255 217 165
-13 -5 -4 255 217 165
-13 -6 -5 255 217 165
-13 2 7 255 217 165
-13 1 8 255 217 165
-13 0 9 255 217 165
-13 -1 10 255 217 165
-13 -14 -5 255 217 165
-14 0 0 255 217 165
-14 -1 -1 255 217 165
-14 -2 -2 255 217 165
-14 -3 -3 255 217 165
-14 -4 -4 255 217 165
-14 -5 -5 255 217 165
-14 3 7 255 217 165
-14 2 8 255 217 165
-14 1 9 255 217 165
-14 0 10 255 217 165
-14 1 1 255 217 165
-15 2 1 255 217 165
-15 1 0 255 217 165
-15 0 -1 255 217 165
-15 -1 -2 255 217 165
-15 -2 -3 255 217 165
-15 -3 -4 255 217 165
-15 -4 -5 255 217 165
-15 4 7 255 217 165
-15 3 8 255 217 165
-15 2 9 255 217 165
-15 1 10 174 202 48
-12 2 5 255 217 165
-13 3 5 255 217 165
-13 2 4 255 217 165
-13 2 6 255 217 165
-14 4 5 255 217 165
-14 3 4 255 217 165
-14 3 6 255 217 165
-14 2 3 255 217 165
-15 5 5 255 217 165
-15 4 4 255 217 165
-15 4 6 255 217 165
-15 3 3 255 217 165
-15 2 2 255 217 165
-16 5 4 255 217 165
-16 5 6 255 217 165
-16 4 3 255 217 165
-16 4 7 255 217 165
-16 3 2 255 217 165
-16 3 8 255 217 165
-17 2 2 255 217 165
-16 2 1 255 217 165
-16 2 9 255 217 165
-18 1 2 255 217 165
-17 1 1 255 217 165
-16 1 0 255 217 165
-16 1 10 174 202 48
-19 0 2 174 202 48
-18 0 1 255 217 165
-17 0 0 255 217 165
-16 0 -1 255 217 165
-19 -1 1 255 217 165
-18 -1 0 255 217 165
-17 -1 -1 255 217 165
-16 -1 -2 255 217 165
-19 -2 0 255 217 165
-18 -2 -1 255 217 165
-17 -2 -2 255 217 165
-16 -2 -3 255 217 165
-19 -3 -1 255 217 165
-18 -3 -2 255 217 165
-17 -3 -3 255 217 165
-16 -3 -4 255 217 165
-19 -4 -2 255 217 165
-18 -4 -3 255 217 165
-17 -4 -4 255 217 165
-16 -4 -5 255 217 165
-19 -5 -3 255 217 165
-18 -5 -4 255 217 165
-17 -5 -5 255 217 165
-19 -6 -4 255 217 165
-18 -6 -5 255 217 165
-19 -7 -5 255 217 165
-19 -14 -4 255 217 165
-19 -13 -5 255 217 165
-18 -14 -5 255 217 165
-6 -2 5 255 217 165
-6 -3 4 255 217 165
-6 -3 6 255 217 165
-5 -4 4 255 217 165
-6 -4 3 255 217 165
-6 -4 7 255 217 165
-4 -5 4 255 217 165
-5 -5 3 255 217 165
-6 -5 8 255 217 165
-3 -6 4 255 217 165
-4 -6 3 255 217 165
-5 -6 2 255 217 165
-6 -6 1 255 217 165
-6 -6 9 92 109 23
-2 -7 4 255 217 165
-3 -7 3 255 217 165
-4 -7 2 255 217 165
-5 -7 1 255 217 165
-6 -7 0 255 217 165
-6 -7 10 255 217 165
-6 -8 -1 255 217 165
-6 -9 -2 255 217 165
-6 -14 1 255 217 165
-6 -13 0 255 217 165
-6 -12 -1 255 217 165
-6 -11 -2 255 217 165
-6 -10 -3 255 217 165
-7 -1 5 255 217 165
-7 -2 4 255 217 165
-7 -2 6 255 217 165
-7 -3 7 255 217 165
-7 -4 8 255 217 165
-7 -5 9 255 217 165
-7 -6 10 255 217 165
-7 -7 -1 255 217 165
-7 -8 -2 255 217 165
-7 -9 -3 255 217 165
-7 -14 0 255 217 165
-7 -13 -1 255 217 165
-7 -12 -2 255 217 165
-7 -11 -3 255 217 165
-7 -10 -4 255 217 165
-8 0 5 255 217 165
-8 -1 4 255 217 165
-8 -1 6 255 217 165
-8 -2 3 255 217 165
-8 -2 7 255 217 165
-8 -3 8 255 217 165
-8 -4 9 255 217 165
-8 -5 10 255 217 165
-8 -7 -2 255 217 165
-8 -8 -3 255 217 165
-8 -9 -4 255 217 165
-8 -14 -1 255 217 165
-8 -13 -2 255 217 165
-8 -12 -3 255 217 165
-8 -11 -4 255 217 165
-8 -10 -5 255 217 165
-10 -2 3 255 217 165
-10 -3 2 255 217 165
-9 -2 2 255 217 165
-9 -2 8 255 217 165
-9 -3 9 255 217 165
-9 -4 10 255 217 165
-8 -6 -1 255 217 165
-9 -6 -2 255 217 165
-9 -7 -3 255 217 165
-9 -8 -4 255 217 165
-9 -9 -5 255 217 165
-9 -14 -2 255 217 165
-9 -13 -3 255 217 165
-9 -12 -4 255 217 165
-9 -11 -5 255 217 165
-10 -3 0 255 217 165
-10 -4 -1 255 217 165
-10 -5 -2 255 217 165
-10 -6 -3 255 217 165
-10 -7 -4 255 217 165
-10 -8 -5 255 217 165
-10 -1 8 255 217 165
-10 -2 9 255 217 165
-10 -3 10 255 217 165
-10 -14 -3 255 217 165
-10 -13 -4 255 217 165
-10 -12 -5 255 217 165
-11 -3 -1 255 217 165
-11 -4 -2 255 217 165
-11 -5 -3 255 217 165
-11 -6 -4 255 217 165
-11 -7 -5 255 217 165
-11 -2 2 255 217 165
-11 0 8 255 217 165
-11 -1 9 255 217 165
-11 -2 10 255 217 165
-11 -14 -4 255 217 165
-11 -13 -5 255 217 165
-11 -2 0 255 217 165
-12 -1 0 255 217 165
-12 -2 -1 255 217 165
-12 -3 -2 255 217 165
-12 -4 -3 255 217 165
-12 -5 -4 255 217 165
-12 -6 -5 255 217 165
-12 -1 2 255 217 165
-12 1 8 255 217 165
-12 0 9 255 217 165
-12 -1 10 255 217 165
-12 -14 -5 255 217 165
-10 -2 1 255 217 165
-11 -1 1 255 217 165
-12 0 1 255 217 165
-13 1 1 255 217 165
-13 0 0 255 217 165
-13 -1 -1 255 217 165
-13 -2 -2 255 217 165
-13 -3 -3 255 217 165
-13 -4 -4 255 217 165
-13 -5 -5 255 217 165
-12 2 7 255 217 165
-13 3 7 255 217 165
-13 2 8 255 217 165
-13 1 9 255 217 165
-13 0 10 255 217 165
-14 1 0 255 217 165
-14 0 -1 255 217 165
-14 -1 -2 255 217 165
-14 -2 -3 255 217 165
-14 -3 -4 255 217 165
-14 -4 -5 255 217 165
-14 4 7 255 217 165
-14 3 8 255 217 165
-14 2 9 255 217 165
-14 1 10 174 202 48
-14 2 1 255 217 165
-15 3 1 255 217 165
-15 2 0 255 217 165
-15 1 -1 255 217 165
-15 0 -2 255 217 165
-15 -1 -3 255 217 165
-15 -2 -4 255 217 165
-15 -3 -5 255 217 165
-15 5 7 255 217 165
-15 4 8 255 217 165
-15 3 9 255 217 165
-15 2 10 174 202 48
-12 3 5 255 217 165
-12 2 4 255 217 165
-12 2 6 255 217 165
-13 4 5 255 217 165
-13 3 4 255 217 165
-13 3 6 255 217 165
-13 2 3 255 217 165
-14 5 5 255 217 165
-14 4 4 255 217 165
-14 4 6 255 217 165
-14 3 3 255 217 165
-14 2 2 255 217 165
-15 6 5 255 217 165
-15 5 4 255 217 165
-15 5 6 255 217 165
-15 4 3 255 217 165
-15 3 2 255 217 165
-16 5 3 255 217 165
-16 4 2 255 217 165
-17 3 2 255 217 165
-16 3 1 255 217 165
-16 3 9 255 217 165
-18 2 2 255 217 165
-17 2 1 255 217 165
-16 2 0 255 217 165
-16 2 10 174 202 48
-19 1 2 174 202 48
-18 1 1 255 217 165
-17 1 0 255 217 165
-16 1 -1 255 217 165
-19 0 1 255 217 165
-18 0 0 255 217 165
-17 0 -1 255 217 165
-16 0 -2 255 217 165
-19 -1 0 255 217 165
-18 -1 -1 255 217 165
-17 -1 -2 255 217 165
-16 -1 -3 255 217 165
-19 -2 -1 255 217 165
-18 -2 -2 255 217 165
-17 -2 -3 255 217 165
-16 -2 -4 255 217 165
-19 -3 -2 255 217 165
-18 -3 -3 255 217 165
-17 -3 -4 255 217 165
-16 -3 -5 255 217 165
-19 -4 -3 255 217 165
-18 -4 -4 255 217 165
-17 -4 -5 255 217 165
-19 -5 -4 255 217 165
-18 -5 -5 255 217 165
-19 -6 -5 255 217 165
-19 -14 -5 255 217 165
-6 -1 5 255 217 165
-6 -2 4 255 217 165
-6 -2 6 255 217 165
-5 -3 4 255 217 165
-6 -3 3 255 217 165
-6 -3 7 255 217 165
-4 -4 4 255 217 165
-5 -4 3 255 217 165
-6 -4 8 255 217 165
-3 -5 4 255 217 165
-4 -5 3 255 217 165
-6 -5 9 92 109 23
-2 -6 4 255 217 165
-3 -6 3 255 217 165
-4 -6 2 255 217 165
-5 -6 1 255 217 165
-6 -6 0 255 217 165
-6 -6 10 255 217 165
-1 -7 4 255 217 165
-2 -7 3 255 217 165
-3 -7 2 255 217 165
-4 -7 1 255 217 165
-5 -7 0 255 217 165
-6 -7 -1 255 217 165
-6 -8 -2 255 217 165
-6 -9 -3 255 217 165
-6 -14 0 255 217 165
-6 -13 -1 255 217 165
-6 -12 -2 255 217 165
-6 -11 -3 255 217 165
-6 -10 -4 255 217 165
-7 0 5 255 217 165
-7 -1 4 255 217 165
-7 -1 6 255 217 165
-7 -2 3 255 217 165
-7 -2 7 255 217 165
-7 -3 8 255 217 165
-7 -4 9 255 217 165
-7 -5 10 255 217 165
-7 -6 -1 255 217 165
-7 -7 -2 255 217 165
-7 -8 -3 255 217 165
-7 -9 -4 255 217 165
-7 -14 -1 255 217 165
-7 -13 -2 255 217 165
-7 -12 -3 255 217 165
-7 -11 -4 255 217 165
-7 -10 -5 255 217 165
-8 1 5 255 217 165
-8 0 4 255 217 165
-8 0 6 255 217 165
-8 -1 3 255 217 165
-8 -1 7 255 217 165
-8 -2 2 255 217 165
-8 -2 8 255 217 165
-8 -3 9 255 217 165
-8 -4 10 255 217 165
-8 -6 -2 255 217 165
-8 -7 -3 255 217 165
-8 -8 -4 255 217 165
-8 -9 -5 255 217 165
-8 -14 -2 255 217 165
-8 -13 -3 255 217 165
-8 -12 -4 255 217 165
-8 -11 -5 255 217 165
-10 -2 2 255 217 165
-9 -1 2 255 217 165
-9 -2 1 255 217 165
-9 -1 8 255 217 165
-9 -2 9 255 217 165
-9 -3 10 255 217 165
-9 -5 -2 255 217 165
-9 -6 -3 255 217 165
-9 -7 -4 255 217 165
-9 -8 -5 255 217 165
-9 -14 -3 255 217 165
-9 -13 -4 255 217 165
-9 -12 -5 255 217 165
-10 -2 0 255 217 165
-10 -3 -1 255 217 165
-10 -4 -2 255 217 165
-10 -5 -3 255 217 165
-10 -6 -4 255 217 165
-10 -7 -5 255 217 165
-10 0 8 255 217 165
-10 -1 9 255 217 165
-10 -2 10 255 217 165
-10 -14 -4 255 217 165
-10 -13 -5 255 217 165
-11 -2 -1 255 217 165
-11 -3 -2 255 217 165
-11 -4 -3 255 217 165
-11 -5 -4 255 217 165
-11 -6 -5 255 217 165
-11 -1 2 255 217 165
-11 1 8 255 217 165
-11 0 9 255 217 165
-11 -1 10 255 217 165
-11 -14 -5 255 217 165
-11 -1 0 255 217 165
-12 0 0 255 217 165
-12 -1 -1 255 217 165
-12 -2 -2 255 217 165
-12 -3 -3 255 217 165
-12 -4 -4 255 217 165
-12 -5 -5 255 217 165
-12 0 2 255 217 165
-12 2 8 255 217 165
-12 1 9 255 217 165
-12 0 10 255 217 165
-10 -1 1 255 217 165
-11 0 1 255 217 165
-12 1 1 255 217 165
-13 2 1 255 217 165
-13 1 0 255 217 165
-13 0 -1 255 217 165
-13 -1 -2 255 217 165
-13 -2 -3 255 217 165
-13 -3 -4 255 217 165
-13 -4 -5 255 217 165
-12 3 7 255 217 165
-13 4 7 255 217 165
-13 3 8 255 217 165
-13 2 9 255 217 165
-13 1 10 255 217 165
-14 2 0 255 217 165
-14 1 -1 255 217 165
-14 0 -2 255 217 165
-14 -1 -3 255 217 165
-14 -2 -4 255 217 165
-14 -3 -5 255 217 165
-14 5 7 255 217 165
-14 4 8 255 217 165
-14 3 9 255 217 165
-14 2 10 174 202 48
-14 3 1 255 217 165
-15 4 1 255 217 165
-15 3 0 255 217 165
-15 2 -1 255 217 165
-15 1 -2 255 217 165
-15 0 -3 255 217 165
-15 -1 -4 255 217 165
-15 -2 -5 255 217 165
-15 6 7 255 217 165
-15 5 8 255 217 165
-15 4 9 255 217 165
-15 3 10 174 202 48
-12 4 5 255 217 165
-12 3 4 255 217 165
-12 3 6 255 217 165
-12 2 3 255 217 165
-13 5 5 255 217 165
-13 4 4 255 217 165
-13 4 6 255 217 165
-13 3 3 255 217 165
-13 2 2 255 217 165
-14 6 5 255 217 165
-14 5 4 255 217 165
-14 5 6 255 217 165
-14 4 3 255 217 165
-14 3 2 255 217 165
-15 6 4 255 217 165
-15 6 6 255 217 165
-15 5 3 255 217 165
-15 4 2 255 217 165
-16 5 2 255 217 165
-17 4 2 255 217 165
-16 4 1 255 217 165
-18 3 2 255 217 165
-17 3 1 255 217 165
-16 3 0 255 217 165
-16 4 9 255 217 165
-16 3 10 174 202 48
-19 2 2 174 202 48
-18 2 1 255 217 165
-17 2 0 255 217 165
-16 2 -1 255 217 165
-19 1 1 255 217 165
-18 1 0 255 217 165
-17 1 -1 255 217 165
-16 1 -2 255 217 165
-19 0 0 255 217 165
-18 0 -1 255 217 165
-17 0 -2 255 217 165
-16 0 -3 255 217 165
-19 -1 -1 255 217 165
-18 -1 -2 255 217 165
-17 -1 -3 255 217 165
-16 -1 -4 255 217 165
-19 -2 -2 255 217 165
-18 -2 -3 255 217 165
-17 -2 -4 255 217 165
-16 -2 -5 255 217 165
-19 -3 -3 255 217 165
-18 -3 -4 255 217 165
-17 -3 -5 255 217 165
-19 -4 -4 255 217 165
-18 -4 -5 255 217 165
-19 -5 -5 255 217 165
-6 0 5 255 217 165
-6 -1 4 255 217 165
-6 -1 6 255 217 165
-5 -2 4 255 217 165
-6 -2 3 255 217 165
-6 -2 7 255 217 165
-4 -3 4 255 217 165
-5 -3 3 255 217 165
-6 -3 8 255 217 165
-3 -4 4 255 217 165
-4 -4 3 255 217 165
-6 -4 9 92 109 23
-2 -5 4 255 217 165
-3 -5 3 255 217 165
-6 -5 10 92 109 23
-1 -6 4 255 217 165
-2 -6 3 255 217 165
-3 -6 2 255 217 165
-4 -6 1 255 217 165
-5 -6 0 255 217 165
-6 -6 -1 255 217 165
0 -7 4 255 217 165
-1 -7 3 255 217 165
-2 -7 2 255 217 165
-3 -7 1 255 217 165
-4 -7 0 255 217 165
-5 -7 -1 255 217 165
-6 -7 -2 255 217 165
-6 -8 -3 255 217 165
-6 -9 -4 255 217 165
-6 -14 -1 255 217 165
-6 -13 -2 255 217 165
-6 -12 -3 255 217 165
-6 -11 -4 255 217 165
-6 -10 -5 255 217 165
-7 1 5 255 217 165
-7 0 4 255 217 165
-7 0 6 255 217 165
-7 -1 3 255 217 165
-7 -1 7 255 217 165
-7 -2 2 255 217 165
-7 -2 8 255 217 165
-7 -3 9 255 217 165
-7 -4 10 255 217 165
-7 -6 -2 255 217 165
-7 -7 -3 255 217 165
-7 -8 -4 255 217 165
-7 -9 -5 255 217 165
-7 -14 -2 255 217 165
-7 -13 -3 255 217 165
-7 -12 -4 255 217 165
-7 -11 -5 255 217 165
-8 2 5 255 217 165
-8 1 4 255 217 165
-8 1 6 255 217 165
-8 0 3 255 217 165
-8 0 7 255 217 165
-8 -1 2 255 217 165
-8 -1 8 255 217 165
-8 -2 1 255 217 165
-8 -2 9 255 217 165
-8 -3 10 255 217 165
-8 -5 -2 255 217 165
-8 -6 -3 255 217 165
-8 -7 -4 255 217 165
-8 -8 -5 255 217 165
-8 -14 -3 255 217 165
-8 -13 -4 255 217 165
-8 -12 -5 255 217 165
-10 -1 2 255 217 165
-9 0 2 255 217 165
-9 -1 1 255 217 165
-9 -2 0 255 217 165
-9 0 8 255 217 165
-9 -1 9 255 217 165
-9 -2 10 255 217 165
-9 -4 -2 255 217 165
-9 -5 -3 255 217 165
-9 -6 -4 255 217 165
-9 -7 -5 255 217 165
-9 -14 -4 255 217 165
-9 -13 -5 255 217 165
-10 -1 0 255 217 165
-10 -2 -1 255 217 165
-10 -3 -2 255 217 165
-10 -4 -3 255 217 165
-10 -5 -4 255 217 165
-10 -6 -5 255 217 165
-10 1 8 255 217 165
-10 0 9 255 217 165
-10 -1 10 255 217 165
-10 -14 -5 255 217 165
-11 -1 -1 255 217 165
-11 -2 -2 255 217 165
-11 -3 -3 255 217 165
-11 -4 -4 255 217 165
-11 -5 -5 255 217 165
-11 2 8 255 217 165
-11 1 9 255 217 165
-11 0 10 255 217 165
-11 0 0 255 217 165
-12 1 0 255 217 165
-12 0 -1 255 217 165
-12 -1 -2 255 217 165
-12 -2 -3 255 217 165
-12 -3 -4 255 217 165
-12 -4 -5 255 217 165
-12 1 2 255 217 165
-12 3 8 255 217 165
-12 2 9 255 217 165
-12 1 10 255 217 165
-10 0 1 255 217 165
-12 2 1 255 217 165
-13 3 1 255 217 165
-13 2 0 255 217 165
-13 1 -1 255 217 165
-13 0 -2 255 217 165
-13 -1 -3 255 217 165
-13 -2 -4 255 217 165
-13 -3 -5 255 217 165
-12 4 7 255 217 165
-13 5 7 255 217 165
-13 4 8 255 217 165
-13 3 9 255 217 165
-13 2 10 255 217 165
-14 3 0 255 217 165
-14 2 -1 255 217 165
-14 1 -2 255 217 165
-14 0 -3 255 217 165
-14 -1 -4 255 217 165
-14 -2 -5 255 217 165
-14 6 7 255 217 165
-14 5 8 255 217 165
-14 4 9 255 217 165
-14 3 10 255 217 165
-14 4 1 255 217 165
-15 5 1 255 217 165
-15 4 0 255 217 165
-15 3 -1 255 217 165
-15 2 -2 255 217 165
-15 1 -3 255 217 165
-15 0 -4 255 217 165
-15 -1 -5 255 217 165
-15 7 7 255 217 165
-15 6 8 255 217 165
-16 5 8 174 202 48
-15 5 9 255 217 165
-15 4 10 174 202 48
-12 5 5 255 217 165
-12 4 4 255 217 165
-12 4 6 255 217 165
-12 3 3 255 217 165
-12 2 2 255 217 165
-13 6 5 255 217 165
-13 5 4 255 217 165
-13 5 6 255 217 165
-13 4 3 255 217 165
-13 3 2 255 217 165
-14 6 4 255 217 165
-14 6 6 255 217 165
-14 5 3 255 217 165
-14 4 2 255 217 165
-15 6 3 255 217 165
-15 5 2 255 217 165
-17 5 2 255 217 165
-16 6 2 255 217 165
-16 5 1 255 217 165
-18 4 2 255 217 165
-17 4 1 255 217 165
-16 4 0 255 217 165
-19 3 2 174 202 48
-18 3 1 255 217 165
-17 3 0 255 217 165
-16 3 -1 255 217 165
-16 5 9 174 202 48
-16 4 10 174 202 48
-19 2 1 255 217 165
-18 2 0 255 217 165
-17 2 -1 255 217 165
-16 2 -2 255 217 165
-19 1 0 255 217 165
-18 1 -1 255 217 165
-17 1 -2 255 217 165
-16 1 -3 255 217 165
-19 0 -1 255 217 165
-18 0 -2 255 217 165
-17 0 -3 255 217 165
-16 0 -4 255 217 165
-19 -1 -2 255 217 165
-18 -1 -3 255 217 165
-17 -1 -4 255 217 165
-16 -1 -5 255 217 165
-19 -2 -3 255 217 165
-18 -2 -4 255 217 165
-17 -2 -5 255 217 165
-19 -3 -4 255 217 165
-18 -3 -5 255 217 165
-19 -4 -5 255 217 165
-6 1 5 255 217 165
-6 0 4 255 217 165
-6 0 6 255 217 165
-5 -1 4 255 217 165
-6 -1 3 255 217 165
-6 -1 7 255 217 165
-4 -2 4 255 217 165
-5 -2 3 255 217 165
-6 -2 2 255 217 165
-6 -2 8 255 217 165
-3 -3 4 255 217 165
-4 -3 3 255 217 165
-6 -3 9 92 109 23
-2 -4 4 255 217 165
-3 -4 3 255 217 165
-6 -4 10 255 217 165
-1 -5 4 255 217 165
-2 -5 3 255 217 165
-3 -5 2 255 217 165
0 -6 4 255 217 165
-2 -6 2 255 217 165
-3 -6 1 255 217 165
-4 -6 0 255 217 165
-5 -6 -1 255 217 165
-6 -6 -2 255 217 165
1 -7 4 255 217 165
0 -7 3 255 217 165
-1 -7 2 255 217 165
-2 -7 1 255 217 165
-3 -7 0 255 217 165
-4 -7 -1 255 217 165
-5 -7 -2 255 217 165
-6 -7 -3 255 217 165
-6 -8 -4 255 217 165
-6 -9 -5 255 217 165
-6 -14 -2 255 217 165
-6 -13 -3 255 217 165
-6 -12 -4 255 217 165
-6 -11 -5 255 217 165
-7 2 5 255 217 165
-7 1 4 255 217 165
-7 1 6 255 217 165
-7 0 3 255 217 165
-7 0 7 255 217 165
-7 -1 2 255 217 165
-7 -1 8 255 217 165
-7 -2 1 255 217 165
-7 -2 9 255 217 165
-7 -3 10 255 217 165
-7 -5 -2 255 217 165
-7 -6 -3 255 217 165
-7 -7 -4 255 217 165
-7 -8 -5 255 217 165
-7 -14 -3 255 217 165
-7 -13 -4 255 217 165
-7 -12 -5 255 217 165
-8 3 5 255 217 165
-8 2 4 255 217 165
-8 2 6 255 217 165
-8 1 3 255 217 165
-8 1 7 255 217 165
-8 0 2 255 217 165
-8 0 8 255 217 165
-8 -1 1 255 217 165
-8 -1 9 255 217 165
-8 -2 0 255 217 165
-8 -2 10 255 217 165
-8 -5 -3 255 217 165
-8 -6 -4 255 217 165
-8 -7 -5 255 217 165
-8 -14 -4 255 217 165
-8 -13 -5 255 217 165
-9 1 2 255 217 165
-9 0 1 255 217 165
-9 -1 0 255 217 165
-9 -2 -1 255 217 165
-9 1 8 255 217 165
-9 0 9 255 217 165
-9 -1 10 255 217 165
-9 -3 -2 255 217 165
-9 -4 -3 255 217 165
-9 -5 -4 255 217 165
-9 -6 -5 255 217 165
-9 -14 -5 255 217 165
-10 0 0 255 217 165
-10 -1 -1 255 217 165
-10 -2 -2 255 217 165
-10 -3 -3 255 217 165
-10 -4 -4 255 217 165
-10 -5 -5 255 217 165
-10 2 8 255 217 165
-10 1 9 255 217 165
-10 0 10 255 217 165
-11 0 -1 255 217 165
-11 -1 -2 255 217 165
-11 -2 -3 255 217 165
-11 -3 -4 255 217 165
-11 -4 -5 255 217 165
-11 3 8 255 217 165
-11 2 9 255 217 165
-11 1 10 255 217 165
-12 2 0 255 217 165
-12 0 -2 255 217 165
-12 -1 -3 255 217 165
-12 -2 -4 255 217 165
-12 -3 -5 255 217 165
-11 1 2 255 217 165
-12 4 8 255 217 165
-12 3 9 255 217 165
-12 2 10 255 217 165
-12 3 1 255 217 165
-13 4 1 255 217 165
-13 3 0 255 217 165
-13 2 -1 255 217 165
-13 1 -2 255 217 165
-13 0 -3 255 217 165
-13 -1 -4 255 217 165
-13 -2 -5 255 217 165
-12 5 7 255 217 165
-13 6 7 255 217 165
-13 5 8 255 217 165
-13 4 9 255 217 165
-13 3 10 255 217 165
-14 4 0 255 217 165
-14 3 -1 255 217 165
-14 2 -2 255 217 165
-14 1 -3 255 217 165
-14 0 -4 255 217 165
-14 -1 -5 255 217 165
-14 7 7 255 217 165
-14 6 8 255 217 165
-14 5 9 255 217 165
-14 4 10 255 217 165
-14 5 1 255 217 165
-15 6 1 255 217 165
-15 5 0 255 217 165
-15 4 -1 255 217 165
-15 3 -2 255 217 165
-15 2 -3 255 217 165
-15 1 -4 255 217 165
-15 0 -5 255 217 165
-15 8 7 255 217 165
-15 7 8 255 217 165
-15 6 9 255 217 165
-15 5 10 174 202 48
-12 6 5 255 217 165
-12 5 4 255 217 165
-12 5 6 255 217 165
-12 4 3 255 217 165
-12 3 2 255 217 165
-11 2 2 255 217 165
-13 6 4 255 217 165
-13 6 6 255 217 165
-13 5 3 255 217 165
-13 4 2 255 217 165
-14 6 3 255 217 165
-14 5 2 255 217 165
-15 6 2 255 217 165
-18 5 2 255 217 165
-17 6 2 255 217 165
-17 5 1 255 217 165
-16 7 2 255 217 165
-16 6 1 255 217 165
-16 5 0 255 217 165
-19 4 2 174 202 48
-18 4 1 255 217 165
-17 4 0 255 217 165
-16 4 -1 255 217 165
-19 3 1 255 217 165
-18 3 0 255 217 165
-17 3 -1 255 217 165
-16 3 -2 255 217 165
-16 6 9 174 202 48
-16 5 10 174 202 48
-19 2 0 255 217 165
-18 2 -1 255 217 165
-17 2 -2 255 217 165
-16 2 -3 255 217 165
-19 1 -1 255 217 165
-18 1 -2 255 217 165
-17 1 -3 255 217 165
-16 1 -4 255 217 165
-19 0 -2 255 217 165
-18 0 -3 255 217 165
-17 0 -4 255 217 165
-16 0 -5 255 217 165
-19 -1 -3 255 217 165
-18 -1 -4 255 217 165
-17 -1 -5 255 217 165
-19 -2 -4 255 217 165
-18 -2 -5 255 217 165
-19 -3 -5 255 217 165
-6 2 5 255 217 165
-6 1 4 255 217 165
-6 1 6 255 217 165
-5 0 4 255 217 165
-6 0 3 255 217 165
-6 0 7 255 217 165
-4 -1 4 255 217 165
-5 -1 3 255 217 165
-6 -1 2 255 217 165
-6 -1 8 255 217 165
-3 -2 4 255 217 165
-4 -2 3 255 217 165
-5 -2 2 255 217 165
-6 -2 9 255 217 165
-2 -3 4 255 217 165
-3 -3 3 255 217 165
-6 -3 10 92 109 23
-1 -4 4 255 217 165
-2 -4 3 255 217 165
-3 -4 2 255 217 165
0 -5 4 255 217 165
-2 -5 2 255 217 165
-3 -5 1 255 217 165
1 -6 4 255 217 165
-2 -6 1 255 217 165
-3 -6 0 255 217 165
-4 -6 -1 255 217 165
-5 -6 -2 255 217 165
-6 -6 -3 255 217 165
2 -7 4 255 217 165
1 -7 3 255 217 165
0 -7 2 255 217 165
-1 -7 1 255 217 165
-2 -7 0 255 217 165
-3 -7 -1 255 217 165
-4 -7 -2 255 217 165
-5 -7 -3 255 217 165
-6 -7 -4 255 217 165
-6 -8 -5 255 217 165
-6 -14 -3 255 217 165
-6 -13 -4 255 217 165
-6 -12 -5 255 217 165
-7 3 5 255 217 165
-7 2 4 255 217 165
-7 2 6 255 217 165
-7 1 3 255 217 165
-7 1 7 255 217 165
-7 0 2 255 217 165
-7 0 8 255 217 165
-7 -1 1 255 217 165
-7 -1 9 255 217 165
-7 -2 0 255 217 165
-7 -2 10 255 217 165
-7 -4 -2 255 217 165
-7 -5 -3 255 217 165
-7 -6 -4 255 217 165
-7 -7 -5 255 217 165
-7 -14 -4 255 217 165
-7 -13 -5 255 217 165
-8 4 5 255 217 165
-8 3 4 255 217 165
-8 3 6 255 217 165
-8 2 3 255 217 165
-8 2 7 255 217 165
-8 1 2 255 217 165
-8 1 8 255 217 165
-8 0 1 255 217 165
-8 0 9 255 217 165
-8 -1 0 255 217 165
-8 -1 10 255 217 165
-8 -2 -1 255 217 165
-8 -4 -3 255 217 165
-8 -5 -4 255 217 165
-8 -6 -5 255 217 165
-8 -14 -5 255 217 165
-9 2 2 255 217 165
-9 0 0 255 217 165
-9 -1 -1 255 217 165
-9 -2 -2 255 217 165
-9 2 8 255 217 165
-9 1 9 255 217 165
-9 0 10 255 217 165
-8 -3 -2 255 217 165
-9 -3 -3 255 217 165
-9 -4 -4 255 217 165
-9 -5 -5 255 217 165
-10 0 -1 255 217 165
-10 -1 -2 255 217 165
-10 -2 -3 255 217 165
-10 -3 -4 255 217 165
-10 -4 -5 255 217 165
-10 3 8 255 217 165
-10 2 9 255 217 165
-10 1 10 255 217 165
-11 0 -2 255 217 165
-11 -1 -3 255 217 165
-11 -2 -4 255 217 165
-11 -3 -5 255 217 165
-11 4 8 255 217 165
-11 3 9 255 217 165
-11 2 10 255 217 165
-12 3 0 255 217 165
-12 0 -3 255 217 165
-12 -1 -4 255 217 165
-12 -2 -5 255 217 165
-12 5 8 255 217 165
-12 4 9 255 217 165
-12 3 10 255 217 165
-12 4 1 255 217 165
-13 5 1 255 217 165
-13 4 0 255 217 165
-13 3 -1 255 217 165
-13 2 -2 255 217 165
-13 1 -3 255 217 165
-13 0 -4 255 217 165
-13 -1 -5 255 217 165
-12 6 7 255 217 165
-13 7 7 255 217 165
-13 6 8 255 217 165
-13 5 9 255 217 165
-13 4 10 255 217 165
-14 5 0 255 217 165
-14 4 -1 255 217 165
-14 3 -2 255 217 165
-14 2 -3 255 217 165
-14 1 -4 255 217 165
-14 0 -5 255 217 165
-14 8 7 255 217 165
-14 7 8 255 217 165
-14 6 9 255 217 165
-14 5 10 255 217 165
-14 6 1 255 217 165
-15 7 1 255 217 165
-15 6 0 255 217 165
-15 5 -1 255 217 165
-15 4 -2 255 217 165
-15 3 -3 255 217 165
-15 2 -4 255 217 165
-15 1 -5 255 217 165
-15 9 7 255 217 165
-15 8 8 255 217 165
-15 7 9 255 217 165
-15 6 10 255 217 165
-12 6 4 255 217 165
-12 6 6 255 217 165
-12 5 3 255 217 165
-12 4 2 255 217 165
-11 3 2 255 217 165
-10 2 2 255 217 165
-13 6 3 255 217 165
-13 5 2 255 217 165
-14 6 2 255 217 165
-15 7 2 255 217 165
-19 5 2 174 202 48
-18 6 2 255 217 165
-18 5 1 255 217 165
-17 7 2 255 217 165
-17 6 1 255 217 165
-17 5 0 255 217 165
-16 8 2 255 217 165
-16 7 1 255 217 165
-16 6 0 255 217 165
-16 5 -1 255 217 165
-19 4 1 255 217 165
-18 4 0 255 217 165
-17 4 -1 255 217 165
-16 4 -2 255 217 165
-19 3 0 255 217 165
-18 3 -1 255 217 165
-17 3 -2 255 217 165
-16 3 -3 255 217 165
-16 7 9 174 202 48
-16 6 10 174 202 48
-19 2 -1 255 217 165
-18 2 -2 255 217 165
-17 2 -3 255 217 165
-16 2 -4 255 217 165
-19 1 -2 255 217 165
-18 1 -3 255 217 165
-17 1 -4 255 217 165
-16 1 -5 255 217 165
-19 0 -3 255 217 165
-18 0 -4 255 217 165
-17 0 -5 255 217 165
-19 -1 -4 255 217 165
-18 -1 -5 255 217 165
-19 -2 -5 255 217 165
-6 3 5 255 217 165
-6 2 4 255 217 165
-6 2 6 255 217 165
-5 1 4 255 217 165
-6 1 3 255 217 165
-6 1 7 255 217 165
-4 0 4 255 217 165
-5 0 3 255 217 165
-6 0 2 255 217 165
-6 0 8 255 217 165
-3 -1 4 255 217 165
-4 -1 3 255 217 165
-5 -1 2 255 217 165
-6 -1 9 255 217 165
-2 -2 4 255 217 165
-3 -2 3 255 217 165
-4 -2 2 255 217 165
-6 -2 10 92 109 23
-1 -3 4 255 217 165
-2 -3 3 255 217 165
-3 -3 2 255 217 165
0 -4 4 255 217 165
-2 -4 2 255 217 165
-3 -4 1 255 217 165
1 -5 4 255 217 165
-2 -5 1 255 217 165
-3 -5 0 255 217 165
2 -6 4 255 217 165
-2 -6 0 255 217 165
-3 -6 -1 255 217 165
-4 -6 -2 255 217 165
-5 -6 -3 255 217 165
-6 -5 -3 255 217 165
-6 -6 -4 255 217 165
3 -7 4 255 217 165
2 -7 3 255 217 165
1 -7 2 255 217 165
0 -7 1 255 217 165
-1 -7 0 255 217 165
-2 -7 -1 255 217 165
-3 -7 -2 255 217 165
-4 -7 -3 255 217 165
-5 -7 -4 255 217 165
-6 -7 -5 255 217 165
-6 -14 -4 255 217 165
-6 -13 -5 255 217 165
-7 4 5 255 217 165
-7 3 4 255 217 165
-7 3 6 255 217 165
-7 2 3 255 217 165
-7 2 7 255 217 165
-7 1 2 255 217 165
-7 1 8 255 217 165
-7 0 1 255 217 165
-7 0 9 255 217 165
-7 -1 0 255 217 165
-7 -1 10 255 217 165
-7 -2 -1 255 217 165
-7 -3 -2 255 217 165
-7 -4 -3 255 217 165
-7 -5 -4 255 217 165
-7 -6 -5 255 217 165
-7 -14 -5 255 217 165
-8 5 5 255 217 165
-8 4 4 255 217 165
-8 4 6 255 217 165
-8 3 3 255 217 165
-8 3 7 255 217 165
-8 2 2 255 217 165
-8 2 8 255 217 165
-8 1 9 255 217 165
-8 0 0 255 217 165
-8 0 10 255 217 165
-8 -1 -1 255 217 165
-8 -2 -2 255 217 165
-8 -3 -3 255 217 165
-8 -4 -4 255 217 165
-8 -5 -5 255 217 165
-9 3 2 255 217 165
-9 0 -1 255 217 165
-9 -1 -2 255 217 165
-9 -2 -3 255 217 165
-9 3 8 255 217 165
-9 2 9 255 217 165
-9 1 10 255 217 165
-9 -3 -4 255 217 165
-9 -4 -5 255 217 165
-10 0 -2 255 217 165
-10 -1 -3 255 217 165
-10 -2 -4 255 217 165
-10 -3 -5 255 217 165
-10 4 8 255 217 165
-10 3 9 255 217 165
-10 2 10 255 217 165
-11 0 -3 255 217 165
-11 -1 -4 255 217 165
-11 -2 -5 255 217 165
-11 5 8 255 217 165
-11 4 9 255 217 165
-11 3 10 255 217 165
-12 4 0 255 217 165
-12 0 -4 255 217 165
-12 -1 -5 255 217 165
-12 6 8 255 217 165
-12 5 9 255 217 165
-12 4 10 255 217 165
-11 4 1 255 217 165
-12 5 1 255 217 165
-13 6 1 255 217 165
-13 5 0 255 217 165
-13 4 -1 255 217 165
-13 3 -2 255 217 165
-13 2 -3 255 217 165
-13 1 -4 255 217 165
-13 0 -5 255 217 165
-12 7 7 255 217 165
-13 8 7 255 217 165
-13 7 8 255 217 165
-13 6 9 255 217 165
-13 5 10 255 217 165
-14 6 0 255 217 165
-14 5 -1 255 217 165
-14 4 -2 255 217 165
-14 3 -3 255 217 165
-14 2 -4 255 217 165
-14 1 -5 255 217 165
-14 9 7 255 217 165
-14 8 8 255 217 165
-14 7 9 255 217 165
-14 6 10 255 217 165
-14 7 1 255 217 165
-15 8 1 255 217 165
-15 7 0 255 217 165
-15 6 -1 255 217 165
-15 5 -2 255 217 165
-15 4 -3 255 217 165
-15 3 -4 255 217 165
-15 2 -5 255 217 165
-15 10 7 255 217 165
-15 9 8 255 217 165
-15 8 9 255 217 165
-15 7 10 255 217 165
-12 6 3 255 217 165
-12 5 2 255 217 165
-11 4 2 255 217 165
-13 6 2 255 217 165
-14 7 2 255 217 165
-15 8 2 255 217 165
-19 6 2 174 202 48
-19 5 1 255 217 165
-18 7 2 255 217 165
-18 6 1 255 217 165
-18 5 0 255 217 165
-17 8 2 255 217 165
-17 7 1 255 217 165
-17 6 0 255 217 165
-17 5 -1 255 217 165
-16 9 2 255 217 165
-16 8 1 255 217 165
-16 7 0 255 217 165
-16 6 -1 255 217 165
-16 5 -2 255 217 165
-19 4 0 255 217 165
-18 4 -1 255 217 165
-17 4 -2 255 217 165
-16 4 -3 255 217 165
-19 3 -1 255 217 165
-18 3 -2 255 217 165
-17 3 -3 255 217 165
-16 3 -4 255 217 165
-16 8 9 174 202 48
-16 7 10 174 202 48
-19 2 -2 255 217 165
-18 2 -3 255 217 165
-17 2 -4 255 217 165
-16 2 -5 255 217 165
-19 1 -3 255 217 165
-18 1 -4 255 217 165
-17 1 -5 255 217 165
-19 0 -4 255 217 165
-18 0 -5 255 217 165
-19 -1 -5 255 217 165
-6 4 5 255 217 165
-6 3 4 255 217 165
-6 3 6 255 217 165
-5 2 4 255 217 165
-6 2 3 255 217 165
-6 2 7 255 217 165
-4 1 4 255 217 165
-5 1 3 255 217 165
-6 1 2 255 217 165
-6 1 8 255 217 165
-3 0 4 255 217 165
-4 0 3 255 217 165
-5 0 2 255 217 165
-6 0 9 255 217 165
-2 -1 4 255 217 165
-3 -1 3 255 217 165
-4 -1 2 255 217 165
-6 -1 10 255 217 165
-1 -2 4 255 217 165
-2 -2 3 255 217 165
-3 -2 2 255 217 165
0 -3 4 255 217 165
-2 -3 2 255 217 165
-3 -3 1 255 217 165
1 -4 4 255 217 165
-2 -4 1 255 217 165
-3 -4 0 255 217 165
2 -5 4 255 217 165
-2 -5 0 255 217 165
-3 -5 -1 255 217 165
3 -6 4 255 217 165
-2 -6 -1 255 217 165
-3 -6 -2 255 217 165
-4 -6 -3 255 217 165
-5 -5 -3 255 217 165
-5 -6 -4 255 217 165
-6 -4 -3 255 217 165
-6 -5 -4 255 217 165
-6 -6 -5 255 217 165
4 -7 4 255 217 165
3 -7 3 255 217 165
2 -7 2 255 217 165
1 -7 1 255 217 165
0 -7 0 255 217 165
-1 -7 -1 255 217 165
-2 -7 -2 255 217 165
-3 -7 -3 255 217 165
-4 -7 -4 255 217 165
-5 -7 -5 255 217 165
-6 -14 -5 255 217 165
-7 5 5 255 217 165
-7 4 4 255 217 165
-7 4 6 255 217 165
-7 3 3 255 217 165
-7 3 7 255 217 165
-7 2 2 255 217 165
-7 2 8 255 217 165
-7 1 9 255 217 165
-7 0 0 255 217 165
-7 0 10 255 217 165
-7 -1 -1 255 217 165
-7 -2 -2 255 217 165
-7 -3 -3 255 217 165
-7 -4 -4 255 217 165
-7 -5 -5 255 217 165
-8 6 5 255 217 165
-8 5 4 255 217 165
-8 5 6 255 217 165
-8 4 3 255 217 165
-8 4 7 255 217 165
-8 3 2 255 217 165
-8 3 8 255 217 165
-8 2 9 255 217 165
-8 1 10 255 217 165
-8 0 -1 255 217 165
-8 -1 -2 255 217 165
-8 -2 -3 255 217 165
-8 -3 -4 255 217 165
-8 -4 -5 255 217 165
-9 4 2 255 217 165
-9 0 -2 255 217 165
-9 -1 -3 255 217 165
-9 -2 -4 255 217 165
-9 4 8 255 217 165
-9 3 9 255 217 165
-9 2 10 255 217 165
-9 -3 -5 255 217 165
-10 0 -3 255 217 165
-10 -1 -4 255 217 165
-10 -2 -5 255 217 165
-10 5 8 255 217 165
-10 4 9 255 217 165
-10 3 10 255 217 165
-11 0 -4 255 217 165
-11 -1 -5 255 217 165
-11 6 8 255 217 165
-11 5 9 255 217 165
-11 4 10 255 217 165
-11 4 0 255 217 165
-12 5 0 255 217 165
-12 0 -5 255 217 165
-12 7 8 255 217 165
-12 6 9 255 217 165
-12 5 10 255 217 165
-10 4 1 255 217 165
-11 5 1 255 217 165
-12 6 1 255 217 165
-13 7 1 255 217 165
-13 6 0 255 217 165
-13 5 -1 255 217 165
-13 4 -2 255 217 165
-13 3 -3 255 217 165
-13 2 -4 255 217 165
-13 1 -5 255 217 165
-11 7 7 255 217 165
-12 8 7 255 217 165
-13 9 7 255 217 165
-13 8 8 255 217 165
-13 7 9 255 217 165
-13 6 10 255 217 165
-14 7 0 255 217 165
-14 6 -1 255 217 165
-14 5 -2 255 217 165
-14 4 -3 255 217 165
-14 3 -4 255 217 165
-14 2 -5 255 217 165
-14 10 7 255 217 165
-14 9 8 255 217 165
-14 8 9 255 217 165
-14 7 10 255 217 165
-14 8 1 255 217 165
-15 9 1 255 217 165
-15 8 0 255 217 165
-15 6 -2 255 217 165
-15 5 -3 255 217 165
-15 4 -4 255 217 165
-15 3 -5 255 217 165
-15 11 7 255 217 165
-15 10 6 255 217 165
-15 10 8 255 217 165
-15 9 9 255 217 165
-15 8 10 174 202 48
-12 6 2 255 217 165
-11 5 2 255 217 165
-10 4 2 255 217 165
-13 7 2 255 217 165
-14 8 2 255 217 165
-15 9 2 255 217 165
-19 7 2 174 202 48
-19 6 1 255 217 165
-19 5 0 255 217 165
-18 8 2 255 217 165
-18 7 1 255 217 165
-18 6 0 255 217 165
-18 5 -1 255 217 165
-17 9 2 255 217 165
-17 8 1 255 217 165
-17 7 0 255 217 165
-17 6 -1 255 217 165
-17 5 -2 255 217 165
-16 10 2 255 217 165
-16 9 1 255 217 165
-16 8 0 255 217 165
-16 6 -2 255 217 165
-16 5 -3 255 217 165
-19 4 -1 255 217 165
-18 4 -2 255 217 165
-17 4 -3 255 217 165
-16 4 -4 255 217 165
-19 3 -2 255 217 165
-18 3 -3 255 217 165
-17 3 -4 255 217 165
-16 3 -5 255 217 165
-16 9 9 174 202 48
-16 8 10 174 202 48
-19 2 -3 255 217 165
-18 2 -4 255 217 165
-17 2 -5 255 217 165
-19 1 -4 255 217 165
-18 1 -5 255 217 165
-19 0 -5 255 217 165
-6 5 5 255 217 165
-6 4 4 255 217 165
-6 4 6 255 217 165
-5 3 4 255 217 165
-6 3 3 255 217 165
-6 3 7 255 217 165
-4 2 4 255 217 165
-5 2 3 255 217 165
-6 2 2 255 217 165
-6 2 8 255 217 165
-3 1 4 255 217 165
-4 1 3 255 217 165
-5 1 2 255 217 165
-6 1 9 255 217 165
-2 0 4 255 217 165
-3 0 3 255 217 165
-4 0 2 255 217 165
-6 0 10 255 217 165
-1 -1 4 255 217 165
-2 -1 3 255 217 165
-3 -1 2 255 217 165
0 -2 4 255 217 165
-2 -2 2 255 217 165
-3 -2 1 255 217 165
1 -3 4 255 217 165
-2 -3 1 255 217 165
-3 -3 0 255 217 165
2 -4 4 255 217 165
-2 -4 0 255 217 165
-3 -4 -1 255 217 165
3 -5 4 255 217 165
-2 -5 -1 255 217 165
-3 -5 -2 255 217 165
4 -6 4 255 217 165
-2 -6 -2 255 217 165
-3 -6 -3 255 217 165
-4 -5 -3 255 217 165
-4 -6 -4 255 217 165
-5 -5 -4 255 217 165
-5 -6 -5 255 217 165
-6 -3 -3 255 217 165
-6 -4 -4 255 217 165
-6 -5 -5 255 217 165
5 -7 4 255 217 165
4 -7 3 255 217 165
3 -7 2 255 217 165
2 -7 1 255 217 165
1 -7 0 255 217 165
0 -7 -1 255 217 165
-1 -7 -2 255 217 165
-2 -7 -3 255 217 165
-3 -7 -4 255 217 165
-4 -7 -5 255 217 165
-7 6 5 255 217 165
-7 5 4 255 217 165
-7 5 6 255 217 165
-7 4 3 255 217 165
-7 4 7 255 217 165
-7 3 2 255 217 165
-7 3 8 255 217 165
-7 2 9 255 217 165
-7 1 10 255 217 165
-7 0 -1 255 217 165
-7 -1 -2 255 217 165
-7 -2 -3 255 217 165
-7 -3 -4 255 217 165
-7 -4 -5 255 217 165
-8 7 5 255 217 165
-8 6 4 255 217 165
-8 6 6 255 217 165
-8 5 3 255 217 165
-8 5 7 255 217 165
-8 4 2 255 217 165
-8 4 8 255 217 165
-8 3 9 255 217 165
-8 2 10 255 217 165
-8 0 -2 255 217 165
-8 -1 -3 255 217 165
-8 -2 -4 255 217 165
-8 -3 -5 255 217 165
-9 5 2 255 217 165
-9 4 1 255 217 165
-9 0 -3 255 217 165
-9 -1 -4 255 217 165
-9 -2 -5 255 217 165
-9 5 8 255 217 165
-9 4 9 255 217 165
-9 3 10 255 217 165
-10 0 -4 255 217 165
-10 -1 -5 255 217 165
-10 6 8 255 217 165
-10 5 9 255 217 165
-10 4 10 255 217 165
-11 0 -5 255 217 165
-11 7 8 255 217 165
-11 6 9 255 217 165
-11 5 10 255 217 165
-10 4 0 255 217 165
-11 5 0 255 217 165
-12 6 0 255 217 165
-12 1 -5 255 217 165
-12 8 8 255 217 165
-12 7 9 255 217 165
-12 6 10 255 217 165
-10 5 1 255 217 165
-11 6 1 255 217 165
-12 7 1 255 217 165
-13 8 1 255 217 165
-13 7 0 255 217 165
-13 6 -1 255 217 165
-13 5 -2 255 217 165
-13 4 -3 255 217 165
-13 3 -4 255 217 165
-13 2 -5 255 217 165
-10 7 7 255 217 165
-11 8 7 255 217 165
-12 9 7 255 217 165
-13 10 7 255 217 165
-13 9 8 255 217 165
-13 8 9 255 217 165
-13 7 10 255 217 165
-14 8 0 255 217 165
-14 6 -2 255 217 165
-14 5 -3 255 217 165
-14 4 -4 255 217 165
-14 3 -5 255 217 165
-14 11 7 255 217 165
-14 10 6 255 217 165
-14 10 8 255 217 165
-14 9 9 255 217 165
-14 8 10 255 217 165
-14 9 1 255 217 165
-15 10 1 255 217 165
-15 9 0 255 217 165
-15 6 -3 255 217 165
-15 5 -4 255 217 165
-15 4 -5 255 217 165
-15 12 7 255 217 165
-15 11 6 255 217 165
-15 11 8 255 217 165
-15 10 5 255 217 165
-15 10 9 255 217 165
-15 9 10 174 202 48
-11 6 2 255 217 165
-12 7 2 255 217 165
-13 8 2 255 217 165
-14 9 2 255 217 165
-15 10 2 255 217 165
-19 8 2 174 202 48
-19 7 1 92 109 23
-19 6 0 255 217 165
-19 5 -1 255 217 165
-18 9 2 255 217 165
-18 8 1 255 217 165
-18 7 0 255 217 165
-18 6 -1 255 217 165
-18 5 -2 255 217 165
-17 10 2 255 217 165
-17 9 1 255 217 165
-17 8 0 255 217 165
-17 7 -1 255 217 165
-17 6 -2 255 217 165
-17 5 -3 255 217 165
-16 11 2 255 217 165
-16 10 1 255 217 165
-16 9 0 255 217 165
-16 6 -3 255 217 165
-16 5 -4 255 217 165
-19 4 -2 255 217 165
-18 4 -3 255 217 165
-17 4 -4 255 217 165
-16 4 -5 255 217 165
-19 3 -3 255 217 165
-18 3 -4 255 217 165
-17 3 -5 255 217 165
-16 10 9 174 202 48
-16 9 10 174 202 48
-19 2 -4 255 217 165
-18 2 -5 255 217 165
-19 1 -5 255 217 165
-6 6 5 255 217 165
-6 5 4 255 217 165
-6 5 6 255 217 165
-5 4 4 255 217 165
-6 4 3 255 217 165
-6 4 7 255 217 165
-4 3 4 255 217 165
-5 3 3 255 217 165
-6 3 2 255 217 165
-6 3 8 255 217 165
-3 2 4 255 217 165
-4 2 3 255 217 165
-5 2 2 255 217 165
-6 2 9 255 217 165
-2 1 4 255 217 165
-3 1 3 255 217 165
-4 1 2 255 217 165
-6 1 10 255 217 165
-1 0 4 255 217 165
-2 0 3 255 217 165
-3 0 2 255 217 165
0 -1 4 255 217 165
-2 -1 2 255 217 165
-3 -1 1 255 217 165
1 -2 4 255 217 165
-2 -2 1 255 217 165
-3 -2 0 255 217 165
2 -3 4 255 217 165
-2 -3 0 255 217 165
-3 -3 -1 255 217 165
3 -4 4 255 217 165
-2 -4 -1 255 217 165
-3 -4 -2 255 217 165
4 -5 4 255 217 165
-2 -5 -2 255 217 165
-3 -5 -3 255 217 165
5 -6 4 255 217 165
-2 -6 -3 255 217 165
-3 -6 -4 255 217 165
-4 -4 -3 255 217 165
-4 -5 -4 255 217 165
-4 -6 -5 255 217 165
-5 -4 -4 255 217 165
-5 -5 -5 255 217 165
-5 -3 -3 255 217 165
-6 -3 -4 255 217 165
-6 -4 -5 255 217 165
-14 -8 18 156 111 55
5 -8 4 255 217 165
5 -7 3 255 217 165
5 -7 5 255 217 165
4 -7 2 255 217 165
3 -7 1 255 217 165
2 -7 0 255 217 165
1 -7 -1 255 217 165
0 -7 -2 255 217 165
-1 -7 -3 255 217 165
-2 -7 -4 255 217 165
-3 -7 -5 255 217 165
-7 7 5 255 217 165
-7 6 4 255 217 165
-7 6 6 255 217 165
-7 5 3 255 217 165
-7 5 7 255 217 165
-7 4 2 255 217 165
-7 4 8 255 217 165
-7 3 9 255 217 165
-7 2 10 255 217 165
-7 0 -2 255 217 165
-7 -1 -3 255 217 165
-7 -2 -4 255 217 165
-7 -3 -5 255 217 165
-8 8 5 255 217 165
-8 7 4 255 217 165
-8 7 6 255 217 165
-8 6 3 255 217 165
-8 6 7 255 217 165
-8 5 2 255 217 165
-8 5 8 255 217 165
-8 4 1 255 217 165
-8 4 9 255 217 165
-8 3 10 255 217 165
-8 0 -3 255 217 165
-8 -1 -4 255 217 165
-8 -2 -5 255 217 165
-9 6 2 255 217 165
-9 5 1 255 217 165
-9 4 0 255 217 165
-9 0 -4 255 217 165
-9 -1 -5 255 217 165
-9 6 8 255 217 165
-9 5 9 255 217 165
-9 4 10 255 217 165
-10 0 -5 255 217 165
-10 7 8 255 217 165
-10 6 9 255 217 165
-10 5 10 255 217 165
-11 1 -5 255 217 165
-11 8 8 255 217 165
-11 7 9 255 217 165
-11 6 10 255 217 165
-10 5 0 255 217 165
-11 6 0 255 217 165
-12 7 0 255 217 165
-12 2 -5 255 217 165
-12 9 8 255 217 165
-12 8 9 255 217 165
-12 7 10 255 217 165
-12 6 11 255 217 165
-10 6 1 255 217 165
-11 7 1 255 217 165
-12 8 1 255 217 165
-13 9 1 255 217 165
-13 8 0 255 217 165
-13 6 -2 255 217 165
-13 5 -3 255 217 165
-13 4 -4 255 217 165
-13 3 -5 255 217 165
-9 7 7 255 217 165
-10 8 7 255 217 165
-11 9 7 255 217 165
-12 10 7 255 217 165
-13 11 7 255 217 165
-13 10 6 255 217 165
-13 10 8 255 217 165
-13 9 9 255 217 165
-13 8 10 255 217 165
-14 9 0 255 217 165
-14 6 -3 255 217 165
-14 5 -4 255 217 165
-14 4 -5 255 217 165
-14 12 7 255 217 165
-14 11 6 255 217 165
-14 11 8 255 217 165
-14 10 5 255 217 165
-14 10 9 255 217 165
-14 9 10 255 217 165
-14 10 1 255 217 165
-15 10 0 255 217 165
-15 6 -4 255 217 165
-15 5 -5 255 217 165
-16 12 7 255 217 165
-15 13 7 255 217 165
-15 12 6 255 217 165
-15 12 8 255 217 165
-16 11 6 255 217 165
-15 11 5 255 217 165
-16 11 8 255 217 165
-15 11 9 255 217 165
-15 10 4 255 217 165
-15 10 10 174 202 48
-10 6 2 255 217 165
-11 7 2 255 217 165
-12 8 2 255 217 165
-13 9 2 255 217 165
-14 10 2 255 217 165
-15 10 3 255 217 165
-19 9 2 174 202 48
-19 8 1 92 109 23
-19 7 0 255 217 165
-19 6 -1 255 217 165
-19 5 -2 255 217 165
-18 10 2 255 217 165
-18 9 1 255 217 165
-18 8 0 255 217 165
-18 7 -1 255 217 165
-18 6 -2 255 217 165
-18 5 -3 255 217 165
-17 11 2 255 217 165
-17 10 1 255 217 165
-17 9 0 255 217 165
-17 8 -1 255 217 165
-17 7 -2 255 217 165
-17 6 -3 255 217 165
-17 5 -4 255 217 165
-16 12 2 255 217 165
-16 11 1 255 217 165
-16 11 3 255 217 165
-16 10 0 255 217 165
-16 6 -4 255 217 165
-16 5 -5 255 217 165
-19 4 -3 255 217 165
-18 4 -4 255 217 165
-17 4 -5 255 217 165
-19 3 -4 255 217 165
-18 3 -5 255 217 165
-16 11 9 255 217 165
-16 10 10 174 202 48
-19 2 -5 255 217 165
-6 7 5 255 217 165
-6 6 4 255 217 165
-6 6 6 255 217 165
-5 5 4 255 217 165
-6 5 3 255 217 165
-6 5 7 255 217 165
-4 4 4 255 217 165
-5 4 3 255 217 165
-6 4 2 255 217 165
-6 4 8 255 217 165
-3 3 4 255 217 165
-4 3 3 255 217 165
-5 3 2 255 217 165
-6 3 9 255 217 165
-2 2 4 255 217 165
-3 2 3 255 217 165
-4 2 2 255 217 165
-6 2 10 255 217 165
-1 1 4 255 217 165
-2 1 3 255 217 165
-3 1 2 255 217 165
0 0 4 255 217 165
-2 0 2 255 217 165
-3 0 1 255 217 165
1 -1 4 255 217 165
-2 -1 1 255 217 165
-3 -1 0 255 217 165
2 -2 4 255 217 165
-2 -2 0 255 217 165
-3 -2 -1 255 217 165
3 -3 4 255 217 165
-2 -3 -1 255 217 165
-3 -3 -2 255 217 165
4 -4 4 255 217 165
-2 -4 -2 255 217 165
-3 -4 -3 255 217 165
5 -5 4 255 217 165
-2 -5 -3 255 217 165
-3 -5 -4 255 217 165
-13 -6 19 156 111 55
5 -6 5 255 217 165
-2 -6 -4 255 217 165
-3 -6 -5 255 217 165
-4 -3 -3 255 217 165
-4 -4 -4 255 217 165
-4 -5 -5 255 217 165
-5 -3 -4 255 217 165
-5 -4 -5 255 217 165
-6 -2 -4 255 217 165
-6 -3 -5 255 217 165
7 -7 4 255 217 165
6 -8 4 255 217 165
-15 -3 11 156 111 55
5 -9 4 255 217 165
5 -8 3 255 217 165
5 -8 5 255 217 165
5 -7 2 255 217 165
5 -7 6 255 217 165
4 -7 1 255 217 165
3 -7 0 255 217 165
2 -7 -1 255 217 165
1 -7 -2 255 217 165
0 -7 -3 255 217 165
-1 -7 -4 255 217 165
-2 -7 -5 255 217 165
-7 8 5 255 217 165
-7 7 4 255 217 165
-7 7 6 255 217 165
-7 6 3 255 217 165
-7 6 7 255 217 165
-7 5 2 255 217 165
-7 5 8 255 217 165
-7 4 1 255 217 165
-7 4 9 255 217 165
-7 3 10 255 217 165
-7 0 -3 255 217 165
-7 -1 -4 255 217 165
-7 -2 -5 255 217 165
-8 9 5 255 217 165
-8 8 4 255 217 165
-8 8 6 255 217 165
-8 7 3 255 217 165
-8 7 7 255 217 165
-8 6 2 255 217 165
-8 6 8 255 217 165
-8 5 1 255 217 165
-8 5 9 255 217 165
-8 4 0 255 217 165
-8 4 10 255 217 165
-8 0 -4 255 217 165
-8 -1 -5 255 217 165
-9 7 2 255 217 165
-9 6 1 255 217 165
-9 5 0 255 217 165
-9 4 -1 255 217 165
-9 0 -5 255 217 165
-9 7 8 255 217 165
-9 6 9 255 217 165
-9 5 10 255 217 165
-10 1 -5 255 217 165
-10 8 8 255 217 165
-10 7 9 255 217 165
-10 6 10 255 217 165
-11 9 8 255 217 165
-11 8 9 255 217 165
-11 7 10 255 217 165
-11 6 11 255 217 165
-10 6 0 255 217 165
-11 7 0 255 217 165
-12 8 0 255 217 165
-12 3 -5 255 217 165
-12 10 8 255 217 165
-12 9 9 255 217 165
-12 8 10 255 217 165
-12 7 11 255 217 165
-12 6 12 174 202 48
-10 7 1 255 217 165
-11 8 1 255 217 165
-12 9 1 255 217 165
-13 10 1 255 217 165
-13 9 0 255 217 165
-13 6 -3 255 217 165
-13 5 -4 255 217 165
-13 4 -5 255 217 165
-9 8 7 255 217 165
-10 9 7 255 217 165
-11 10 7 255 217 165
-12 11 7 255 217 165
-12 10 6 255 217 165
-13 12 7 255 217 165
-13 11 6 255 217 165
-13 11 8 255 217 165
-13 10 5 255 217 165
-13 10 9 255 217 165
-13 9 10 255 217 165
-14 10 0 255 217 165
-14 6 -4 255 217 165
-14 5 -5 255 217 165
-14 13 7 255 217 165
-14 12 6 255 217 165
-14 12 8 255 217 165
-14 11 5 255 217 165
-14 11 9 255 217 165
-14 10 4 255 217 165
-14 10 10 255 217 165
-15 6 -5 255 217 165
-16 13 7 255 217 165
-16 12 6 255 217 165
-15 14 7 255 217 165
-15 13 6 255 217 165
-15 13 8 255 217 165
-15 12 5 255 217 165
-15 12 9 255 217 165
-16 11 5 255 217 165
-15 11 10 174 202 48
-12 9 2 255 217 165
-13 10 2 255 217 165
-14 10 3 255 217 165
-19 10 2 174 202 48
-19 9 1 92 109 23
-19 8 0 255 217 165
-19 7 -1 255 217 165
-19 6 -2 255 217 165
-19 5 -3 255 217 165
-18 11 2 255 217 165
-18 10 1 255 217 165
-18 9 0 255 217 165
-18 8 -1 255 217 165
-18 7 -2 255 217 165
-18 6 -3 255 217 165
-18 5 -4 255 217 165
-17 12 2 255 217 165
-17 11 1 255 217 165
-17 10 0 255 217 165
-17 9 -1 255 217 165
-17 8 -2 255 217 165
-17 7 -3 255 217 165
-17 6 -4 255 217 165
-17 5 -5 255 217 165
-16 13 2 255 217 165
-16 12 1 255 217 165
-16 12 3 255 217 165
-16 11 0 255 217 165
-16 11 4 255 217 165
-16 6 -5 255 217 165
-19 4 -4 255 217 165
-18 4 -5 255 217 165
-19 3 -5 255 217 165
-16 12 9 92 109 23
-16 11 10 174 202 48
-6 8 5 255 217 165
-6 7 4 255 217 165
-6 7 6 255 217 165
-5 6 4 255 217 165
-6 6 3 255 217 165
-6 6 7 255 217 165
-4 5 4 255 217 165
-6 5 2 255 217 165
-6 5 8 255 217 165
-3 4 4 255 217 165
-4 4 3 255 217 165
-5 4 2 255 217 165
-6 4 1 255 217 165
-6 4 9 255 217 165
-2 3 4 255 217 165
-3 3 3 255 217 165
-4 3 2 255 217 165
-6 3 10 255 217 165
-1 2 4 255 217 165
-2 2 3 255 217 165
-3 2 2 255 217 165
0 1 4 255 217 165
-2 1 2 255 217 165
-3 1 1 255 217 165
1 0 4 255 217 165
-2 0 1 255 217 165
-3 0 0 255 217 165
2 -1 4 255 217 165
-2 -1 0 255 217 165
-3 -1 -1 255 217 165
3 -2 4 255 217 165
-2 -2 -1 255 217 165
-3 -2 -2 255 217 165
4 -3 4 255 217 165
-2 -3 -2 255 217 165
-3 -3 -3 255 217 165
5 -4 4 255 217 165
-2 -4 -3 255 217 165
-3 -4 -4 255 217 165
-11 -5 15 156 111 55
5 -5 5 255 217 165
-2 -5 -4 255 217 165
-3 -5 -5 255 217 165
7 -6 4 255 217 165
-14 -6 18 156 111 55
5 -6 6 255 217 165
-2 -6 -5 255 217 165
-4 -3 -4 255 217 165
-4 -4 -5 255 217 165
-5 -2 -4 255 217 165
-5 -3 -5 255 217 165
-6 -1 -4 255 217 165
-6 -2 -5 255 217 165
8 -7 4 255 217 165
7 -8 4 255 217 165
-11 -5 17 156 111 55
6 -9 4 255 217 165
-10 -4 11 156 111 55
5 -10 4 255 217 165
5 -9 3 255 217 165
5 -9 5 255 217 165
5 -8 2 255 217 165
5 -8 6 255 217 165
5 -7 1 255 217 165
5 -7 7 255 217 165
4 -7 0 255 217 165
3 -7 -1 255 217 165
2 -7 -2 255 217 165
1 -7 -3 255 217 165
0 -7 -4 255 217 165
-1 -7 -5 255 217 165
-7 9 5 255 217 165
-7 8 4 255 217 165
-7 8 6 255 217 165
-7 7 3 255 217 165
-7 7 7 255 217 165
-7 6 2 255 217 165
-7 6 8 255 217 165
-7 5 1 255 217 165
-7 5 9 255 217 165
-7 4 0 255 217 165
-7 4 10 255 217 165
-7 0 -4 255 217 165
-7 -1 -5 255 217 165
-8 10 5 255 217 165
-8 9 4 255 217 165
-8 9 6 255 217 165
-8 8 3 255 217 165
-8 8 7 255 217 165
-8 7 2 255 217 165
-8 7 8 255 217 165
-8 6 1 255 217 165
-8 6 9 255 217 165
-8 5 0 255 217 165
-8 5 10 255 217 165
-8 4 -1 255 217 165
-8 0 -5 255 217 165
-9 8 2 255 217 165
-9 7 1 255 217 165
-9 6 0 255 217 165
-9 5 -1 255 217 165
-9 4 -2 255 217 165
-9 1 -5 255 217 165
-9 8 8 255 217 165
-9 7 9 255 217 165
-9 6 10 255 217 165
-10 2 -5 255 217 165
-10 9 8 255 217 165
-10 8 9 255 217 165
-10 7 10 255 217 165
-10 6 11 255 217 165
-11 10 8 255 217 165
-11 9 9 255 217 165
-11 8 10 255 217 165
-11 7 11 255 217 165
-11 6 12 255 217 165
-10 7 0 255 217 165
-11 8 0 255 217 165
-12 9 0 255 217 165
-11 3 -5 255 217 165
-12 4 -5 255 217 165
-12 11 8 255 217 165
-12 10 9 255 217 165
-12 9 10 255 217 165
-12 8 11 255 217 165
-12 7 12 255 217 165
-12 6 13 174 202 48
-10 8 1 255 217 165
-11 9 1 255 217 165
-12 10 1 255 217 165
-13 11 1 255 217 165
-13 10 0 255 217 165
-13 6 -4 255 217 165
-13 5 -5 255 217 165
-9 9 7 255 217 165
-10 10 7 255 217 165
-11 11 7 255 217 165
-11 10 6 255 217 165
-12 12 7 255 217 165
-12 11 6 255 217 165
-12 10 5 255 217 165
-13 13 7 255 217 165
-13 12 6 255 217 165
-13 12 8 255 217 165
-13 11 5 255 217 165
-13 11 9 255 217 165
-13 10 4 255 217 165
-13 10 10 255 217 165
-14 6 -5 255 217 165
-14 14 7 255 217 165
-14 13 6 255 217 165
-14 13 8 255 217 165
-14 12 5 255 217 165
-14 12 9 255 217 165
-14 11 10 255 217 165
-15 7 -5 255 217 165
-16 14 7 255 217 165
-16 13 6 255 217 165
-16 13 8 255 217 165
-16 12 5 255 217 165
-15 15 7 255 217 165
