ply
format ascii 1.0
comment : MagicaVoxel @ Ephtracy
element vertex 910
property float x
property float y
property float z
property uchar red
property uchar green
property uchar blue
end_header
-10 -8 0 153 102 0
-10 -9 0 153 102 0
-10 -7 0 153 102 0
-11 -8 0 153 102 0
-9 -8 0 153 102 0
-10 -10 0 153 102 0
-11 -9 0 153 102 0
-9 -9 0 153 102 0
-10 -6 0 153 102 0
-11 -7 0 153 102 0
-9 -7 0 153 102 0
-12 -8 0 153 102 0
-8 -8 0 153 102 0
-10 -11 0 153 102 0
-11 -10 0 153 102 0
-9 -10 0 153 102 0
-12 -9 0 153 102 0
-8 -9 0 153 102 0
-10 -5 0 153 102 0
-11 -6 0 153 102 0
-9 -6 0 153 102 0
-12 -7 0 153 102 0
-8 -7 0 153 102 0
-13 -8 0 153 102 0
-7 -8 0 153 102 0
-10 -12 0 153 102 0
-11 -11 0 153 102 0
-9 -11 0 153 102 0
-12 -10 0 153 102 0
-8 -10 0 153 102 0
-13 -9 0 153 102 0
-7 -9 0 153 102 0
-10 -4 0 153 102 0
-11 -5 0 153 102 0
-9 -5 0 153 102 0
-12 -6 0 153 102 0
-8 -6 0 153 102 0
-13 -7 0 153 102 0
-7 -7 0 153 102 0
-14 -8 0 153 102 0
-6 -8 0 153 102 0
-10 -13 0 153 102 0
-11 -12 0 153 102 0
-9 -12 0 153 102 0
-12 -11 0 153 102 0
-8 -11 0 153 102 0
-13 -10 0 153 102 0
-7 -10 0 153 102 0
-14 -9 0 153 102 0
-6 -9 0 153 102 0
-10 -3 0 153 102 0
-11 -4 0 153 102 0
-9 -4 0 153 102 0
-12 -5 0 153 102 0
-8 -5 0 153 102 0
-13 -6 0 153 102 0
-7 -6 0 153 102 0
-14 -7 0 153 102 0
-6 -7 0 153 102 0
-15 -8 0 153 102 0
-5 -8 0 153 102 0
-10 -14 0 153 102 0
-11 -13 0 153 102 0
-9 -13 0 153 102 0
-12 -12 0 153 102 0
-8 -12 0 153 102 0
-13 -11 0 153 102 0
-7 -11 0 153 102 0
-14 -10 0 153 102 0
-6 -10 0 153 102 0
-15 -9 0 153 102 0
-5 -9 0 153 102 0
-10 -2 0 153 102 0
-11 -3 0 153 102 0
-9 -3 0 153 102 0
-12 -4 0 153 102 0
-8 -4 0 153 102 0
-13 -5 0 153 102 0
-7 -5 0 153 102 0
-14 -6 0 153 102 0
-6 -6 0 153 102 0
-15 -7 0 153 102 0
-5 -7 0 153 102 0
-16 -8 0 153 102 0
-4 -8 0 153 102 0
-10 -15 0 153 102 0
-11 -14 0 153 102 0
-9 -14 0 153 102 0
-12 -13 0 153 102 0
-8 -13 0 153 102 0
-13 -12 0 153 102 0
-7 -12 0 153 102 0
-14 -11 0 153 102 0
-6 -11 0 153 102 0
-15 -10 0 153 102 0
-5 -10 0 153 102 0
-16 -9 0 153 102 0
-4 -9 0 153 102 0
-10 -1 0 153 102 0
-11 -2 0 153 102 0
-9 -2 0 153 102 0
-12 -3 0 153 102 0
-8 -3 0 153 102 0
-13 -4 0 153 102 0
-7 -4 0 153 102 0
-14 -5 0 153 102 0
-6 -5 0 153 102 0
-15 -6 0 153 102 0
-5 -6 0 153 102 0
-16 -7 0 153 102 0
-4 -7 0 153 102 0
-17 -8 0 153 102 0
-3 -8 0 153 102 0
-10 -16 0 153 102 0
-11 -15 0 153 102 0
-9 -15 0 153 102 0
-12 -14 0 153 102 0
-8 -14 0 153 102 0
-13 -13 0 153 102 0
-7 -13 0 153 102 0
-14 -12 0 153 102 0
-6 -12 0 153 102 0
-15 -11 0 153 102 0
-5 -11 0 153 102 0
-16 -10 0 153 102 0
-4 -10 0 153 102 0
-17 -9 0 153 102 0
-3 -9 0 153 102 0
-10 0 0 153 102 0
-11 -1 0 153 102 0
-9 -1 0 153 102 0
-12 -2 0 153 102 0
-8 -2 0 153 102 0
-13 -3 0 153 102 0
-7 -3 0 153 102 0
-14 -4 0 153 102 0
-6 -4 0 153 102 0
-15 -5 0 153 102 0
-5 -5 0 153 102 0
-16 -6 0 153 102 0
-4 -6 0 153 102 0
-17 -7 0 153 102 0
-3 -7 0 153 102 0
-18 -8 0 153 102 0
-2 -8 0 153 102 0
-10 -17 0 153 102 0
-11 -16 0 153 102 0
-9 -16 0 153 102 0
-12 -15 0 153 102 0
-8 -15 0 153 102 0
-13 -14 0 153 102 0
-7 -14 0 153 102 0
-14 -13 0 153 102 0
-6 -13 0 153 102 0
-15 -12 0 153 102 0
-5 -12 0 153 102 0
-16 -11 0 153 102 0
-4 -11 0 153 102 0
-17 -10 0 153 102 0
-3 -10 0 153 102 0
-18 -9 0 153 102 0
-2 -9 0 153 102 0
-10 1 0 153 102 0
-11 0 0 153 102 0
-9 0 0 153 102 0
-12 -1 0 153 102 0
-8 -1 0 153 102 0
-13 -2 0 153 102 0
-7 -2 0 153 102 0
-14 -3 0 153 102 0
-6 -3 0 153 102 0
-15 -4 0 153 102 0
-5 -4 0 153 102 0
-16 -5 0 153 102 0
-4 -5 0 153 102 0
-17 -6 0 153 102 0
-3 -6 0 153 102 0
-18 -7 0 153 102 0
-2 -7 0 153 102 0
-19 -8 0 153 102 0
-1 -8 0 153 102 0
-10 -18 0 153 102 0
-11 -17 0 153 102 0
-9 -17 0 153 102 0
-12 -16 0 153 102 0
-8 -16 0 153 102 0
-13 -15 0 153 102 0
-7 -15 0 153 102 0
-14 -14 0 153 102 0
-6 -14 0 153 102 0
-15 -13 0 153 102 0
-5 -13 0 153 102 0
-16 -12 0 153 102 0
-4 -12 0 153 102 0
-17 -11 0 153 102 0
-3 -11 0 153 102 0
-18 -10 0 153 102 0
-2 -10 0 153 102 0
-19 -9 0 153 102 0
-1 -9 0 153 102 0
-10 2 0 153 102 0
-11 1 0 153 102 0
-9 1 0 153 102 0
-12 0 0 153 102 0
-8 0 0 153 102 0
-13 -1 0 153 102 0
-7 -1 0 153 102 0
-14 -2 0 153 102 0
-6 -2 0 153 102 0
-15 -3 0 153 102 0
-5 -3 0 153 102 0
-16 -4 0 153 102 0
-4 -4 0 153 102 0
-17 -5 0 153 102 0
-3 -5 0 153 102 0
-18 -6 0 153 102 0
-2 -6 0 153 102 0
-19 -7 0 153 102 0
-1 -7 0 153 102 0
-20 -8 0 153 102 0
0 -8 0 153 102 0
-10 -19 0 153 102 0
-11 -18 0 153 102 0
-9 -18 0 153 102 0
-12 -17 0 153 102 0
-8 -17 0 153 102 0
-13 -16 0 153 102 0
-7 -16 0 153 102 0
-14 -15 0 153 102 0
-6 -15 0 153 102 0
-15 -14 0 153 102 0
-5 -14 0 153 102 0
-16 -13 0 153 102 0
-4 -13 0 153 102 0
-17 -12 0 153 102 0
-3 -12 0 153 102 0
-18 -11 0 153 102 0
-2 -11 0 153 102 0
-19 -10 0 153 102 0
-1 -10 0 153 102 0
-20 -9 0 153 102 0
0 -9 0 153 102 0
-10 3 0 153 102 0
-11 2 0 153 102 0
-9 2 0 153 102 0
-12 1 0 153 102 0
-8 1 0 153 102 0
-13 0 0 153 102 0
-7 0 0 153 102 0
-14 -1 0 153 102 0
-6 -1 0 153 102 0
-15 -2 0 153 102 0
-5 -2 0 153 102 0
-16 -3 0 153 102 0
-4 -3 0 153 102 0
-17 -4 0 153 102 0
-3 -4 0 153 102 0
-18 -5 0 153 102 0
-2 -5 0 153 102 0
-19 -6 0 153 102 0
-1 -6 0 153 102 0
-20 -7 0 153 102 0
0 -7 0 153 102 0
1 -8 0 153 102 0
-10 -20 0 153 102 0
-11 -19 0 153 102 0
-9 -19 0 153 102 0
-12 -18 0 153 102 0
-8 -18 0 153 102 0
-13 -17 0 153 102 0
-7 -17 0 153 102 0
-14 -16 0 153 102 0
-6 -16 0 153 102 0
-15 -15 0 153 102 0
-5 -15 0 153 102 0
-16 -14 0 153 102 0
-4 -14 0 153 102 0
-17 -13 0 153 102 0
-3 -13 0 153 102 0
-18 -12 0 153 102 0
-2 -12 0 153 102 0
-19 -11 0 153 102 0
-1 -11 0 153 102 0
-20 -10 0 153 102 0
0 -10 0 153 102 0
1 -9 0 153 102 0
-10 4 0 153 102 0
-11 3 0 153 102 0
-9 3 0 153 102 0
-12 2 0 153 102 0
-8 2 0 153 102 0
-13 1 0 153 102 0
-7 1 0 153 102 0
-14 0 0 153 102 0
-6 0 0 153 102 0
-15 -1 0 153 102 0
-5 -1 0 153 102 0
-16 -2 0 153 102 0
-4 -2 0 153 102 0
-17 -3 0 153 102 0
-3 -3 0 153 102 0
-18 -4 0 153 102 0
-2 -4 0 153 102 0
-19 -5 0 153 102 0
-1 -5 0 153 102 0
-20 -6 0 153 102 0
0 -6 0 153 102 0
1 -7 0 153 102 0
2 -8 0 153 102 0
-11 -20 0 153 102 0
-9 -20 0 153 102 0
-12 -19 0 153 102 0
-8 -19 0 153 102 0
-13 -18 0 153 102 0
-7 -18 0 153 102 0
-14 -17 0 153 102 0
-6 -17 0 153 102 0
-15 -16 0 153 102 0
-5 -16 0 153 102 0
-16 -15 0 153 102 0
-4 -15 0 153 102 0
-17 -14 0 153 102 0
-3 -14 0 153 102 0
-18 -13 0 153 102 0
-2 -13 0 153 102 0
-19 -12 0 153 102 0
-1 -12 0 153 102 0
-20 -11 0 153 102 0
0 -11 0 153 102 0
1 -10 0 153 102 0
2 -9 0 153 102 0
-11 4 0 153 102 0
-9 4 0 153 102 0
-12 3 0 153 102 0
-8 3 0 153 102 0
-13 2 0 153 102 0
-7 2 0 153 102 0
-14 1 0 153 102 0
-6 1 0 153 102 0
-15 0 0 153 102 0
-5 0 0 153 102 0
-16 -1 0 153 102 0
-4 -1 0 153 102 0
-17 -2 0 153 102 0
-3 -2 0 153 102 0
-18 -3 0 153 102 0
-2 -3 0 153 102 0
-19 -4 0 153 102 0
-1 -4 0 153 102 0
-20 -5 0 153 102 0
0 -5 0 153 102 0
1 -6 0 153 102 0
2 -7 0 153 102 0
3 -8 0 153 102 0
-12 -20 0 153 102 0
-8 -20 0 153 102 0
-13 -19 0 153 102 0
-7 -19 0 153 102 0
-14 -18 0 153 102 0
-6 -18 0 153 102 0
-15 -17 0 153 102 0
-5 -17 0 153 102 0
-16 -16 0 153 102 0
-4 -16 0 153 102 0
-17 -15 0 153 102 0
-3 -15 0 153 102 0
-18 -14 0 153 102 0
-2 -14 0 153 102 0
-19 -13 0 153 102 0
-1 -13 0 153 102 0
-20 -12 0 153 102 0
0 -12 0 153 102 0
1 -11 0 153 102 0
2 -10 0 153 102 0
3 -9 0 153 102 0
-12 4 0 153 102 0
-8 4 0 153 102 0
-13 3 0 153 102 0
-7 3 0 153 102 0
-14 2 0 153 102 0
-6 2 0 153 102 0
-15 1 0 153 102 0
-5 1 0 153 102 0
-16 0 0 153 102 0
-4 0 0 153 102 0
-17 -1 0 153 102 0
-3 -1 0 153 102 0
-18 -2 0 153 102 0
-2 -2 0 153 102 0
-19 -3 0 153 102 0
-1 -3 0 153 102 0
-20 -4 0 153 102 0
0 -4 0 153 102 0
1 -5 0 153 102 0
2 -6 0 153 102 0
3 -7 0 153 102 0
4 -8 0 153 102 0
-13 -20 0 153 102 0
-7 -20 0 153 102 0
-14 -19 0 153 102 0
-6 -19 0 153 102 0
-15 -18 0 153 102 0
-5 -18 0 153 102 0
-16 -17 0 153 102 0
-4 -17 0 153 102 0
-17 -16 0 153 102 0
-3 -16 0 153 102 0
-18 -15 0 153 102 0
-2 -15 0 153 102 0
-19 -14 0 153 102 0
-1 -14 0 153 102 0
-20 -13 0 153 102 0
0 -13 0 153 102 0
1 -12 0 153 102 0
2 -11 0 153 102 0
3 -10 0 153 102 0
4 -9 0 153 102 0
-13 4 0 153 102 0
-7 4 0 153 102 0
-14 3 0 153 102 0
-6 3 0 153 102 0
-15 2 0 153 102 0
-5 2 0 153 102 0
-16 1 0 153 102 0
-4 1 0 153 102 0
-17 0 0 153 102 0
-3 0 0 153 102 0
-18 -1 0 153 102 0
-2 -1 0 153 102 0
-19 -2 0 153 102 0
-1 -2 0 153 102 0
-20 -3 0 153 102 0
0 -3 0 153 102 0
1 -4 0 153 102 0
2 -5 0 153 102 0
3 -6 0 153 102 0
4 -7 0 153 102 0
-14 -20 0 153 102 0
-6 -20 0 153 102 0
-15 -19 0 153 102 0
-5 -19 0 153 102 0
-16 -18 0 153 102 0
-4 -18 0 153 102 0
-17 -17 0 153 102 0
-3 -17 0 153 102 0
-18 -16 0 153 102 0
-2 -16 0 153 102 0
-19 -15 0 153 102 0
-1 -15 0 153 102 0
-20 -14 0 153 102 0
0 -14 0 153 102 0
1 -13 0 153 102 0
2 -12 0 153 102 0
3 -11 0 153 102 0
4 -10 0 153 102 0
-14 4 0 153 102 0
-6 4 0 153 102 0
-15 3 0 153 102 0
-5 3 0 153 102 0
-16 2 0 153 102 0
-4 2 0 153 102 0
-17 1 0 153 102 0
-3 1 0 153 102 0
-18 0 0 153 102 0
-2 0 0 153 102 0
-19 -1 0 153 102 0
-1 -1 0 153 102 0
-20 -2 0 153 102 0
0 -2 0 153 102 0
1 -3 0 153 102 0
2 -4 0 153 102 0
3 -5 0 153 102 0
4 -6 0 153 102 0
-15 -20 0 153 102 0
-5 -20 0 153 102 0
-16 -19 0 153 102 0
-4 -19 0 153 102 0
-17 -18 0 153 102 0
-3 -18 0 153 102 0
-18 -17 0 153 102 0
-2 -17 0 153 102 0
-19 -16 0 153 102 0
-1 -16 0 153 102 0
-20 -15 0 153 102 0
0 -15 0 153 102 0
1 -14 0 153 102 0
2 -13 0 153 102 0
3 -12 0 153 102 0
4 -11 0 153 102 0
-15 4 0 153 102 0
-5 4 0 153 102 0
-16 3 0 153 102 0
-4 3 0 153 102 0
-17 2 0 153 102 0
-3 2 0 153 102 0
-18 1 0 153 102 0
-2 1 0 153 102 0
-19 0 0 153 102 0
-1 0 0 153 102 0
-20 -1 0 153 102 0
0 -1 0 153 102 0
1 -2 0 153 102 0
2 -3 0 153 102 0
3 -4 0 153 102 0
4 -5 0 153 102 0
-16 -20 0 153 102 0
-4 -20 0 153 102 0
-17 -19 0 153 102 0
-3 -19 0 153 102 0
-18 -18 0 153 102 0
-2 -18 0 153 102 0
-19 -17 0 153 102 0
-1 -17 0 153 102 0
-20 -16 0 153 102 0
0 -16 0 153 102 0
1 -15 0 153 102 0
2 -14 0 153 102 0
3 -13 0 153 102 0
4 -12 0 153 102 0
-16 4 0 153 102 0
-4 4 0 153 102 0
-17 3 0 153 102 0
-3 3 0 153 102 0
-18 2 0 153 102 0
-2 2 0 153 102 0
-19 1 0 153 102 0
-1 1 0 153 102 0
-20 0 0 153 102 0
0 0 0 153 102 0
1 -1 0 153 102 0
2 -2 0 153 102 0
3 -3 0 153 102 0
4 -4 0 153 102 0
-17 -20 0 153 102 0
-3 -20 0 153 102 0
-18 -19 0 153 102 0
-2 -19 0 153 102 0
-19 -18 0 153 102 0
-1 -18 0 153 102 0
-20 -17 0 153 102 0
0 -17 0 153 102 0
1 -16 0 153 102 0
2 -15 0 153 102 0
3 -14 0 153 102 0
4 -13 0 153 102 0
-17 4 0 153 102 0
-3 4 0 153 102 0
-18 3 0 153 102 0
-2 3 0 153 102 0
-19 2 0 153 102 0
-1 2 0 153 102 0
-20 1 0 153 102 0
0 1 0 153 102 0
1 0 0 153 102 0
2 -1 0 153 102 0
3 -2 0 153 102 0
4 -3 0 153 102 0
-18 -20 0 153 102 0
-2 -20 0 153 102 0
-19 -19 0 153 102 0
-1 -19 0 153 102 0
-20 -18 0 153 102 0
0 -18 0 153 102 0
1 -17 0 153 102 0
2 -16 0 153 102 0
3 -15 0 153 102 0
4 -14 0 153 102 0
-18 4 0 153 102 0
-2 4 0 153 102 0
-19 3 0 153 102 0
-1 3 0 153 102 0
-20 2 0 153 102 0
0 2 0 153 102 0
1 1 0 153 102 0
2 0 0 153 102 0
3 -1 0 153 102 0
4 -2 0 153 102 0
-19 -20 0 153 102 0
-1 -20 0 153 102 0
-20 -19 0 153 102 0
0 -19 0 153 102 0
1 -18 0 153 102 0
2 -17 0 153 102 0
3 -16 0 153 102 0
4 -15 0 153 102 0
-19 4 0 153 102 0
-1 4 0 153 102 0
-20 3 0 153 102 0
0 3 0 153 102 0
1 2 0 153 102 0
2 1 0 153 102 0
3 0 0 153 102 0
4 -1 0 153 102 0
-20 -20 0 153 102 0
0 -20 0 153 102 0
1 -19 0 153 102 0
2 -18 0 153 102 0
3 -17 0 153 102 0
4 -16 0 153 102 0
-20 4 0 153 102 0
0 4 0 153 102 0
1 3 0 153 102 0
2 2 0 153 102 0
3 1 0 153 102 0
4 0 0 153 102 0
1 -20 0 153 102 0
2 -19 0 153 102 0
3 -18 0 153 102 0
4 -17 0 153 102 0
1 4 0 153 102 0
2 3 0 153 102 0
3 2 0 153 102 0
4 1 0 153 102 0
2 -20 0 153 102 0
3 -19 0 153 102 0
4 -18 0 153 102 0
2 4 0 153 102 0
3 3 0 153 102 0
4 2 0 153 102 0
3 -20 0 153 102 0
4 -19 0 153 102 0
3 4 0 153 102 0
4 3 0 153 102 0
4 -20 0 153 102 0
4 4 0 153 102 0
-20 -16 1 51 102 255
-19 -16 1 51 102 255
-20 -15 2 51 102 255
-20 -14 3 51 102 255
-19 -15 2 51 102 255
-19 -14 3 51 102 255
-20 -13 4 51 102 255
-19 -13 4 51 102 255
-20 -12 5 51 102 255
-19 -12 5 51 102 255
-20 -11 6 51 102 255
-19 -11 6 51 102 255
-18 -11 6 51 102 255
-18 -12 5 51 102 255
-18 -13 4 51 102 255
-18 -14 3 51 102 255
-18 -15 2 51 102 255
-18 -16 1 51 102 255
-20 -10 6 51 102 255
-19 -10 6 51 102 255
-18 -10 6 51 102 255
-18 -9 6 51 102 255
-18 -8 6 51 102 255
-18 -7 6 51 102 255
-18 -6 6 51 102 255
-18 -5 6 51 102 255
-18 -4 6 51 102 255
-18 -3 6 51 102 255
-19 -9 6 51 102 255
-19 -8 6 51 102 255
-19 -7 6 51 102 255
-19 -6 6 51 102 255
-19 -5 6 51 102 255
-19 -4 6 51 102 255
-19 -3 6 51 102 255
-20 -9 6 51 102 255
-20 -8 6 51 102 255
-20 -7 6 51 102 255
-20 -6 6 51 102 255
-20 -5 6 51 102 255
-20 -4 6 51 102 255
-20 -3 6 51 102 255
-17 -7 6 51 102 255
-16 -7 6 51 102 255
-15 -7 6 51 102 255
-14 -7 6 51 102 255
-13 -7 6 51 102 255
-12 -7 6 51 102 255
-11 -7 6 51 102 255
-10 -7 6 51 102 255
-9 -7 6 51 102 255
-8 -7 6 51 102 255
-17 -8 6 51 102 255
-16 -8 6 51 102 255
-15 -8 6 51 102 255
-14 -8 6 51 102 255
-13 -8 6 51 102 255
-12 -8 6 51 102 255
-11 -8 6 51 102 255
-10 -8 6 51 102 255
-9 -8 6 51 102 255
-8 -8 6 51 102 255
-17 -6 6 51 102 255
-16 -6 6 51 102 255
-15 -6 6 51 102 255
-14 -6 6 51 102 255
-13 -6 6 51 102 255
-12 -6 6 51 102 255
-11 -6 6 51 102 255
-10 -6 6 51 102 255
-9 -6 6 51 102 255
-8 -6 6 51 102 255
-17 -9 6 51 102 255
-16 -9 6 51 102 255
-15 -9 6 51 102 255
-14 -9 6 51 102 255
-13 -9 6 51 102 255
-12 -9 6 51 102 255
-11 -9 6 51 102 255
-10 -9 6 51 102 255
-9 -9 6 51 102 255
-8 -9 6 51 102 255
-17 -5 6 51 102 255
-16 -5 6 51 102 255
-15 -5 6 51 102 255
-14 -5 6 51 102 255
-13 -5 6 51 102 255
-12 -5 6 51 102 255
-11 -5 6 51 102 255
-10 -5 6 51 102 255
-9 -5 6 51 102 255
-8 -5 6 51 102 255
-17 -10 6 51 102 255
-16 -10 6 51 102 255
-15 -10 6 51 102 255
-14 -10 6 51 102 255
-13 -10 6 51 102 255
-12 -10 6 51 102 255
-11 -10 6 51 102 255
-10 -10 6 51 102 255
-9 -10 6 51 102 255
-8 -10 6 51 102 255
-17 -4 6 51 102 255
-16 -4 6 51 102 255
-15 -4 6 51 102 255
-14 -4 6 51 102 255
-13 -4 6 51 102 255
-12 -4 6 51 102 255
-11 -4 6 51 102 255
-10 -4 6 51 102 255
-9 -4 6 51 102 255
-8 -4 6 51 102 255
-17 -11 6 51 102 255
-16 -11 6 51 102 255
-15 -11 6 51 102 255
-14 -11 6 51 102 255
-13 -11 6 51 102 255
-12 -11 6 51 102 255
-11 -11 6 51 102 255
-10 -11 6 51 102 255
-9 -11 6 51 102 255
-8 -11 6 51 102 255
-17 -3 6 51 102 255
-16 -3 6 51 102 255
-15 -3 6 51 102 255
-14 -3 6 51 102 255
-13 -3 6 51 102 255
-12 -3 6 51 102 255
-11 -3 6 51 102 255
-10 -3 6 51 102 255
-9 -3 6 51 102 255
-8 -3 6 51 102 255
-8 -2 6 51 102 255
-10 -2 6 51 102 255
-9 -2 6 51 102 255
-8 -1 7 51 102 255
-9 -1 7 51 102 255
-10 -1 7 51 102 255
-10 0 8 51 102 255
-9 0 8 51 102 255
-8 0 8 51 102 255
-10 1 9 51 102 255
-9 1 9 51 102 255
-8 1 9 51 102 255
-10 2 10 51 102 255
-9 2 10 51 102 255
-8 2 10 51 102 255
-8 4 10 51 102 255
-9 4 10 51 102 255
-10 4 10 51 102 255
-7 4 10 51 102 255
-6 4 10 51 102 255
-5 4 10 51 102 255
-4 4 10 51 102 255
-3 4 10 51 102 255
-2 4 10 51 102 255
-1 4 10 51 102 255
0 4 10 51 102 255
1 4 10 51 102 255
2 4 10 51 102 255
3 4 10 51 102 255
4 4 10 51 102 255
-7 3 10 51 102 255
-6 3 10 51 102 255
-5 3 10 51 102 255
-4 3 10 51 102 255
-3 3 10 51 102 255
-2 3 10 51 102 255
-1 3 10 51 102 255
0 3 10 51 102 255
1 3 10 51 102 255
2 3 10 51 102 255
3 3 10 51 102 255
4 3 10 51 102 255
-7 2 10 51 102 255
-6 2 10 51 102 255
-5 2 10 51 102 255
-4 2 10 51 102 255
-3 2 10 51 102 255
-2 2 10 51 102 255
-1 2 10 51 102 255
0 2 10 51 102 255
1 2 10 51 102 255
2 2 10 51 102 255
3 2 10 51 102 255
4 2 10 51 102 255
4 1 10 51 102 255
3 1 10 51 102 255
-3 1 10 51 102 255
-2 1 10 51 102 255
-1 1 10 51 102 255
0 1 10 51 102 255
1 1 10 51 102 255
2 1 10 51 102 255
-8 3 10 51 102 255
3 -6 10 51 102 255
3 -5 10 51 102 255
3 -4 10 51 102 255
3 -3 10 51 102 255
3 -2 10 51 102 255
3 -1 10 51 102 255
3 0 10 51 102 255
-9 3 10 51 102 255
2 -6 10 51 102 255
2 -5 10 51 102 255
2 -4 10 51 102 255
2 -3 10 51 102 255
2 -2 10 51 102 255
2 -1 10 51 102 255
2 0 10 51 102 255
-10 3 10 51 102 255
4 -6 10 51 102 255
4 -5 10 51 102 255
4 -4 10 51 102 255
4 -3 10 51 102 255
4 -2 10 51 102 255
4 -1 10 51 102 255
4 0 10 51 102 255
-3 0 10 51 102 255
1 -6 10 51 102 255
1 -5 10 51 102 255
1 -4 10 51 102 255
1 -3 10 51 102 255
1 -2 10 51 102 255
1 -1 10 51 102 255
1 0 10 51 102 255
-3 -1 10 51 102 255
0 -6 10 51 102 255
0 -5 10 51 102 255
0 -4 10 51 102 255
0 -3 10 51 102 255
0 -2 10 51 102 255
0 -1 10 51 102 255
0 0 10 51 102 255
-3 -2 10 51 102 255
-1 -6 10 51 102 255
-1 -5 10 51 102 255
-1 -4 10 51 102 255
-1 -3 10 51 102 255
-1 -2 10 51 102 255
-1 -1 10 51 102 255
-1 0 10 51 102 255
-3 -3 10 51 102 255
-2 -6 10 51 102 255
-2 -5 10 51 102 255
-2 -4 10 51 102 255
-2 -3 10 51 102 255
-2 -2 10 51 102 255
-2 -1 10 51 102 255
-2 0 10 51 102 255
-3 -4 10 51 102 255
-3 -6 10 51 102 255
-3 -5 10 51 102 255
-3 -7 10 51 102 255
-2 -7 10 51 102 255
-1 -7 10 51 102 255
0 -7 10 51 102 255
1 -7 10 51 102 255
2 -7 10 51 102 255
3 -7 10 51 102 255
4 -7 10 51 102 255
-3 -8 11 51 102 255
-2 -8 11 51 102 255
-1 -8 11 51 102 255
0 -8 11 51 102 255
1 -8 11 51 102 255
2 -8 11 51 102 255
3 -8 11 51 102 255
4 -8 11 51 102 255
-3 -9 12 51 102 255
-2 -9 12 51 102 255
-1 -9 12 51 102 255
0 -9 12 51 102 255
1 -9 12 51 102 255
2 -9 12 51 102 255
3 -9 12 51 102 255
4 -9 12 51 102 255
-3 -10 13 51 102 255
-2 -10 13 51 102 255
-1 -10 13 51 102 255
0 -10 13 51 102 255
1 -10 13 51 102 255
2 -10 13 51 102 255
3 -10 13 51 102 255
4 -10 13 51 102 255
