ply
format ascii 1.0
comment : MagicaVoxel @ Ephtracy
element vertex 554
property float x
property float y
property float z
property uchar red
property uchar green
property uchar blue
end_header
1 1 20 153 102 51
2 6 20 153 102 51
2 1 20 153 102 51
11 2 22 153 102 51
3 6 20 153 102 51
3 1 20 153 102 51
12 3 22 153 102 51
4 6 20 153 102 51
4 1 20 153 102 51
1 0 20 153 102 51
5 1 20 153 102 51
12 1 22 153 102 51
6 1 20 153 102 51
0 2 20 153 102 51
13 2 22 153 102 51
1 2 20 153 102 51
12 2 22 153 102 51
2 0 20 153 102 51
2 2 20 153 102 51
10 2 22 153 102 51
8 19 32 0 102 0
10 3 22 153 102 51
5 6 20 153 102 51
10 5 22 153 102 51
1 6 20 153 102 51
7 19 32 0 102 0
10 1 22 153 102 51
6 19 32 0 102 0
10 4 22 153 102 51
5 19 32 0 102 0
11 3 22 153 102 51
0 6 20 153 102 51
4 19 32 0 102 0
3 19 32 0 102 0
2 19 32 0 102 0
11 5 22 153 102 51
1 19 32 0 102 0
10 0 22 153 102 51
6 5 20 153 102 51
11 1 22 153 102 51
0 6 21 0 102 0
0 19 32 0 102 0
11 4 22 153 102 51
8 18 32 0 102 0
3 2 20 153 102 51
7 18 32 0 102 0
12 5 22 153 102 51
5 5 20 153 102 51
11 0 22 153 102 51
0 5 21 0 102 0
3 0 20 153 102 51
0 0 20 153 102 51
6 18 32 0 102 0
12 4 22 153 102 51
4 2 20 153 102 51
19 5 22 153 102 51
4 5 20 153 102 51
5 18 32 0 102 0
1 6 21 0 102 0
0 4 21 0 102 0
1 5 21 0 102 0
4 18 32 0 102 0
13 5 22 153 102 51
3 18 32 0 102 0
0 1 20 153 102 51
2 18 32 255 255 153
12 0 22 153 102 51
3 5 20 153 102 51
19 4 22 153 102 51
6 6 21 0 102 0
1 18 32 0 102 0
6 13 32 0 102 0
0 18 32 0 102 0
5 2 20 153 102 51
6 2 20 153 102 51
13 4 22 153 102 51
6 6 20 153 102 51
18 5 22 153 102 51
2 5 20 153 102 51
14 5 22 153 102 51
0 3 21 0 102 0
19 0 22 153 102 51
1 4 21 0 102 0
4 1 21 0 102 0
6 5 21 0 102 0
8 17 32 0 102 0
7 17 32 0 102 0
6 17 32 0 102 0
13 0 22 153 102 51
5 17 32 0 102 0
4 17 32 0 102 0
3 17 32 255 255 153
0 3 20 153 102 51
7 13 32 0 102 0
19 3 22 153 102 51
5 6 21 0 102 0
13 3 22 153 102 51
8 13 32 0 102 0
4 0 21 0 102 0
18 4 22 153 102 51
1 3 20 153 102 51
14 4 22 153 102 51
4 6 21 0 102 0
17 5 22 153 102 51
1 5 20 153 102 51
15 5 22 153 102 51
0 2 21 0 102 0
2 3 20 153 102 51
1 3 21 0 102 0
19 1 22 153 102 51
6 4 21 0 102 0
3 3 20 153 102 51
6 14 32 0 102 0
2 17 32 255 255 0
13 1 22 153 102 51
1 17 32 255 255 153
4 3 20 153 102 51
0 17 32 0 102 0
8 16 32 0 102 0
7 16 32 0 102 0
18 0 22 153 102 51
6 16 32 0 102 0
5 3 20 153 102 51
5 5 21 0 102 0
14 0 22 153 102 51
7 14 32 0 102 0
19 2 22 153 102 51
8 14 32 0 102 0
6 3 20 153 102 51
4 0 20 153 102 51
0 4 20 153 102 51
18 3 22 153 102 51
1 4 20 153 102 51
14 3 22 153 102 51
0 5 20 153 102 51
17 4 22 153 102 51
0 0 21 0 102 0
15 4 22 153 102 51
0 1 21 0 102 0
5 16 32 0 102 0
1 2 21 0 102 0
16 5 22 153 102 51
6 3 21 0 102 0
6 0 20 153 102 51
3 5 21 0 102 0
4 16 32 0 102 0
18 1 22 153 102 51
3 16 32 0 102 0
14 1 22 153 102 51
2 16 32 255 255 153
1 16 32 0 102 0
0 16 32 0 102 0
8 15 32 0 102 0
7 15 32 0 102 0
6 15 32 0 102 0
5 15 32 0 102 0
4 15 32 0 102 0
5 4 21 0 102 0
3 15 32 0 102 0
13 10 31 153 102 51
2 15 32 0 102 0
12 9 31 153 102 51
3 1 21 0 102 0
5 1 21 0 102 0
2 4 20 153 102 51
17 0 22 153 102 51
1 15 32 0 102 0
15 0 22 153 102 51
0 15 32 0 102 0
18 2 22 153 102 51
1 0 21 0 102 0
14 2 22 153 102 51
1 1 21 0 102 0
17 3 22 153 102 51
6 2 21 0 102 0
18 17 27 0 102 0
3 6 21 0 102 0
17 17 27 51 153 255
5 3 21 0 102 0
15 3 22 153 102 51
2 5 21 0 102 0
16 4 22 153 102 51
16 17 27 0 102 0
17 1 22 153 102 51
18 16 27 51 153 255
17 16 27 0 51 255
16 16 27 51 153 255
3 17 31 153 102 51
18 15 27 0 102 0
15 1 22 153 102 51
17 15 27 51 153 255
6 0 21 0 102 0
16 15 27 0 102 0
16 0 22 153 102 51
2 0 21 0 102 0
3 4 20 153 102 51
6 1 21 0 102 0
13 18 26 153 102 51
2 1 21 0 102 0
5 0 20 153 102 51
14 11 26 153 102 51
15 12 26 153 102 51
17 2 22 153 102 51
15 10 26 153 102 51
15 2 22 153 102 51
4 4 20 153 102 51
16 3 22 153 102 51
13 13 26 153 102 51
16 1 22 153 102 51
5 2 21 0 102 0
16 2 22 153 102 51
2 6 21 0 102 0
19 5 23 0 102 0
4 5 21 0 102 0
18 5 23 0 102 0
5 0 21 0 102 0
17 5 23 0 102 0
3 0 21 0 102 0
5 4 20 153 102 51
6 4 20 153 102 51
14 12 26 153 102 51
13 17 26 153 102 51
14 18 26 153 102 51
15 11 26 153 102 51
16 10 26 153 102 51
13 14 26 153 102 51
14 13 26 153 102 51
13 16 26 153 102 51
14 17 26 153 102 51
15 18 26 153 102 51
16 11 26 153 102 51
19 10 26 153 102 51
17 10 26 153 102 51
13 15 26 153 102 51
14 14 26 153 102 51
14 16 26 153 102 51
15 17 26 153 102 51
16 18 26 153 102 51
19 11 26 153 102 51
17 11 26 153 102 51
18 10 26 153 102 51
14 15 26 153 102 51
15 14 26 153 102 51
15 16 26 153 102 51
16 17 26 153 102 51
19 18 26 153 102 51
17 18 26 153 102 51
19 12 26 153 102 51
17 12 26 153 102 51
18 11 26 153 102 51
15 15 26 153 102 51
10 0 23 0 102 0
11 0 23 0 102 0
12 0 23 0 102 0
13 0 23 0 102 0
14 0 23 0 102 0
15 0 23 0 102 0
16 0 23 0 102 0
17 0 23 0 102 0
18 0 23 0 102 0
19 0 23 0 102 0
10 1 23 0 102 0
11 1 23 0 102 0
12 1 23 255 51 102
13 1 23 0 102 0
14 1 23 0 102 0
15 1 23 0 102 0
16 1 23 0 102 0
17 1 23 0 102 0
18 1 23 0 102 0
19 1 23 0 102 0
10 2 23 0 102 0
11 2 23 255 51 102
12 2 23 255 0 0
13 2 23 255 51 102
14 2 23 0 102 0
15 2 23 0 102 0
16 2 23 0 102 0
17 2 23 0 102 0
18 2 23 0 102 0
19 2 23 0 102 0
10 3 23 0 102 0
11 3 23 0 102 0
12 3 23 255 51 102
13 3 23 0 102 0
14 3 23 0 102 0
15 3 23 0 102 0
16 3 23 0 102 0
17 3 23 0 102 0
18 3 23 0 102 0
19 3 23 0 102 0
10 4 23 0 102 0
11 4 23 0 102 0
12 4 23 0 102 0
13 4 23 0 102 0
14 4 23 0 102 0
15 4 23 0 102 0
16 4 23 0 102 0
17 4 23 0 102 0
18 4 23 0 102 0
19 4 23 0 102 0
10 5 23 0 102 0
11 5 23 0 102 0
12 5 23 0 102 0
13 5 23 0 102 0
14 5 23 0 102 0
15 5 23 0 102 0
16 5 23 0 102 0
13 10 27 0 102 0
14 10 27 0 102 0
15 10 27 0 102 0
16 10 27 0 102 0
17 10 27 0 102 0
18 10 27 0 102 0
19 10 27 0 102 0
13 11 27 0 102 0
14 11 27 0 102 0
15 11 27 0 102 0
16 11 27 0 102 0
17 11 27 0 102 0
18 11 27 0 102 0
19 11 27 0 102 0
13 12 27 0 102 0
14 12 27 0 102 0
16 12 26 153 102 51
15 13 26 153 102 51
16 14 26 153 102 51
18 12 27 0 102 0
19 12 27 0 102 0
13 13 27 0 102 0
14 13 27 0 102 0
16 13 26 153 102 51
17 13 26 153 102 51
13 10 26 153 102 51
18 13 27 0 102 0
19 13 27 0 102 0
13 14 27 0 102 0
14 14 27 0 102 0
13 11 26 153 102 51
14 10 26 153 102 51
13 12 26 153 102 51
18 14 27 0 102 0
19 14 27 0 102 0
13 15 27 0 102 0
14 15 27 0 102 0
15 15 27 0 102 0
17 14 27 0 102 0
15 14 27 0 102 0
17 12 27 0 102 0
19 15 27 0 102 0
13 16 27 0 102 0
14 16 27 0 102 0
15 16 27 0 102 0
15 12 27 0 102 0
17 13 27 0 102 0
15 13 27 0 102 0
19 16 27 0 102 0
13 17 27 0 102 0
14 17 27 0 102 0
15 17 27 0 102 0
16 14 27 0 102 0
16 12 27 0 102 0
16 13 27 0 102 0
19 17 27 0 102 0
13 18 27 0 102 0
14 18 27 0 102 0
15 18 27 0 102 0
16 18 27 0 102 0
17 18 27 0 102 0
18 18 27 0 102 0
19 18 27 0 102 0
17 5 24 0 102 0
18 5 24 0 102 0
4 4 21 0 102 0
17 6 24 0 102 0
18 6 24 0 102 0
2 3 21 204 0 255
17 6 25 0 102 0
18 6 25 0 102 0
3 4 21 204 0 255
17 7 25 0 102 0
18 7 25 0 102 0
3 3 21 204 0 153
17 7 26 0 102 0
18 7 26 0 102 0
2 4 21 0 102 0
17 8 26 0 102 0
18 8 26 0 102 0
4 3 21 204 0 255
17 8 27 0 102 0
18 8 27 0 102 0
3 2 21 204 0 255
17 9 27 0 102 0
18 9 27 0 102 0
4 2 21 0 102 0
18 15 26 153 102 51
18 14 26 153 102 51
18 16 26 153 102 51
17 15 26 153 102 51
19 15 26 153 102 51
18 13 26 153 102 51
17 14 26 153 102 51
19 14 26 153 102 51
18 17 26 153 102 51
17 16 26 153 102 51
19 16 26 153 102 51
16 15 26 153 102 51
18 12 26 153 102 51
19 13 26 153 102 51
18 18 26 153 102 51
17 17 26 153 102 51
19 17 26 153 102 51
16 16 26 153 102 51
6 8 32 0 102 0
7 8 32 0 102 0
8 8 32 0 102 0
9 8 32 0 102 0
10 8 32 0 102 0
11 8 32 0 102 0
12 8 32 0 102 0
13 8 32 0 102 0
14 8 32 0 102 0
6 9 32 0 102 0
7 9 32 0 102 0
8 9 32 0 102 0
9 9 32 0 102 0
10 9 32 0 102 0
11 9 32 0 102 0
12 9 32 51 204 51
13 9 32 0 102 0
14 9 32 0 102 0
6 10 32 0 102 0
7 10 32 0 102 0
8 10 32 0 102 0
9 10 32 0 102 0
10 10 32 0 102 0
11 10 32 51 204 51
12 10 32 51 255 0
13 10 32 51 204 51
14 10 32 0 102 0
6 11 32 0 102 0
7 11 32 0 102 0
8 11 32 0 102 0
9 11 32 0 102 0
10 11 32 0 102 0
11 11 32 0 102 0
12 11 32 51 204 51
13 11 32 0 102 0
14 11 32 0 102 0
6 12 32 0 102 0
7 12 32 0 102 0
8 12 32 0 102 0
9 12 32 0 102 0
10 12 32 0 102 0
11 12 32 0 102 0
12 12 32 0 102 0
13 12 32 0 102 0
14 12 32 0 102 0
5 17 31 153 102 51
5 16 31 153 102 51
5 18 31 153 102 51
4 17 31 153 102 51
6 17 31 153 102 51
5 15 31 153 102 51
4 16 31 153 102 51
6 16 31 153 102 51
5 19 31 153 102 51
4 18 31 153 102 51
6 18 31 153 102 51
7 17 31 153 102 51
4 15 31 153 102 51
6 15 31 153 102 51
3 16 31 153 102 51
7 16 31 153 102 51
4 19 31 153 102 51
6 19 31 153 102 51
3 18 31 153 102 51
7 18 31 153 102 51
8 17 31 153 102 51
3 15 31 153 102 51
7 15 31 153 102 51
8 16 31 153 102 51
3 19 31 153 102 51
7 19 31 153 102 51
8 18 31 153 102 51
2 15 31 153 102 51
8 15 31 153 102 51
2 19 31 153 102 51
8 19 31 153 102 51
1 15 31 153 102 51
1 19 31 153 102 51
1 16 31 153 102 51
0 15 31 153 102 51
1 18 31 153 102 51
0 19 31 153 102 51
0 16 31 153 102 51
0 18 31 153 102 51
0 17 31 153 102 51
7 9 31 153 102 51
7 8 31 153 102 51
7 10 31 153 102 51
6 9 31 153 102 51
8 9 31 153 102 51
6 8 31 153 102 51
8 8 31 153 102 51
7 11 31 153 102 51
6 10 31 153 102 51
8 10 31 153 102 51
9 9 31 153 102 51
9 8 31 153 102 51
7 12 31 153 102 51
6 11 31 153 102 51
8 11 31 153 102 51
9 10 31 153 102 51
10 9 31 153 102 51
10 8 31 153 102 51
6 12 31 153 102 51
8 12 31 153 102 51
9 11 31 153 102 51
10 10 31 153 102 51
11 9 31 153 102 51
11 8 31 153 102 51
9 12 31 153 102 51
10 11 31 153 102 51
12 8 31 153 102 51
10 12 31 153 102 51
11 11 31 153 102 51
13 8 31 153 102 51
11 12 31 153 102 51
13 9 31 153 102 51
14 8 31 153 102 51
12 12 31 153 102 51
14 9 31 153 102 51
13 12 31 153 102 51
14 10 31 153 102 51
13 11 31 153 102 51
14 12 31 153 102 51
14 11 31 153 102 51
12 10 31 153 102 51
11 10 31 153 102 51
12 11 31 153 102 51
2 18 31 153 102 51
1 17 31 153 102 51
2 17 31 153 102 51
2 16 31 153 102 51
2 2 21 0 102 0
16 7 25 0 102 0
16 7 26 0 102 0
16 6 25 0 102 0
16 8 26 0 102 0
16 6 24 0 102 0
16 8 27 0 102 0
16 5 24 0 102 0
16 9 27 0 102 0
