ply
format ascii 1.0
comment : MagicaVoxel @ Ephtracy
element vertex 1140
property float x
property float y
property float z
property uchar red
property uchar green
property uchar blue
end_header
-12 -11 0 255 102 0
-12 -12 0 255 102 0
-12 -10 0 255 102 0
-13 -11 0 255 102 0
-14 -20 0 255 102 0
-12 -13 0 255 102 0
-13 -12 0 255 102 0
-15 -20 1 255 102 0
-12 -9 0 255 102 0
-13 -10 0 255 102 0
-16 -20 2 255 102 0
-14 -11 0 255 102 0
-3 -20 0 255 102 0
-12 -14 0 255 102 0
-13 -13 0 255 102 0
-8 -20 1 255 102 0
-14 -12 0 255 102 0
-7 -20 2 255 102 0
-12 -8 0 255 102 0
-13 -9 0 255 102 0
-13 -20 0 255 102 0
-14 -10 0 255 102 0
-14 -20 1 255 102 0
-15 -11 0 255 102 0
-15 -20 2 255 102 0
-12 -15 0 255 102 0
-13 -14 0 255 102 0
-2 -20 0 255 102 0
-14 -13 0 255 102 0
-2 -20 1 255 102 0
-15 -12 0 255 102 0
-8 -20 2 255 102 0
-12 -7 0 255 102 0
-13 -8 0 255 102 0
-12 -20 0 255 102 0
-14 -9 0 255 102 0
-13 -20 1 255 102 0
-15 -10 0 255 102 0
-14 -20 2 255 102 0
-16 -11 0 255 102 0
-8 -11 0 255 102 0
-12 -16 0 255 102 0
-13 -15 0 255 102 0
-1 -20 2 255 102 0
-14 -14 0 255 102 0
-1 -20 1 255 102 0
-15 -13 0 255 102 0
-20 -20 0 255 102 0
-16 -12 0 255 102 0
-8 -12 0 255 102 0
-12 -6 0 255 102 0
-13 -7 0 255 102 0
-12 -20 1 255 102 0
-14 -8 0 255 102 0
-13 -20 2 255 102 0
-15 -9 0 255 102 0
-19 -20 0 255 102 0
-16 -10 0 255 102 0
-8 -10 0 255 102 0
-17 -11 0 255 102 0
-7 -11 0 255 102 0
-12 -17 0 255 102 0
-13 -16 0 255 102 0
-1 -20 0 255 102 0
-14 -15 0 255 102 0
-12 -20 2 255 102 0
-15 -14 0 255 102 0
-20 -20 1 255 102 0
-16 -13 0 255 102 0
-8 -13 0 255 102 0
-17 -12 0 255 102 0
-7 -12 0 255 102 0
-12 -5 0 255 102 0
-13 -6 0 255 102 0
-5 -17 2 255 102 0
-14 -7 0 255 102 0
-6 -18 2 255 102 0
-15 -8 0 255 102 0
-7 -19 2 255 102 0
-16 -9 0 255 102 0
-8 -9 0 255 102 0
-17 -10 0 255 102 0
-7 -10 0 255 102 0
-18 -11 0 255 102 0
-6 -11 0 255 102 0
-12 -18 0 255 102 0
-13 -17 0 255 102 0
-7 -20 0 255 102 0
-14 -16 0 255 102 0
-4 -16 2 255 102 0
-15 -15 0 255 102 0
-1 -8 2 255 102 0
-16 -14 0 255 102 0
-8 -14 0 255 102 0
-17 -13 0 255 102 0
-7 -13 0 255 102 0
-18 -12 0 255 102 0
-6 -12 0 255 102 0
-12 -4 0 255 102 0
-13 -5 0 255 102 0
-2 -7 2 255 102 0
-14 -6 0 255 102 0
-3 -6 2 255 102 0
-15 -7 0 255 102 0
-4 -5 2 255 102 0
-16 -8 0 255 102 0
-8 -8 0 255 102 0
-17 -9 0 255 102 0
-7 -9 0 255 102 0
-18 -10 0 255 102 0
-6 -10 0 255 102 0
-19 -11 0 255 102 0
-5 -11 0 255 102 0
-12 -19 0 255 102 0
-13 -18 0 255 102 0
-17 -20 0 255 102 0
-14 -17 0 255 102 0
-6 -20 1 255 102 0
-15 -16 0 255 102 0
-5 -4 2 255 102 0
-16 -15 0 255 102 0
-8 -15 0 255 102 0
-17 -14 0 255 102 0
-7 -14 0 255 102 0
-18 -13 0 255 102 0
-6 -13 0 255 102 0
-19 -12 0 255 102 0
-5 -12 0 255 102 0
-12 -3 0 255 102 0
-13 -4 0 255 102 0
-6 -3 2 255 102 0
-14 -5 0 255 102 0
-7 -2 2 255 102 0
-15 -6 0 255 102 0
-8 -1 2 255 102 0
-16 -7 0 255 102 0
-8 -7 0 255 102 0
-17 -8 0 255 102 0
-7 -8 0 255 102 0
-18 -9 0 255 102 0
-6 -9 0 255 102 0
-19 -10 0 255 102 0
-5 -10 0 255 102 0
-20 -11 0 255 102 0
-4 -11 0 255 102 0
-1 -1 2 255 102 0
-13 -19 0 255 102 0
-4 -20 0 255 102 0
-14 -18 0 255 102 0
-18 -20 1 255 102 0
-15 -17 0 255 102 0
-5 -20 2 255 102 0
-16 -16 0 255 102 0
-8 -16 0 255 102 0
-17 -15 0 255 102 0
-7 -15 0 255 102 0
-18 -14 0 255 102 0
-6 -14 0 255 102 0
-19 -13 0 255 102 0
-5 -13 0 255 102 0
-20 -12 0 255 102 0
-4 -12 0 255 102 0
-12 -2 0 255 102 0
-13 -3 0 255 102 0
-1 -12 2 255 102 0
-14 -4 0 255 102 0
-2 -13 2 255 102 0
-15 -5 0 255 102 0
-3 -14 2 255 102 0
-16 -6 0 255 102 0
-8 -6 0 255 102 0
-17 -7 0 255 102 0
-7 -7 0 255 102 0
-18 -8 0 255 102 0
-6 -8 0 255 102 0
-19 -9 0 255 102 0
-5 -9 0 255 102 0
-20 -10 0 255 102 0
-4 -10 0 255 102 0
-3 -11 0 255 102 0
-1 -19 2 255 102 0
-1 -2 2 255 102 0
-14 -19 0 255 102 0
-3 -20 1 255 102 0
-15 -18 0 255 102 0
-19 -20 2 255 102 0
-16 -17 0 255 102 0
-8 -17 0 255 102 0
-17 -16 0 255 102 0
-7 -16 0 255 102 0
-18 -15 0 255 102 0
-6 -15 0 255 102 0
-19 -14 0 255 102 0
-5 -14 0 255 102 0
-20 -13 0 255 102 0
-4 -13 0 255 102 0
-3 -12 0 255 102 0
-12 -1 0 255 102 0
-13 -2 0 255 102 0
-4 -15 2 255 102 0
-14 -3 0 255 102 0
-5 -16 2 255 102 0
-15 -4 0 255 102 0
-6 -17 2 255 102 0
-16 -5 0 255 102 0
-8 -5 0 255 102 0
-17 -6 0 255 102 0
-7 -6 0 255 102 0
-18 -7 0 255 102 0
-6 -7 0 255 102 0
-19 -8 0 255 102 0
-5 -8 0 255 102 0
-20 -9 0 255 102 0
-4 -9 0 255 102 0
-3 -10 0 255 102 0
-2 -11 0 255 102 0
-2 -1 2 255 102 0
-1 -18 2 255 102 0
-15 -19 0 255 102 0
-2 -20 2 255 102 0
-16 -18 0 255 102 0
-8 -18 0 255 102 0
-17 -17 0 255 102 0
-7 -17 0 255 102 0
-18 -16 0 255 102 0
-6 -16 0 255 102 0
-19 -15 0 255 102 0
-5 -15 0 255 102 0
-20 -14 0 255 102 0
-4 -14 0 255 102 0
-3 -13 0 255 102 0
-2 -12 0 255 102 0
-13 -1 0 255 102 0
-7 -18 2 255 102 0
-14 -2 0 255 102 0
-8 -19 2 255 102 0
-15 -3 0 255 102 0
-3 -15 2 255 102 0
-16 -4 0 255 102 0
-8 -4 0 255 102 0
-17 -5 0 255 102 0
-7 -5 0 255 102 0
-18 -6 0 255 102 0
-6 -6 0 255 102 0
-19 -7 0 255 102 0
-5 -7 0 255 102 0
-20 -8 0 255 102 0
-4 -8 0 255 102 0
-3 -9 0 255 102 0
-2 -10 0 255 102 0
-1 -11 0 255 102 0
-2 -19 2 255 102 0
-1 -3 2 255 102 0
-16 -19 0 255 102 0
-8 -19 0 255 102 0
-17 -18 0 255 102 0
-7 -18 0 255 102 0
-18 -17 0 255 102 0
-6 -17 0 255 102 0
-19 -16 0 255 102 0
-5 -16 0 255 102 0
-20 -15 0 255 102 0
-4 -15 0 255 102 0
-3 -14 0 255 102 0
-2 -13 0 255 102 0
-1 -12 0 255 102 0
-14 -1 0 255 102 0
-1 -9 2 255 102 0
-15 -2 0 255 102 0
-2 -8 2 255 102 0
-16 -3 0 255 102 0
-8 -3 0 255 102 0
-17 -4 0 255 102 0
-7 -4 0 255 102 0
-18 -5 0 255 102 0
-6 -5 0 255 102 0
-19 -6 0 255 102 0
-5 -6 0 255 102 0
-20 -7 0 255 102 0
-4 -7 0 255 102 0
-3 -8 0 255 102 0
-2 -9 0 255 102 0
-1 -10 0 255 102 0
-2 -2 2 255 102 0
-3 -1 2 255 102 0
-17 -19 0 255 102 0
-7 -19 0 255 102 0
-18 -18 0 255 102 0
-6 -18 0 255 102 0
-19 -17 0 255 102 0
-5 -17 0 255 102 0
-20 -16 0 255 102 0
-4 -16 0 255 102 0
-3 -15 0 255 102 0
-2 -14 0 255 102 0
-1 -13 0 255 102 0
-15 -1 0 255 102 0
-3 -7 2 255 102 0
-16 -2 0 255 102 0
-8 -2 0 255 102 0
-17 -3 0 255 102 0
-7 -3 0 255 102 0
-18 -4 0 255 102 0
-6 -4 0 255 102 0
-19 -5 0 255 102 0
-5 -5 0 255 102 0
-20 -6 0 255 102 0
-4 -6 0 255 102 0
-3 -7 0 255 102 0
-2 -8 0 255 102 0
-1 -9 0 255 102 0
-1 -17 2 255 102 0
-2 -18 2 255 102 0
-18 -19 0 255 102 0
-6 -19 0 255 102 0
-19 -18 0 255 102 0
-5 -18 0 255 102 0
-20 -17 0 255 102 0
-4 -17 0 255 102 0
-3 -16 0 255 102 0
-2 -15 0 255 102 0
-1 -14 0 255 102 0
-16 -1 0 255 102 0
-8 -1 0 255 102 0
-17 -2 0 255 102 0
-7 -2 0 255 102 0
-18 -3 0 255 102 0
-6 -3 0 255 102 0
-19 -4 0 255 102 0
-5 -4 0 255 102 0
-20 -5 0 255 102 0
-4 -5 0 255 102 0
-3 -6 0 255 102 0
-2 -7 0 255 102 0
-1 -8 0 255 102 0
-3 -19 2 255 102 0
-1 -4 2 255 102 0
-19 -19 0 255 102 0
-5 -19 0 255 102 0
-20 -18 0 255 102 0
-4 -18 0 255 102 0
-3 -17 0 255 102 0
-2 -16 0 255 102 0
-1 -15 0 255 102 0
-17 -1 0 255 102 0
-7 -1 0 255 102 0
-18 -2 0 255 102 0
-6 -2 0 255 102 0
-19 -3 0 255 102 0
-5 -3 0 255 102 0
-20 -4 0 255 102 0
-4 -4 0 255 102 0
-3 -5 0 255 102 0
-2 -6 0 255 102 0
-1 -7 0 255 102 0
-2 -3 2 255 102 0
-3 -2 2 255 102 0
-20 -19 0 255 102 0
-4 -19 0 255 102 0
-3 -18 0 255 102 0
-2 -17 0 255 102 0
-1 -16 0 255 102 0
-18 -1 0 255 102 0
-6 -1 0 255 102 0
-19 -2 0 255 102 0
-5 -2 0 255 102 0
-20 -3 0 255 102 0
-4 -3 0 255 102 0
-3 -4 0 255 102 0
-2 -5 0 255 102 0
-1 -6 0 255 102 0
-4 -1 2 255 102 0
-1 -16 2 255 102 0
-3 -19 0 255 102 0
-2 -18 0 255 102 0
-1 -17 0 255 102 0
-19 -1 0 255 102 0
-5 -1 0 255 102 0
-20 -2 0 255 102 0
-4 -2 0 255 102 0
-3 -3 0 255 102 0
-2 -4 0 255 102 0
-1 -5 0 255 102 0
-2 -17 2 255 102 0
-2 -19 0 255 102 0
-1 -18 0 255 102 0
-20 -1 0 255 102 0
-4 -1 0 255 102 0
-3 -2 0 255 102 0
-2 -3 0 255 102 0
-1 -4 0 255 102 0
-3 -18 2 255 102 0
-1 -19 0 255 102 0
-3 -1 0 255 102 0
-2 -2 0 255 102 0
-1 -3 0 255 102 0
-4 -19 2 255 102 0
-2 -1 0 255 102 0
-1 -2 0 255 102 0
-1 -1 0 255 102 0
-4 -6 2 255 102 0
-5 -5 2 255 102 0
-6 -4 2 255 102 0
-7 -3 2 255 102 0
-8 -2 2 255 102 0
-1 -11 2 255 102 0
-2 -12 2 255 102 0
-3 -13 2 255 102 0
-4 -14 2 255 102 0
-5 -15 2 255 102 0
-6 -16 2 255 102 0
-12 -10 1 255 102 0
-8 -10 1 255 102 0
-7 -17 2 255 102 0
-8 -18 2 255 102 0
-3 -20 2 255 102 0
-12 -11 1 255 102 0
-8 -11 1 255 102 0
-2 -14 2 255 102 0
-1 -10 2 255 102 0
-2 -9 2 255 102 0
-12 -9 1 255 102 0
-8 -9 1 255 102 0
-13 -10 1 255 102 0
-7 -10 1 255 102 0
-3 -8 2 255 102 0
-4 -7 2 255 102 0
-5 -6 2 255 102 0
-12 -12 1 255 102 0
-8 -12 1 255 102 0
-13 -11 1 255 102 0
-7 -11 1 255 102 0
-6 -5 2 255 102 0
-7 -4 2 255 102 0
-8 -3 2 255 102 0
-12 -8 1 255 102 0
-8 -8 1 255 102 0
-13 -9 1 255 102 0
-7 -9 1 255 102 0
-14 -10 1 255 102 0
-6 -10 1 255 102 0
-2 -11 2 255 102 0
-3 -12 2 255 102 0
-4 -13 2 255 102 0
-12 -13 1 255 102 0
-8 -13 1 255 102 0
-13 -12 1 255 102 0
-7 -12 1 255 102 0
-14 -11 1 255 102 0
-6 -11 1 255 102 0
-5 -14 2 255 102 0
-6 -15 2 255 102 0
-7 -16 2 255 102 0
-12 -7 1 255 102 0
-8 -7 1 255 102 0
-13 -8 1 255 102 0
-7 -8 1 255 102 0
-14 -9 1 255 102 0
-6 -9 1 255 102 0
-15 -10 1 255 102 0
-5 -10 1 255 102 0
-8 -17 2 255 102 0
-18 -20 2 255 102 0
-4 -20 1 255 102 0
-12 -14 1 255 102 0
-8 -14 1 255 102 0
-13 -13 1 255 102 0
-7 -13 1 255 102 0
-14 -12 1 255 102 0
-6 -12 1 255 102 0
-15 -11 1 255 102 0
-5 -11 1 255 102 0
-1 -13 2 255 102 0
-2 -10 2 255 102 0
-3 -9 2 255 102 0
-12 -6 1 255 102 0
-8 -6 1 255 102 0
-13 -7 1 255 102 0
-7 -7 1 255 102 0
-14 -8 1 255 102 0
-6 -8 1 255 102 0
-15 -9 1 255 102 0
-5 -9 1 255 102 0
-16 -10 1 255 102 0
-4 -10 1 255 102 0
-15 -20 0 255 102 0
-4 -8 2 255 102 0
-5 -7 2 255 102 0
-12 -15 1 255 102 0
-8 -15 1 255 102 0
-13 -14 1 255 102 0
-7 -14 1 255 102 0
-14 -13 1 255 102 0
-6 -13 1 255 102 0
-15 -12 1 255 102 0
-5 -12 1 255 102 0
-16 -11 1 255 102 0
-4 -11 1 255 102 0
-6 -6 2 255 102 0
-7 -5 2 255 102 0
-8 -4 2 255 102 0
-12 -5 1 255 102 0
-8 -5 1 255 102 0
-13 -6 1 255 102 0
-7 -6 1 255 102 0
-14 -7 1 255 102 0
-6 -7 1 255 102 0
-15 -8 1 255 102 0
-5 -8 1 255 102 0
-16 -9 1 255 102 0
-4 -9 1 255 102 0
-17 -10 1 255 102 0
-3 -10 1 255 102 0
-6 -20 0 255 102 0
-16 -20 1 255 102 0
-17 -20 2 255 102 0
-12 -16 1 255 102 0
-8 -16 1 255 102 0
-13 -15 1 255 102 0
-7 -15 1 255 102 0
-14 -14 1 255 102 0
-6 -14 1 255 102 0
-15 -13 1 255 102 0
-5 -13 1 255 102 0
-16 -12 1 255 102 0
-4 -12 1 255 102 0
-17 -11 1 255 102 0
-3 -11 1 255 102 0
-3 -11 2 255 102 0
-4 -12 2 255 102 0
-5 -13 2 255 102 0
-12 -4 1 255 102 0
-8 -4 1 255 102 0
-13 -5 1 255 102 0
-7 -5 1 255 102 0
-14 -6 1 255 102 0
-6 -6 1 255 102 0
-15 -7 1 255 102 0
-5 -7 1 255 102 0
-16 -8 1 255 102 0
-4 -8 1 255 102 0
-17 -9 1 255 102 0
-3 -9 1 255 102 0
-18 -10 1 255 102 0
-2 -10 1 255 102 0
-18 -20 0 255 102 0
-5 -20 1 255 102 0
-4 -20 2 255 102 0
-12 -17 1 255 102 0
-8 -17 1 255 102 0
-13 -16 1 255 102 0
-7 -16 1 255 102 0
-14 -15 1 255 102 0
-6 -15 1 255 102 0
-15 -14 1 255 102 0
-5 -14 1 255 102 0
-16 -13 1 255 102 0
-4 -13 1 255 102 0
-17 -12 1 255 102 0
-3 -12 1 255 102 0
-18 -11 1 255 102 0
-2 -11 1 255 102 0
-6 -14 2 255 102 0
-7 -15 2 255 102 0
-8 -16 2 255 102 0
-12 -3 1 255 102 0
-8 -3 1 255 102 0
-13 -4 1 255 102 0
-7 -4 1 255 102 0
-14 -5 1 255 102 0
-6 -5 1 255 102 0
-15 -6 1 255 102 0
-5 -6 1 255 102 0
-16 -7 1 255 102 0
-4 -7 1 255 102 0
-17 -8 1 255 102 0
-3 -8 1 255 102 0
-18 -9 1 255 102 0
-2 -9 1 255 102 0
-19 -10 1 255 102 0
-1 -10 1 255 102 0
-1 -5 2 255 102 0
-19 -20 1 255 102 0
-20 -20 2 255 102 0
-12 -18 1 255 102 0
-8 -18 1 255 102 0
-13 -17 1 255 102 0
-7 -17 1 255 102 0
-14 -16 1 255 102 0
-6 -16 1 255 102 0
-15 -15 1 255 102 0
-5 -15 1 255 102 0
-16 -14 1 255 102 0
-4 -14 1 255 102 0
-17 -13 1 255 102 0
-3 -13 1 255 102 0
-18 -12 1 255 102 0
-2 -12 1 255 102 0
-19 -11 1 255 102 0
-1 -11 1 255 102 0
-6 -20 2 255 102 0
-17 -20 1 255 102 0
-12 -2 1 255 102 0
-8 -2 1 255 102 0
-13 -3 1 255 102 0
-7 -3 1 255 102 0
-14 -4 1 255 102 0
-6 -4 1 255 102 0
-15 -5 1 255 102 0
-5 -5 1 255 102 0
-16 -6 1 255 102 0
-4 -6 1 255 102 0
-17 -7 1 255 102 0
-3 -7 1 255 102 0
-18 -8 1 255 102 0
-2 -8 1 255 102 0
-19 -9 1 255 102 0
-1 -9 1 255 102 0
-20 -10 1 255 102 0
-2 -4 2 255 102 0
-3 -3 2 255 102 0
-12 -19 1 255 102 0
-8 -19 1 255 102 0
-13 -18 1 255 102 0
-7 -18 1 255 102 0
-14 -17 1 255 102 0
-6 -17 1 255 102 0
-15 -16 1 255 102 0
-5 -16 1 255 102 0
-16 -15 1 255 102 0
-4 -15 1 255 102 0
-17 -14 1 255 102 0
-3 -14 1 255 102 0
-18 -13 1 255 102 0
-2 -13 1 255 102 0
-19 -12 1 255 102 0
-1 -12 1 255 102 0
-20 -11 1 255 102 0
-12 -1 1 255 102 0
-8 -1 1 255 102 0
-13 -2 1 255 102 0
-7 -2 1 255 102 0
-14 -3 1 255 102 0
-6 -3 1 255 102 0
-15 -4 1 255 102 0
-5 -4 1 255 102 0
-16 -5 1 255 102 0
-4 -5 1 255 102 0
-17 -6 1 255 102 0
-3 -6 1 255 102 0
-18 -7 1 255 102 0
-2 -7 1 255 102 0
-19 -8 1 255 102 0
-1 -8 1 255 102 0
-20 -9 1 255 102 0
-4 -2 2 255 102 0
-5 -1 2 255 102 0
-13 -19 1 255 102 0
-7 -19 1 255 102 0
-14 -18 1 255 102 0
-6 -18 1 255 102 0
-15 -17 1 255 102 0
-5 -17 1 255 102 0
-16 -16 1 255 102 0
-4 -16 1 255 102 0
-17 -15 1 255 102 0
-3 -15 1 255 102 0
-18 -14 1 255 102 0
-2 -14 1 255 102 0
-19 -13 1 255 102 0
-1 -13 1 255 102 0
-20 -12 1 255 102 0
-13 -1 1 255 102 0
-7 -1 1 255 102 0
-14 -2 1 255 102 0
-6 -2 1 255 102 0
-15 -3 1 255 102 0
-5 -3 1 255 102 0
-16 -4 1 255 102 0
-4 -4 1 255 102 0
-17 -5 1 255 102 0
-3 -5 1 255 102 0
-18 -6 1 255 102 0
-2 -6 1 255 102 0
-19 -7 1 255 102 0
-1 -7 1 255 102 0
-20 -8 1 255 102 0
-1 -15 2 255 102 0
-2 -16 2 255 102 0
-14 -19 1 255 102 0
-6 -19 1 255 102 0
-15 -18 1 255 102 0
-5 -18 1 255 102 0
-16 -17 1 255 102 0
-4 -17 1 255 102 0
-17 -16 1 255 102 0
-3 -16 1 255 102 0
-18 -15 1 255 102 0
-2 -15 1 255 102 0
-19 -14 1 255 102 0
-1 -14 1 255 102 0
-20 -13 1 255 102 0
-14 -1 1 255 102 0
-6 -1 1 255 102 0
-15 -2 1 255 102 0
-5 -2 1 255 102 0
-16 -3 1 255 102 0
-4 -3 1 255 102 0
-17 -4 1 255 102 0
-3 -4 1 255 102 0
-18 -5 1 255 102 0
-2 -5 1 255 102 0
-19 -6 1 255 102 0
-1 -6 1 255 102 0
-20 -7 1 255 102 0
-3 -17 2 255 102 0
-4 -18 2 255 102 0
-15 -19 1 255 102 0
-5 -19 1 255 102 0
-16 -18 1 255 102 0
-4 -18 1 255 102 0
-17 -17 1 255 102 0
-3 -17 1 255 102 0
-18 -16 1 255 102 0
-2 -16 1 255 102 0
-19 -15 1 255 102 0
-1 -15 1 255 102 0
-20 -14 1 255 102 0
-15 -1 1 255 102 0
-5 -1 1 255 102 0
-16 -2 1 255 102 0
-4 -2 1 255 102 0
-17 -3 1 255 102 0
-3 -3 1 255 102 0
-18 -4 1 255 102 0
-2 -4 1 255 102 0
-19 -5 1 255 102 0
-1 -5 1 255 102 0
-20 -6 1 255 102 0
-5 -19 2 255 102 0
-1 -6 2 255 102 0
-16 -19 1 255 102 0
-4 -19 1 255 102 0
-17 -18 1 255 102 0
-3 -18 1 255 102 0
-18 -17 1 255 102 0
-2 -17 1 255 102 0
-19 -16 1 255 102 0
-1 -16 1 255 102 0
-20 -15 1 255 102 0
-16 -1 1 255 102 0
-4 -1 1 255 102 0
-17 -2 1 255 102 0
-3 -2 1 255 102 0
-18 -3 1 255 102 0
-2 -3 1 255 102 0
-19 -4 1 255 102 0
-1 -4 1 255 102 0
-20 -5 1 255 102 0
-2 -5 2 255 102 0
-3 -4 2 255 102 0
-17 -19 1 255 102 0
-3 -19 1 255 102 0
-18 -18 1 255 102 0
-2 -18 1 255 102 0
-19 -17 1 255 102 0
-1 -17 1 255 102 0
-20 -16 1 255 102 0
-17 -1 1 255 102 0
-3 -1 1 255 102 0
-18 -2 1 255 102 0
-2 -2 1 255 102 0
-19 -3 1 255 102 0
-1 -3 1 255 102 0
-20 -4 1 255 102 0
-4 -3 2 255 102 0
-5 -2 2 255 102 0
-18 -19 1 255 102 0
-2 -19 1 255 102 0
-19 -18 1 255 102 0
-1 -18 1 255 102 0
-20 -17 1 255 102 0
-18 -1 1 255 102 0
-2 -1 1 255 102 0
-19 -2 1 255 102 0
-1 -2 1 255 102 0
-20 -3 1 255 102 0
-6 -1 2 255 102 0
-1 -14 2 255 102 0
-19 -19 1 255 102 0
-1 -19 1 255 102 0
-20 -18 1 255 102 0
-19 -1 1 255 102 0
-1 -1 1 255 102 0
-20 -2 1 255 102 0
-2 -15 2 255 102 0
-3 -16 2 255 102 0
-20 -19 1 255 102 0
-20 -1 1 255 102 0
-4 -17 2 255 102 0
-18 -10 2 255 102 0
-18 -11 2 255 102 0
-18 -9 2 255 102 0
-19 -10 2 255 102 0
-17 -10 2 255 102 0
-18 -12 2 255 102 0
-19 -11 2 255 102 0
-17 -11 2 255 102 0
-18 -8 2 255 102 0
-19 -9 2 255 102 0
-17 -9 2 255 102 0
-20 -10 2 255 102 0
-16 -10 2 255 102 0
-18 -13 2 255 102 0
-19 -12 2 255 102 0
-17 -12 2 255 102 0
-20 -11 2 255 102 0
-16 -11 2 255 102 0
-18 -7 2 255 102 0
-19 -8 2 255 102 0
-17 -8 2 255 102 0
-20 -9 2 255 102 0
-16 -9 2 255 102 0
-15 -10 2 255 102 0
-18 -14 2 255 102 0
-19 -13 2 255 102 0
-17 -13 2 255 102 0
-20 -12 2 255 102 0
-16 -12 2 255 102 0
-15 -11 2 255 102 0
-18 -6 2 255 102 0
-19 -7 2 255 102 0
-17 -7 2 255 102 0
-20 -8 2 255 102 0
-16 -8 2 255 102 0
-15 -9 2 255 102 0
-14 -10 2 255 102 0
-18 -15 2 255 102 0
-19 -14 2 255 102 0
-17 -14 2 255 102 0
-20 -13 2 255 102 0
-16 -13 2 255 102 0
-15 -12 2 255 0 204
-14 -11 2 255 102 0
-18 -5 2 255 102 0
-19 -6 2 255 102 0
-17 -6 2 255 102 0
-20 -7 2 255 102 0
-16 -7 2 255 102 0
-15 -8 2 255 102 0
-14 -9 2 255 102 0
-13 -10 2 255 102 0
-18 -16 2 255 102 0
-19 -15 2 255 102 0
-17 -15 2 255 102 0
-20 -14 2 255 102 0
-16 -14 2 255 102 0
-15 -13 2 255 102 0
-14 -12 2 255 102 0
-13 -11 2 255 102 0
-18 -4 2 255 102 0
-19 -5 2 255 102 0
-17 -5 2 255 102 0
-20 -6 2 255 102 0
-16 -6 2 255 102 0
-15 -7 2 255 102 0
-14 -8 2 255 102 0
-13 -9 2 255 102 0
-12 -10 2 255 102 0
-18 -17 2 255 102 0
-19 -16 2 255 102 0
-17 -16 2 255 102 0
-20 -15 2 255 102 0
-16 -15 2 255 102 0
-15 -14 2 255 102 0
-14 -13 2 255 102 0
-13 -12 2 255 102 0
-12 -11 2 255 102 0
-18 -3 2 255 102 0
-19 -4 2 255 102 0
-17 -4 2 255 102 0
-20 -5 2 255 102 0
-16 -5 2 255 102 0
-15 -6 2 255 102 0
-14 -7 2 255 102 0
-13 -8 2 255 102 0
-12 -9 2 255 102 0
-5 -20 0 255 102 0
-18 -18 2 255 102 0
-19 -17 2 255 102 0
-17 -17 2 255 102 0
-20 -16 2 255 102 0
-16 -16 2 255 102 0
-15 -15 2 255 102 0
-14 -14 2 255 102 0
-13 -13 2 255 102 0
-12 -12 2 255 102 0
-7 -1 2 255 102 0
-18 -2 2 255 102 0
-19 -3 2 255 102 0
-17 -3 2 255 102 0
-20 -4 2 255 102 0
-16 -4 2 255 102 0
-15 -5 2 255 102 0
-14 -6 2 255 102 0
-13 -7 2 255 102 0
-12 -8 2 255 102 0
-3 -10 2 255 102 0
-4 -9 2 255 102 0
-18 -19 2 255 102 0
-19 -18 2 255 102 0
-17 -18 2 255 102 0
-20 -17 2 255 102 0
-16 -17 2 255 102 0
-15 -16 2 255 102 0
-14 -15 2 255 102 0
-13 -14 2 255 102 0
-12 -13 2 255 102 0
-5 -8 2 255 102 0
-6 -7 2 255 102 0
-18 -1 2 255 102 0
-19 -2 2 255 102 0
-17 -2 2 255 102 0
-20 -3 2 255 102 0
-16 -3 2 255 102 0
-15 -4 2 255 102 0
-14 -5 2 255 102 0
-13 -6 2 255 102 0
-12 -7 2 255 102 0
-7 -6 2 255 102 0
-8 -5 2 255 102 0
-12 -1 2 255 102 0
-5 -18 2 255 102 0
-19 -19 2 255 102 0
-17 -19 2 255 102 0
-20 -18 2 255 102 0
-16 -18 2 255 102 0
-15 -17 2 255 102 0
-14 -16 2 255 102 0
-13 -15 2 255 102 0
-12 -14 2 255 102 0
-4 -11 2 255 102 0
-5 -12 2 255 102 0
-6 -13 2 255 102 0
-19 -1 2 255 102 0
-17 -1 2 255 102 0
-20 -2 2 255 102 0
-16 -2 2 255 102 0
-15 -3 2 255 102 0
-14 -4 2 255 102 0
-13 -5 2 255 102 0
-12 -6 2 255 102 0
-7 -14 2 255 102 0
-8 -15 2 255 102 0
-7 -20 1 255 102 0
-8 -10 2 255 102 0
-6 -19 2 255 102 0
-1 -7 2 255 102 0
-20 -19 2 255 102 0
-16 -19 2 255 102 0
-15 -18 2 255 102 0
-14 -17 2 255 102 0
-13 -16 2 255 102 0
-12 -15 2 255 102 0
-16 -20 0 255 102 0
-12 -19 2 255 102 0
-6 -2 2 255 102 0
-8 -11 2 255 102 0
-20 -1 2 255 102 0
-16 -1 2 255 102 0
-15 -2 2 255 102 0
-14 -3 2 255 102 0
-13 -4 2 255 102 0
-12 -5 2 255 102 0
-4 -10 2 255 102 0
-5 -9 2 255 102 0
-6 -8 2 255 102 0
-8 -9 2 255 102 0
-7 -10 2 255 102 0
-2 -6 2 255 102 0
-3 -5 2 255 102 0
-15 -19 2 255 102 0
-14 -18 2 255 102 0
-13 -17 2 255 102 0
-12 -16 2 255 102 0
-7 -7 2 255 102 0
-8 -6 2 255 102 0
-12 -2 2 255 102 0
-8 -12 2 255 102 0
-7 -11 2 255 102 0
-15 -1 2 255 102 0
-14 -2 2 255 102 0
-13 -3 2 255 102 0
-12 -4 2 255 102 0
-13 -1 2 255 102 0
-5 -11 2 255 102 0
-6 -12 2 255 102 0
-8 -8 2 255 102 0
-7 -9 2 255 102 0
-6 -10 2 255 102 0
-4 -4 2 255 102 0
-14 -19 2 255 102 0
-13 -18 2 255 102 0
-12 -17 2 255 102 0
-7 -13 2 255 102 0
-8 -14 2 255 102 0
-8 -20 0 255 102 0
-8 -13 2 255 102 0
-7 -12 2 255 102 0
-6 -11 2 255 102 0
-14 -1 2 255 102 0
-13 -2 2 255 102 0
-12 -3 2 255 102 0
-12 -18 2 255 102 0
-13 -19 2 255 102 0
-5 -3 2 255 102 0
-8 -7 2 255 102 0
-7 -8 2 255 102 0
-6 -9 2 255 102 0
-5 -10 2 255 102 0
-10 -17 0 51 0 204
-10 -18 0 51 0 204
-10 -16 0 51 0 204
-11 -17 0 51 0 204
-9 -17 0 51 0 204
-10 -19 0 51 0 204
-11 -18 0 51 0 204
-9 -18 0 51 0 204
-10 -15 0 51 0 204
-11 -16 0 51 0 204
-9 -16 0 51 0 204
-10 -20 0 51 0 204
-11 -19 0 51 0 204
-9 -19 0 51 0 204
-10 -14 0 51 0 204
-11 -15 0 51 0 204
-9 -15 0 51 0 204
-11 -20 0 51 0 204
-9 -20 0 51 0 204
-10 -13 0 51 0 204
-11 -14 0 51 0 204
-9 -14 0 51 0 204
-10 -12 0 51 0 204
-11 -13 0 51 0 204
-9 -13 0 51 0 204
-10 -11 0 51 0 204
-11 -12 0 51 0 204
-9 -12 0 51 0 204
-10 -10 0 51 0 204
-11 -11 0 51 0 204
-9 -11 0 51 0 204
-10 -9 0 51 0 204
-11 -10 0 51 0 204
-9 -10 0 51 0 204
-10 -8 0 51 0 204
-11 -9 0 51 0 204
-9 -9 0 51 0 204
-10 -7 0 51 0 204
-11 -8 0 51 0 204
-9 -8 0 51 0 204
-10 -6 0 51 0 204
-11 -7 0 51 0 204
-9 -7 0 51 0 204
-10 -5 0 51 0 204
-11 -6 0 51 0 204
-9 -6 0 51 0 204
-10 -4 0 51 0 204
-11 -5 0 51 0 204
-9 -5 0 51 0 204
-10 -3 0 51 0 204
-11 -4 0 51 0 204
-9 -4 0 51 0 204
-10 -2 0 51 0 204
-11 -3 0 51 0 204
-9 -3 0 51 0 204
-10 -1 0 51 0 204
-11 -2 0 51 0 204
-9 -2 0 51 0 204
-11 -1 0 51 0 204
-9 -1 0 51 0 204
-10 -19 1 51 0 204
-10 -20 1 51 0 204
-10 -18 1 51 0 204
-11 -19 1 51 0 204
-9 -19 1 51 0 204
-11 -20 1 51 0 204
-9 -20 1 51 0 204
-10 -17 1 51 0 204
-11 -18 1 51 0 204
-9 -18 1 51 0 204
-10 -16 1 51 0 204
-11 -17 1 51 0 204
-9 -17 1 51 0 204
-10 -15 1 51 0 204
-11 -16 1 51 0 204
-9 -16 1 51 0 204
-10 -14 1 51 0 204
-11 -15 1 51 0 204
-9 -15 1 51 0 204
-10 -13 1 51 0 204
-11 -14 1 51 0 204
-9 -14 1 51 0 204
-10 -12 1 51 0 204
-11 -13 1 51 0 204
-9 -13 1 51 0 204
-10 -11 1 51 0 204
-11 -12 1 51 0 204
-9 -12 1 51 0 204
-10 -10 1 51 0 204
-11 -11 1 51 0 204
-9 -11 1 51 0 204
-10 -9 1 51 0 204
-11 -10 1 51 0 204
-9 -10 1 51 0 204
-10 -8 1 51 0 204
-11 -9 1 51 0 204
-9 -9 1 51 0 204
-10 -7 1 51 0 204
-11 -8 1 51 0 204
-9 -8 1 51 0 204
-10 -6 1 51 0 204
-11 -7 1 51 0 204
-9 -7 1 51 0 204
-10 -5 1 51 0 204
-11 -6 1 51 0 204
-9 -6 1 51 0 204
-10 -4 1 51 0 204
-11 -5 1 51 0 204
-9 -5 1 51 0 204
-10 -3 1 51 0 204
-11 -4 1 51 0 204
-9 -4 1 51 0 204
-10 -2 1 51 0 204
-11 -3 1 51 0 204
-9 -3 1 51 0 204
-10 -1 1 51 0 204
-11 -2 1 51 0 204
-9 -2 1 51 0 204
-11 -1 1 51 0 204
-9 -1 1 51 0 204
